2025-06-22 16:16:19 INFO Using LLM api key #AIzaSyARJfdVOsI9AKUK6gxvUszL_bn5Z_lr5Wg)
2025-06-22 16:16:19 INFO Using LLM api key #AIzaSyCK6miE77n6z7PUf0RNgj8seMiiVET-wqk)
2025-06-22 16:16:19 INFO Using LLM api key #AIzaSyCK6miE77n6z7PUf0RNgj8seMiiVET-wqk)
2025-06-22 16:26:12 INFO An exception occured: Traceback (most recent call last):
  File "/Users/macbook/miniconda3/envs/eoh/lib/python3.12/site-packages/google/api_core/grpc_helpers.py", line 76, in error_remapped_callable
    return callable_(*args, **kwargs)
           ^^^^^^^^^^^^^^^^^^^^^^^^^^
  File "/Users/macbook/miniconda3/envs/eoh/lib/python3.12/site-packages/grpc/_interceptor.py", line 277, in __call__
    response, ignored_call = self._with_call(
                             ^^^^^^^^^^^^^^^^
  File "/Users/macbook/miniconda3/envs/eoh/lib/python3.12/site-packages/grpc/_interceptor.py", line 332, in _with_call
    return call.result(), call
           ^^^^^^^^^^^^^
  File "/Users/macbook/miniconda3/envs/eoh/lib/python3.12/site-packages/grpc/_channel.py", line 440, in result
    raise self
  File "/Users/macbook/miniconda3/envs/eoh/lib/python3.12/site-packages/grpc/_interceptor.py", line 315, in continuation
    response, call = self._thunk(new_method).with_call(
                     ^^^^^^^^^^^^^^^^^^^^^^^^^^^^^^^^^^
  File "/Users/macbook/miniconda3/envs/eoh/lib/python3.12/site-packages/grpc/_channel.py", line 1198, in with_call
    return _end_unary_response_blocking(state, call, True, None)
           ^^^^^^^^^^^^^^^^^^^^^^^^^^^^^^^^^^^^^^^^^^^^^^^^^^^^^
  File "/Users/macbook/miniconda3/envs/eoh/lib/python3.12/site-packages/grpc/_channel.py", line 1006, in _end_unary_response_blocking
    raise _InactiveRpcError(state)  # pytype: disable=not-instantiable
    ^^^^^^^^^^^^^^^^^^^^^^^^^^^^^^
grpc._channel._InactiveRpcError: <_InactiveRpcError of RPC that terminated with:
	status = StatusCode.UNAVAILABLE
	details = "DNS resolution failed for generativelanguage.googleapis.com:443: C-ares status is not ARES_SUCCESS qtype=SRV name=_grpclb._tcp.generativelanguage.googleapis.com: DNS query cancelled"
	debug_error_string = "UNKNOWN:Error received from peer  {created_time:"2025-06-22T16:26:12.848787+07:00", grpc_status:14, grpc_message:"DNS resolution failed for generativelanguage.googleapis.com:443: C-ares status is not ARES_SUCCESS qtype=SRV name=_grpclb._tcp.generativelanguage.googleapis.com: DNS query cancelled"}"
>

The above exception was the direct cause of the following exception:

Traceback (most recent call last):
  File "/Users/macbook/miniconda3/envs/eoh/lib/python3.12/site-packages/google/api_core/retry/retry_unary.py", line 147, in retry_target
    result = target()
             ^^^^^^^^
  File "/Users/macbook/miniconda3/envs/eoh/lib/python3.12/site-packages/google/api_core/timeout.py", line 130, in func_with_timeout
    return func(*args, **kwargs)
           ^^^^^^^^^^^^^^^^^^^^^
  File "/Users/macbook/miniconda3/envs/eoh/lib/python3.12/site-packages/google/api_core/grpc_helpers.py", line 78, in error_remapped_callable
    raise exceptions.from_grpc_error(exc) from exc
google.api_core.exceptions.ServiceUnavailable: 503 DNS resolution failed for generativelanguage.googleapis.com:443: C-ares status is not ARES_SUCCESS qtype=SRV name=_grpclb._tcp.generativelanguage.googleapis.com: DNS query cancelled

The above exception was the direct cause of the following exception:

Traceback (most recent call last):
  File "/Users/macbook/Documents/Code/LLMdesignedEA-comp/llamea_with_hs.py", line 158, in initialize_single
    new_individual = chosen_llm.sample_solution(session_messages, role_index=role_index)
                     ^^^^^^^^^^^^^^^^^^^^^^^^^^^^^^^^^^^^^^^^^^^^^^^^^^^^^^^^^^^^^^^^^^^
  File "/Users/macbook/Documents/Code/LLMdesignedEA-comp/llamea/llm.py", line 106, in sample_solution
    message = self.query(session_messages)
              ^^^^^^^^^^^^^^^^^^^^^^^^^^^^
  File "/Users/macbook/Documents/Code/LLMdesignedEA-comp/llamea/llm.py", line 288, in query
    response = chat_session.send_message(last["content"])
               ^^^^^^^^^^^^^^^^^^^^^^^^^^^^^^^^^^^^^^^^^^
  File "/Users/macbook/miniconda3/envs/eoh/lib/python3.12/site-packages/google/generativeai/generative_models.py", line 578, in send_message
    response = self.model.generate_content(
               ^^^^^^^^^^^^^^^^^^^^^^^^^^^^
  File "/Users/macbook/miniconda3/envs/eoh/lib/python3.12/site-packages/google/generativeai/generative_models.py", line 331, in generate_content
    response = self._client.generate_content(
               ^^^^^^^^^^^^^^^^^^^^^^^^^^^^^^
  File "/Users/macbook/miniconda3/envs/eoh/lib/python3.12/site-packages/google/ai/generativelanguage_v1beta/services/generative_service/client.py", line 835, in generate_content
    response = rpc(
               ^^^^
  File "/Users/macbook/miniconda3/envs/eoh/lib/python3.12/site-packages/google/api_core/gapic_v1/method.py", line 131, in __call__
    return wrapped_func(*args, **kwargs)
           ^^^^^^^^^^^^^^^^^^^^^^^^^^^^^
  File "/Users/macbook/miniconda3/envs/eoh/lib/python3.12/site-packages/google/api_core/retry/retry_unary.py", line 294, in retry_wrapped_func
    return retry_target(
           ^^^^^^^^^^^^^
  File "/Users/macbook/miniconda3/envs/eoh/lib/python3.12/site-packages/google/api_core/retry/retry_unary.py", line 156, in retry_target
    next_sleep = _retry_error_helper(
                 ^^^^^^^^^^^^^^^^^^^^
  File "/Users/macbook/miniconda3/envs/eoh/lib/python3.12/site-packages/google/api_core/retry/retry_base.py", line 229, in _retry_error_helper
    raise final_exc from source_exc
google.api_core.exceptions.RetryError: Timeout of 600.0s exceeded, last exception: 503 DNS resolution failed for generativelanguage.googleapis.com:443: C-ares status is not ARES_SUCCESS qtype=SRV name=_grpclb._tcp.generativelanguage.googleapis.com: DNS query cancelled
.
2025-06-22 16:26:12 INFO Using LLM api key #AIzaSyARJfdVOsI9AKUK6gxvUszL_bn5Z_lr5Wg)
2025-06-22 16:26:15 INFO An exception occured: Traceback (most recent call last):
  File "/Users/macbook/miniconda3/envs/eoh/lib/python3.12/site-packages/google/api_core/grpc_helpers.py", line 76, in error_remapped_callable
    return callable_(*args, **kwargs)
           ^^^^^^^^^^^^^^^^^^^^^^^^^^
  File "/Users/macbook/miniconda3/envs/eoh/lib/python3.12/site-packages/grpc/_interceptor.py", line 277, in __call__
    response, ignored_call = self._with_call(
                             ^^^^^^^^^^^^^^^^
  File "/Users/macbook/miniconda3/envs/eoh/lib/python3.12/site-packages/grpc/_interceptor.py", line 332, in _with_call
    return call.result(), call
           ^^^^^^^^^^^^^
  File "/Users/macbook/miniconda3/envs/eoh/lib/python3.12/site-packages/grpc/_channel.py", line 440, in result
    raise self
  File "/Users/macbook/miniconda3/envs/eoh/lib/python3.12/site-packages/grpc/_interceptor.py", line 315, in continuation
    response, call = self._thunk(new_method).with_call(
                     ^^^^^^^^^^^^^^^^^^^^^^^^^^^^^^^^^^
  File "/Users/macbook/miniconda3/envs/eoh/lib/python3.12/site-packages/grpc/_channel.py", line 1198, in with_call
    return _end_unary_response_blocking(state, call, True, None)
           ^^^^^^^^^^^^^^^^^^^^^^^^^^^^^^^^^^^^^^^^^^^^^^^^^^^^^
  File "/Users/macbook/miniconda3/envs/eoh/lib/python3.12/site-packages/grpc/_channel.py", line 1006, in _end_unary_response_blocking
    raise _InactiveRpcError(state)  # pytype: disable=not-instantiable
    ^^^^^^^^^^^^^^^^^^^^^^^^^^^^^^
grpc._channel._InactiveRpcError: <_InactiveRpcError of RPC that terminated with:
	status = StatusCode.UNAVAILABLE
	details = "DNS resolution failed for generativelanguage.googleapis.com:443: C-ares status is not ARES_SUCCESS qtype=SRV name=_grpclb._tcp.generativelanguage.googleapis.com: DNS query cancelled"
	debug_error_string = "UNKNOWN:Error received from peer  {created_time:"2025-06-22T16:26:15.483022+07:00", grpc_status:14, grpc_message:"DNS resolution failed for generativelanguage.googleapis.com:443: C-ares status is not ARES_SUCCESS qtype=SRV name=_grpclb._tcp.generativelanguage.googleapis.com: DNS query cancelled"}"
>

The above exception was the direct cause of the following exception:

Traceback (most recent call last):
  File "/Users/macbook/miniconda3/envs/eoh/lib/python3.12/site-packages/google/api_core/retry/retry_unary.py", line 147, in retry_target
    result = target()
             ^^^^^^^^
  File "/Users/macbook/miniconda3/envs/eoh/lib/python3.12/site-packages/google/api_core/timeout.py", line 130, in func_with_timeout
    return func(*args, **kwargs)
           ^^^^^^^^^^^^^^^^^^^^^
  File "/Users/macbook/miniconda3/envs/eoh/lib/python3.12/site-packages/google/api_core/grpc_helpers.py", line 78, in error_remapped_callable
    raise exceptions.from_grpc_error(exc) from exc
google.api_core.exceptions.ServiceUnavailable: 503 DNS resolution failed for generativelanguage.googleapis.com:443: C-ares status is not ARES_SUCCESS qtype=SRV name=_grpclb._tcp.generativelanguage.googleapis.com: DNS query cancelled

The above exception was the direct cause of the following exception:

Traceback (most recent call last):
  File "/Users/macbook/Documents/Code/LLMdesignedEA-comp/llamea_with_hs.py", line 158, in initialize_single
    new_individual = chosen_llm.sample_solution(session_messages, role_index=role_index)
                     ^^^^^^^^^^^^^^^^^^^^^^^^^^^^^^^^^^^^^^^^^^^^^^^^^^^^^^^^^^^^^^^^^^^
  File "/Users/macbook/Documents/Code/LLMdesignedEA-comp/llamea/llm.py", line 106, in sample_solution
    message = self.query(session_messages)
              ^^^^^^^^^^^^^^^^^^^^^^^^^^^^
  File "/Users/macbook/Documents/Code/LLMdesignedEA-comp/llamea/llm.py", line 288, in query
    response = chat_session.send_message(last["content"])
               ^^^^^^^^^^^^^^^^^^^^^^^^^^^^^^^^^^^^^^^^^^
  File "/Users/macbook/miniconda3/envs/eoh/lib/python3.12/site-packages/google/generativeai/generative_models.py", line 578, in send_message
    response = self.model.generate_content(
               ^^^^^^^^^^^^^^^^^^^^^^^^^^^^
  File "/Users/macbook/miniconda3/envs/eoh/lib/python3.12/site-packages/google/generativeai/generative_models.py", line 331, in generate_content
    response = self._client.generate_content(
               ^^^^^^^^^^^^^^^^^^^^^^^^^^^^^^
  File "/Users/macbook/miniconda3/envs/eoh/lib/python3.12/site-packages/google/ai/generativelanguage_v1beta/services/generative_service/client.py", line 835, in generate_content
    response = rpc(
               ^^^^
  File "/Users/macbook/miniconda3/envs/eoh/lib/python3.12/site-packages/google/api_core/gapic_v1/method.py", line 131, in __call__
    return wrapped_func(*args, **kwargs)
           ^^^^^^^^^^^^^^^^^^^^^^^^^^^^^
  File "/Users/macbook/miniconda3/envs/eoh/lib/python3.12/site-packages/google/api_core/retry/retry_unary.py", line 294, in retry_wrapped_func
    return retry_target(
           ^^^^^^^^^^^^^
  File "/Users/macbook/miniconda3/envs/eoh/lib/python3.12/site-packages/google/api_core/retry/retry_unary.py", line 156, in retry_target
    next_sleep = _retry_error_helper(
                 ^^^^^^^^^^^^^^^^^^^^
  File "/Users/macbook/miniconda3/envs/eoh/lib/python3.12/site-packages/google/api_core/retry/retry_base.py", line 229, in _retry_error_helper
    raise final_exc from source_exc
google.api_core.exceptions.RetryError: Timeout of 600.0s exceeded, last exception: 503 DNS resolution failed for generativelanguage.googleapis.com:443: C-ares status is not ARES_SUCCESS qtype=SRV name=_grpclb._tcp.generativelanguage.googleapis.com: DNS query cancelled
.
2025-06-22 16:26:15 INFO Using LLM api key #AIzaSyCK6miE77n6z7PUf0RNgj8seMiiVET-wqk)
2025-06-22 16:26:19 INFO An exception occured: Traceback (most recent call last):
  File "/Users/macbook/miniconda3/envs/eoh/lib/python3.12/site-packages/google/api_core/grpc_helpers.py", line 76, in error_remapped_callable
    return callable_(*args, **kwargs)
           ^^^^^^^^^^^^^^^^^^^^^^^^^^
  File "/Users/macbook/miniconda3/envs/eoh/lib/python3.12/site-packages/grpc/_interceptor.py", line 277, in __call__
    response, ignored_call = self._with_call(
                             ^^^^^^^^^^^^^^^^
  File "/Users/macbook/miniconda3/envs/eoh/lib/python3.12/site-packages/grpc/_interceptor.py", line 332, in _with_call
    return call.result(), call
           ^^^^^^^^^^^^^
  File "/Users/macbook/miniconda3/envs/eoh/lib/python3.12/site-packages/grpc/_channel.py", line 440, in result
    raise self
  File "/Users/macbook/miniconda3/envs/eoh/lib/python3.12/site-packages/grpc/_interceptor.py", line 315, in continuation
    response, call = self._thunk(new_method).with_call(
                     ^^^^^^^^^^^^^^^^^^^^^^^^^^^^^^^^^^
  File "/Users/macbook/miniconda3/envs/eoh/lib/python3.12/site-packages/grpc/_channel.py", line 1198, in with_call
    return _end_unary_response_blocking(state, call, True, None)
           ^^^^^^^^^^^^^^^^^^^^^^^^^^^^^^^^^^^^^^^^^^^^^^^^^^^^^
  File "/Users/macbook/miniconda3/envs/eoh/lib/python3.12/site-packages/grpc/_channel.py", line 1006, in _end_unary_response_blocking
    raise _InactiveRpcError(state)  # pytype: disable=not-instantiable
    ^^^^^^^^^^^^^^^^^^^^^^^^^^^^^^
grpc._channel._InactiveRpcError: <_InactiveRpcError of RPC that terminated with:
	status = StatusCode.UNAVAILABLE
	details = "DNS resolution failed for generativelanguage.googleapis.com:443: C-ares status is not ARES_SUCCESS qtype=SRV name=_grpclb._tcp.generativelanguage.googleapis.com: DNS query cancelled"
	debug_error_string = "UNKNOWN:Error received from peer  {grpc_message:"DNS resolution failed for generativelanguage.googleapis.com:443: C-ares status is not ARES_SUCCESS qtype=SRV name=_grpclb._tcp.generativelanguage.googleapis.com: DNS query cancelled", grpc_status:14, created_time:"2025-06-22T16:26:19.768096+07:00"}"
>

The above exception was the direct cause of the following exception:

Traceback (most recent call last):
  File "/Users/macbook/miniconda3/envs/eoh/lib/python3.12/site-packages/google/api_core/retry/retry_unary.py", line 147, in retry_target
    result = target()
             ^^^^^^^^
  File "/Users/macbook/miniconda3/envs/eoh/lib/python3.12/site-packages/google/api_core/timeout.py", line 130, in func_with_timeout
    return func(*args, **kwargs)
           ^^^^^^^^^^^^^^^^^^^^^
  File "/Users/macbook/miniconda3/envs/eoh/lib/python3.12/site-packages/google/api_core/grpc_helpers.py", line 78, in error_remapped_callable
    raise exceptions.from_grpc_error(exc) from exc
google.api_core.exceptions.ServiceUnavailable: 503 DNS resolution failed for generativelanguage.googleapis.com:443: C-ares status is not ARES_SUCCESS qtype=SRV name=_grpclb._tcp.generativelanguage.googleapis.com: DNS query cancelled

The above exception was the direct cause of the following exception:

Traceback (most recent call last):
  File "/Users/macbook/Documents/Code/LLMdesignedEA-comp/llamea_with_hs.py", line 158, in initialize_single
    new_individual = chosen_llm.sample_solution(session_messages, role_index=role_index)
                     ^^^^^^^^^^^^^^^^^^^^^^^^^^^^^^^^^^^^^^^^^^^^^^^^^^^^^^^^^^^^^^^^^^^
  File "/Users/macbook/Documents/Code/LLMdesignedEA-comp/llamea/llm.py", line 106, in sample_solution
    message = self.query(session_messages)
              ^^^^^^^^^^^^^^^^^^^^^^^^^^^^
  File "/Users/macbook/Documents/Code/LLMdesignedEA-comp/llamea/llm.py", line 288, in query
    response = chat_session.send_message(last["content"])
               ^^^^^^^^^^^^^^^^^^^^^^^^^^^^^^^^^^^^^^^^^^
  File "/Users/macbook/miniconda3/envs/eoh/lib/python3.12/site-packages/google/generativeai/generative_models.py", line 578, in send_message
    response = self.model.generate_content(
               ^^^^^^^^^^^^^^^^^^^^^^^^^^^^
  File "/Users/macbook/miniconda3/envs/eoh/lib/python3.12/site-packages/google/generativeai/generative_models.py", line 331, in generate_content
    response = self._client.generate_content(
               ^^^^^^^^^^^^^^^^^^^^^^^^^^^^^^
  File "/Users/macbook/miniconda3/envs/eoh/lib/python3.12/site-packages/google/ai/generativelanguage_v1beta/services/generative_service/client.py", line 835, in generate_content
    response = rpc(
               ^^^^
  File "/Users/macbook/miniconda3/envs/eoh/lib/python3.12/site-packages/google/api_core/gapic_v1/method.py", line 131, in __call__
    return wrapped_func(*args, **kwargs)
           ^^^^^^^^^^^^^^^^^^^^^^^^^^^^^
  File "/Users/macbook/miniconda3/envs/eoh/lib/python3.12/site-packages/google/api_core/retry/retry_unary.py", line 294, in retry_wrapped_func
    return retry_target(
           ^^^^^^^^^^^^^
  File "/Users/macbook/miniconda3/envs/eoh/lib/python3.12/site-packages/google/api_core/retry/retry_unary.py", line 156, in retry_target
    next_sleep = _retry_error_helper(
                 ^^^^^^^^^^^^^^^^^^^^
  File "/Users/macbook/miniconda3/envs/eoh/lib/python3.12/site-packages/google/api_core/retry/retry_base.py", line 229, in _retry_error_helper
    raise final_exc from source_exc
google.api_core.exceptions.RetryError: Timeout of 600.0s exceeded, last exception: 503 DNS resolution failed for generativelanguage.googleapis.com:443: C-ares status is not ARES_SUCCESS qtype=SRV name=_grpclb._tcp.generativelanguage.googleapis.com: DNS query cancelled
.
2025-06-22 16:26:19 INFO Using LLM api key #AIzaSyARJfdVOsI9AKUK6gxvUszL_bn5Z_lr5Wg)
2025-06-22 16:36:07 INFO An exception occured: Traceback (most recent call last):
  File "/Users/macbook/miniconda3/envs/eoh/lib/python3.12/site-packages/google/api_core/grpc_helpers.py", line 76, in error_remapped_callable
    return callable_(*args, **kwargs)
           ^^^^^^^^^^^^^^^^^^^^^^^^^^
  File "/Users/macbook/miniconda3/envs/eoh/lib/python3.12/site-packages/grpc/_interceptor.py", line 277, in __call__
    response, ignored_call = self._with_call(
                             ^^^^^^^^^^^^^^^^
  File "/Users/macbook/miniconda3/envs/eoh/lib/python3.12/site-packages/grpc/_interceptor.py", line 332, in _with_call
    return call.result(), call
           ^^^^^^^^^^^^^
  File "/Users/macbook/miniconda3/envs/eoh/lib/python3.12/site-packages/grpc/_channel.py", line 440, in result
    raise self
  File "/Users/macbook/miniconda3/envs/eoh/lib/python3.12/site-packages/grpc/_interceptor.py", line 315, in continuation
    response, call = self._thunk(new_method).with_call(
                     ^^^^^^^^^^^^^^^^^^^^^^^^^^^^^^^^^^
  File "/Users/macbook/miniconda3/envs/eoh/lib/python3.12/site-packages/grpc/_channel.py", line 1198, in with_call
    return _end_unary_response_blocking(state, call, True, None)
           ^^^^^^^^^^^^^^^^^^^^^^^^^^^^^^^^^^^^^^^^^^^^^^^^^^^^^
  File "/Users/macbook/miniconda3/envs/eoh/lib/python3.12/site-packages/grpc/_channel.py", line 1006, in _end_unary_response_blocking
    raise _InactiveRpcError(state)  # pytype: disable=not-instantiable
    ^^^^^^^^^^^^^^^^^^^^^^^^^^^^^^
grpc._channel._InactiveRpcError: <_InactiveRpcError of RPC that terminated with:
	status = StatusCode.UNAVAILABLE
	details = "DNS resolution failed for generativelanguage.googleapis.com:443: C-ares status is not ARES_SUCCESS qtype=SRV name=_grpclb._tcp.generativelanguage.googleapis.com: DNS query cancelled"
	debug_error_string = "UNKNOWN:Error received from peer  {created_time:"2025-06-22T16:36:07.131454+07:00", grpc_status:14, grpc_message:"DNS resolution failed for generativelanguage.googleapis.com:443: C-ares status is not ARES_SUCCESS qtype=SRV name=_grpclb._tcp.generativelanguage.googleapis.com: DNS query cancelled"}"
>

The above exception was the direct cause of the following exception:

Traceback (most recent call last):
  File "/Users/macbook/miniconda3/envs/eoh/lib/python3.12/site-packages/google/api_core/retry/retry_unary.py", line 147, in retry_target
    result = target()
             ^^^^^^^^
  File "/Users/macbook/miniconda3/envs/eoh/lib/python3.12/site-packages/google/api_core/timeout.py", line 130, in func_with_timeout
    return func(*args, **kwargs)
           ^^^^^^^^^^^^^^^^^^^^^
  File "/Users/macbook/miniconda3/envs/eoh/lib/python3.12/site-packages/google/api_core/grpc_helpers.py", line 78, in error_remapped_callable
    raise exceptions.from_grpc_error(exc) from exc
google.api_core.exceptions.ServiceUnavailable: 503 DNS resolution failed for generativelanguage.googleapis.com:443: C-ares status is not ARES_SUCCESS qtype=SRV name=_grpclb._tcp.generativelanguage.googleapis.com: DNS query cancelled

The above exception was the direct cause of the following exception:

Traceback (most recent call last):
  File "/Users/macbook/Documents/Code/LLMdesignedEA-comp/llamea_with_hs.py", line 158, in initialize_single
    new_individual = chosen_llm.sample_solution(session_messages, role_index=role_index)
                     ^^^^^^^^^^^^^^^^^^^^^^^^^^^^^^^^^^^^^^^^^^^^^^^^^^^^^^^^^^^^^^^^^^^
  File "/Users/macbook/Documents/Code/LLMdesignedEA-comp/llamea/llm.py", line 106, in sample_solution
    message = self.query(session_messages)
              ^^^^^^^^^^^^^^^^^^^^^^^^^^^^
  File "/Users/macbook/Documents/Code/LLMdesignedEA-comp/llamea/llm.py", line 288, in query
    response = chat_session.send_message(last["content"])
               ^^^^^^^^^^^^^^^^^^^^^^^^^^^^^^^^^^^^^^^^^^
  File "/Users/macbook/miniconda3/envs/eoh/lib/python3.12/site-packages/google/generativeai/generative_models.py", line 578, in send_message
    response = self.model.generate_content(
               ^^^^^^^^^^^^^^^^^^^^^^^^^^^^
  File "/Users/macbook/miniconda3/envs/eoh/lib/python3.12/site-packages/google/generativeai/generative_models.py", line 331, in generate_content
    response = self._client.generate_content(
               ^^^^^^^^^^^^^^^^^^^^^^^^^^^^^^
  File "/Users/macbook/miniconda3/envs/eoh/lib/python3.12/site-packages/google/ai/generativelanguage_v1beta/services/generative_service/client.py", line 835, in generate_content
    response = rpc(
               ^^^^
  File "/Users/macbook/miniconda3/envs/eoh/lib/python3.12/site-packages/google/api_core/gapic_v1/method.py", line 131, in __call__
    return wrapped_func(*args, **kwargs)
           ^^^^^^^^^^^^^^^^^^^^^^^^^^^^^
  File "/Users/macbook/miniconda3/envs/eoh/lib/python3.12/site-packages/google/api_core/retry/retry_unary.py", line 294, in retry_wrapped_func
    return retry_target(
           ^^^^^^^^^^^^^
  File "/Users/macbook/miniconda3/envs/eoh/lib/python3.12/site-packages/google/api_core/retry/retry_unary.py", line 156, in retry_target
    next_sleep = _retry_error_helper(
                 ^^^^^^^^^^^^^^^^^^^^
  File "/Users/macbook/miniconda3/envs/eoh/lib/python3.12/site-packages/google/api_core/retry/retry_base.py", line 229, in _retry_error_helper
    raise final_exc from source_exc
google.api_core.exceptions.RetryError: Timeout of 600.0s exceeded, last exception: 503 DNS resolution failed for generativelanguage.googleapis.com:443: C-ares status is not ARES_SUCCESS qtype=SRV name=_grpclb._tcp.generativelanguage.googleapis.com: DNS query cancelled
.
2025-06-22 16:36:07 INFO Using LLM api key #AIzaSyCK6miE77n6z7PUf0RNgj8seMiiVET-wqk)
2025-06-22 16:36:07 INFO An exception occured: Traceback (most recent call last):
  File "/Users/macbook/miniconda3/envs/eoh/lib/python3.12/site-packages/google/api_core/grpc_helpers.py", line 76, in error_remapped_callable
    return callable_(*args, **kwargs)
           ^^^^^^^^^^^^^^^^^^^^^^^^^^
  File "/Users/macbook/miniconda3/envs/eoh/lib/python3.12/site-packages/grpc/_interceptor.py", line 277, in __call__
    response, ignored_call = self._with_call(
                             ^^^^^^^^^^^^^^^^
  File "/Users/macbook/miniconda3/envs/eoh/lib/python3.12/site-packages/grpc/_interceptor.py", line 332, in _with_call
    return call.result(), call
           ^^^^^^^^^^^^^
  File "/Users/macbook/miniconda3/envs/eoh/lib/python3.12/site-packages/grpc/_channel.py", line 440, in result
    raise self
  File "/Users/macbook/miniconda3/envs/eoh/lib/python3.12/site-packages/grpc/_interceptor.py", line 315, in continuation
    response, call = self._thunk(new_method).with_call(
                     ^^^^^^^^^^^^^^^^^^^^^^^^^^^^^^^^^^
  File "/Users/macbook/miniconda3/envs/eoh/lib/python3.12/site-packages/grpc/_channel.py", line 1198, in with_call
    return _end_unary_response_blocking(state, call, True, None)
           ^^^^^^^^^^^^^^^^^^^^^^^^^^^^^^^^^^^^^^^^^^^^^^^^^^^^^
  File "/Users/macbook/miniconda3/envs/eoh/lib/python3.12/site-packages/grpc/_channel.py", line 1006, in _end_unary_response_blocking
    raise _InactiveRpcError(state)  # pytype: disable=not-instantiable
    ^^^^^^^^^^^^^^^^^^^^^^^^^^^^^^
grpc._channel._InactiveRpcError: <_InactiveRpcError of RPC that terminated with:
	status = StatusCode.UNAVAILABLE
	details = "DNS resolution failed for generativelanguage.googleapis.com:443: C-ares status is not ARES_SUCCESS qtype=SRV name=_grpclb._tcp.generativelanguage.googleapis.com: DNS query cancelled"
	debug_error_string = "UNKNOWN:Error received from peer  {grpc_message:"DNS resolution failed for generativelanguage.googleapis.com:443: C-ares status is not ARES_SUCCESS qtype=SRV name=_grpclb._tcp.generativelanguage.googleapis.com: DNS query cancelled", grpc_status:14, created_time:"2025-06-22T16:36:07.945251+07:00"}"
>

The above exception was the direct cause of the following exception:

Traceback (most recent call last):
  File "/Users/macbook/miniconda3/envs/eoh/lib/python3.12/site-packages/google/api_core/retry/retry_unary.py", line 147, in retry_target
    result = target()
             ^^^^^^^^
  File "/Users/macbook/miniconda3/envs/eoh/lib/python3.12/site-packages/google/api_core/timeout.py", line 130, in func_with_timeout
    return func(*args, **kwargs)
           ^^^^^^^^^^^^^^^^^^^^^
  File "/Users/macbook/miniconda3/envs/eoh/lib/python3.12/site-packages/google/api_core/grpc_helpers.py", line 78, in error_remapped_callable
    raise exceptions.from_grpc_error(exc) from exc
google.api_core.exceptions.ServiceUnavailable: 503 DNS resolution failed for generativelanguage.googleapis.com:443: C-ares status is not ARES_SUCCESS qtype=SRV name=_grpclb._tcp.generativelanguage.googleapis.com: DNS query cancelled

The above exception was the direct cause of the following exception:

Traceback (most recent call last):
  File "/Users/macbook/Documents/Code/LLMdesignedEA-comp/llamea_with_hs.py", line 158, in initialize_single
    new_individual = chosen_llm.sample_solution(session_messages, role_index=role_index)
                     ^^^^^^^^^^^^^^^^^^^^^^^^^^^^^^^^^^^^^^^^^^^^^^^^^^^^^^^^^^^^^^^^^^^
  File "/Users/macbook/Documents/Code/LLMdesignedEA-comp/llamea/llm.py", line 106, in sample_solution
    message = self.query(session_messages)
              ^^^^^^^^^^^^^^^^^^^^^^^^^^^^
  File "/Users/macbook/Documents/Code/LLMdesignedEA-comp/llamea/llm.py", line 288, in query
    response = chat_session.send_message(last["content"])
               ^^^^^^^^^^^^^^^^^^^^^^^^^^^^^^^^^^^^^^^^^^
  File "/Users/macbook/miniconda3/envs/eoh/lib/python3.12/site-packages/google/generativeai/generative_models.py", line 578, in send_message
    response = self.model.generate_content(
               ^^^^^^^^^^^^^^^^^^^^^^^^^^^^
  File "/Users/macbook/miniconda3/envs/eoh/lib/python3.12/site-packages/google/generativeai/generative_models.py", line 331, in generate_content
    response = self._client.generate_content(
               ^^^^^^^^^^^^^^^^^^^^^^^^^^^^^^
  File "/Users/macbook/miniconda3/envs/eoh/lib/python3.12/site-packages/google/ai/generativelanguage_v1beta/services/generative_service/client.py", line 835, in generate_content
    response = rpc(
               ^^^^
  File "/Users/macbook/miniconda3/envs/eoh/lib/python3.12/site-packages/google/api_core/gapic_v1/method.py", line 131, in __call__
    return wrapped_func(*args, **kwargs)
           ^^^^^^^^^^^^^^^^^^^^^^^^^^^^^
  File "/Users/macbook/miniconda3/envs/eoh/lib/python3.12/site-packages/google/api_core/retry/retry_unary.py", line 294, in retry_wrapped_func
    return retry_target(
           ^^^^^^^^^^^^^
  File "/Users/macbook/miniconda3/envs/eoh/lib/python3.12/site-packages/google/api_core/retry/retry_unary.py", line 156, in retry_target
    next_sleep = _retry_error_helper(
                 ^^^^^^^^^^^^^^^^^^^^
  File "/Users/macbook/miniconda3/envs/eoh/lib/python3.12/site-packages/google/api_core/retry/retry_base.py", line 229, in _retry_error_helper
    raise final_exc from source_exc
google.api_core.exceptions.RetryError: Timeout of 600.0s exceeded, last exception: 503 DNS resolution failed for generativelanguage.googleapis.com:443: C-ares status is not ARES_SUCCESS qtype=SRV name=_grpclb._tcp.generativelanguage.googleapis.com: DNS query cancelled
.
2025-06-22 16:36:07 INFO Using LLM api key #AIzaSyARJfdVOsI9AKUK6gxvUszL_bn5Z_lr5Wg)
2025-06-22 16:36:15 INFO An exception occured: Traceback (most recent call last):
  File "/Users/macbook/miniconda3/envs/eoh/lib/python3.12/site-packages/google/api_core/grpc_helpers.py", line 76, in error_remapped_callable
    return callable_(*args, **kwargs)
           ^^^^^^^^^^^^^^^^^^^^^^^^^^
  File "/Users/macbook/miniconda3/envs/eoh/lib/python3.12/site-packages/grpc/_interceptor.py", line 277, in __call__
    response, ignored_call = self._with_call(
                             ^^^^^^^^^^^^^^^^
  File "/Users/macbook/miniconda3/envs/eoh/lib/python3.12/site-packages/grpc/_interceptor.py", line 332, in _with_call
    return call.result(), call
           ^^^^^^^^^^^^^
  File "/Users/macbook/miniconda3/envs/eoh/lib/python3.12/site-packages/grpc/_channel.py", line 440, in result
    raise self
  File "/Users/macbook/miniconda3/envs/eoh/lib/python3.12/site-packages/grpc/_interceptor.py", line 315, in continuation
    response, call = self._thunk(new_method).with_call(
                     ^^^^^^^^^^^^^^^^^^^^^^^^^^^^^^^^^^
  File "/Users/macbook/miniconda3/envs/eoh/lib/python3.12/site-packages/grpc/_channel.py", line 1198, in with_call
    return _end_unary_response_blocking(state, call, True, None)
           ^^^^^^^^^^^^^^^^^^^^^^^^^^^^^^^^^^^^^^^^^^^^^^^^^^^^^
  File "/Users/macbook/miniconda3/envs/eoh/lib/python3.12/site-packages/grpc/_channel.py", line 1006, in _end_unary_response_blocking
    raise _InactiveRpcError(state)  # pytype: disable=not-instantiable
    ^^^^^^^^^^^^^^^^^^^^^^^^^^^^^^
grpc._channel._InactiveRpcError: <_InactiveRpcError of RPC that terminated with:
	status = StatusCode.UNAVAILABLE
	details = "DNS resolution failed for generativelanguage.googleapis.com:443: C-ares status is not ARES_SUCCESS qtype=A name=generativelanguage.googleapis.com is_balancer=0: DNS query cancelled"
	debug_error_string = "UNKNOWN:Error received from peer  {grpc_message:"DNS resolution failed for generativelanguage.googleapis.com:443: C-ares status is not ARES_SUCCESS qtype=A name=generativelanguage.googleapis.com is_balancer=0: DNS query cancelled", grpc_status:14, created_time:"2025-06-22T16:36:15.105929+07:00"}"
>

The above exception was the direct cause of the following exception:

Traceback (most recent call last):
  File "/Users/macbook/miniconda3/envs/eoh/lib/python3.12/site-packages/google/api_core/retry/retry_unary.py", line 147, in retry_target
    result = target()
             ^^^^^^^^
  File "/Users/macbook/miniconda3/envs/eoh/lib/python3.12/site-packages/google/api_core/timeout.py", line 130, in func_with_timeout
    return func(*args, **kwargs)
           ^^^^^^^^^^^^^^^^^^^^^
  File "/Users/macbook/miniconda3/envs/eoh/lib/python3.12/site-packages/google/api_core/grpc_helpers.py", line 78, in error_remapped_callable
    raise exceptions.from_grpc_error(exc) from exc
google.api_core.exceptions.ServiceUnavailable: 503 DNS resolution failed for generativelanguage.googleapis.com:443: C-ares status is not ARES_SUCCESS qtype=A name=generativelanguage.googleapis.com is_balancer=0: DNS query cancelled

The above exception was the direct cause of the following exception:

Traceback (most recent call last):
  File "/Users/macbook/Documents/Code/LLMdesignedEA-comp/llamea_with_hs.py", line 158, in initialize_single
    new_individual = chosen_llm.sample_solution(session_messages, role_index=role_index)
                     ^^^^^^^^^^^^^^^^^^^^^^^^^^^^^^^^^^^^^^^^^^^^^^^^^^^^^^^^^^^^^^^^^^^
  File "/Users/macbook/Documents/Code/LLMdesignedEA-comp/llamea/llm.py", line 106, in sample_solution
    message = self.query(session_messages)
              ^^^^^^^^^^^^^^^^^^^^^^^^^^^^
  File "/Users/macbook/Documents/Code/LLMdesignedEA-comp/llamea/llm.py", line 288, in query
    response = chat_session.send_message(last["content"])
               ^^^^^^^^^^^^^^^^^^^^^^^^^^^^^^^^^^^^^^^^^^
  File "/Users/macbook/miniconda3/envs/eoh/lib/python3.12/site-packages/google/generativeai/generative_models.py", line 578, in send_message
    response = self.model.generate_content(
               ^^^^^^^^^^^^^^^^^^^^^^^^^^^^
  File "/Users/macbook/miniconda3/envs/eoh/lib/python3.12/site-packages/google/generativeai/generative_models.py", line 331, in generate_content
    response = self._client.generate_content(
               ^^^^^^^^^^^^^^^^^^^^^^^^^^^^^^
  File "/Users/macbook/miniconda3/envs/eoh/lib/python3.12/site-packages/google/ai/generativelanguage_v1beta/services/generative_service/client.py", line 835, in generate_content
    response = rpc(
               ^^^^
  File "/Users/macbook/miniconda3/envs/eoh/lib/python3.12/site-packages/google/api_core/gapic_v1/method.py", line 131, in __call__
    return wrapped_func(*args, **kwargs)
           ^^^^^^^^^^^^^^^^^^^^^^^^^^^^^
  File "/Users/macbook/miniconda3/envs/eoh/lib/python3.12/site-packages/google/api_core/retry/retry_unary.py", line 294, in retry_wrapped_func
    return retry_target(
           ^^^^^^^^^^^^^
  File "/Users/macbook/miniconda3/envs/eoh/lib/python3.12/site-packages/google/api_core/retry/retry_unary.py", line 156, in retry_target
    next_sleep = _retry_error_helper(
                 ^^^^^^^^^^^^^^^^^^^^
  File "/Users/macbook/miniconda3/envs/eoh/lib/python3.12/site-packages/google/api_core/retry/retry_base.py", line 229, in _retry_error_helper
    raise final_exc from source_exc
google.api_core.exceptions.RetryError: Timeout of 600.0s exceeded, last exception: 503 DNS resolution failed for generativelanguage.googleapis.com:443: C-ares status is not ARES_SUCCESS qtype=A name=generativelanguage.googleapis.com is_balancer=0: DNS query cancelled
.
