2025-06-20 18:14:12 INFO Initializing first population
2025-06-20 18:14:12 INFO Initializing population from 4 seed files...
2025-06-20 18:14:14 INFO [ERROR] Evaluation failed: Traceback (most recent call last):
  File "/Users/macbook/Documents/Code/LLMdesignedEA-comp/llamea_reflection.py", line 269, in evaluate_fitness
    result = future.result(timeout=timeout_seconds)
             ^^^^^^^^^^^^^^^^^^^^^^^^^^^^^^^^^^^^^^
  File "/Users/macbook/miniconda3/envs/eoh/lib/python3.12/concurrent/futures/_base.py", line 456, in result
    return self.__get_result()
           ^^^^^^^^^^^^^^^^^^^
  File "/Users/macbook/miniconda3/envs/eoh/lib/python3.12/concurrent/futures/_base.py", line 401, in __get_result
    raise self._exception
concurrent.futures.process.BrokenProcessPool: A process in the process pool was terminated abruptly while the future was running or pending.

2025-06-20 18:14:16 INFO [ERROR] Evaluation failed: Traceback (most recent call last):
  File "/Users/macbook/Documents/Code/LLMdesignedEA-comp/llamea_reflection.py", line 269, in evaluate_fitness
    result = future.result(timeout=timeout_seconds)
             ^^^^^^^^^^^^^^^^^^^^^^^^^^^^^^^^^^^^^^
  File "/Users/macbook/miniconda3/envs/eoh/lib/python3.12/concurrent/futures/_base.py", line 456, in result
    return self.__get_result()
           ^^^^^^^^^^^^^^^^^^^
  File "/Users/macbook/miniconda3/envs/eoh/lib/python3.12/concurrent/futures/_base.py", line 401, in __get_result
    raise self._exception
concurrent.futures.process.BrokenProcessPool: A process in the process pool was terminated abruptly while the future was running or pending.

2025-06-20 18:14:17 INFO [ERROR] Evaluation failed: Traceback (most recent call last):
  File "/Users/macbook/Documents/Code/LLMdesignedEA-comp/llamea_reflection.py", line 269, in evaluate_fitness
    result = future.result(timeout=timeout_seconds)
             ^^^^^^^^^^^^^^^^^^^^^^^^^^^^^^^^^^^^^^
  File "/Users/macbook/miniconda3/envs/eoh/lib/python3.12/concurrent/futures/_base.py", line 456, in result
    return self.__get_result()
           ^^^^^^^^^^^^^^^^^^^
  File "/Users/macbook/miniconda3/envs/eoh/lib/python3.12/concurrent/futures/_base.py", line 401, in __get_result
    raise self._exception
concurrent.futures.process.BrokenProcessPool: A process in the process pool was terminated abruptly while the future was running or pending.

2025-06-20 18:14:19 INFO [ERROR] Evaluation failed: Traceback (most recent call last):
  File "/Users/macbook/Documents/Code/LLMdesignedEA-comp/llamea_reflection.py", line 269, in evaluate_fitness
    result = future.result(timeout=timeout_seconds)
             ^^^^^^^^^^^^^^^^^^^^^^^^^^^^^^^^^^^^^^
  File "/Users/macbook/miniconda3/envs/eoh/lib/python3.12/concurrent/futures/_base.py", line 456, in result
    return self.__get_result()
           ^^^^^^^^^^^^^^^^^^^
  File "/Users/macbook/miniconda3/envs/eoh/lib/python3.12/concurrent/futures/_base.py", line 401, in __get_result
    raise self._exception
concurrent.futures.process.BrokenProcessPool: A process in the process pool was terminated abruptly while the future was running or pending.

2025-06-20 18:14:19 INFO Started evolutionary loop, best so far: -inf
2025-06-20 18:14:19 INFO --- Performing Long-Term Reflection at Generation 1 ---
2025-06-20 18:14:19 WARNING Skipping reflection: No valid individuals in population.
2025-06-20 18:14:19 INFO Generating offspring via Crossover...
