2025-06-24 06:29:27 INFO Using LLM api key #AIzaSyCK6miE77n6z7PUf0RNgj8seMiiVET-wqk)
2025-06-24 06:29:27 INFO Using LLM api key #AIzaSyCK6miE77n6z7PUf0RNgj8seMiiVET-wqk)
2025-06-24 06:29:27 INFO Using LLM api key #AIzaSyARJfdVOsI9AKUK6gxvUszL_bn5Z_lr5Wg)
2025-06-24 06:29:34 INFO Using LLM api key #AIzaSyARJfdVOsI9AKUK6gxvUszL_bn5Z_lr5Wg)
2025-06-24 06:29:36 INFO Using LLM api key #AIzaSyCK6miE77n6z7PUf0RNgj8seMiiVET-wqk)
2025-06-24 06:29:36 INFO Using LLM api key #AIzaSyARJfdVOsI9AKUK6gxvUszL_bn5Z_lr5Wg)
2025-06-24 06:29:41 INFO Using LLM api key #AIzaSyCK6miE77n6z7PUf0RNgj8seMiiVET-wqk)
2025-06-24 06:29:43 INFO Using LLM api key #AIzaSyARJfdVOsI9AKUK6gxvUszL_bn5Z_lr5Wg)
2025-06-24 06:29:43 INFO Using LLM api key #AIzaSyCK6miE77n6z7PUf0RNgj8seMiiVET-wqk)
2025-06-24 06:29:49 INFO Using LLM api key #AIzaSyARJfdVOsI9AKUK6gxvUszL_bn5Z_lr5Wg)
2025-06-24 06:29:50 INFO Using LLM api key #AIzaSyCK6miE77n6z7PUf0RNgj8seMiiVET-wqk)
2025-06-24 06:39:50 INFO An exception occured: Traceback (most recent call last):
  File "/Users/macbook/Documents/Code/LLMdesignedEA-comp/llamea_with_hs.py", line 190, in initialize_single
    new_individual = chosen_llm.sample_solution(session_messages, role_index=role_index)
                     ^^^^^^^^^^^^^^^^^^^^^^^^^^^^^^^^^^^^^^^^^^^^^^^^^^^^^^^^^^^^^^^^^^^
  File "/Users/macbook/Documents/Code/LLMdesignedEA-comp/llamea/llm.py", line 106, in sample_solution
    message = self.query(session_messages)
              ^^^^^^^^^^^^^^^^^^^^^^^^^^^^
  File "/Users/macbook/Documents/Code/LLMdesignedEA-comp/llamea/llm.py", line 288, in query
    response = chat_session.send_message(last["content"])
               ^^^^^^^^^^^^^^^^^^^^^^^^^^^^^^^^^^^^^^^^^^
  File "/Users/macbook/miniconda3/envs/eoh/lib/python3.12/site-packages/google/generativeai/generative_models.py", line 578, in send_message
    response = self.model.generate_content(
               ^^^^^^^^^^^^^^^^^^^^^^^^^^^^
  File "/Users/macbook/miniconda3/envs/eoh/lib/python3.12/site-packages/google/generativeai/generative_models.py", line 331, in generate_content
    response = self._client.generate_content(
               ^^^^^^^^^^^^^^^^^^^^^^^^^^^^^^
  File "/Users/macbook/miniconda3/envs/eoh/lib/python3.12/site-packages/google/ai/generativelanguage_v1beta/services/generative_service/client.py", line 835, in generate_content
    response = rpc(
               ^^^^
  File "/Users/macbook/miniconda3/envs/eoh/lib/python3.12/site-packages/google/api_core/gapic_v1/method.py", line 131, in __call__
    return wrapped_func(*args, **kwargs)
           ^^^^^^^^^^^^^^^^^^^^^^^^^^^^^
  File "/Users/macbook/miniconda3/envs/eoh/lib/python3.12/site-packages/google/api_core/retry/retry_unary.py", line 294, in retry_wrapped_func
    return retry_target(
           ^^^^^^^^^^^^^
  File "/Users/macbook/miniconda3/envs/eoh/lib/python3.12/site-packages/google/api_core/retry/retry_unary.py", line 156, in retry_target
    next_sleep = _retry_error_helper(
                 ^^^^^^^^^^^^^^^^^^^^
  File "/Users/macbook/miniconda3/envs/eoh/lib/python3.12/site-packages/google/api_core/retry/retry_base.py", line 214, in _retry_error_helper
    raise final_exc from source_exc
  File "/Users/macbook/miniconda3/envs/eoh/lib/python3.12/site-packages/google/api_core/retry/retry_unary.py", line 147, in retry_target
    result = target()
             ^^^^^^^^
  File "/Users/macbook/miniconda3/envs/eoh/lib/python3.12/site-packages/google/api_core/timeout.py", line 130, in func_with_timeout
    return func(*args, **kwargs)
           ^^^^^^^^^^^^^^^^^^^^^
  File "/Users/macbook/miniconda3/envs/eoh/lib/python3.12/site-packages/google/api_core/grpc_helpers.py", line 78, in error_remapped_callable
    raise exceptions.from_grpc_error(exc) from exc
google.api_core.exceptions.DeadlineExceeded: 504 Deadline Exceeded
.
