2025-06-15 08:40:29 INFO --- GNBG Problem Parameters for f8 ---
  Dimension: 30, MaxEvals: 500000
  Search Bounds: [-100, 100]
  Number of Components: 1
  Known Optimum Value: -656.788998
  Lambda (Curvature): [1]
  Mu (Asymmetry/Depth): [0.2 0.2]
----------------------------------------
2025-06-15 08:40:30 ERROR Can not run the algorithm
2025-06-15 08:40:30 INFO Run function 8 complete. FEHistory len: 7451, AOCC: 0.0000
2025-06-15 08:40:30 INFO FeHistory: [159152.82754802 203856.42245806 248694.95842813 ... 384131.56316887
 429338.76587353 314276.9556697 ]
2025-06-15 08:40:30 INFO Expected Optimum FE: -656.7889979935655
2025-06-15 08:40:30 INFO Multimodal (single component) AOCC mean: 0.0000
2025-06-15 08:40:30 INFO AOCC mean: 0.0000
2025-06-15 08:40:30 INFO --- GNBG Problem Parameters for f8 ---
  Dimension: 30, MaxEvals: 500000
  Search Bounds: [-100, 100]
  Number of Components: 1
  Known Optimum Value: -656.788998
  Lambda (Curvature): [1]
  Mu (Asymmetry/Depth): [0.2 0.2]
----------------------------------------
2025-06-15 08:40:31 INFO --- GNBG Problem Parameters for f8 ---
  Dimension: 30, MaxEvals: 500000
  Search Bounds: [-100, 100]
  Number of Components: 1
  Known Optimum Value: -656.788998
  Lambda (Curvature): [1]
  Mu (Asymmetry/Depth): [0.2 0.2]
----------------------------------------
2025-06-15 08:40:31 INFO --- GNBG Problem Parameters for f8 ---
  Dimension: 30, MaxEvals: 500000
  Search Bounds: [-100, 100]
  Number of Components: 1
  Known Optimum Value: -656.788998
  Lambda (Curvature): [1]
  Mu (Asymmetry/Depth): [0.2 0.2]
----------------------------------------
2025-06-15 08:40:31 INFO --- GNBG Problem Parameters for f8 ---
  Dimension: 30, MaxEvals: 500000
  Search Bounds: [-100, 100]
  Number of Components: 1
  Known Optimum Value: -656.788998
  Lambda (Curvature): [1]
  Mu (Asymmetry/Depth): [0.2 0.2]
----------------------------------------
2025-06-15 08:40:31 INFO --- GNBG Problem Parameters for f8 ---
  Dimension: 30, MaxEvals: 500000
  Search Bounds: [-100, 100]
  Number of Components: 1
  Known Optimum Value: -656.788998
  Lambda (Curvature): [1]
  Mu (Asymmetry/Depth): [0.2 0.2]
----------------------------------------
2025-06-15 08:40:35 INFO Run function 8 complete. FEHistory len: 50000, AOCC: 0.0000
2025-06-15 08:40:35 INFO FeHistory: [179577.74506812 199611.8063375  140582.80019398 ...  51359.21991907
  51470.65570772  51912.22225709]
2025-06-15 08:40:35 INFO Expected Optimum FE: -656.7889979935655
2025-06-15 08:40:35 INFO Multimodal (single component) AOCC mean: 0.0000
2025-06-15 08:40:35 INFO AOCC mean: 0.0000
2025-06-15 08:40:36 INFO Run function 8 complete. FEHistory len: 50000, AOCC: 0.0000
2025-06-15 08:40:36 INFO FeHistory: [141647.71278855 206102.78138872 225895.27392554 ...   3931.09639078
   1873.03496901   3559.18885404]
2025-06-15 08:40:36 INFO Expected Optimum FE: -656.7889979935655
2025-06-15 08:40:36 INFO Multimodal (single component) AOCC mean: 0.0000
2025-06-15 08:40:36 INFO AOCC mean: 0.0000
2025-06-15 08:40:36 INFO Run function 8 complete. FEHistory len: 50000, AOCC: 0.0000
2025-06-15 08:40:36 INFO FeHistory: [185371.08659477 273127.89848574 163345.84534688 ...  42694.78492585
  42192.93671836  35258.24686969]
2025-06-15 08:40:36 INFO Expected Optimum FE: -656.7889979935655
2025-06-15 08:40:36 INFO Multimodal (single component) AOCC mean: 0.0000
2025-06-15 08:40:36 INFO AOCC mean: 0.0000
2025-06-15 08:40:36 INFO Run function 8 complete. FEHistory len: 50000, AOCC: 0.0000
2025-06-15 08:40:36 INFO FeHistory: [143125.18354021  89909.12321764 174296.45291363 ...  29221.13729587
  29203.54640511  29220.41329483]
2025-06-15 08:40:36 INFO Expected Optimum FE: -656.7889979935655
2025-06-15 08:40:36 INFO Multimodal (single component) AOCC mean: 0.0000
2025-06-15 08:40:36 INFO AOCC mean: 0.0000
2025-06-15 08:40:38 INFO Run function 8 complete. FEHistory len: 50000, AOCC: 0.0000
2025-06-15 08:40:38 INFO FeHistory: [202312.45281159 301732.51086434 214178.2153457  ... 141339.11432996
  36797.22859163  33605.00563694]
2025-06-15 08:40:38 INFO Expected Optimum FE: -656.7889979935655
2025-06-15 08:40:38 INFO Multimodal (single component) AOCC mean: 0.0000
2025-06-15 08:40:38 INFO AOCC mean: 0.0000
2025-06-15 08:40:56 INFO An exception occured: Traceback (most recent call last):
  File "/Users/macbook/Documents/Code/LLMdesignedEA-comp/llamea/llamea_multi_prompts.py", line 316, in evolve_solution
    evolved_individual = self.llm.sample_solution(
                         ^^^^^^^^^^^^^^^^^^^^^^^^^
  File "/Users/macbook/Documents/Code/LLMdesignedEA-comp/llamea/llm.py", line 106, in sample_solution
    message = self.query(session_messages)
              ^^^^^^^^^^^^^^^^^^^^^^^^^^^^
  File "/Users/macbook/Documents/Code/LLMdesignedEA-comp/llamea/llm.py", line 278, in query
    response = chat_session.send_message(last["content"])
               ^^^^^^^^^^^^^^^^^^^^^^^^^^^^^^^^^^^^^^^^^^
  File "/Users/macbook/miniconda3/envs/eoh/lib/python3.12/site-packages/google/generativeai/generative_models.py", line 578, in send_message
    response = self.model.generate_content(
               ^^^^^^^^^^^^^^^^^^^^^^^^^^^^
  File "/Users/macbook/miniconda3/envs/eoh/lib/python3.12/site-packages/google/generativeai/generative_models.py", line 331, in generate_content
    response = self._client.generate_content(
               ^^^^^^^^^^^^^^^^^^^^^^^^^^^^^^
  File "/Users/macbook/miniconda3/envs/eoh/lib/python3.12/site-packages/google/ai/generativelanguage_v1beta/services/generative_service/client.py", line 835, in generate_content
    response = rpc(
               ^^^^
  File "/Users/macbook/miniconda3/envs/eoh/lib/python3.12/site-packages/google/api_core/gapic_v1/method.py", line 131, in __call__
    return wrapped_func(*args, **kwargs)
           ^^^^^^^^^^^^^^^^^^^^^^^^^^^^^
  File "/Users/macbook/miniconda3/envs/eoh/lib/python3.12/site-packages/google/api_core/retry/retry_unary.py", line 294, in retry_wrapped_func
    return retry_target(
           ^^^^^^^^^^^^^
  File "/Users/macbook/miniconda3/envs/eoh/lib/python3.12/site-packages/google/api_core/retry/retry_unary.py", line 156, in retry_target
    next_sleep = _retry_error_helper(
                 ^^^^^^^^^^^^^^^^^^^^
  File "/Users/macbook/miniconda3/envs/eoh/lib/python3.12/site-packages/google/api_core/retry/retry_base.py", line 214, in _retry_error_helper
    raise final_exc from source_exc
  File "/Users/macbook/miniconda3/envs/eoh/lib/python3.12/site-packages/google/api_core/retry/retry_unary.py", line 147, in retry_target
    result = target()
             ^^^^^^^^
  File "/Users/macbook/miniconda3/envs/eoh/lib/python3.12/site-packages/google/api_core/timeout.py", line 130, in func_with_timeout
    return func(*args, **kwargs)
           ^^^^^^^^^^^^^^^^^^^^^
  File "/Users/macbook/miniconda3/envs/eoh/lib/python3.12/site-packages/google/api_core/grpc_helpers.py", line 78, in error_remapped_callable
    raise exceptions.from_grpc_error(exc) from exc
google.api_core.exceptions.ResourceExhausted: 429 You exceeded your current quota, please check your plan and billing details. For more information on this error, head to: https://ai.google.dev/gemini-api/docs/rate-limits. [violations {
  quota_metric: "generativelanguage.googleapis.com/generate_content_free_tier_requests"
  quota_id: "GenerateRequestsPerMinutePerProjectPerModel-FreeTier"
  quota_dimensions {
    key: "model"
    value: "gemini-1.5-flash"
  }
  quota_dimensions {
    key: "location"
    value: "global"
  }
  quota_value: 15
}
, links {
  description: "Learn more about Gemini API quotas"
  url: "https://ai.google.dev/gemini-api/docs/rate-limits"
}
, retry_delay {
  seconds: 3
}
]
.
2025-06-15 08:41:04 INFO --- GNBG Problem Parameters for f8 ---
  Dimension: 30, MaxEvals: 500000
  Search Bounds: [-100, 100]
  Number of Components: 1
  Known Optimum Value: -656.788998
  Lambda (Curvature): [1]
  Mu (Asymmetry/Depth): [0.2 0.2]
----------------------------------------
2025-06-15 08:41:04 INFO --- GNBG Problem Parameters for f8 ---
  Dimension: 30, MaxEvals: 500000
  Search Bounds: [-100, 100]
  Number of Components: 1
  Known Optimum Value: -656.788998
  Lambda (Curvature): [1]
  Mu (Asymmetry/Depth): [0.2 0.2]
----------------------------------------
2025-06-15 08:41:05 INFO --- GNBG Problem Parameters for f8 ---
  Dimension: 30, MaxEvals: 500000
  Search Bounds: [-100, 100]
  Number of Components: 1
  Known Optimum Value: -656.788998
  Lambda (Curvature): [1]
  Mu (Asymmetry/Depth): [0.2 0.2]
----------------------------------------
2025-06-15 08:41:05 INFO --- GNBG Problem Parameters for f8 ---
  Dimension: 30, MaxEvals: 500000
  Search Bounds: [-100, 100]
  Number of Components: 1
  Known Optimum Value: -656.788998
  Lambda (Curvature): [1]
  Mu (Asymmetry/Depth): [0.2 0.2]
----------------------------------------
2025-06-15 08:41:06 INFO --- GNBG Problem Parameters for f8 ---
  Dimension: 30, MaxEvals: 500000
  Search Bounds: [-100, 100]
  Number of Components: 1
  Known Optimum Value: -656.788998
  Lambda (Curvature): [1]
  Mu (Asymmetry/Depth): [0.2 0.2]
----------------------------------------
2025-06-15 08:41:06 ERROR Can not run the algorithm
2025-06-15 08:41:06 INFO Run function 8 complete. FEHistory len: 20, AOCC: 0.0000
2025-06-15 08:41:06 INFO FeHistory: [201847.645423   235187.42243034 169616.56846316 123411.61738988
 168108.96429512 233976.63370537 225906.04992466 210374.13415156
 249304.27835132 103745.39525955 276077.58626261 205963.73703817
 177993.16567209 220996.750439   121113.02611955 232024.68475028
 195343.70326106 223697.18981331 211651.40570502 195898.38316165]
2025-06-15 08:41:06 INFO Expected Optimum FE: -656.7889979935655
2025-06-15 08:41:06 INFO Multimodal (single component) AOCC mean: 0.0000
2025-06-15 08:41:06 INFO AOCC mean: 0.0000
2025-06-15 08:41:10 INFO Run function 8 complete. FEHistory len: 50000, AOCC: 0.0011
2025-06-15 08:41:10 INFO FeHistory: [132726.63142807 185299.98013126 163141.06203519 ...   -464.46585932
   -438.048624     -491.2004911 ]
2025-06-15 08:41:10 INFO Expected Optimum FE: -656.7889979935655
2025-06-15 08:41:10 INFO Multimodal (single component) AOCC mean: 0.0011
2025-06-15 08:41:10 INFO AOCC mean: 0.0011
2025-06-15 08:41:11 INFO Run function 8 complete. FEHistory len: 50000, AOCC: 0.0000
2025-06-15 08:41:11 INFO FeHistory: [133897.81653377 184340.71221879 196965.30521539 ...  24654.25643109
  26485.22834871  22165.45897907]
2025-06-15 08:41:11 INFO Expected Optimum FE: -656.7889979935655
2025-06-15 08:41:11 INFO Multimodal (single component) AOCC mean: 0.0000
2025-06-15 08:41:11 INFO AOCC mean: 0.0000
2025-06-15 08:41:22 INFO Run function 8 complete. FEHistory len: 50000, AOCC: 0.0000
2025-06-15 08:41:22 INFO FeHistory: [115106.8707767  133442.30144856 197295.69750985 ...  26191.0392109
  26195.32929115  26172.33811699]
2025-06-15 08:41:22 INFO Expected Optimum FE: -656.7889979935655
2025-06-15 08:41:22 INFO Multimodal (single component) AOCC mean: 0.0000
2025-06-15 08:41:22 INFO AOCC mean: 0.0000
2025-06-15 08:41:43 INFO Run function 8 complete. FEHistory len: 50000, AOCC: 0.0000
2025-06-15 08:41:43 INFO FeHistory: [332421.21976672 135578.13498803 216729.96025981 ...  27778.02121054
  27851.00485654  27779.72155599]
2025-06-15 08:41:43 INFO Expected Optimum FE: -656.7889979935655
2025-06-15 08:41:43 INFO Multimodal (single component) AOCC mean: 0.0000
2025-06-15 08:41:43 INFO AOCC mean: 0.0000
2025-06-15 08:41:52 INFO --- GNBG Problem Parameters for f8 ---
  Dimension: 30, MaxEvals: 500000
  Search Bounds: [-100, 100]
  Number of Components: 1
  Known Optimum Value: -656.788998
  Lambda (Curvature): [1]
  Mu (Asymmetry/Depth): [0.2 0.2]
----------------------------------------
2025-06-15 08:41:52 INFO --- GNBG Problem Parameters for f8 ---
  Dimension: 30, MaxEvals: 500000
  Search Bounds: [-100, 100]
  Number of Components: 1
  Known Optimum Value: -656.788998
  Lambda (Curvature): [1]
  Mu (Asymmetry/Depth): [0.2 0.2]
----------------------------------------
2025-06-15 08:41:52 ERROR Can not run the algorithm
2025-06-15 08:41:52 INFO Run function 8 complete. FEHistory len: 6, AOCC: 0.0000
2025-06-15 08:41:52 INFO FeHistory: [174578.64278169 169696.49597245 179759.82135738 178405.58879737
 178311.77745504 178173.44065544]
2025-06-15 08:41:52 INFO Expected Optimum FE: -656.7889979935655
2025-06-15 08:41:52 INFO Multimodal (single component) AOCC mean: 0.0000
2025-06-15 08:41:52 INFO AOCC mean: 0.0000
2025-06-15 08:41:52 INFO --- GNBG Problem Parameters for f8 ---
  Dimension: 30, MaxEvals: 500000
  Search Bounds: [-100, 100]
  Number of Components: 1
  Known Optimum Value: -656.788998
  Lambda (Curvature): [1]
  Mu (Asymmetry/Depth): [0.2 0.2]
----------------------------------------
2025-06-15 08:41:52 ERROR Can not run the algorithm
2025-06-15 08:41:52 INFO Run function 8 complete. FEHistory len: 6, AOCC: 0.0000
2025-06-15 08:41:52 INFO FeHistory: [107976.63588963 107749.52851826 109271.62116466 108994.0806312
 109864.63538399 106591.74307917]
2025-06-15 08:41:52 INFO Expected Optimum FE: -656.7889979935655
2025-06-15 08:41:52 INFO Multimodal (single component) AOCC mean: 0.0000
2025-06-15 08:41:52 INFO AOCC mean: 0.0000
2025-06-15 08:41:52 INFO --- GNBG Problem Parameters for f8 ---
  Dimension: 30, MaxEvals: 500000
  Search Bounds: [-100, 100]
  Number of Components: 1
  Known Optimum Value: -656.788998
  Lambda (Curvature): [1]
  Mu (Asymmetry/Depth): [0.2 0.2]
----------------------------------------
2025-06-15 08:41:52 ERROR Can not run the algorithm
2025-06-15 08:41:52 INFO Run function 8 complete. FEHistory len: 6, AOCC: 0.0000
2025-06-15 08:41:52 INFO FeHistory: [143282.05317161 143068.8440353  146766.46714368 138236.80053116
 143429.66165405 144409.86647117]
2025-06-15 08:41:52 INFO Expected Optimum FE: -656.7889979935655
2025-06-15 08:41:52 INFO Multimodal (single component) AOCC mean: 0.0000
2025-06-15 08:41:52 INFO AOCC mean: 0.0000
2025-06-15 08:41:53 INFO --- GNBG Problem Parameters for f8 ---
  Dimension: 30, MaxEvals: 500000
  Search Bounds: [-100, 100]
  Number of Components: 1
  Known Optimum Value: -656.788998
  Lambda (Curvature): [1]
  Mu (Asymmetry/Depth): [0.2 0.2]
----------------------------------------
2025-06-15 08:41:54 INFO --- GNBG Problem Parameters for f8 ---
  Dimension: 30, MaxEvals: 500000
  Search Bounds: [-100, 100]
  Number of Components: 1
  Known Optimum Value: -656.788998
  Lambda (Curvature): [1]
  Mu (Asymmetry/Depth): [0.2 0.2]
----------------------------------------
2025-06-15 08:41:54 INFO Run function 8 complete. FEHistory len: 340, AOCC: 0.0000
2025-06-15 08:41:54 INFO FeHistory: [196172.07239595 245109.53956388 214816.40869158 198570.5899937
 172907.16747633 288630.3427383  173612.79102609 182111.46213867
 154336.26519313 166437.92422289 190539.57976679 247732.76755853
 222507.89362406 192599.53433925 161718.94013553 194466.47275555
 223424.34541673 201397.17651395 258567.47160744 171023.55813676
 165385.88453359 164536.98749586 155487.8754937  204337.25581605
 169051.32659525 178028.80962638 176628.15560148 187238.45112089
 151114.08125043 197571.42035371 189782.81657534 319600.44392985
 158171.03084    168456.94124254 124832.17763448 165854.81085343
 138700.1576313  190894.70721216 169199.47566337 176635.23795694
 122237.82033432 141392.66926967 155139.61480002 148183.05363823
 150079.2261823  155342.69917714 163118.39970344 187485.99776628
 165399.24632741 162470.15306666 116442.96367678 161389.41882023
 139136.99699331 145673.92369415 144928.01006462 293821.22229217
 185125.24505194 203542.92324439 154132.99789091 157699.83658513
 116227.49771442 140288.00905722 123386.27357413 134262.66852578
 214245.35898039 136133.14315609  95614.34191751 112519.78227263
 162041.16757342 157401.63294666 143602.43746941 115036.32880971
 138902.43979887 116047.68045068 122782.09136354 124227.37421279
 173906.40817358 154301.85425418 215660.36397001 185741.80621333
  91583.74043847 179415.31234785 105769.24269317 115780.16024275
  96357.09066616 115979.13837384 130811.46910108 154865.45984516
 125784.61467168 127441.12528211 133846.91925038  99279.59077554
 172549.30432757 104888.85584269 115942.49431158 113389.46126204
 126869.64365539 114111.35186439 111641.36203127 113086.77012452
  93226.84035572  88734.36695821  83253.29882993 104387.17302382
 104862.50142961 140051.2178161  145231.35516906 108452.39275233
 107889.76631681 109512.96109144  77878.76213498 169827.06202202
  87929.71476815  94999.04740325  97369.11544431  93632.16941513
  96711.14255087 108215.94537078 192102.26853798 119977.33212546
 127573.0659896   74780.07279693  99601.27724435  97739.61095386
  91581.41706182 104255.48755452  96304.02824315 125851.96527124
  80744.88290119 124823.13193256  83938.89852712  77861.02180566
  76618.85330545  95471.53816204  94042.35206949  89487.16610359
  93140.75985298  95165.13329379  89395.03754751  90758.83630237
  59037.73654301 122792.53812233  84035.71850466  85608.26375553
  82767.30030192  90929.87175967  83616.96956994  83284.71155278
  79436.24559685 106929.16465417  66780.63292842  86791.07753067
  72648.96939191  78372.82502835 114641.62688802  93973.45719227
  82703.15334543  98006.19524365 111106.91575917 146847.27242454
  66577.34906979  65709.60143924  77294.2172303  108504.21106022
  71874.75992698  94859.79013033  79514.92042976 131865.473689
  84375.62471759 160240.61521796  99193.10194231  65522.98551646
  68311.33372549 100739.71371067  72915.27482329  70624.84440541
  77248.57237069  81036.32240963  80876.34131186  80028.943322
  58173.62000426  98125.38862159  57186.91166166  76681.18810078
  67708.32428186  73659.3392231   64928.3430905   72822.12931536
 152294.09327735  79036.78822423  67955.95148258  83324.43223168
  61189.16204048  83324.43223168  71894.14998978  68833.81984934
  88673.7197969   68344.6994268   76150.3226798   62571.20116593
  58618.69098964  61343.36240442  69538.60906858  62500.26270539
  62552.08605614  64304.92466132  50524.29924832  81819.0041988
  75532.11298775  66476.3275077   63373.00939479  54593.80386333
  57166.60582134  54771.91746702  62452.71295408  62068.27267796
  55406.35043976  71440.71241415  52299.68741953  58809.72680849
  80816.36686623  59370.29575611  53623.72654293  54331.69865948
  52637.75246186  51938.18932386 101480.28717787  62442.64899916
  85560.55140864 121869.45524041  48232.32675389  82781.60828682
  52851.94963611  57214.00513085  90790.61527653  59446.14889977
  72781.31221861  81522.30260892  94691.31138481  56132.097939
  46960.41502108  54146.03451469  52075.00200066 106019.56097999
  50781.04213639  47839.96009874  63240.40095452 104911.7812321
  51199.28584812  54593.45509089  62946.55795965  50793.514718
  79043.82738939  53978.58987615  53984.73697688  53423.89794403
  77231.35725112  51931.31917176  62592.01607295  56875.45441778
  86853.26295723  76107.15090882  70457.10148759  44394.40415109
  48066.95669786  49154.11390218  55464.66295123  96040.74367178
  56908.92589402  50937.17773818  44943.66259112  54803.44578912
  48796.13581986  44369.27275837  44369.81099552  84145.6061996
  48104.00019112  47662.60882423  48906.50857978  56265.11357924
  43795.247923    42246.37635506 104185.21684667  46989.27120145
  63516.97627486  49003.43836929  47521.33127006  52024.48084327
  50480.93458026  49982.40063941  43766.32963635  41701.46091555
  46916.24375538  40053.21529103  45181.45006048  45013.31153966
  50264.66265122  44386.54815865  50271.46596623  75528.38965788
  73404.12570209  40832.71358265  44641.50691798  47777.38557741
  46563.76927497  50639.04240976  49163.2020819   41123.31231878
  47014.91428746  44753.61065469  76490.17232478  38711.41580752
  40325.87629784  43702.06256081  44442.12463704  42965.36387294
 107735.86170978  45461.70294329  46483.57388119  45691.61007332
  73624.27313462  41070.08635917 113116.30533824  41158.65553333
  40663.02240617  33759.96862692  44272.22664425  44601.3624983
  41856.24198393  75259.09828504  34078.62436906  42722.12149595
  43353.07957006  42409.43199727  41315.49392376  46607.27472743
  43583.77388966  45810.42997219  41399.65579017  48772.02075295]
2025-06-15 08:41:54 INFO Expected Optimum FE: -656.7889979935655
2025-06-15 08:41:54 INFO Multimodal (single component) AOCC mean: 0.0000
2025-06-15 08:41:54 INFO AOCC mean: 0.0000
2025-06-15 08:41:56 INFO Run function 8 complete. FEHistory len: 50000, AOCC: 0.0000
2025-06-15 08:41:56 INFO FeHistory: [213643.37989606 234058.98896528 198427.69071646 ... 176198.50079193
 180238.21442502 178114.14829245]
2025-06-15 08:41:56 INFO Expected Optimum FE: -656.7889979935655
2025-06-15 08:41:56 INFO Multimodal (single component) AOCC mean: 0.0000
2025-06-15 08:41:56 INFO AOCC mean: 0.0000
2025-06-15 08:41:58 INFO Run function 8 complete. FEHistory len: 50000, AOCC: 0.0000
2025-06-15 08:41:58 INFO FeHistory: [221681.54267294 168964.72653349 185542.44540317 ... 146184.25860361
 286170.08823276 172546.95349276]
2025-06-15 08:41:58 INFO Expected Optimum FE: -656.7889979935655
2025-06-15 08:41:58 INFO Multimodal (single component) AOCC mean: 0.0000
2025-06-15 08:41:58 INFO AOCC mean: 0.0000
2025-06-15 08:41:58 INFO An exception occured: Traceback (most recent call last):
  File "/Users/macbook/Documents/Code/LLMdesignedEA-comp/llamea/llamea_multi_prompts.py", line 316, in evolve_solution
    evolved_individual = self.llm.sample_solution(
                         ^^^^^^^^^^^^^^^^^^^^^^^^^
  File "/Users/macbook/Documents/Code/LLMdesignedEA-comp/llamea/llm.py", line 106, in sample_solution
    message = self.query(session_messages)
              ^^^^^^^^^^^^^^^^^^^^^^^^^^^^
  File "/Users/macbook/Documents/Code/LLMdesignedEA-comp/llamea/llm.py", line 278, in query
    response = chat_session.send_message(last["content"])
               ^^^^^^^^^^^^^^^^^^^^^^^^^^^^^^^^^^^^^^^^^^
  File "/Users/macbook/miniconda3/envs/eoh/lib/python3.12/site-packages/google/generativeai/generative_models.py", line 578, in send_message
    response = self.model.generate_content(
               ^^^^^^^^^^^^^^^^^^^^^^^^^^^^
  File "/Users/macbook/miniconda3/envs/eoh/lib/python3.12/site-packages/google/generativeai/generative_models.py", line 331, in generate_content
    response = self._client.generate_content(
               ^^^^^^^^^^^^^^^^^^^^^^^^^^^^^^
  File "/Users/macbook/miniconda3/envs/eoh/lib/python3.12/site-packages/google/ai/generativelanguage_v1beta/services/generative_service/client.py", line 835, in generate_content
    response = rpc(
               ^^^^
  File "/Users/macbook/miniconda3/envs/eoh/lib/python3.12/site-packages/google/api_core/gapic_v1/method.py", line 131, in __call__
    return wrapped_func(*args, **kwargs)
           ^^^^^^^^^^^^^^^^^^^^^^^^^^^^^
  File "/Users/macbook/miniconda3/envs/eoh/lib/python3.12/site-packages/google/api_core/retry/retry_unary.py", line 294, in retry_wrapped_func
    return retry_target(
           ^^^^^^^^^^^^^
  File "/Users/macbook/miniconda3/envs/eoh/lib/python3.12/site-packages/google/api_core/retry/retry_unary.py", line 156, in retry_target
    next_sleep = _retry_error_helper(
                 ^^^^^^^^^^^^^^^^^^^^
  File "/Users/macbook/miniconda3/envs/eoh/lib/python3.12/site-packages/google/api_core/retry/retry_base.py", line 214, in _retry_error_helper
    raise final_exc from source_exc
  File "/Users/macbook/miniconda3/envs/eoh/lib/python3.12/site-packages/google/api_core/retry/retry_unary.py", line 147, in retry_target
    result = target()
             ^^^^^^^^
  File "/Users/macbook/miniconda3/envs/eoh/lib/python3.12/site-packages/google/api_core/timeout.py", line 130, in func_with_timeout
    return func(*args, **kwargs)
           ^^^^^^^^^^^^^^^^^^^^^
  File "/Users/macbook/miniconda3/envs/eoh/lib/python3.12/site-packages/google/api_core/grpc_helpers.py", line 78, in error_remapped_callable
    raise exceptions.from_grpc_error(exc) from exc
google.api_core.exceptions.ResourceExhausted: 429 You exceeded your current quota, please check your plan and billing details. For more information on this error, head to: https://ai.google.dev/gemini-api/docs/rate-limits. [violations {
  quota_metric: "generativelanguage.googleapis.com/generate_content_free_tier_requests"
  quota_id: "GenerateRequestsPerMinutePerProjectPerModel-FreeTier"
  quota_dimensions {
    key: "model"
    value: "gemini-1.5-flash"
  }
  quota_dimensions {
    key: "location"
    value: "global"
  }
  quota_value: 15
}
, links {
  description: "Learn more about Gemini API quotas"
  url: "https://ai.google.dev/gemini-api/docs/rate-limits"
}
, retry_delay {
  seconds: 1
}
]
.
2025-06-15 08:41:58 INFO An exception occured: Traceback (most recent call last):
  File "/Users/macbook/Documents/Code/LLMdesignedEA-comp/llamea/llamea_multi_prompts.py", line 316, in evolve_solution
    evolved_individual = self.llm.sample_solution(
                         ^^^^^^^^^^^^^^^^^^^^^^^^^
  File "/Users/macbook/Documents/Code/LLMdesignedEA-comp/llamea/llm.py", line 106, in sample_solution
    message = self.query(session_messages)
              ^^^^^^^^^^^^^^^^^^^^^^^^^^^^
  File "/Users/macbook/Documents/Code/LLMdesignedEA-comp/llamea/llm.py", line 278, in query
    response = chat_session.send_message(last["content"])
               ^^^^^^^^^^^^^^^^^^^^^^^^^^^^^^^^^^^^^^^^^^
  File "/Users/macbook/miniconda3/envs/eoh/lib/python3.12/site-packages/google/generativeai/generative_models.py", line 578, in send_message
    response = self.model.generate_content(
               ^^^^^^^^^^^^^^^^^^^^^^^^^^^^
  File "/Users/macbook/miniconda3/envs/eoh/lib/python3.12/site-packages/google/generativeai/generative_models.py", line 331, in generate_content
    response = self._client.generate_content(
               ^^^^^^^^^^^^^^^^^^^^^^^^^^^^^^
  File "/Users/macbook/miniconda3/envs/eoh/lib/python3.12/site-packages/google/ai/generativelanguage_v1beta/services/generative_service/client.py", line 835, in generate_content
    response = rpc(
               ^^^^
  File "/Users/macbook/miniconda3/envs/eoh/lib/python3.12/site-packages/google/api_core/gapic_v1/method.py", line 131, in __call__
    return wrapped_func(*args, **kwargs)
           ^^^^^^^^^^^^^^^^^^^^^^^^^^^^^
  File "/Users/macbook/miniconda3/envs/eoh/lib/python3.12/site-packages/google/api_core/retry/retry_unary.py", line 294, in retry_wrapped_func
    return retry_target(
           ^^^^^^^^^^^^^
  File "/Users/macbook/miniconda3/envs/eoh/lib/python3.12/site-packages/google/api_core/retry/retry_unary.py", line 156, in retry_target
    next_sleep = _retry_error_helper(
                 ^^^^^^^^^^^^^^^^^^^^
  File "/Users/macbook/miniconda3/envs/eoh/lib/python3.12/site-packages/google/api_core/retry/retry_base.py", line 214, in _retry_error_helper
    raise final_exc from source_exc
  File "/Users/macbook/miniconda3/envs/eoh/lib/python3.12/site-packages/google/api_core/retry/retry_unary.py", line 147, in retry_target
    result = target()
             ^^^^^^^^
  File "/Users/macbook/miniconda3/envs/eoh/lib/python3.12/site-packages/google/api_core/timeout.py", line 130, in func_with_timeout
    return func(*args, **kwargs)
           ^^^^^^^^^^^^^^^^^^^^^
  File "/Users/macbook/miniconda3/envs/eoh/lib/python3.12/site-packages/google/api_core/grpc_helpers.py", line 78, in error_remapped_callable
    raise exceptions.from_grpc_error(exc) from exc
google.api_core.exceptions.ResourceExhausted: 429 You exceeded your current quota, please check your plan and billing details. For more information on this error, head to: https://ai.google.dev/gemini-api/docs/rate-limits. [violations {
  quota_metric: "generativelanguage.googleapis.com/generate_content_free_tier_requests"
  quota_id: "GenerateRequestsPerMinutePerProjectPerModel-FreeTier"
  quota_dimensions {
    key: "model"
    value: "gemini-1.5-flash"
  }
  quota_dimensions {
    key: "location"
    value: "global"
  }
  quota_value: 15
}
, links {
  description: "Learn more about Gemini API quotas"
  url: "https://ai.google.dev/gemini-api/docs/rate-limits"
}
, retry_delay {
  seconds: 1
}
]
.
2025-06-15 08:42:04 INFO --- GNBG Problem Parameters for f8 ---
  Dimension: 30, MaxEvals: 500000
  Search Bounds: [-100, 100]
  Number of Components: 1
  Known Optimum Value: -656.788998
  Lambda (Curvature): [1]
  Mu (Asymmetry/Depth): [0.2 0.2]
----------------------------------------
2025-06-15 08:42:04 INFO Run function 8 complete. FEHistory len: 690, AOCC: 0.0000
2025-06-15 08:42:04 INFO FeHistory: [228136.03822933 202818.42081452 178394.2005742  254955.59134702
 269479.92116509 262633.58351931 193535.50532559 187777.30417597
 250748.86294468 493635.53471348 226925.90504956 307676.46622139
 442737.70475187 299967.5798092  323362.08813005 394470.81215652
 295437.54969828 321557.28919163 339335.5349374  370575.95830575
 390961.11221522 306158.21509414 277789.19131351 486176.23444996
 279252.55398463 264563.51738085 481228.92329165 458609.57591961
 304561.80894242 346406.04794443 367948.22626883 302566.59276373
 432508.09904268 278960.97856844 343388.9549805  309392.58012228
 263979.53065726 408800.86654012 339250.61535138 357384.80385054
 379183.99761865 265713.98375496 370191.44743767 413379.20085324
 317056.98060782 426576.90382652 462218.72515353 308535.17761046
 398111.85150081 339470.79529203 404335.50838646 418064.90780444
 269510.47046391 404432.1772211  331289.13722911 455983.58493012
 401468.55403172 317078.92698205 296281.90376438 256089.10097074
 383860.21084939 476480.01492571 415832.94029099 324449.51309471
 128325.05044016 348724.66235728 353499.71124008 329929.25246091
 325306.85692821 363559.72740853 410332.16959791 310952.11058406
 363732.40900195 408510.08916063 381359.59468615 316007.36889481
 328002.45721159 363216.40495127 312731.631055   286054.66794442
 320499.98173732 348400.5189558  340721.65272552 362057.93427234
 307882.72577026 399997.90088523 408950.26474633 286114.7795843
 378257.21440006 265139.48789785 334977.91981347 368411.33610444
 363550.55621099 506004.83832241 330507.27962484 322195.62762051
 368613.00563889 399646.21970125 461683.27785467 474169.77674323
 409045.47963026 245890.66221708 361825.82954673 372525.1808216
 460955.37430066 380239.4889497  323093.78916736 474417.97936448
 322234.63311402 481996.83599636 337340.95576246 466281.21646533
 447884.86364436 337095.99419976 280004.17495425 466360.8197633
 403236.81682029 467134.35604262 515103.86781837 304032.83791746
 418882.56720828 486999.1712771  416227.84464924 348099.19149087
 369518.17982737 406221.06426914 267037.16378483 397531.39481299
 318925.3842448  419181.44438723 345613.60858337 380827.74690841
 261148.21045716 258410.94314442 352090.36367185 401541.3416119
 266705.55669359 250168.23518774 219544.3875765  236877.48163601
 196278.86745374 270705.6508171  299889.08195295 287695.01451355
 231993.33615414 426213.76412051 274938.86631682 425076.16352428
 425578.56290557 456106.11327128 353606.66270084 509925.69697867
 399084.26389636 348325.32623949 404640.00999186 397280.2826956
 429774.76284817 416606.27843825 391657.7055715  300625.38493726
 353291.1548711  472081.8459736  405154.03583028 358887.21006624
 369761.62409921 405533.86314998 409191.00828361 415114.483834
 263652.86641224 361704.22432229 386427.81916636 338697.94118171
 374379.47055613 452434.63882618 385540.38786189 393546.78123106
 320083.99088084 336405.19529523 457940.72986963 333401.70315837
 472157.70615028 384510.58786313 447716.76604248 306275.79221328
 392399.01168728 387479.09249398 389513.19763728 391572.74059519
 450136.25721289 341634.5049138  390186.02638385 475098.54638137
 397652.37713984 377373.0790365  342007.03312196 471262.81606225
 447352.73443688 321186.22167319 459538.17076301 346865.25866694
 302550.24200605 370907.30403169 148934.49828331 251092.89295434
 447461.27105414 268337.35160473 324522.91780846 338932.81479592
 353327.87101748 312706.76927    285032.31085013 411946.11717975
 357316.8778657  400361.58743559 541109.03080674 284723.57858034
 397302.8059879  252498.17070399 393530.94021193 274375.75837132
 352544.182168   463745.66807115 422008.49502371 331526.62573248
 348123.68569627 286852.79842357 441318.3854005  285121.96795984
 332115.82596633 452290.2246954  341772.70785171 453262.3314497
 523195.35878366 411506.70390072 431948.55154863 465867.75073304
 375363.28153066 392599.20371923 314683.81761915 388614.96766467
 395396.75094786 285250.26673711 403880.91482397 364975.3029921
 266793.16760358 417062.61893955 269296.83554178 333010.06845214
 258508.82687597 464347.87581746 406688.59463286 446906.23936748
 410300.81559421 390116.1292016  361051.65145419 347949.82365189
 248526.47669254 367649.02569766 378403.85701729 369648.46286726
 430447.15179031 341647.56538763 409676.02410513 406139.6756662
 166762.14990009 349605.51597911 275628.05195455 341762.73176888
 274330.24218907 325547.45193871 362309.95338283 299412.94012108
 326858.50714375 467328.14757381 403221.91087161 318009.82866654
 260598.3130078  335998.46734388 323441.90688644 423688.35513934
 339491.27777193 302530.3410204  380814.38572419 426092.4726679
 300103.02653115 396625.00712055 281070.93604012 336303.91984302
 402350.84228878 401205.62701822 312944.31820437 379459.10802128
 396811.20023244 399010.70084932 355534.84781529 360159.68509787
 394154.99935116 479296.77621075 381451.18871295 433029.03551901
 397754.94764859 416346.67634773 357497.0463437  364360.3854887
 221330.35222319 517672.32874854 394051.42116563 404223.72562548
 337040.81363613 314971.81064333 381570.43405116 463215.26172108
 279297.36696076 520708.10488032 336929.63782004 230532.97734028
 365255.55073197 404930.04237181 303389.96738556 286101.12068784
 327436.56512294 443448.49029824 438544.90694486 432947.22725058
 424291.59473065 487877.86668967 136079.51038107 206294.7444189
 330142.68021427 337767.22606141 314576.70791229 350742.57097053
 241282.03245743 353395.57717962 352818.61340665 278798.27164827
 433273.28416434 260817.88784294 382831.33763908 317990.57743862
 410215.46873515 245152.40315583 375931.47268923 389704.25755645
 398871.66773617 343470.39846074 421466.49857501 415888.27864912
 311577.45285817 387918.36372161 443606.71865257 366078.10554638
 338413.44785697 391683.3151855  348986.74884752 273314.76048885
 362857.49755795 296328.63747132 365352.3629731  391314.4248222
 442278.95781817 295397.82684325 269819.56595377 385765.14863505
 408138.13088935 383423.93148886 375514.06251519 261141.29256625
 370767.97358692 454494.36696885 425033.6026898  331755.21776026
 303826.48907241 366188.4045672  294472.68171439 411063.94884081
 354033.97085649 430825.24903629 382508.54869773 364832.18561586
 368375.30324784 395917.56946994 357530.00636885 491363.02939837
 265779.20336649 274691.05308424 446930.03806417 487758.56816563
 184510.97822916 263127.61172411 313623.94737294 394110.07781368
 342368.63553018 309506.50167681 453694.14144486 452070.37223549
 383547.92331611 287988.41438041 379969.71927024 252705.85448191
 291156.79629988 251193.45473318 449733.2930858  257274.58426435
 407097.58643786 437190.94301748 412045.97013942 426725.01916338
 220678.58198882 293677.73169815 348760.79922241 516309.77166005
 410134.37157172 439873.59739603 370968.9859574  361698.85649582
 335350.18881323 344544.64983794 419649.81683907 380084.43294463
 338103.61652152 374105.77208907 447110.0007462  422936.31825366
 357341.00063744 261058.50559116 297625.65631789 441050.84145117
 431204.0782464  460824.52733962 286570.90138788 256903.43527613
 325899.98810799 372058.86547707 406425.05385779 431294.92709695
 430507.35942749 247773.61911922 411443.53903026 405254.68489728
 358821.45964259 389784.43574187 315780.60532915 348521.76844123
 388712.54101953 497212.19162409 537103.58327562 391715.57165322
 474928.30718215 440986.88463371 139480.49870691 350508.88275782
 389465.14970856 353392.23364068 300943.59465908 296361.67220484
 319529.2125759  314847.38825582 439690.60589353 341234.8138993
 222104.85310138 266681.49949999 356826.56302988 379289.43894761
 280713.30106992 336405.70891804 293901.5056887  299710.6221581
 375808.90305807 277190.10018334 498757.31086219 393962.04240095
 412797.37223507 296844.03201841 322784.06572256 386779.86018299
 543978.18222802 327320.4614708  333375.10955103 461206.54766237
 451681.58308431 358183.6525131  366030.58589949 311928.34679532
 341511.217578   372114.97202749 357937.60759679 376924.28240632
 380641.2102665  389572.94076756 312088.1573134  311256.0884312
 307707.48670224 432286.06653025 367795.40656777 475815.8085523
 432029.93792387 380718.96268512 431757.34071596 304952.06502821
 311380.46304502 353350.20503144 453778.03905109 335285.77243892
 298921.39257728 458835.32877511 409986.92367002 430021.3054377
 461084.14508619 300078.71925514 418472.15959605 269616.91502702
 233318.9043705  427269.49343272 303081.19490434 263096.49170937
 242323.82940152 380148.70490532 391756.55738327 318656.60906308
 355900.51677245 348391.45149918 348088.74601734 380759.14285505
 327559.44562832 450162.2998224  305903.76109413 371071.49482533
 387996.50757529 300016.99850942 399023.44830714 407622.21385624
 320801.63120985 450127.63945147 302741.90051191 305621.27274792
 420879.72006589 418257.98024269 255686.03028531 401804.28023769
 295760.2599252  310887.87180072 471802.50934571 416611.63235524
 291821.79139275 576326.75862108 423249.29684502 391424.28398825
 279533.51204946 253115.09720527 450796.65380635 385889.93316522
 398746.22567645 417656.51113641 392280.98270427 332066.48314956
 331336.53920931 337705.7306927  334456.74556992 447558.10074497
 199829.74997049 307577.22748371 385355.70729622 364065.50214265
 407700.60672786 417872.75072991 191024.404225   266192.92256282
 379023.81049208 411134.46786649 390493.53234284 334805.66412066
 375762.70939453 386374.45507976 355198.18811528 397681.55497679
 414344.88764774 399527.73672272 497416.67754188 389237.01487312
 312884.09523065 468282.72931002 284737.59396651 435388.93857881
 355893.09602053 453083.6000378  306037.92237627 481631.11637798
 400505.09291022 290551.77832932 382031.1533564  319896.34899792
 441163.66297537 453906.9302609  426040.50768089 380730.82345304
 475449.87880137 453203.76978187 335748.1973079  509687.74227831
 238253.70365412 435735.08729991 466430.49860569 449474.0060342
 360890.51659825 328986.4383825  406803.06326377 280755.45935529
 462474.85796278 445095.81426005 447417.83995422 439435.68797155
 324764.29709632 343311.43488273 325242.20879466 438867.16689695
 411223.37751834 421268.69939417 422785.75676276 401436.40137241
 397073.05172005 412354.91997997 324072.72222756 441020.69198673
 497005.89356864 556967.94307957 285565.99112765 411206.30075264
 156611.67382412 372263.54764099 564049.16288221 247240.26656223
 197073.0784728  402931.51131516 401747.45962822 305368.22931575
 368450.80509679 268167.17665994 344451.61104521 321334.35261218
 284865.25840801 320934.10418845 386855.2404235  351185.32696877
 471879.76614214 289227.52539392 403576.35497873 486006.91425309
 336245.02621994 352794.66778219 388532.0409259  408178.71290261
 295414.71765008 244362.45881279 206980.5791393  389024.84601577
 377192.04028741 361526.32840609 262994.77911831 408991.81162671
 265889.34250839 432958.17794638 267547.8794527  408386.68905551
 520764.16924198 342775.51400232 356545.29405197 315412.63014131
 459381.1847902  452926.57268455 437110.94376563 378284.62105488
 309294.57164747 423643.95909716 339447.77892176 410304.72160016
 332053.63870093 265956.04410867 394955.00372029 473823.35321145
 372001.40628478 422094.02590305 278032.3640965  452704.78498326
 386667.52522192 415194.22963342 341636.71160849 360468.18598198
 443882.22289667 434729.41589322]
2025-06-15 08:42:04 INFO Expected Optimum FE: -656.7889979935655
2025-06-15 08:42:04 INFO Multimodal (single component) AOCC mean: 0.0000
2025-06-15 08:42:04 INFO AOCC mean: 0.0000
2025-06-15 08:42:04 INFO --- GNBG Problem Parameters for f8 ---
  Dimension: 30, MaxEvals: 500000
  Search Bounds: [-100, 100]
  Number of Components: 1
  Known Optimum Value: -656.788998
  Lambda (Curvature): [1]
  Mu (Asymmetry/Depth): [0.2 0.2]
----------------------------------------
2025-06-15 08:42:05 INFO --- GNBG Problem Parameters for f8 ---
  Dimension: 30, MaxEvals: 500000
  Search Bounds: [-100, 100]
  Number of Components: 1
  Known Optimum Value: -656.788998
  Lambda (Curvature): [1]
  Mu (Asymmetry/Depth): [0.2 0.2]
----------------------------------------
2025-06-15 08:42:06 ERROR Can not run the algorithm
2025-06-15 08:42:06 INFO --- GNBG Problem Parameters for f8 ---
  Dimension: 30, MaxEvals: 500000
  Search Bounds: [-100, 100]
  Number of Components: 1
  Known Optimum Value: -656.788998
  Lambda (Curvature): [1]
  Mu (Asymmetry/Depth): [0.2 0.2]
----------------------------------------
2025-06-15 08:42:06 ERROR Can not run the algorithm
2025-06-15 08:42:06 INFO Run function 8 complete. FEHistory len: 7440, AOCC: 0.0000
2025-06-15 08:42:06 INFO FeHistory: [120437.24399269 241979.75821142 208527.50285473 ... 301078.20560304
 395206.45234433 432854.68302785]
2025-06-15 08:42:06 INFO Expected Optimum FE: -656.7889979935655
2025-06-15 08:42:06 INFO Multimodal (single component) AOCC mean: 0.0000
2025-06-15 08:42:06 INFO AOCC mean: 0.0000
2025-06-15 08:42:06 INFO Run function 8 complete. FEHistory len: 6, AOCC: 0.0000
2025-06-15 08:42:06 INFO FeHistory: [129870.54255959 132824.65154629 128240.10403304 126596.94186079
 133751.35738932 132451.82395333]
2025-06-15 08:42:06 INFO Expected Optimum FE: -656.7889979935655
2025-06-15 08:42:06 INFO Multimodal (single component) AOCC mean: 0.0000
2025-06-15 08:42:06 INFO AOCC mean: 0.0000
2025-06-15 08:42:09 INFO Run function 8 complete. FEHistory len: 50000, AOCC: 0.0000
2025-06-15 08:42:09 INFO FeHistory: [226103.17423013 278937.57454569 261486.88696863 ... 514077.12970142
 470709.17704021 327038.65161541]
2025-06-15 08:42:09 INFO Expected Optimum FE: -656.7889979935655
2025-06-15 08:42:09 INFO Multimodal (single component) AOCC mean: 0.0000
2025-06-15 08:42:09 INFO AOCC mean: 0.0000
2025-06-15 08:42:09 INFO An exception occured: Traceback (most recent call last):
  File "/Users/macbook/Documents/Code/LLMdesignedEA-comp/llamea/llamea_multi_prompts.py", line 316, in evolve_solution
    evolved_individual = self.llm.sample_solution(
                         ^^^^^^^^^^^^^^^^^^^^^^^^^
  File "/Users/macbook/Documents/Code/LLMdesignedEA-comp/llamea/llm.py", line 106, in sample_solution
    message = self.query(session_messages)
              ^^^^^^^^^^^^^^^^^^^^^^^^^^^^
  File "/Users/macbook/Documents/Code/LLMdesignedEA-comp/llamea/llm.py", line 278, in query
    response = chat_session.send_message(last["content"])
               ^^^^^^^^^^^^^^^^^^^^^^^^^^^^^^^^^^^^^^^^^^
  File "/Users/macbook/miniconda3/envs/eoh/lib/python3.12/site-packages/google/generativeai/generative_models.py", line 578, in send_message
    response = self.model.generate_content(
               ^^^^^^^^^^^^^^^^^^^^^^^^^^^^
  File "/Users/macbook/miniconda3/envs/eoh/lib/python3.12/site-packages/google/generativeai/generative_models.py", line 331, in generate_content
    response = self._client.generate_content(
               ^^^^^^^^^^^^^^^^^^^^^^^^^^^^^^
  File "/Users/macbook/miniconda3/envs/eoh/lib/python3.12/site-packages/google/ai/generativelanguage_v1beta/services/generative_service/client.py", line 835, in generate_content
    response = rpc(
               ^^^^
  File "/Users/macbook/miniconda3/envs/eoh/lib/python3.12/site-packages/google/api_core/gapic_v1/method.py", line 131, in __call__
    return wrapped_func(*args, **kwargs)
           ^^^^^^^^^^^^^^^^^^^^^^^^^^^^^
  File "/Users/macbook/miniconda3/envs/eoh/lib/python3.12/site-packages/google/api_core/retry/retry_unary.py", line 294, in retry_wrapped_func
    return retry_target(
           ^^^^^^^^^^^^^
  File "/Users/macbook/miniconda3/envs/eoh/lib/python3.12/site-packages/google/api_core/retry/retry_unary.py", line 156, in retry_target
    next_sleep = _retry_error_helper(
                 ^^^^^^^^^^^^^^^^^^^^
  File "/Users/macbook/miniconda3/envs/eoh/lib/python3.12/site-packages/google/api_core/retry/retry_base.py", line 214, in _retry_error_helper
    raise final_exc from source_exc
  File "/Users/macbook/miniconda3/envs/eoh/lib/python3.12/site-packages/google/api_core/retry/retry_unary.py", line 147, in retry_target
    result = target()
             ^^^^^^^^
  File "/Users/macbook/miniconda3/envs/eoh/lib/python3.12/site-packages/google/api_core/timeout.py", line 130, in func_with_timeout
    return func(*args, **kwargs)
           ^^^^^^^^^^^^^^^^^^^^^
  File "/Users/macbook/miniconda3/envs/eoh/lib/python3.12/site-packages/google/api_core/grpc_helpers.py", line 78, in error_remapped_callable
    raise exceptions.from_grpc_error(exc) from exc
google.api_core.exceptions.ResourceExhausted: 429 You exceeded your current quota, please check your plan and billing details. For more information on this error, head to: https://ai.google.dev/gemini-api/docs/rate-limits. [violations {
  quota_metric: "generativelanguage.googleapis.com/generate_content_free_tier_requests"
  quota_id: "GenerateRequestsPerMinutePerProjectPerModel-FreeTier"
  quota_dimensions {
    key: "model"
    value: "gemini-1.5-flash"
  }
  quota_dimensions {
    key: "location"
    value: "global"
  }
  quota_value: 15
}
, links {
  description: "Learn more about Gemini API quotas"
  url: "https://ai.google.dev/gemini-api/docs/rate-limits"
}
, retry_delay {
  seconds: 50
}
]
.
2025-06-15 08:42:09 INFO An exception occured: Traceback (most recent call last):
  File "/Users/macbook/Documents/Code/LLMdesignedEA-comp/llamea/llamea_multi_prompts.py", line 316, in evolve_solution
    evolved_individual = self.llm.sample_solution(
                         ^^^^^^^^^^^^^^^^^^^^^^^^^
  File "/Users/macbook/Documents/Code/LLMdesignedEA-comp/llamea/llm.py", line 106, in sample_solution
    message = self.query(session_messages)
              ^^^^^^^^^^^^^^^^^^^^^^^^^^^^
  File "/Users/macbook/Documents/Code/LLMdesignedEA-comp/llamea/llm.py", line 278, in query
    response = chat_session.send_message(last["content"])
               ^^^^^^^^^^^^^^^^^^^^^^^^^^^^^^^^^^^^^^^^^^
  File "/Users/macbook/miniconda3/envs/eoh/lib/python3.12/site-packages/google/generativeai/generative_models.py", line 578, in send_message
    response = self.model.generate_content(
               ^^^^^^^^^^^^^^^^^^^^^^^^^^^^
  File "/Users/macbook/miniconda3/envs/eoh/lib/python3.12/site-packages/google/generativeai/generative_models.py", line 331, in generate_content
    response = self._client.generate_content(
               ^^^^^^^^^^^^^^^^^^^^^^^^^^^^^^
  File "/Users/macbook/miniconda3/envs/eoh/lib/python3.12/site-packages/google/ai/generativelanguage_v1beta/services/generative_service/client.py", line 835, in generate_content
    response = rpc(
               ^^^^
  File "/Users/macbook/miniconda3/envs/eoh/lib/python3.12/site-packages/google/api_core/gapic_v1/method.py", line 131, in __call__
    return wrapped_func(*args, **kwargs)
           ^^^^^^^^^^^^^^^^^^^^^^^^^^^^^
  File "/Users/macbook/miniconda3/envs/eoh/lib/python3.12/site-packages/google/api_core/retry/retry_unary.py", line 294, in retry_wrapped_func
    return retry_target(
           ^^^^^^^^^^^^^
  File "/Users/macbook/miniconda3/envs/eoh/lib/python3.12/site-packages/google/api_core/retry/retry_unary.py", line 156, in retry_target
    next_sleep = _retry_error_helper(
                 ^^^^^^^^^^^^^^^^^^^^
  File "/Users/macbook/miniconda3/envs/eoh/lib/python3.12/site-packages/google/api_core/retry/retry_base.py", line 214, in _retry_error_helper
    raise final_exc from source_exc
  File "/Users/macbook/miniconda3/envs/eoh/lib/python3.12/site-packages/google/api_core/retry/retry_unary.py", line 147, in retry_target
    result = target()
             ^^^^^^^^
  File "/Users/macbook/miniconda3/envs/eoh/lib/python3.12/site-packages/google/api_core/timeout.py", line 130, in func_with_timeout
    return func(*args, **kwargs)
           ^^^^^^^^^^^^^^^^^^^^^
  File "/Users/macbook/miniconda3/envs/eoh/lib/python3.12/site-packages/google/api_core/grpc_helpers.py", line 78, in error_remapped_callable
    raise exceptions.from_grpc_error(exc) from exc
google.api_core.exceptions.ResourceExhausted: 429 You exceeded your current quota, please check your plan and billing details. For more information on this error, head to: https://ai.google.dev/gemini-api/docs/rate-limits. [violations {
  quota_metric: "generativelanguage.googleapis.com/generate_content_free_tier_requests"
  quota_id: "GenerateRequestsPerMinutePerProjectPerModel-FreeTier"
  quota_dimensions {
    key: "model"
    value: "gemini-1.5-flash"
  }
  quota_dimensions {
    key: "location"
    value: "global"
  }
  quota_value: 15
}
, links {
  description: "Learn more about Gemini API quotas"
  url: "https://ai.google.dev/gemini-api/docs/rate-limits"
}
, retry_delay {
  seconds: 50
}
]
.
2025-06-15 08:42:09 INFO An exception occured: Traceback (most recent call last):
  File "/Users/macbook/Documents/Code/LLMdesignedEA-comp/llamea/llamea_multi_prompts.py", line 316, in evolve_solution
    evolved_individual = self.llm.sample_solution(
                         ^^^^^^^^^^^^^^^^^^^^^^^^^
  File "/Users/macbook/Documents/Code/LLMdesignedEA-comp/llamea/llm.py", line 106, in sample_solution
    message = self.query(session_messages)
              ^^^^^^^^^^^^^^^^^^^^^^^^^^^^
  File "/Users/macbook/Documents/Code/LLMdesignedEA-comp/llamea/llm.py", line 278, in query
    response = chat_session.send_message(last["content"])
               ^^^^^^^^^^^^^^^^^^^^^^^^^^^^^^^^^^^^^^^^^^
  File "/Users/macbook/miniconda3/envs/eoh/lib/python3.12/site-packages/google/generativeai/generative_models.py", line 578, in send_message
    response = self.model.generate_content(
               ^^^^^^^^^^^^^^^^^^^^^^^^^^^^
  File "/Users/macbook/miniconda3/envs/eoh/lib/python3.12/site-packages/google/generativeai/generative_models.py", line 331, in generate_content
    response = self._client.generate_content(
               ^^^^^^^^^^^^^^^^^^^^^^^^^^^^^^
  File "/Users/macbook/miniconda3/envs/eoh/lib/python3.12/site-packages/google/ai/generativelanguage_v1beta/services/generative_service/client.py", line 835, in generate_content
    response = rpc(
               ^^^^
  File "/Users/macbook/miniconda3/envs/eoh/lib/python3.12/site-packages/google/api_core/gapic_v1/method.py", line 131, in __call__
    return wrapped_func(*args, **kwargs)
           ^^^^^^^^^^^^^^^^^^^^^^^^^^^^^
  File "/Users/macbook/miniconda3/envs/eoh/lib/python3.12/site-packages/google/api_core/retry/retry_unary.py", line 294, in retry_wrapped_func
    return retry_target(
           ^^^^^^^^^^^^^
  File "/Users/macbook/miniconda3/envs/eoh/lib/python3.12/site-packages/google/api_core/retry/retry_unary.py", line 156, in retry_target
    next_sleep = _retry_error_helper(
                 ^^^^^^^^^^^^^^^^^^^^
  File "/Users/macbook/miniconda3/envs/eoh/lib/python3.12/site-packages/google/api_core/retry/retry_base.py", line 214, in _retry_error_helper
    raise final_exc from source_exc
  File "/Users/macbook/miniconda3/envs/eoh/lib/python3.12/site-packages/google/api_core/retry/retry_unary.py", line 147, in retry_target
    result = target()
             ^^^^^^^^
  File "/Users/macbook/miniconda3/envs/eoh/lib/python3.12/site-packages/google/api_core/timeout.py", line 130, in func_with_timeout
    return func(*args, **kwargs)
           ^^^^^^^^^^^^^^^^^^^^^
  File "/Users/macbook/miniconda3/envs/eoh/lib/python3.12/site-packages/google/api_core/grpc_helpers.py", line 78, in error_remapped_callable
    raise exceptions.from_grpc_error(exc) from exc
google.api_core.exceptions.ResourceExhausted: 429 You exceeded your current quota, please check your plan and billing details. For more information on this error, head to: https://ai.google.dev/gemini-api/docs/rate-limits. [violations {
  quota_metric: "generativelanguage.googleapis.com/generate_content_free_tier_requests"
  quota_id: "GenerateRequestsPerMinutePerProjectPerModel-FreeTier"
  quota_dimensions {
    key: "model"
    value: "gemini-1.5-flash"
  }
  quota_dimensions {
    key: "location"
    value: "global"
  }
  quota_value: 15
}
, links {
  description: "Learn more about Gemini API quotas"
  url: "https://ai.google.dev/gemini-api/docs/rate-limits"
}
, retry_delay {
  seconds: 50
}
]
.
2025-06-15 08:42:09 INFO An exception occured: Traceback (most recent call last):
  File "/Users/macbook/Documents/Code/LLMdesignedEA-comp/llamea/llamea_multi_prompts.py", line 316, in evolve_solution
    evolved_individual = self.llm.sample_solution(
                         ^^^^^^^^^^^^^^^^^^^^^^^^^
  File "/Users/macbook/Documents/Code/LLMdesignedEA-comp/llamea/llm.py", line 106, in sample_solution
    message = self.query(session_messages)
              ^^^^^^^^^^^^^^^^^^^^^^^^^^^^
  File "/Users/macbook/Documents/Code/LLMdesignedEA-comp/llamea/llm.py", line 278, in query
    response = chat_session.send_message(last["content"])
               ^^^^^^^^^^^^^^^^^^^^^^^^^^^^^^^^^^^^^^^^^^
  File "/Users/macbook/miniconda3/envs/eoh/lib/python3.12/site-packages/google/generativeai/generative_models.py", line 578, in send_message
    response = self.model.generate_content(
               ^^^^^^^^^^^^^^^^^^^^^^^^^^^^
  File "/Users/macbook/miniconda3/envs/eoh/lib/python3.12/site-packages/google/generativeai/generative_models.py", line 331, in generate_content
    response = self._client.generate_content(
               ^^^^^^^^^^^^^^^^^^^^^^^^^^^^^^
  File "/Users/macbook/miniconda3/envs/eoh/lib/python3.12/site-packages/google/ai/generativelanguage_v1beta/services/generative_service/client.py", line 835, in generate_content
    response = rpc(
               ^^^^
  File "/Users/macbook/miniconda3/envs/eoh/lib/python3.12/site-packages/google/api_core/gapic_v1/method.py", line 131, in __call__
    return wrapped_func(*args, **kwargs)
           ^^^^^^^^^^^^^^^^^^^^^^^^^^^^^
  File "/Users/macbook/miniconda3/envs/eoh/lib/python3.12/site-packages/google/api_core/retry/retry_unary.py", line 294, in retry_wrapped_func
    return retry_target(
           ^^^^^^^^^^^^^
  File "/Users/macbook/miniconda3/envs/eoh/lib/python3.12/site-packages/google/api_core/retry/retry_unary.py", line 156, in retry_target
    next_sleep = _retry_error_helper(
                 ^^^^^^^^^^^^^^^^^^^^
  File "/Users/macbook/miniconda3/envs/eoh/lib/python3.12/site-packages/google/api_core/retry/retry_base.py", line 214, in _retry_error_helper
    raise final_exc from source_exc
  File "/Users/macbook/miniconda3/envs/eoh/lib/python3.12/site-packages/google/api_core/retry/retry_unary.py", line 147, in retry_target
    result = target()
             ^^^^^^^^
  File "/Users/macbook/miniconda3/envs/eoh/lib/python3.12/site-packages/google/api_core/timeout.py", line 130, in func_with_timeout
    return func(*args, **kwargs)
           ^^^^^^^^^^^^^^^^^^^^^
  File "/Users/macbook/miniconda3/envs/eoh/lib/python3.12/site-packages/google/api_core/grpc_helpers.py", line 78, in error_remapped_callable
    raise exceptions.from_grpc_error(exc) from exc
google.api_core.exceptions.ResourceExhausted: 429 You exceeded your current quota, please check your plan and billing details. For more information on this error, head to: https://ai.google.dev/gemini-api/docs/rate-limits. [violations {
  quota_metric: "generativelanguage.googleapis.com/generate_content_free_tier_requests"
  quota_id: "GenerateRequestsPerMinutePerProjectPerModel-FreeTier"
  quota_dimensions {
    key: "model"
    value: "gemini-1.5-flash"
  }
  quota_dimensions {
    key: "location"
    value: "global"
  }
  quota_value: 15
}
, links {
  description: "Learn more about Gemini API quotas"
  url: "https://ai.google.dev/gemini-api/docs/rate-limits"
}
, retry_delay {
  seconds: 50
}
]
.
2025-06-15 08:42:09 INFO An exception occured: Traceback (most recent call last):
  File "/Users/macbook/Documents/Code/LLMdesignedEA-comp/llamea/llamea_multi_prompts.py", line 316, in evolve_solution
    evolved_individual = self.llm.sample_solution(
                         ^^^^^^^^^^^^^^^^^^^^^^^^^
  File "/Users/macbook/Documents/Code/LLMdesignedEA-comp/llamea/llm.py", line 106, in sample_solution
    message = self.query(session_messages)
              ^^^^^^^^^^^^^^^^^^^^^^^^^^^^
  File "/Users/macbook/Documents/Code/LLMdesignedEA-comp/llamea/llm.py", line 278, in query
    response = chat_session.send_message(last["content"])
               ^^^^^^^^^^^^^^^^^^^^^^^^^^^^^^^^^^^^^^^^^^
  File "/Users/macbook/miniconda3/envs/eoh/lib/python3.12/site-packages/google/generativeai/generative_models.py", line 578, in send_message
    response = self.model.generate_content(
               ^^^^^^^^^^^^^^^^^^^^^^^^^^^^
  File "/Users/macbook/miniconda3/envs/eoh/lib/python3.12/site-packages/google/generativeai/generative_models.py", line 331, in generate_content
    response = self._client.generate_content(
               ^^^^^^^^^^^^^^^^^^^^^^^^^^^^^^
  File "/Users/macbook/miniconda3/envs/eoh/lib/python3.12/site-packages/google/ai/generativelanguage_v1beta/services/generative_service/client.py", line 835, in generate_content
    response = rpc(
               ^^^^
  File "/Users/macbook/miniconda3/envs/eoh/lib/python3.12/site-packages/google/api_core/gapic_v1/method.py", line 131, in __call__
    return wrapped_func(*args, **kwargs)
           ^^^^^^^^^^^^^^^^^^^^^^^^^^^^^
  File "/Users/macbook/miniconda3/envs/eoh/lib/python3.12/site-packages/google/api_core/retry/retry_unary.py", line 294, in retry_wrapped_func
    return retry_target(
           ^^^^^^^^^^^^^
  File "/Users/macbook/miniconda3/envs/eoh/lib/python3.12/site-packages/google/api_core/retry/retry_unary.py", line 156, in retry_target
    next_sleep = _retry_error_helper(
                 ^^^^^^^^^^^^^^^^^^^^
  File "/Users/macbook/miniconda3/envs/eoh/lib/python3.12/site-packages/google/api_core/retry/retry_base.py", line 214, in _retry_error_helper
    raise final_exc from source_exc
  File "/Users/macbook/miniconda3/envs/eoh/lib/python3.12/site-packages/google/api_core/retry/retry_unary.py", line 147, in retry_target
    result = target()
             ^^^^^^^^
  File "/Users/macbook/miniconda3/envs/eoh/lib/python3.12/site-packages/google/api_core/timeout.py", line 130, in func_with_timeout
    return func(*args, **kwargs)
           ^^^^^^^^^^^^^^^^^^^^^
  File "/Users/macbook/miniconda3/envs/eoh/lib/python3.12/site-packages/google/api_core/grpc_helpers.py", line 78, in error_remapped_callable
    raise exceptions.from_grpc_error(exc) from exc
google.api_core.exceptions.ResourceExhausted: 429 You exceeded your current quota, please check your plan and billing details. For more information on this error, head to: https://ai.google.dev/gemini-api/docs/rate-limits. [violations {
  quota_metric: "generativelanguage.googleapis.com/generate_content_free_tier_requests"
  quota_id: "GenerateRequestsPerMinutePerProjectPerModel-FreeTier"
  quota_dimensions {
    key: "model"
    value: "gemini-1.5-flash"
  }
  quota_dimensions {
    key: "location"
    value: "global"
  }
  quota_value: 15
}
, links {
  description: "Learn more about Gemini API quotas"
  url: "https://ai.google.dev/gemini-api/docs/rate-limits"
}
, retry_delay {
  seconds: 50
}
]
.
2025-06-15 08:42:09 INFO An exception occured: Traceback (most recent call last):
  File "/Users/macbook/Documents/Code/LLMdesignedEA-comp/llamea/llamea_multi_prompts.py", line 316, in evolve_solution
    evolved_individual = self.llm.sample_solution(
                         ^^^^^^^^^^^^^^^^^^^^^^^^^
  File "/Users/macbook/Documents/Code/LLMdesignedEA-comp/llamea/llm.py", line 106, in sample_solution
    message = self.query(session_messages)
              ^^^^^^^^^^^^^^^^^^^^^^^^^^^^
  File "/Users/macbook/Documents/Code/LLMdesignedEA-comp/llamea/llm.py", line 278, in query
    response = chat_session.send_message(last["content"])
               ^^^^^^^^^^^^^^^^^^^^^^^^^^^^^^^^^^^^^^^^^^
  File "/Users/macbook/miniconda3/envs/eoh/lib/python3.12/site-packages/google/generativeai/generative_models.py", line 578, in send_message
    response = self.model.generate_content(
               ^^^^^^^^^^^^^^^^^^^^^^^^^^^^
  File "/Users/macbook/miniconda3/envs/eoh/lib/python3.12/site-packages/google/generativeai/generative_models.py", line 331, in generate_content
    response = self._client.generate_content(
               ^^^^^^^^^^^^^^^^^^^^^^^^^^^^^^
  File "/Users/macbook/miniconda3/envs/eoh/lib/python3.12/site-packages/google/ai/generativelanguage_v1beta/services/generative_service/client.py", line 835, in generate_content
    response = rpc(
               ^^^^
  File "/Users/macbook/miniconda3/envs/eoh/lib/python3.12/site-packages/google/api_core/gapic_v1/method.py", line 131, in __call__
    return wrapped_func(*args, **kwargs)
           ^^^^^^^^^^^^^^^^^^^^^^^^^^^^^
  File "/Users/macbook/miniconda3/envs/eoh/lib/python3.12/site-packages/google/api_core/retry/retry_unary.py", line 294, in retry_wrapped_func
    return retry_target(
           ^^^^^^^^^^^^^
  File "/Users/macbook/miniconda3/envs/eoh/lib/python3.12/site-packages/google/api_core/retry/retry_unary.py", line 156, in retry_target
    next_sleep = _retry_error_helper(
                 ^^^^^^^^^^^^^^^^^^^^
  File "/Users/macbook/miniconda3/envs/eoh/lib/python3.12/site-packages/google/api_core/retry/retry_base.py", line 214, in _retry_error_helper
    raise final_exc from source_exc
  File "/Users/macbook/miniconda3/envs/eoh/lib/python3.12/site-packages/google/api_core/retry/retry_unary.py", line 147, in retry_target
    result = target()
             ^^^^^^^^
  File "/Users/macbook/miniconda3/envs/eoh/lib/python3.12/site-packages/google/api_core/timeout.py", line 130, in func_with_timeout
    return func(*args, **kwargs)
           ^^^^^^^^^^^^^^^^^^^^^
  File "/Users/macbook/miniconda3/envs/eoh/lib/python3.12/site-packages/google/api_core/grpc_helpers.py", line 78, in error_remapped_callable
    raise exceptions.from_grpc_error(exc) from exc
google.api_core.exceptions.ResourceExhausted: 429 You exceeded your current quota, please check your plan and billing details. For more information on this error, head to: https://ai.google.dev/gemini-api/docs/rate-limits. [violations {
  quota_metric: "generativelanguage.googleapis.com/generate_content_free_tier_requests"
  quota_id: "GenerateRequestsPerMinutePerProjectPerModel-FreeTier"
  quota_dimensions {
    key: "model"
    value: "gemini-1.5-flash"
  }
  quota_dimensions {
    key: "location"
    value: "global"
  }
  quota_value: 15
}
, links {
  description: "Learn more about Gemini API quotas"
  url: "https://ai.google.dev/gemini-api/docs/rate-limits"
}
, retry_delay {
  seconds: 50
}
]
.
2025-06-15 08:42:10 INFO An exception occured: Traceback (most recent call last):
  File "/Users/macbook/Documents/Code/LLMdesignedEA-comp/llamea/llamea_multi_prompts.py", line 316, in evolve_solution
    evolved_individual = self.llm.sample_solution(
                         ^^^^^^^^^^^^^^^^^^^^^^^^^
  File "/Users/macbook/Documents/Code/LLMdesignedEA-comp/llamea/llm.py", line 106, in sample_solution
    message = self.query(session_messages)
              ^^^^^^^^^^^^^^^^^^^^^^^^^^^^
  File "/Users/macbook/Documents/Code/LLMdesignedEA-comp/llamea/llm.py", line 278, in query
    response = chat_session.send_message(last["content"])
               ^^^^^^^^^^^^^^^^^^^^^^^^^^^^^^^^^^^^^^^^^^
  File "/Users/macbook/miniconda3/envs/eoh/lib/python3.12/site-packages/google/generativeai/generative_models.py", line 578, in send_message
    response = self.model.generate_content(
               ^^^^^^^^^^^^^^^^^^^^^^^^^^^^
  File "/Users/macbook/miniconda3/envs/eoh/lib/python3.12/site-packages/google/generativeai/generative_models.py", line 331, in generate_content
    response = self._client.generate_content(
               ^^^^^^^^^^^^^^^^^^^^^^^^^^^^^^
  File "/Users/macbook/miniconda3/envs/eoh/lib/python3.12/site-packages/google/ai/generativelanguage_v1beta/services/generative_service/client.py", line 835, in generate_content
    response = rpc(
               ^^^^
  File "/Users/macbook/miniconda3/envs/eoh/lib/python3.12/site-packages/google/api_core/gapic_v1/method.py", line 131, in __call__
    return wrapped_func(*args, **kwargs)
           ^^^^^^^^^^^^^^^^^^^^^^^^^^^^^
  File "/Users/macbook/miniconda3/envs/eoh/lib/python3.12/site-packages/google/api_core/retry/retry_unary.py", line 294, in retry_wrapped_func
    return retry_target(
           ^^^^^^^^^^^^^
  File "/Users/macbook/miniconda3/envs/eoh/lib/python3.12/site-packages/google/api_core/retry/retry_unary.py", line 156, in retry_target
    next_sleep = _retry_error_helper(
                 ^^^^^^^^^^^^^^^^^^^^
  File "/Users/macbook/miniconda3/envs/eoh/lib/python3.12/site-packages/google/api_core/retry/retry_base.py", line 214, in _retry_error_helper
    raise final_exc from source_exc
  File "/Users/macbook/miniconda3/envs/eoh/lib/python3.12/site-packages/google/api_core/retry/retry_unary.py", line 147, in retry_target
    result = target()
             ^^^^^^^^
  File "/Users/macbook/miniconda3/envs/eoh/lib/python3.12/site-packages/google/api_core/timeout.py", line 130, in func_with_timeout
    return func(*args, **kwargs)
           ^^^^^^^^^^^^^^^^^^^^^
  File "/Users/macbook/miniconda3/envs/eoh/lib/python3.12/site-packages/google/api_core/grpc_helpers.py", line 78, in error_remapped_callable
    raise exceptions.from_grpc_error(exc) from exc
google.api_core.exceptions.ResourceExhausted: 429 You exceeded your current quota, please check your plan and billing details. For more information on this error, head to: https://ai.google.dev/gemini-api/docs/rate-limits. [violations {
  quota_metric: "generativelanguage.googleapis.com/generate_content_free_tier_requests"
  quota_id: "GenerateRequestsPerMinutePerProjectPerModel-FreeTier"
  quota_dimensions {
    key: "model"
    value: "gemini-1.5-flash"
  }
  quota_dimensions {
    key: "location"
    value: "global"
  }
  quota_value: 15
}
, links {
  description: "Learn more about Gemini API quotas"
  url: "https://ai.google.dev/gemini-api/docs/rate-limits"
}
, retry_delay {
  seconds: 49
}
]
.
2025-06-15 08:42:10 INFO An exception occured: Traceback (most recent call last):
  File "/Users/macbook/Documents/Code/LLMdesignedEA-comp/llamea/llamea_multi_prompts.py", line 316, in evolve_solution
    evolved_individual = self.llm.sample_solution(
                         ^^^^^^^^^^^^^^^^^^^^^^^^^
  File "/Users/macbook/Documents/Code/LLMdesignedEA-comp/llamea/llm.py", line 106, in sample_solution
    message = self.query(session_messages)
              ^^^^^^^^^^^^^^^^^^^^^^^^^^^^
  File "/Users/macbook/Documents/Code/LLMdesignedEA-comp/llamea/llm.py", line 278, in query
    response = chat_session.send_message(last["content"])
               ^^^^^^^^^^^^^^^^^^^^^^^^^^^^^^^^^^^^^^^^^^
  File "/Users/macbook/miniconda3/envs/eoh/lib/python3.12/site-packages/google/generativeai/generative_models.py", line 578, in send_message
    response = self.model.generate_content(
               ^^^^^^^^^^^^^^^^^^^^^^^^^^^^
  File "/Users/macbook/miniconda3/envs/eoh/lib/python3.12/site-packages/google/generativeai/generative_models.py", line 331, in generate_content
    response = self._client.generate_content(
               ^^^^^^^^^^^^^^^^^^^^^^^^^^^^^^
  File "/Users/macbook/miniconda3/envs/eoh/lib/python3.12/site-packages/google/ai/generativelanguage_v1beta/services/generative_service/client.py", line 835, in generate_content
    response = rpc(
               ^^^^
  File "/Users/macbook/miniconda3/envs/eoh/lib/python3.12/site-packages/google/api_core/gapic_v1/method.py", line 131, in __call__
    return wrapped_func(*args, **kwargs)
           ^^^^^^^^^^^^^^^^^^^^^^^^^^^^^
  File "/Users/macbook/miniconda3/envs/eoh/lib/python3.12/site-packages/google/api_core/retry/retry_unary.py", line 294, in retry_wrapped_func
    return retry_target(
           ^^^^^^^^^^^^^
  File "/Users/macbook/miniconda3/envs/eoh/lib/python3.12/site-packages/google/api_core/retry/retry_unary.py", line 156, in retry_target
    next_sleep = _retry_error_helper(
                 ^^^^^^^^^^^^^^^^^^^^
  File "/Users/macbook/miniconda3/envs/eoh/lib/python3.12/site-packages/google/api_core/retry/retry_base.py", line 214, in _retry_error_helper
    raise final_exc from source_exc
  File "/Users/macbook/miniconda3/envs/eoh/lib/python3.12/site-packages/google/api_core/retry/retry_unary.py", line 147, in retry_target
    result = target()
             ^^^^^^^^
  File "/Users/macbook/miniconda3/envs/eoh/lib/python3.12/site-packages/google/api_core/timeout.py", line 130, in func_with_timeout
    return func(*args, **kwargs)
           ^^^^^^^^^^^^^^^^^^^^^
  File "/Users/macbook/miniconda3/envs/eoh/lib/python3.12/site-packages/google/api_core/grpc_helpers.py", line 78, in error_remapped_callable
    raise exceptions.from_grpc_error(exc) from exc
google.api_core.exceptions.ResourceExhausted: 429 You exceeded your current quota, please check your plan and billing details. For more information on this error, head to: https://ai.google.dev/gemini-api/docs/rate-limits. [violations {
  quota_metric: "generativelanguage.googleapis.com/generate_content_free_tier_requests"
  quota_id: "GenerateRequestsPerMinutePerProjectPerModel-FreeTier"
  quota_dimensions {
    key: "model"
    value: "gemini-1.5-flash"
  }
  quota_dimensions {
    key: "location"
    value: "global"
  }
  quota_value: 15
}
, links {
  description: "Learn more about Gemini API quotas"
  url: "https://ai.google.dev/gemini-api/docs/rate-limits"
}
, retry_delay {
  seconds: 49
}
]
.
2025-06-15 08:42:10 INFO An exception occured: Traceback (most recent call last):
  File "/Users/macbook/Documents/Code/LLMdesignedEA-comp/llamea/llamea_multi_prompts.py", line 316, in evolve_solution
    evolved_individual = self.llm.sample_solution(
                         ^^^^^^^^^^^^^^^^^^^^^^^^^
  File "/Users/macbook/Documents/Code/LLMdesignedEA-comp/llamea/llm.py", line 106, in sample_solution
    message = self.query(session_messages)
              ^^^^^^^^^^^^^^^^^^^^^^^^^^^^
  File "/Users/macbook/Documents/Code/LLMdesignedEA-comp/llamea/llm.py", line 278, in query
    response = chat_session.send_message(last["content"])
               ^^^^^^^^^^^^^^^^^^^^^^^^^^^^^^^^^^^^^^^^^^
  File "/Users/macbook/miniconda3/envs/eoh/lib/python3.12/site-packages/google/generativeai/generative_models.py", line 578, in send_message
    response = self.model.generate_content(
               ^^^^^^^^^^^^^^^^^^^^^^^^^^^^
  File "/Users/macbook/miniconda3/envs/eoh/lib/python3.12/site-packages/google/generativeai/generative_models.py", line 331, in generate_content
    response = self._client.generate_content(
               ^^^^^^^^^^^^^^^^^^^^^^^^^^^^^^
  File "/Users/macbook/miniconda3/envs/eoh/lib/python3.12/site-packages/google/ai/generativelanguage_v1beta/services/generative_service/client.py", line 835, in generate_content
    response = rpc(
               ^^^^
  File "/Users/macbook/miniconda3/envs/eoh/lib/python3.12/site-packages/google/api_core/gapic_v1/method.py", line 131, in __call__
    return wrapped_func(*args, **kwargs)
           ^^^^^^^^^^^^^^^^^^^^^^^^^^^^^
  File "/Users/macbook/miniconda3/envs/eoh/lib/python3.12/site-packages/google/api_core/retry/retry_unary.py", line 294, in retry_wrapped_func
    return retry_target(
           ^^^^^^^^^^^^^
  File "/Users/macbook/miniconda3/envs/eoh/lib/python3.12/site-packages/google/api_core/retry/retry_unary.py", line 156, in retry_target
    next_sleep = _retry_error_helper(
                 ^^^^^^^^^^^^^^^^^^^^
  File "/Users/macbook/miniconda3/envs/eoh/lib/python3.12/site-packages/google/api_core/retry/retry_base.py", line 214, in _retry_error_helper
    raise final_exc from source_exc
  File "/Users/macbook/miniconda3/envs/eoh/lib/python3.12/site-packages/google/api_core/retry/retry_unary.py", line 147, in retry_target
    result = target()
             ^^^^^^^^
  File "/Users/macbook/miniconda3/envs/eoh/lib/python3.12/site-packages/google/api_core/timeout.py", line 130, in func_with_timeout
    return func(*args, **kwargs)
           ^^^^^^^^^^^^^^^^^^^^^
  File "/Users/macbook/miniconda3/envs/eoh/lib/python3.12/site-packages/google/api_core/grpc_helpers.py", line 78, in error_remapped_callable
    raise exceptions.from_grpc_error(exc) from exc
google.api_core.exceptions.ResourceExhausted: 429 You exceeded your current quota, please check your plan and billing details. For more information on this error, head to: https://ai.google.dev/gemini-api/docs/rate-limits. [violations {
  quota_metric: "generativelanguage.googleapis.com/generate_content_free_tier_requests"
  quota_id: "GenerateRequestsPerMinutePerProjectPerModel-FreeTier"
  quota_dimensions {
    key: "model"
    value: "gemini-1.5-flash"
  }
  quota_dimensions {
    key: "location"
    value: "global"
  }
  quota_value: 15
}
, links {
  description: "Learn more about Gemini API quotas"
  url: "https://ai.google.dev/gemini-api/docs/rate-limits"
}
, retry_delay {
  seconds: 49
}
]
.
2025-06-15 08:42:10 INFO An exception occured: Traceback (most recent call last):
  File "/Users/macbook/Documents/Code/LLMdesignedEA-comp/llamea/llamea_multi_prompts.py", line 316, in evolve_solution
    evolved_individual = self.llm.sample_solution(
                         ^^^^^^^^^^^^^^^^^^^^^^^^^
  File "/Users/macbook/Documents/Code/LLMdesignedEA-comp/llamea/llm.py", line 106, in sample_solution
    message = self.query(session_messages)
              ^^^^^^^^^^^^^^^^^^^^^^^^^^^^
  File "/Users/macbook/Documents/Code/LLMdesignedEA-comp/llamea/llm.py", line 278, in query
    response = chat_session.send_message(last["content"])
               ^^^^^^^^^^^^^^^^^^^^^^^^^^^^^^^^^^^^^^^^^^
  File "/Users/macbook/miniconda3/envs/eoh/lib/python3.12/site-packages/google/generativeai/generative_models.py", line 578, in send_message
    response = self.model.generate_content(
               ^^^^^^^^^^^^^^^^^^^^^^^^^^^^
  File "/Users/macbook/miniconda3/envs/eoh/lib/python3.12/site-packages/google/generativeai/generative_models.py", line 331, in generate_content
    response = self._client.generate_content(
               ^^^^^^^^^^^^^^^^^^^^^^^^^^^^^^
  File "/Users/macbook/miniconda3/envs/eoh/lib/python3.12/site-packages/google/ai/generativelanguage_v1beta/services/generative_service/client.py", line 835, in generate_content
    response = rpc(
               ^^^^
  File "/Users/macbook/miniconda3/envs/eoh/lib/python3.12/site-packages/google/api_core/gapic_v1/method.py", line 131, in __call__
    return wrapped_func(*args, **kwargs)
           ^^^^^^^^^^^^^^^^^^^^^^^^^^^^^
  File "/Users/macbook/miniconda3/envs/eoh/lib/python3.12/site-packages/google/api_core/retry/retry_unary.py", line 294, in retry_wrapped_func
    return retry_target(
           ^^^^^^^^^^^^^
  File "/Users/macbook/miniconda3/envs/eoh/lib/python3.12/site-packages/google/api_core/retry/retry_unary.py", line 156, in retry_target
    next_sleep = _retry_error_helper(
                 ^^^^^^^^^^^^^^^^^^^^
  File "/Users/macbook/miniconda3/envs/eoh/lib/python3.12/site-packages/google/api_core/retry/retry_base.py", line 214, in _retry_error_helper
    raise final_exc from source_exc
  File "/Users/macbook/miniconda3/envs/eoh/lib/python3.12/site-packages/google/api_core/retry/retry_unary.py", line 147, in retry_target
    result = target()
             ^^^^^^^^
  File "/Users/macbook/miniconda3/envs/eoh/lib/python3.12/site-packages/google/api_core/timeout.py", line 130, in func_with_timeout
    return func(*args, **kwargs)
           ^^^^^^^^^^^^^^^^^^^^^
  File "/Users/macbook/miniconda3/envs/eoh/lib/python3.12/site-packages/google/api_core/grpc_helpers.py", line 78, in error_remapped_callable
    raise exceptions.from_grpc_error(exc) from exc
google.api_core.exceptions.ResourceExhausted: 429 You exceeded your current quota, please check your plan and billing details. For more information on this error, head to: https://ai.google.dev/gemini-api/docs/rate-limits. [violations {
  quota_metric: "generativelanguage.googleapis.com/generate_content_free_tier_requests"
  quota_id: "GenerateRequestsPerMinutePerProjectPerModel-FreeTier"
  quota_dimensions {
    key: "model"
    value: "gemini-1.5-flash"
  }
  quota_dimensions {
    key: "location"
    value: "global"
  }
  quota_value: 15
}
, links {
  description: "Learn more about Gemini API quotas"
  url: "https://ai.google.dev/gemini-api/docs/rate-limits"
}
, retry_delay {
  seconds: 49
}
]
.
2025-06-15 08:42:10 INFO An exception occured: Traceback (most recent call last):
  File "/Users/macbook/Documents/Code/LLMdesignedEA-comp/llamea/llamea_multi_prompts.py", line 316, in evolve_solution
    evolved_individual = self.llm.sample_solution(
                         ^^^^^^^^^^^^^^^^^^^^^^^^^
  File "/Users/macbook/Documents/Code/LLMdesignedEA-comp/llamea/llm.py", line 106, in sample_solution
    message = self.query(session_messages)
              ^^^^^^^^^^^^^^^^^^^^^^^^^^^^
  File "/Users/macbook/Documents/Code/LLMdesignedEA-comp/llamea/llm.py", line 278, in query
    response = chat_session.send_message(last["content"])
               ^^^^^^^^^^^^^^^^^^^^^^^^^^^^^^^^^^^^^^^^^^
  File "/Users/macbook/miniconda3/envs/eoh/lib/python3.12/site-packages/google/generativeai/generative_models.py", line 578, in send_message
    response = self.model.generate_content(
               ^^^^^^^^^^^^^^^^^^^^^^^^^^^^
  File "/Users/macbook/miniconda3/envs/eoh/lib/python3.12/site-packages/google/generativeai/generative_models.py", line 331, in generate_content
    response = self._client.generate_content(
               ^^^^^^^^^^^^^^^^^^^^^^^^^^^^^^
  File "/Users/macbook/miniconda3/envs/eoh/lib/python3.12/site-packages/google/ai/generativelanguage_v1beta/services/generative_service/client.py", line 835, in generate_content
    response = rpc(
               ^^^^
  File "/Users/macbook/miniconda3/envs/eoh/lib/python3.12/site-packages/google/api_core/gapic_v1/method.py", line 131, in __call__
    return wrapped_func(*args, **kwargs)
           ^^^^^^^^^^^^^^^^^^^^^^^^^^^^^
  File "/Users/macbook/miniconda3/envs/eoh/lib/python3.12/site-packages/google/api_core/retry/retry_unary.py", line 294, in retry_wrapped_func
    return retry_target(
           ^^^^^^^^^^^^^
  File "/Users/macbook/miniconda3/envs/eoh/lib/python3.12/site-packages/google/api_core/retry/retry_unary.py", line 156, in retry_target
    next_sleep = _retry_error_helper(
                 ^^^^^^^^^^^^^^^^^^^^
  File "/Users/macbook/miniconda3/envs/eoh/lib/python3.12/site-packages/google/api_core/retry/retry_base.py", line 214, in _retry_error_helper
    raise final_exc from source_exc
  File "/Users/macbook/miniconda3/envs/eoh/lib/python3.12/site-packages/google/api_core/retry/retry_unary.py", line 147, in retry_target
    result = target()
             ^^^^^^^^
  File "/Users/macbook/miniconda3/envs/eoh/lib/python3.12/site-packages/google/api_core/timeout.py", line 130, in func_with_timeout
    return func(*args, **kwargs)
           ^^^^^^^^^^^^^^^^^^^^^
  File "/Users/macbook/miniconda3/envs/eoh/lib/python3.12/site-packages/google/api_core/grpc_helpers.py", line 78, in error_remapped_callable
    raise exceptions.from_grpc_error(exc) from exc
google.api_core.exceptions.ResourceExhausted: 429 You exceeded your current quota, please check your plan and billing details. For more information on this error, head to: https://ai.google.dev/gemini-api/docs/rate-limits. [violations {
  quota_metric: "generativelanguage.googleapis.com/generate_content_free_tier_requests"
  quota_id: "GenerateRequestsPerMinutePerProjectPerModel-FreeTier"
  quota_dimensions {
    key: "model"
    value: "gemini-1.5-flash"
  }
  quota_dimensions {
    key: "location"
    value: "global"
  }
  quota_value: 15
}
, links {
  description: "Learn more about Gemini API quotas"
  url: "https://ai.google.dev/gemini-api/docs/rate-limits"
}
, retry_delay {
  seconds: 49
}
]
.
2025-06-15 08:42:10 INFO An exception occured: Traceback (most recent call last):
  File "/Users/macbook/Documents/Code/LLMdesignedEA-comp/llamea/llamea_multi_prompts.py", line 316, in evolve_solution
    evolved_individual = self.llm.sample_solution(
                         ^^^^^^^^^^^^^^^^^^^^^^^^^
  File "/Users/macbook/Documents/Code/LLMdesignedEA-comp/llamea/llm.py", line 106, in sample_solution
    message = self.query(session_messages)
              ^^^^^^^^^^^^^^^^^^^^^^^^^^^^
  File "/Users/macbook/Documents/Code/LLMdesignedEA-comp/llamea/llm.py", line 278, in query
    response = chat_session.send_message(last["content"])
               ^^^^^^^^^^^^^^^^^^^^^^^^^^^^^^^^^^^^^^^^^^
  File "/Users/macbook/miniconda3/envs/eoh/lib/python3.12/site-packages/google/generativeai/generative_models.py", line 578, in send_message
    response = self.model.generate_content(
               ^^^^^^^^^^^^^^^^^^^^^^^^^^^^
  File "/Users/macbook/miniconda3/envs/eoh/lib/python3.12/site-packages/google/generativeai/generative_models.py", line 331, in generate_content
    response = self._client.generate_content(
               ^^^^^^^^^^^^^^^^^^^^^^^^^^^^^^
  File "/Users/macbook/miniconda3/envs/eoh/lib/python3.12/site-packages/google/ai/generativelanguage_v1beta/services/generative_service/client.py", line 835, in generate_content
    response = rpc(
               ^^^^
  File "/Users/macbook/miniconda3/envs/eoh/lib/python3.12/site-packages/google/api_core/gapic_v1/method.py", line 131, in __call__
    return wrapped_func(*args, **kwargs)
           ^^^^^^^^^^^^^^^^^^^^^^^^^^^^^
  File "/Users/macbook/miniconda3/envs/eoh/lib/python3.12/site-packages/google/api_core/retry/retry_unary.py", line 294, in retry_wrapped_func
    return retry_target(
           ^^^^^^^^^^^^^
  File "/Users/macbook/miniconda3/envs/eoh/lib/python3.12/site-packages/google/api_core/retry/retry_unary.py", line 156, in retry_target
    next_sleep = _retry_error_helper(
                 ^^^^^^^^^^^^^^^^^^^^
  File "/Users/macbook/miniconda3/envs/eoh/lib/python3.12/site-packages/google/api_core/retry/retry_base.py", line 214, in _retry_error_helper
    raise final_exc from source_exc
  File "/Users/macbook/miniconda3/envs/eoh/lib/python3.12/site-packages/google/api_core/retry/retry_unary.py", line 147, in retry_target
    result = target()
             ^^^^^^^^
  File "/Users/macbook/miniconda3/envs/eoh/lib/python3.12/site-packages/google/api_core/timeout.py", line 130, in func_with_timeout
    return func(*args, **kwargs)
           ^^^^^^^^^^^^^^^^^^^^^
  File "/Users/macbook/miniconda3/envs/eoh/lib/python3.12/site-packages/google/api_core/grpc_helpers.py", line 78, in error_remapped_callable
    raise exceptions.from_grpc_error(exc) from exc
google.api_core.exceptions.ResourceExhausted: 429 You exceeded your current quota, please check your plan and billing details. For more information on this error, head to: https://ai.google.dev/gemini-api/docs/rate-limits. [violations {
  quota_metric: "generativelanguage.googleapis.com/generate_content_free_tier_requests"
  quota_id: "GenerateRequestsPerMinutePerProjectPerModel-FreeTier"
  quota_dimensions {
    key: "model"
    value: "gemini-1.5-flash"
  }
  quota_dimensions {
    key: "location"
    value: "global"
  }
  quota_value: 15
}
, links {
  description: "Learn more about Gemini API quotas"
  url: "https://ai.google.dev/gemini-api/docs/rate-limits"
}
, retry_delay {
  seconds: 49
}
]
.
2025-06-15 08:42:11 INFO An exception occured: Traceback (most recent call last):
  File "/Users/macbook/Documents/Code/LLMdesignedEA-comp/llamea/llamea_multi_prompts.py", line 316, in evolve_solution
    evolved_individual = self.llm.sample_solution(
                         ^^^^^^^^^^^^^^^^^^^^^^^^^
  File "/Users/macbook/Documents/Code/LLMdesignedEA-comp/llamea/llm.py", line 106, in sample_solution
    message = self.query(session_messages)
              ^^^^^^^^^^^^^^^^^^^^^^^^^^^^
  File "/Users/macbook/Documents/Code/LLMdesignedEA-comp/llamea/llm.py", line 278, in query
    response = chat_session.send_message(last["content"])
               ^^^^^^^^^^^^^^^^^^^^^^^^^^^^^^^^^^^^^^^^^^
  File "/Users/macbook/miniconda3/envs/eoh/lib/python3.12/site-packages/google/generativeai/generative_models.py", line 578, in send_message
    response = self.model.generate_content(
               ^^^^^^^^^^^^^^^^^^^^^^^^^^^^
  File "/Users/macbook/miniconda3/envs/eoh/lib/python3.12/site-packages/google/generativeai/generative_models.py", line 331, in generate_content
    response = self._client.generate_content(
               ^^^^^^^^^^^^^^^^^^^^^^^^^^^^^^
  File "/Users/macbook/miniconda3/envs/eoh/lib/python3.12/site-packages/google/ai/generativelanguage_v1beta/services/generative_service/client.py", line 835, in generate_content
    response = rpc(
               ^^^^
  File "/Users/macbook/miniconda3/envs/eoh/lib/python3.12/site-packages/google/api_core/gapic_v1/method.py", line 131, in __call__
    return wrapped_func(*args, **kwargs)
           ^^^^^^^^^^^^^^^^^^^^^^^^^^^^^
  File "/Users/macbook/miniconda3/envs/eoh/lib/python3.12/site-packages/google/api_core/retry/retry_unary.py", line 294, in retry_wrapped_func
    return retry_target(
           ^^^^^^^^^^^^^
  File "/Users/macbook/miniconda3/envs/eoh/lib/python3.12/site-packages/google/api_core/retry/retry_unary.py", line 156, in retry_target
    next_sleep = _retry_error_helper(
                 ^^^^^^^^^^^^^^^^^^^^
  File "/Users/macbook/miniconda3/envs/eoh/lib/python3.12/site-packages/google/api_core/retry/retry_base.py", line 214, in _retry_error_helper
    raise final_exc from source_exc
  File "/Users/macbook/miniconda3/envs/eoh/lib/python3.12/site-packages/google/api_core/retry/retry_unary.py", line 147, in retry_target
    result = target()
             ^^^^^^^^
  File "/Users/macbook/miniconda3/envs/eoh/lib/python3.12/site-packages/google/api_core/timeout.py", line 130, in func_with_timeout
    return func(*args, **kwargs)
           ^^^^^^^^^^^^^^^^^^^^^
  File "/Users/macbook/miniconda3/envs/eoh/lib/python3.12/site-packages/google/api_core/grpc_helpers.py", line 78, in error_remapped_callable
    raise exceptions.from_grpc_error(exc) from exc
google.api_core.exceptions.ResourceExhausted: 429 You exceeded your current quota, please check your plan and billing details. For more information on this error, head to: https://ai.google.dev/gemini-api/docs/rate-limits. [violations {
  quota_metric: "generativelanguage.googleapis.com/generate_content_free_tier_requests"
  quota_id: "GenerateRequestsPerMinutePerProjectPerModel-FreeTier"
  quota_dimensions {
    key: "model"
    value: "gemini-1.5-flash"
  }
  quota_dimensions {
    key: "location"
    value: "global"
  }
  quota_value: 15
}
, links {
  description: "Learn more about Gemini API quotas"
  url: "https://ai.google.dev/gemini-api/docs/rate-limits"
}
, retry_delay {
  seconds: 49
}
]
.
2025-06-15 08:42:11 INFO An exception occured: Traceback (most recent call last):
  File "/Users/macbook/Documents/Code/LLMdesignedEA-comp/llamea/llamea_multi_prompts.py", line 316, in evolve_solution
    evolved_individual = self.llm.sample_solution(
                         ^^^^^^^^^^^^^^^^^^^^^^^^^
  File "/Users/macbook/Documents/Code/LLMdesignedEA-comp/llamea/llm.py", line 106, in sample_solution
    message = self.query(session_messages)
              ^^^^^^^^^^^^^^^^^^^^^^^^^^^^
  File "/Users/macbook/Documents/Code/LLMdesignedEA-comp/llamea/llm.py", line 278, in query
    response = chat_session.send_message(last["content"])
               ^^^^^^^^^^^^^^^^^^^^^^^^^^^^^^^^^^^^^^^^^^
  File "/Users/macbook/miniconda3/envs/eoh/lib/python3.12/site-packages/google/generativeai/generative_models.py", line 578, in send_message
    response = self.model.generate_content(
               ^^^^^^^^^^^^^^^^^^^^^^^^^^^^
  File "/Users/macbook/miniconda3/envs/eoh/lib/python3.12/site-packages/google/generativeai/generative_models.py", line 331, in generate_content
    response = self._client.generate_content(
               ^^^^^^^^^^^^^^^^^^^^^^^^^^^^^^
  File "/Users/macbook/miniconda3/envs/eoh/lib/python3.12/site-packages/google/ai/generativelanguage_v1beta/services/generative_service/client.py", line 835, in generate_content
    response = rpc(
               ^^^^
  File "/Users/macbook/miniconda3/envs/eoh/lib/python3.12/site-packages/google/api_core/gapic_v1/method.py", line 131, in __call__
    return wrapped_func(*args, **kwargs)
           ^^^^^^^^^^^^^^^^^^^^^^^^^^^^^
  File "/Users/macbook/miniconda3/envs/eoh/lib/python3.12/site-packages/google/api_core/retry/retry_unary.py", line 294, in retry_wrapped_func
    return retry_target(
           ^^^^^^^^^^^^^
  File "/Users/macbook/miniconda3/envs/eoh/lib/python3.12/site-packages/google/api_core/retry/retry_unary.py", line 156, in retry_target
    next_sleep = _retry_error_helper(
                 ^^^^^^^^^^^^^^^^^^^^
  File "/Users/macbook/miniconda3/envs/eoh/lib/python3.12/site-packages/google/api_core/retry/retry_base.py", line 214, in _retry_error_helper
    raise final_exc from source_exc
  File "/Users/macbook/miniconda3/envs/eoh/lib/python3.12/site-packages/google/api_core/retry/retry_unary.py", line 147, in retry_target
    result = target()
             ^^^^^^^^
  File "/Users/macbook/miniconda3/envs/eoh/lib/python3.12/site-packages/google/api_core/timeout.py", line 130, in func_with_timeout
    return func(*args, **kwargs)
           ^^^^^^^^^^^^^^^^^^^^^
  File "/Users/macbook/miniconda3/envs/eoh/lib/python3.12/site-packages/google/api_core/grpc_helpers.py", line 78, in error_remapped_callable
    raise exceptions.from_grpc_error(exc) from exc
google.api_core.exceptions.ResourceExhausted: 429 You exceeded your current quota, please check your plan and billing details. For more information on this error, head to: https://ai.google.dev/gemini-api/docs/rate-limits. [violations {
  quota_metric: "generativelanguage.googleapis.com/generate_content_free_tier_requests"
  quota_id: "GenerateRequestsPerMinutePerProjectPerModel-FreeTier"
  quota_dimensions {
    key: "model"
    value: "gemini-1.5-flash"
  }
  quota_dimensions {
    key: "location"
    value: "global"
  }
  quota_value: 15
}
, links {
  description: "Learn more about Gemini API quotas"
  url: "https://ai.google.dev/gemini-api/docs/rate-limits"
}
, retry_delay {
  seconds: 49
}
]
.
2025-06-15 08:42:11 INFO An exception occured: Traceback (most recent call last):
  File "/Users/macbook/Documents/Code/LLMdesignedEA-comp/llamea/llamea_multi_prompts.py", line 316, in evolve_solution
    evolved_individual = self.llm.sample_solution(
                         ^^^^^^^^^^^^^^^^^^^^^^^^^
  File "/Users/macbook/Documents/Code/LLMdesignedEA-comp/llamea/llm.py", line 106, in sample_solution
    message = self.query(session_messages)
              ^^^^^^^^^^^^^^^^^^^^^^^^^^^^
  File "/Users/macbook/Documents/Code/LLMdesignedEA-comp/llamea/llm.py", line 278, in query
    response = chat_session.send_message(last["content"])
               ^^^^^^^^^^^^^^^^^^^^^^^^^^^^^^^^^^^^^^^^^^
  File "/Users/macbook/miniconda3/envs/eoh/lib/python3.12/site-packages/google/generativeai/generative_models.py", line 578, in send_message
    response = self.model.generate_content(
               ^^^^^^^^^^^^^^^^^^^^^^^^^^^^
  File "/Users/macbook/miniconda3/envs/eoh/lib/python3.12/site-packages/google/generativeai/generative_models.py", line 331, in generate_content
    response = self._client.generate_content(
               ^^^^^^^^^^^^^^^^^^^^^^^^^^^^^^
  File "/Users/macbook/miniconda3/envs/eoh/lib/python3.12/site-packages/google/ai/generativelanguage_v1beta/services/generative_service/client.py", line 835, in generate_content
    response = rpc(
               ^^^^
  File "/Users/macbook/miniconda3/envs/eoh/lib/python3.12/site-packages/google/api_core/gapic_v1/method.py", line 131, in __call__
    return wrapped_func(*args, **kwargs)
           ^^^^^^^^^^^^^^^^^^^^^^^^^^^^^
  File "/Users/macbook/miniconda3/envs/eoh/lib/python3.12/site-packages/google/api_core/retry/retry_unary.py", line 294, in retry_wrapped_func
    return retry_target(
           ^^^^^^^^^^^^^
  File "/Users/macbook/miniconda3/envs/eoh/lib/python3.12/site-packages/google/api_core/retry/retry_unary.py", line 156, in retry_target
    next_sleep = _retry_error_helper(
                 ^^^^^^^^^^^^^^^^^^^^
  File "/Users/macbook/miniconda3/envs/eoh/lib/python3.12/site-packages/google/api_core/retry/retry_base.py", line 214, in _retry_error_helper
    raise final_exc from source_exc
  File "/Users/macbook/miniconda3/envs/eoh/lib/python3.12/site-packages/google/api_core/retry/retry_unary.py", line 147, in retry_target
    result = target()
             ^^^^^^^^
  File "/Users/macbook/miniconda3/envs/eoh/lib/python3.12/site-packages/google/api_core/timeout.py", line 130, in func_with_timeout
    return func(*args, **kwargs)
           ^^^^^^^^^^^^^^^^^^^^^
  File "/Users/macbook/miniconda3/envs/eoh/lib/python3.12/site-packages/google/api_core/grpc_helpers.py", line 78, in error_remapped_callable
    raise exceptions.from_grpc_error(exc) from exc
google.api_core.exceptions.ResourceExhausted: 429 You exceeded your current quota, please check your plan and billing details. For more information on this error, head to: https://ai.google.dev/gemini-api/docs/rate-limits. [violations {
  quota_metric: "generativelanguage.googleapis.com/generate_content_free_tier_requests"
  quota_id: "GenerateRequestsPerMinutePerProjectPerModel-FreeTier"
  quota_dimensions {
    key: "model"
    value: "gemini-1.5-flash"
  }
  quota_dimensions {
    key: "location"
    value: "global"
  }
  quota_value: 15
}
, links {
  description: "Learn more about Gemini API quotas"
  url: "https://ai.google.dev/gemini-api/docs/rate-limits"
}
, retry_delay {
  seconds: 49
}
]
.
2025-06-15 08:42:11 INFO An exception occured: Traceback (most recent call last):
  File "/Users/macbook/Documents/Code/LLMdesignedEA-comp/llamea/llamea_multi_prompts.py", line 316, in evolve_solution
    evolved_individual = self.llm.sample_solution(
                         ^^^^^^^^^^^^^^^^^^^^^^^^^
  File "/Users/macbook/Documents/Code/LLMdesignedEA-comp/llamea/llm.py", line 106, in sample_solution
    message = self.query(session_messages)
              ^^^^^^^^^^^^^^^^^^^^^^^^^^^^
  File "/Users/macbook/Documents/Code/LLMdesignedEA-comp/llamea/llm.py", line 278, in query
    response = chat_session.send_message(last["content"])
               ^^^^^^^^^^^^^^^^^^^^^^^^^^^^^^^^^^^^^^^^^^
  File "/Users/macbook/miniconda3/envs/eoh/lib/python3.12/site-packages/google/generativeai/generative_models.py", line 578, in send_message
    response = self.model.generate_content(
               ^^^^^^^^^^^^^^^^^^^^^^^^^^^^
  File "/Users/macbook/miniconda3/envs/eoh/lib/python3.12/site-packages/google/generativeai/generative_models.py", line 331, in generate_content
    response = self._client.generate_content(
               ^^^^^^^^^^^^^^^^^^^^^^^^^^^^^^
  File "/Users/macbook/miniconda3/envs/eoh/lib/python3.12/site-packages/google/ai/generativelanguage_v1beta/services/generative_service/client.py", line 835, in generate_content
    response = rpc(
               ^^^^
  File "/Users/macbook/miniconda3/envs/eoh/lib/python3.12/site-packages/google/api_core/gapic_v1/method.py", line 131, in __call__
    return wrapped_func(*args, **kwargs)
           ^^^^^^^^^^^^^^^^^^^^^^^^^^^^^
  File "/Users/macbook/miniconda3/envs/eoh/lib/python3.12/site-packages/google/api_core/retry/retry_unary.py", line 294, in retry_wrapped_func
    return retry_target(
           ^^^^^^^^^^^^^
  File "/Users/macbook/miniconda3/envs/eoh/lib/python3.12/site-packages/google/api_core/retry/retry_unary.py", line 156, in retry_target
    next_sleep = _retry_error_helper(
                 ^^^^^^^^^^^^^^^^^^^^
  File "/Users/macbook/miniconda3/envs/eoh/lib/python3.12/site-packages/google/api_core/retry/retry_base.py", line 214, in _retry_error_helper
    raise final_exc from source_exc
  File "/Users/macbook/miniconda3/envs/eoh/lib/python3.12/site-packages/google/api_core/retry/retry_unary.py", line 147, in retry_target
    result = target()
             ^^^^^^^^
  File "/Users/macbook/miniconda3/envs/eoh/lib/python3.12/site-packages/google/api_core/timeout.py", line 130, in func_with_timeout
    return func(*args, **kwargs)
           ^^^^^^^^^^^^^^^^^^^^^
  File "/Users/macbook/miniconda3/envs/eoh/lib/python3.12/site-packages/google/api_core/grpc_helpers.py", line 78, in error_remapped_callable
    raise exceptions.from_grpc_error(exc) from exc
google.api_core.exceptions.ResourceExhausted: 429 You exceeded your current quota, please check your plan and billing details. For more information on this error, head to: https://ai.google.dev/gemini-api/docs/rate-limits. [violations {
  quota_metric: "generativelanguage.googleapis.com/generate_content_free_tier_requests"
  quota_id: "GenerateRequestsPerMinutePerProjectPerModel-FreeTier"
  quota_dimensions {
    key: "model"
    value: "gemini-1.5-flash"
  }
  quota_dimensions {
    key: "location"
    value: "global"
  }
  quota_value: 15
}
, links {
  description: "Learn more about Gemini API quotas"
  url: "https://ai.google.dev/gemini-api/docs/rate-limits"
}
, retry_delay {
  seconds: 49
}
]
.
2025-06-15 08:42:11 INFO An exception occured: Traceback (most recent call last):
  File "/Users/macbook/Documents/Code/LLMdesignedEA-comp/llamea/llamea_multi_prompts.py", line 316, in evolve_solution
    evolved_individual = self.llm.sample_solution(
                         ^^^^^^^^^^^^^^^^^^^^^^^^^
  File "/Users/macbook/Documents/Code/LLMdesignedEA-comp/llamea/llm.py", line 106, in sample_solution
    message = self.query(session_messages)
              ^^^^^^^^^^^^^^^^^^^^^^^^^^^^
  File "/Users/macbook/Documents/Code/LLMdesignedEA-comp/llamea/llm.py", line 278, in query
    response = chat_session.send_message(last["content"])
               ^^^^^^^^^^^^^^^^^^^^^^^^^^^^^^^^^^^^^^^^^^
  File "/Users/macbook/miniconda3/envs/eoh/lib/python3.12/site-packages/google/generativeai/generative_models.py", line 578, in send_message
    response = self.model.generate_content(
               ^^^^^^^^^^^^^^^^^^^^^^^^^^^^
  File "/Users/macbook/miniconda3/envs/eoh/lib/python3.12/site-packages/google/generativeai/generative_models.py", line 331, in generate_content
    response = self._client.generate_content(
               ^^^^^^^^^^^^^^^^^^^^^^^^^^^^^^
  File "/Users/macbook/miniconda3/envs/eoh/lib/python3.12/site-packages/google/ai/generativelanguage_v1beta/services/generative_service/client.py", line 835, in generate_content
    response = rpc(
               ^^^^
  File "/Users/macbook/miniconda3/envs/eoh/lib/python3.12/site-packages/google/api_core/gapic_v1/method.py", line 131, in __call__
    return wrapped_func(*args, **kwargs)
           ^^^^^^^^^^^^^^^^^^^^^^^^^^^^^
  File "/Users/macbook/miniconda3/envs/eoh/lib/python3.12/site-packages/google/api_core/retry/retry_unary.py", line 294, in retry_wrapped_func
    return retry_target(
           ^^^^^^^^^^^^^
  File "/Users/macbook/miniconda3/envs/eoh/lib/python3.12/site-packages/google/api_core/retry/retry_unary.py", line 156, in retry_target
    next_sleep = _retry_error_helper(
                 ^^^^^^^^^^^^^^^^^^^^
  File "/Users/macbook/miniconda3/envs/eoh/lib/python3.12/site-packages/google/api_core/retry/retry_base.py", line 214, in _retry_error_helper
    raise final_exc from source_exc
  File "/Users/macbook/miniconda3/envs/eoh/lib/python3.12/site-packages/google/api_core/retry/retry_unary.py", line 147, in retry_target
    result = target()
             ^^^^^^^^
  File "/Users/macbook/miniconda3/envs/eoh/lib/python3.12/site-packages/google/api_core/timeout.py", line 130, in func_with_timeout
    return func(*args, **kwargs)
           ^^^^^^^^^^^^^^^^^^^^^
  File "/Users/macbook/miniconda3/envs/eoh/lib/python3.12/site-packages/google/api_core/grpc_helpers.py", line 78, in error_remapped_callable
    raise exceptions.from_grpc_error(exc) from exc
google.api_core.exceptions.ResourceExhausted: 429 You exceeded your current quota, please check your plan and billing details. For more information on this error, head to: https://ai.google.dev/gemini-api/docs/rate-limits. [violations {
  quota_metric: "generativelanguage.googleapis.com/generate_content_free_tier_requests"
  quota_id: "GenerateRequestsPerMinutePerProjectPerModel-FreeTier"
  quota_dimensions {
    key: "model"
    value: "gemini-1.5-flash"
  }
  quota_dimensions {
    key: "location"
    value: "global"
  }
  quota_value: 15
}
, links {
  description: "Learn more about Gemini API quotas"
  url: "https://ai.google.dev/gemini-api/docs/rate-limits"
}
, retry_delay {
  seconds: 49
}
]
.
2025-06-15 08:42:11 INFO An exception occured: Traceback (most recent call last):
  File "/Users/macbook/Documents/Code/LLMdesignedEA-comp/llamea/llamea_multi_prompts.py", line 316, in evolve_solution
    evolved_individual = self.llm.sample_solution(
                         ^^^^^^^^^^^^^^^^^^^^^^^^^
  File "/Users/macbook/Documents/Code/LLMdesignedEA-comp/llamea/llm.py", line 106, in sample_solution
    message = self.query(session_messages)
              ^^^^^^^^^^^^^^^^^^^^^^^^^^^^
  File "/Users/macbook/Documents/Code/LLMdesignedEA-comp/llamea/llm.py", line 278, in query
    response = chat_session.send_message(last["content"])
               ^^^^^^^^^^^^^^^^^^^^^^^^^^^^^^^^^^^^^^^^^^
  File "/Users/macbook/miniconda3/envs/eoh/lib/python3.12/site-packages/google/generativeai/generative_models.py", line 578, in send_message
    response = self.model.generate_content(
               ^^^^^^^^^^^^^^^^^^^^^^^^^^^^
  File "/Users/macbook/miniconda3/envs/eoh/lib/python3.12/site-packages/google/generativeai/generative_models.py", line 331, in generate_content
    response = self._client.generate_content(
               ^^^^^^^^^^^^^^^^^^^^^^^^^^^^^^
  File "/Users/macbook/miniconda3/envs/eoh/lib/python3.12/site-packages/google/ai/generativelanguage_v1beta/services/generative_service/client.py", line 835, in generate_content
    response = rpc(
               ^^^^
  File "/Users/macbook/miniconda3/envs/eoh/lib/python3.12/site-packages/google/api_core/gapic_v1/method.py", line 131, in __call__
    return wrapped_func(*args, **kwargs)
           ^^^^^^^^^^^^^^^^^^^^^^^^^^^^^
  File "/Users/macbook/miniconda3/envs/eoh/lib/python3.12/site-packages/google/api_core/retry/retry_unary.py", line 294, in retry_wrapped_func
    return retry_target(
           ^^^^^^^^^^^^^
  File "/Users/macbook/miniconda3/envs/eoh/lib/python3.12/site-packages/google/api_core/retry/retry_unary.py", line 156, in retry_target
    next_sleep = _retry_error_helper(
                 ^^^^^^^^^^^^^^^^^^^^
  File "/Users/macbook/miniconda3/envs/eoh/lib/python3.12/site-packages/google/api_core/retry/retry_base.py", line 214, in _retry_error_helper
    raise final_exc from source_exc
  File "/Users/macbook/miniconda3/envs/eoh/lib/python3.12/site-packages/google/api_core/retry/retry_unary.py", line 147, in retry_target
    result = target()
             ^^^^^^^^
  File "/Users/macbook/miniconda3/envs/eoh/lib/python3.12/site-packages/google/api_core/timeout.py", line 130, in func_with_timeout
    return func(*args, **kwargs)
           ^^^^^^^^^^^^^^^^^^^^^
  File "/Users/macbook/miniconda3/envs/eoh/lib/python3.12/site-packages/google/api_core/grpc_helpers.py", line 78, in error_remapped_callable
    raise exceptions.from_grpc_error(exc) from exc
google.api_core.exceptions.ResourceExhausted: 429 You exceeded your current quota, please check your plan and billing details. For more information on this error, head to: https://ai.google.dev/gemini-api/docs/rate-limits. [violations {
  quota_metric: "generativelanguage.googleapis.com/generate_content_free_tier_requests"
  quota_id: "GenerateRequestsPerMinutePerProjectPerModel-FreeTier"
  quota_dimensions {
    key: "model"
    value: "gemini-1.5-flash"
  }
  quota_dimensions {
    key: "location"
    value: "global"
  }
  quota_value: 15
}
, links {
  description: "Learn more about Gemini API quotas"
  url: "https://ai.google.dev/gemini-api/docs/rate-limits"
}
, retry_delay {
  seconds: 49
}
]
.
2025-06-15 08:42:11 INFO An exception occured: Traceback (most recent call last):
  File "/Users/macbook/Documents/Code/LLMdesignedEA-comp/llamea/llamea_multi_prompts.py", line 316, in evolve_solution
    evolved_individual = self.llm.sample_solution(
                         ^^^^^^^^^^^^^^^^^^^^^^^^^
  File "/Users/macbook/Documents/Code/LLMdesignedEA-comp/llamea/llm.py", line 106, in sample_solution
    message = self.query(session_messages)
              ^^^^^^^^^^^^^^^^^^^^^^^^^^^^
  File "/Users/macbook/Documents/Code/LLMdesignedEA-comp/llamea/llm.py", line 278, in query
    response = chat_session.send_message(last["content"])
               ^^^^^^^^^^^^^^^^^^^^^^^^^^^^^^^^^^^^^^^^^^
  File "/Users/macbook/miniconda3/envs/eoh/lib/python3.12/site-packages/google/generativeai/generative_models.py", line 578, in send_message
    response = self.model.generate_content(
               ^^^^^^^^^^^^^^^^^^^^^^^^^^^^
  File "/Users/macbook/miniconda3/envs/eoh/lib/python3.12/site-packages/google/generativeai/generative_models.py", line 331, in generate_content
    response = self._client.generate_content(
               ^^^^^^^^^^^^^^^^^^^^^^^^^^^^^^
  File "/Users/macbook/miniconda3/envs/eoh/lib/python3.12/site-packages/google/ai/generativelanguage_v1beta/services/generative_service/client.py", line 835, in generate_content
    response = rpc(
               ^^^^
  File "/Users/macbook/miniconda3/envs/eoh/lib/python3.12/site-packages/google/api_core/gapic_v1/method.py", line 131, in __call__
    return wrapped_func(*args, **kwargs)
           ^^^^^^^^^^^^^^^^^^^^^^^^^^^^^
  File "/Users/macbook/miniconda3/envs/eoh/lib/python3.12/site-packages/google/api_core/retry/retry_unary.py", line 294, in retry_wrapped_func
    return retry_target(
           ^^^^^^^^^^^^^
  File "/Users/macbook/miniconda3/envs/eoh/lib/python3.12/site-packages/google/api_core/retry/retry_unary.py", line 156, in retry_target
    next_sleep = _retry_error_helper(
                 ^^^^^^^^^^^^^^^^^^^^
  File "/Users/macbook/miniconda3/envs/eoh/lib/python3.12/site-packages/google/api_core/retry/retry_base.py", line 214, in _retry_error_helper
    raise final_exc from source_exc
  File "/Users/macbook/miniconda3/envs/eoh/lib/python3.12/site-packages/google/api_core/retry/retry_unary.py", line 147, in retry_target
    result = target()
             ^^^^^^^^
  File "/Users/macbook/miniconda3/envs/eoh/lib/python3.12/site-packages/google/api_core/timeout.py", line 130, in func_with_timeout
    return func(*args, **kwargs)
           ^^^^^^^^^^^^^^^^^^^^^
  File "/Users/macbook/miniconda3/envs/eoh/lib/python3.12/site-packages/google/api_core/grpc_helpers.py", line 78, in error_remapped_callable
    raise exceptions.from_grpc_error(exc) from exc
google.api_core.exceptions.ResourceExhausted: 429 You exceeded your current quota, please check your plan and billing details. For more information on this error, head to: https://ai.google.dev/gemini-api/docs/rate-limits. [violations {
  quota_metric: "generativelanguage.googleapis.com/generate_content_free_tier_requests"
  quota_id: "GenerateRequestsPerMinutePerProjectPerModel-FreeTier"
  quota_dimensions {
    key: "model"
    value: "gemini-1.5-flash"
  }
  quota_dimensions {
    key: "location"
    value: "global"
  }
  quota_value: 15
}
, links {
  description: "Learn more about Gemini API quotas"
  url: "https://ai.google.dev/gemini-api/docs/rate-limits"
}
, retry_delay {
  seconds: 48
}
]
.
2025-06-15 08:42:11 INFO An exception occured: Traceback (most recent call last):
  File "/Users/macbook/Documents/Code/LLMdesignedEA-comp/llamea/llamea_multi_prompts.py", line 316, in evolve_solution
    evolved_individual = self.llm.sample_solution(
                         ^^^^^^^^^^^^^^^^^^^^^^^^^
  File "/Users/macbook/Documents/Code/LLMdesignedEA-comp/llamea/llm.py", line 106, in sample_solution
    message = self.query(session_messages)
              ^^^^^^^^^^^^^^^^^^^^^^^^^^^^
  File "/Users/macbook/Documents/Code/LLMdesignedEA-comp/llamea/llm.py", line 278, in query
    response = chat_session.send_message(last["content"])
               ^^^^^^^^^^^^^^^^^^^^^^^^^^^^^^^^^^^^^^^^^^
  File "/Users/macbook/miniconda3/envs/eoh/lib/python3.12/site-packages/google/generativeai/generative_models.py", line 578, in send_message
    response = self.model.generate_content(
               ^^^^^^^^^^^^^^^^^^^^^^^^^^^^
  File "/Users/macbook/miniconda3/envs/eoh/lib/python3.12/site-packages/google/generativeai/generative_models.py", line 331, in generate_content
    response = self._client.generate_content(
               ^^^^^^^^^^^^^^^^^^^^^^^^^^^^^^
  File "/Users/macbook/miniconda3/envs/eoh/lib/python3.12/site-packages/google/ai/generativelanguage_v1beta/services/generative_service/client.py", line 835, in generate_content
    response = rpc(
               ^^^^
  File "/Users/macbook/miniconda3/envs/eoh/lib/python3.12/site-packages/google/api_core/gapic_v1/method.py", line 131, in __call__
    return wrapped_func(*args, **kwargs)
           ^^^^^^^^^^^^^^^^^^^^^^^^^^^^^
  File "/Users/macbook/miniconda3/envs/eoh/lib/python3.12/site-packages/google/api_core/retry/retry_unary.py", line 294, in retry_wrapped_func
    return retry_target(
           ^^^^^^^^^^^^^
  File "/Users/macbook/miniconda3/envs/eoh/lib/python3.12/site-packages/google/api_core/retry/retry_unary.py", line 156, in retry_target
    next_sleep = _retry_error_helper(
                 ^^^^^^^^^^^^^^^^^^^^
  File "/Users/macbook/miniconda3/envs/eoh/lib/python3.12/site-packages/google/api_core/retry/retry_base.py", line 214, in _retry_error_helper
    raise final_exc from source_exc
  File "/Users/macbook/miniconda3/envs/eoh/lib/python3.12/site-packages/google/api_core/retry/retry_unary.py", line 147, in retry_target
    result = target()
             ^^^^^^^^
  File "/Users/macbook/miniconda3/envs/eoh/lib/python3.12/site-packages/google/api_core/timeout.py", line 130, in func_with_timeout
    return func(*args, **kwargs)
           ^^^^^^^^^^^^^^^^^^^^^
  File "/Users/macbook/miniconda3/envs/eoh/lib/python3.12/site-packages/google/api_core/grpc_helpers.py", line 78, in error_remapped_callable
    raise exceptions.from_grpc_error(exc) from exc
google.api_core.exceptions.ResourceExhausted: 429 You exceeded your current quota, please check your plan and billing details. For more information on this error, head to: https://ai.google.dev/gemini-api/docs/rate-limits. [violations {
  quota_metric: "generativelanguage.googleapis.com/generate_content_free_tier_requests"
  quota_id: "GenerateRequestsPerMinutePerProjectPerModel-FreeTier"
  quota_dimensions {
    key: "model"
    value: "gemini-1.5-flash"
  }
  quota_dimensions {
    key: "location"
    value: "global"
  }
  quota_value: 15
}
, links {
  description: "Learn more about Gemini API quotas"
  url: "https://ai.google.dev/gemini-api/docs/rate-limits"
}
, retry_delay {
  seconds: 48
}
]
.
2025-06-15 08:42:11 INFO An exception occured: Traceback (most recent call last):
  File "/Users/macbook/Documents/Code/LLMdesignedEA-comp/llamea/llamea_multi_prompts.py", line 316, in evolve_solution
    evolved_individual = self.llm.sample_solution(
                         ^^^^^^^^^^^^^^^^^^^^^^^^^
  File "/Users/macbook/Documents/Code/LLMdesignedEA-comp/llamea/llm.py", line 106, in sample_solution
    message = self.query(session_messages)
              ^^^^^^^^^^^^^^^^^^^^^^^^^^^^
  File "/Users/macbook/Documents/Code/LLMdesignedEA-comp/llamea/llm.py", line 278, in query
    response = chat_session.send_message(last["content"])
               ^^^^^^^^^^^^^^^^^^^^^^^^^^^^^^^^^^^^^^^^^^
  File "/Users/macbook/miniconda3/envs/eoh/lib/python3.12/site-packages/google/generativeai/generative_models.py", line 578, in send_message
    response = self.model.generate_content(
               ^^^^^^^^^^^^^^^^^^^^^^^^^^^^
  File "/Users/macbook/miniconda3/envs/eoh/lib/python3.12/site-packages/google/generativeai/generative_models.py", line 331, in generate_content
    response = self._client.generate_content(
               ^^^^^^^^^^^^^^^^^^^^^^^^^^^^^^
  File "/Users/macbook/miniconda3/envs/eoh/lib/python3.12/site-packages/google/ai/generativelanguage_v1beta/services/generative_service/client.py", line 835, in generate_content
    response = rpc(
               ^^^^
  File "/Users/macbook/miniconda3/envs/eoh/lib/python3.12/site-packages/google/api_core/gapic_v1/method.py", line 131, in __call__
    return wrapped_func(*args, **kwargs)
           ^^^^^^^^^^^^^^^^^^^^^^^^^^^^^
  File "/Users/macbook/miniconda3/envs/eoh/lib/python3.12/site-packages/google/api_core/retry/retry_unary.py", line 294, in retry_wrapped_func
    return retry_target(
           ^^^^^^^^^^^^^
  File "/Users/macbook/miniconda3/envs/eoh/lib/python3.12/site-packages/google/api_core/retry/retry_unary.py", line 156, in retry_target
    next_sleep = _retry_error_helper(
                 ^^^^^^^^^^^^^^^^^^^^
  File "/Users/macbook/miniconda3/envs/eoh/lib/python3.12/site-packages/google/api_core/retry/retry_base.py", line 214, in _retry_error_helper
    raise final_exc from source_exc
  File "/Users/macbook/miniconda3/envs/eoh/lib/python3.12/site-packages/google/api_core/retry/retry_unary.py", line 147, in retry_target
    result = target()
             ^^^^^^^^
  File "/Users/macbook/miniconda3/envs/eoh/lib/python3.12/site-packages/google/api_core/timeout.py", line 130, in func_with_timeout
    return func(*args, **kwargs)
           ^^^^^^^^^^^^^^^^^^^^^
  File "/Users/macbook/miniconda3/envs/eoh/lib/python3.12/site-packages/google/api_core/grpc_helpers.py", line 78, in error_remapped_callable
    raise exceptions.from_grpc_error(exc) from exc
google.api_core.exceptions.ResourceExhausted: 429 You exceeded your current quota, please check your plan and billing details. For more information on this error, head to: https://ai.google.dev/gemini-api/docs/rate-limits. [violations {
  quota_metric: "generativelanguage.googleapis.com/generate_content_free_tier_requests"
  quota_id: "GenerateRequestsPerMinutePerProjectPerModel-FreeTier"
  quota_dimensions {
    key: "model"
    value: "gemini-1.5-flash"
  }
  quota_dimensions {
    key: "location"
    value: "global"
  }
  quota_value: 15
}
, links {
  description: "Learn more about Gemini API quotas"
  url: "https://ai.google.dev/gemini-api/docs/rate-limits"
}
, retry_delay {
  seconds: 48
}
]
.
2025-06-15 08:42:11 INFO An exception occured: Traceback (most recent call last):
  File "/Users/macbook/Documents/Code/LLMdesignedEA-comp/llamea/llamea_multi_prompts.py", line 316, in evolve_solution
    evolved_individual = self.llm.sample_solution(
                         ^^^^^^^^^^^^^^^^^^^^^^^^^
  File "/Users/macbook/Documents/Code/LLMdesignedEA-comp/llamea/llm.py", line 106, in sample_solution
    message = self.query(session_messages)
              ^^^^^^^^^^^^^^^^^^^^^^^^^^^^
  File "/Users/macbook/Documents/Code/LLMdesignedEA-comp/llamea/llm.py", line 278, in query
    response = chat_session.send_message(last["content"])
               ^^^^^^^^^^^^^^^^^^^^^^^^^^^^^^^^^^^^^^^^^^
  File "/Users/macbook/miniconda3/envs/eoh/lib/python3.12/site-packages/google/generativeai/generative_models.py", line 578, in send_message
    response = self.model.generate_content(
               ^^^^^^^^^^^^^^^^^^^^^^^^^^^^
  File "/Users/macbook/miniconda3/envs/eoh/lib/python3.12/site-packages/google/generativeai/generative_models.py", line 331, in generate_content
    response = self._client.generate_content(
               ^^^^^^^^^^^^^^^^^^^^^^^^^^^^^^
  File "/Users/macbook/miniconda3/envs/eoh/lib/python3.12/site-packages/google/ai/generativelanguage_v1beta/services/generative_service/client.py", line 835, in generate_content
    response = rpc(
               ^^^^
  File "/Users/macbook/miniconda3/envs/eoh/lib/python3.12/site-packages/google/api_core/gapic_v1/method.py", line 131, in __call__
    return wrapped_func(*args, **kwargs)
           ^^^^^^^^^^^^^^^^^^^^^^^^^^^^^
  File "/Users/macbook/miniconda3/envs/eoh/lib/python3.12/site-packages/google/api_core/retry/retry_unary.py", line 294, in retry_wrapped_func
    return retry_target(
           ^^^^^^^^^^^^^
  File "/Users/macbook/miniconda3/envs/eoh/lib/python3.12/site-packages/google/api_core/retry/retry_unary.py", line 156, in retry_target
    next_sleep = _retry_error_helper(
                 ^^^^^^^^^^^^^^^^^^^^
  File "/Users/macbook/miniconda3/envs/eoh/lib/python3.12/site-packages/google/api_core/retry/retry_base.py", line 214, in _retry_error_helper
    raise final_exc from source_exc
  File "/Users/macbook/miniconda3/envs/eoh/lib/python3.12/site-packages/google/api_core/retry/retry_unary.py", line 147, in retry_target
    result = target()
             ^^^^^^^^
  File "/Users/macbook/miniconda3/envs/eoh/lib/python3.12/site-packages/google/api_core/timeout.py", line 130, in func_with_timeout
    return func(*args, **kwargs)
           ^^^^^^^^^^^^^^^^^^^^^
  File "/Users/macbook/miniconda3/envs/eoh/lib/python3.12/site-packages/google/api_core/grpc_helpers.py", line 78, in error_remapped_callable
    raise exceptions.from_grpc_error(exc) from exc
google.api_core.exceptions.ResourceExhausted: 429 You exceeded your current quota, please check your plan and billing details. For more information on this error, head to: https://ai.google.dev/gemini-api/docs/rate-limits. [violations {
  quota_metric: "generativelanguage.googleapis.com/generate_content_free_tier_requests"
  quota_id: "GenerateRequestsPerMinutePerProjectPerModel-FreeTier"
  quota_dimensions {
    key: "model"
    value: "gemini-1.5-flash"
  }
  quota_dimensions {
    key: "location"
    value: "global"
  }
  quota_value: 15
}
, links {
  description: "Learn more about Gemini API quotas"
  url: "https://ai.google.dev/gemini-api/docs/rate-limits"
}
, retry_delay {
  seconds: 48
}
]
.
2025-06-15 08:42:11 INFO An exception occured: Traceback (most recent call last):
  File "/Users/macbook/Documents/Code/LLMdesignedEA-comp/llamea/llamea_multi_prompts.py", line 316, in evolve_solution
    evolved_individual = self.llm.sample_solution(
                         ^^^^^^^^^^^^^^^^^^^^^^^^^
  File "/Users/macbook/Documents/Code/LLMdesignedEA-comp/llamea/llm.py", line 106, in sample_solution
    message = self.query(session_messages)
              ^^^^^^^^^^^^^^^^^^^^^^^^^^^^
  File "/Users/macbook/Documents/Code/LLMdesignedEA-comp/llamea/llm.py", line 278, in query
    response = chat_session.send_message(last["content"])
               ^^^^^^^^^^^^^^^^^^^^^^^^^^^^^^^^^^^^^^^^^^
  File "/Users/macbook/miniconda3/envs/eoh/lib/python3.12/site-packages/google/generativeai/generative_models.py", line 578, in send_message
    response = self.model.generate_content(
               ^^^^^^^^^^^^^^^^^^^^^^^^^^^^
  File "/Users/macbook/miniconda3/envs/eoh/lib/python3.12/site-packages/google/generativeai/generative_models.py", line 331, in generate_content
    response = self._client.generate_content(
               ^^^^^^^^^^^^^^^^^^^^^^^^^^^^^^
  File "/Users/macbook/miniconda3/envs/eoh/lib/python3.12/site-packages/google/ai/generativelanguage_v1beta/services/generative_service/client.py", line 835, in generate_content
    response = rpc(
               ^^^^
  File "/Users/macbook/miniconda3/envs/eoh/lib/python3.12/site-packages/google/api_core/gapic_v1/method.py", line 131, in __call__
    return wrapped_func(*args, **kwargs)
           ^^^^^^^^^^^^^^^^^^^^^^^^^^^^^
  File "/Users/macbook/miniconda3/envs/eoh/lib/python3.12/site-packages/google/api_core/retry/retry_unary.py", line 294, in retry_wrapped_func
    return retry_target(
           ^^^^^^^^^^^^^
  File "/Users/macbook/miniconda3/envs/eoh/lib/python3.12/site-packages/google/api_core/retry/retry_unary.py", line 156, in retry_target
    next_sleep = _retry_error_helper(
                 ^^^^^^^^^^^^^^^^^^^^
  File "/Users/macbook/miniconda3/envs/eoh/lib/python3.12/site-packages/google/api_core/retry/retry_base.py", line 214, in _retry_error_helper
    raise final_exc from source_exc
  File "/Users/macbook/miniconda3/envs/eoh/lib/python3.12/site-packages/google/api_core/retry/retry_unary.py", line 147, in retry_target
    result = target()
             ^^^^^^^^
  File "/Users/macbook/miniconda3/envs/eoh/lib/python3.12/site-packages/google/api_core/timeout.py", line 130, in func_with_timeout
    return func(*args, **kwargs)
           ^^^^^^^^^^^^^^^^^^^^^
  File "/Users/macbook/miniconda3/envs/eoh/lib/python3.12/site-packages/google/api_core/grpc_helpers.py", line 78, in error_remapped_callable
    raise exceptions.from_grpc_error(exc) from exc
google.api_core.exceptions.ResourceExhausted: 429 You exceeded your current quota, please check your plan and billing details. For more information on this error, head to: https://ai.google.dev/gemini-api/docs/rate-limits. [violations {
  quota_metric: "generativelanguage.googleapis.com/generate_content_free_tier_requests"
  quota_id: "GenerateRequestsPerMinutePerProjectPerModel-FreeTier"
  quota_dimensions {
    key: "model"
    value: "gemini-1.5-flash"
  }
  quota_dimensions {
    key: "location"
    value: "global"
  }
  quota_value: 15
}
, links {
  description: "Learn more about Gemini API quotas"
  url: "https://ai.google.dev/gemini-api/docs/rate-limits"
}
, retry_delay {
  seconds: 48
}
]
.
2025-06-15 08:42:11 INFO An exception occured: Traceback (most recent call last):
  File "/Users/macbook/Documents/Code/LLMdesignedEA-comp/llamea/llamea_multi_prompts.py", line 316, in evolve_solution
    evolved_individual = self.llm.sample_solution(
                         ^^^^^^^^^^^^^^^^^^^^^^^^^
  File "/Users/macbook/Documents/Code/LLMdesignedEA-comp/llamea/llm.py", line 106, in sample_solution
    message = self.query(session_messages)
              ^^^^^^^^^^^^^^^^^^^^^^^^^^^^
  File "/Users/macbook/Documents/Code/LLMdesignedEA-comp/llamea/llm.py", line 278, in query
    response = chat_session.send_message(last["content"])
               ^^^^^^^^^^^^^^^^^^^^^^^^^^^^^^^^^^^^^^^^^^
  File "/Users/macbook/miniconda3/envs/eoh/lib/python3.12/site-packages/google/generativeai/generative_models.py", line 578, in send_message
    response = self.model.generate_content(
               ^^^^^^^^^^^^^^^^^^^^^^^^^^^^
  File "/Users/macbook/miniconda3/envs/eoh/lib/python3.12/site-packages/google/generativeai/generative_models.py", line 331, in generate_content
    response = self._client.generate_content(
               ^^^^^^^^^^^^^^^^^^^^^^^^^^^^^^
  File "/Users/macbook/miniconda3/envs/eoh/lib/python3.12/site-packages/google/ai/generativelanguage_v1beta/services/generative_service/client.py", line 835, in generate_content
    response = rpc(
               ^^^^
  File "/Users/macbook/miniconda3/envs/eoh/lib/python3.12/site-packages/google/api_core/gapic_v1/method.py", line 131, in __call__
    return wrapped_func(*args, **kwargs)
           ^^^^^^^^^^^^^^^^^^^^^^^^^^^^^
  File "/Users/macbook/miniconda3/envs/eoh/lib/python3.12/site-packages/google/api_core/retry/retry_unary.py", line 294, in retry_wrapped_func
    return retry_target(
           ^^^^^^^^^^^^^
  File "/Users/macbook/miniconda3/envs/eoh/lib/python3.12/site-packages/google/api_core/retry/retry_unary.py", line 156, in retry_target
    next_sleep = _retry_error_helper(
                 ^^^^^^^^^^^^^^^^^^^^
  File "/Users/macbook/miniconda3/envs/eoh/lib/python3.12/site-packages/google/api_core/retry/retry_base.py", line 214, in _retry_error_helper
    raise final_exc from source_exc
  File "/Users/macbook/miniconda3/envs/eoh/lib/python3.12/site-packages/google/api_core/retry/retry_unary.py", line 147, in retry_target
    result = target()
             ^^^^^^^^
  File "/Users/macbook/miniconda3/envs/eoh/lib/python3.12/site-packages/google/api_core/timeout.py", line 130, in func_with_timeout
    return func(*args, **kwargs)
           ^^^^^^^^^^^^^^^^^^^^^
  File "/Users/macbook/miniconda3/envs/eoh/lib/python3.12/site-packages/google/api_core/grpc_helpers.py", line 78, in error_remapped_callable
    raise exceptions.from_grpc_error(exc) from exc
google.api_core.exceptions.ResourceExhausted: 429 You exceeded your current quota, please check your plan and billing details. For more information on this error, head to: https://ai.google.dev/gemini-api/docs/rate-limits. [violations {
  quota_metric: "generativelanguage.googleapis.com/generate_content_free_tier_requests"
  quota_id: "GenerateRequestsPerMinutePerProjectPerModel-FreeTier"
  quota_dimensions {
    key: "model"
    value: "gemini-1.5-flash"
  }
  quota_dimensions {
    key: "location"
    value: "global"
  }
  quota_value: 15
}
, links {
  description: "Learn more about Gemini API quotas"
  url: "https://ai.google.dev/gemini-api/docs/rate-limits"
}
, retry_delay {
  seconds: 48
}
]
.
2025-06-15 08:42:12 INFO An exception occured: Traceback (most recent call last):
  File "/Users/macbook/Documents/Code/LLMdesignedEA-comp/llamea/llamea_multi_prompts.py", line 316, in evolve_solution
    evolved_individual = self.llm.sample_solution(
                         ^^^^^^^^^^^^^^^^^^^^^^^^^
  File "/Users/macbook/Documents/Code/LLMdesignedEA-comp/llamea/llm.py", line 106, in sample_solution
    message = self.query(session_messages)
              ^^^^^^^^^^^^^^^^^^^^^^^^^^^^
  File "/Users/macbook/Documents/Code/LLMdesignedEA-comp/llamea/llm.py", line 278, in query
    response = chat_session.send_message(last["content"])
               ^^^^^^^^^^^^^^^^^^^^^^^^^^^^^^^^^^^^^^^^^^
  File "/Users/macbook/miniconda3/envs/eoh/lib/python3.12/site-packages/google/generativeai/generative_models.py", line 578, in send_message
    response = self.model.generate_content(
               ^^^^^^^^^^^^^^^^^^^^^^^^^^^^
  File "/Users/macbook/miniconda3/envs/eoh/lib/python3.12/site-packages/google/generativeai/generative_models.py", line 331, in generate_content
    response = self._client.generate_content(
               ^^^^^^^^^^^^^^^^^^^^^^^^^^^^^^
  File "/Users/macbook/miniconda3/envs/eoh/lib/python3.12/site-packages/google/ai/generativelanguage_v1beta/services/generative_service/client.py", line 835, in generate_content
    response = rpc(
               ^^^^
  File "/Users/macbook/miniconda3/envs/eoh/lib/python3.12/site-packages/google/api_core/gapic_v1/method.py", line 131, in __call__
    return wrapped_func(*args, **kwargs)
           ^^^^^^^^^^^^^^^^^^^^^^^^^^^^^
  File "/Users/macbook/miniconda3/envs/eoh/lib/python3.12/site-packages/google/api_core/retry/retry_unary.py", line 294, in retry_wrapped_func
    return retry_target(
           ^^^^^^^^^^^^^
  File "/Users/macbook/miniconda3/envs/eoh/lib/python3.12/site-packages/google/api_core/retry/retry_unary.py", line 156, in retry_target
    next_sleep = _retry_error_helper(
                 ^^^^^^^^^^^^^^^^^^^^
  File "/Users/macbook/miniconda3/envs/eoh/lib/python3.12/site-packages/google/api_core/retry/retry_base.py", line 214, in _retry_error_helper
    raise final_exc from source_exc
  File "/Users/macbook/miniconda3/envs/eoh/lib/python3.12/site-packages/google/api_core/retry/retry_unary.py", line 147, in retry_target
    result = target()
             ^^^^^^^^
  File "/Users/macbook/miniconda3/envs/eoh/lib/python3.12/site-packages/google/api_core/timeout.py", line 130, in func_with_timeout
    return func(*args, **kwargs)
           ^^^^^^^^^^^^^^^^^^^^^
  File "/Users/macbook/miniconda3/envs/eoh/lib/python3.12/site-packages/google/api_core/grpc_helpers.py", line 78, in error_remapped_callable
    raise exceptions.from_grpc_error(exc) from exc
google.api_core.exceptions.ResourceExhausted: 429 You exceeded your current quota, please check your plan and billing details. For more information on this error, head to: https://ai.google.dev/gemini-api/docs/rate-limits. [violations {
  quota_metric: "generativelanguage.googleapis.com/generate_content_free_tier_requests"
  quota_id: "GenerateRequestsPerMinutePerProjectPerModel-FreeTier"
  quota_dimensions {
    key: "model"
    value: "gemini-1.5-flash"
  }
  quota_dimensions {
    key: "location"
    value: "global"
  }
  quota_value: 15
}
, links {
  description: "Learn more about Gemini API quotas"
  url: "https://ai.google.dev/gemini-api/docs/rate-limits"
}
, retry_delay {
  seconds: 47
}
]
.
2025-06-15 08:42:12 INFO An exception occured: Traceback (most recent call last):
  File "/Users/macbook/Documents/Code/LLMdesignedEA-comp/llamea/llamea_multi_prompts.py", line 316, in evolve_solution
    evolved_individual = self.llm.sample_solution(
                         ^^^^^^^^^^^^^^^^^^^^^^^^^
  File "/Users/macbook/Documents/Code/LLMdesignedEA-comp/llamea/llm.py", line 106, in sample_solution
    message = self.query(session_messages)
              ^^^^^^^^^^^^^^^^^^^^^^^^^^^^
  File "/Users/macbook/Documents/Code/LLMdesignedEA-comp/llamea/llm.py", line 278, in query
    response = chat_session.send_message(last["content"])
               ^^^^^^^^^^^^^^^^^^^^^^^^^^^^^^^^^^^^^^^^^^
  File "/Users/macbook/miniconda3/envs/eoh/lib/python3.12/site-packages/google/generativeai/generative_models.py", line 578, in send_message
    response = self.model.generate_content(
               ^^^^^^^^^^^^^^^^^^^^^^^^^^^^
  File "/Users/macbook/miniconda3/envs/eoh/lib/python3.12/site-packages/google/generativeai/generative_models.py", line 331, in generate_content
    response = self._client.generate_content(
               ^^^^^^^^^^^^^^^^^^^^^^^^^^^^^^
  File "/Users/macbook/miniconda3/envs/eoh/lib/python3.12/site-packages/google/ai/generativelanguage_v1beta/services/generative_service/client.py", line 835, in generate_content
    response = rpc(
               ^^^^
  File "/Users/macbook/miniconda3/envs/eoh/lib/python3.12/site-packages/google/api_core/gapic_v1/method.py", line 131, in __call__
    return wrapped_func(*args, **kwargs)
           ^^^^^^^^^^^^^^^^^^^^^^^^^^^^^
  File "/Users/macbook/miniconda3/envs/eoh/lib/python3.12/site-packages/google/api_core/retry/retry_unary.py", line 294, in retry_wrapped_func
    return retry_target(
           ^^^^^^^^^^^^^
  File "/Users/macbook/miniconda3/envs/eoh/lib/python3.12/site-packages/google/api_core/retry/retry_unary.py", line 156, in retry_target
    next_sleep = _retry_error_helper(
                 ^^^^^^^^^^^^^^^^^^^^
  File "/Users/macbook/miniconda3/envs/eoh/lib/python3.12/site-packages/google/api_core/retry/retry_base.py", line 214, in _retry_error_helper
    raise final_exc from source_exc
  File "/Users/macbook/miniconda3/envs/eoh/lib/python3.12/site-packages/google/api_core/retry/retry_unary.py", line 147, in retry_target
    result = target()
             ^^^^^^^^
  File "/Users/macbook/miniconda3/envs/eoh/lib/python3.12/site-packages/google/api_core/timeout.py", line 130, in func_with_timeout
    return func(*args, **kwargs)
           ^^^^^^^^^^^^^^^^^^^^^
  File "/Users/macbook/miniconda3/envs/eoh/lib/python3.12/site-packages/google/api_core/grpc_helpers.py", line 78, in error_remapped_callable
    raise exceptions.from_grpc_error(exc) from exc
google.api_core.exceptions.ResourceExhausted: 429 You exceeded your current quota, please check your plan and billing details. For more information on this error, head to: https://ai.google.dev/gemini-api/docs/rate-limits. [violations {
  quota_metric: "generativelanguage.googleapis.com/generate_content_free_tier_requests"
  quota_id: "GenerateRequestsPerMinutePerProjectPerModel-FreeTier"
  quota_dimensions {
    key: "model"
    value: "gemini-1.5-flash"
  }
  quota_dimensions {
    key: "location"
    value: "global"
  }
  quota_value: 15
}
, links {
  description: "Learn more about Gemini API quotas"
  url: "https://ai.google.dev/gemini-api/docs/rate-limits"
}
, retry_delay {
  seconds: 47
}
]
.
2025-06-15 08:42:12 INFO An exception occured: Traceback (most recent call last):
  File "/Users/macbook/Documents/Code/LLMdesignedEA-comp/llamea/llamea_multi_prompts.py", line 316, in evolve_solution
    evolved_individual = self.llm.sample_solution(
                         ^^^^^^^^^^^^^^^^^^^^^^^^^
  File "/Users/macbook/Documents/Code/LLMdesignedEA-comp/llamea/llm.py", line 106, in sample_solution
    message = self.query(session_messages)
              ^^^^^^^^^^^^^^^^^^^^^^^^^^^^
  File "/Users/macbook/Documents/Code/LLMdesignedEA-comp/llamea/llm.py", line 278, in query
    response = chat_session.send_message(last["content"])
               ^^^^^^^^^^^^^^^^^^^^^^^^^^^^^^^^^^^^^^^^^^
  File "/Users/macbook/miniconda3/envs/eoh/lib/python3.12/site-packages/google/generativeai/generative_models.py", line 578, in send_message
    response = self.model.generate_content(
               ^^^^^^^^^^^^^^^^^^^^^^^^^^^^
  File "/Users/macbook/miniconda3/envs/eoh/lib/python3.12/site-packages/google/generativeai/generative_models.py", line 331, in generate_content
    response = self._client.generate_content(
               ^^^^^^^^^^^^^^^^^^^^^^^^^^^^^^
  File "/Users/macbook/miniconda3/envs/eoh/lib/python3.12/site-packages/google/ai/generativelanguage_v1beta/services/generative_service/client.py", line 835, in generate_content
    response = rpc(
               ^^^^
  File "/Users/macbook/miniconda3/envs/eoh/lib/python3.12/site-packages/google/api_core/gapic_v1/method.py", line 131, in __call__
    return wrapped_func(*args, **kwargs)
           ^^^^^^^^^^^^^^^^^^^^^^^^^^^^^
  File "/Users/macbook/miniconda3/envs/eoh/lib/python3.12/site-packages/google/api_core/retry/retry_unary.py", line 294, in retry_wrapped_func
    return retry_target(
           ^^^^^^^^^^^^^
  File "/Users/macbook/miniconda3/envs/eoh/lib/python3.12/site-packages/google/api_core/retry/retry_unary.py", line 156, in retry_target
    next_sleep = _retry_error_helper(
                 ^^^^^^^^^^^^^^^^^^^^
  File "/Users/macbook/miniconda3/envs/eoh/lib/python3.12/site-packages/google/api_core/retry/retry_base.py", line 214, in _retry_error_helper
    raise final_exc from source_exc
  File "/Users/macbook/miniconda3/envs/eoh/lib/python3.12/site-packages/google/api_core/retry/retry_unary.py", line 147, in retry_target
    result = target()
             ^^^^^^^^
  File "/Users/macbook/miniconda3/envs/eoh/lib/python3.12/site-packages/google/api_core/timeout.py", line 130, in func_with_timeout
    return func(*args, **kwargs)
           ^^^^^^^^^^^^^^^^^^^^^
  File "/Users/macbook/miniconda3/envs/eoh/lib/python3.12/site-packages/google/api_core/grpc_helpers.py", line 78, in error_remapped_callable
    raise exceptions.from_grpc_error(exc) from exc
google.api_core.exceptions.ResourceExhausted: 429 You exceeded your current quota, please check your plan and billing details. For more information on this error, head to: https://ai.google.dev/gemini-api/docs/rate-limits. [violations {
  quota_metric: "generativelanguage.googleapis.com/generate_content_free_tier_requests"
  quota_id: "GenerateRequestsPerMinutePerProjectPerModel-FreeTier"
  quota_dimensions {
    key: "model"
    value: "gemini-1.5-flash"
  }
  quota_dimensions {
    key: "location"
    value: "global"
  }
  quota_value: 15
}
, links {
  description: "Learn more about Gemini API quotas"
  url: "https://ai.google.dev/gemini-api/docs/rate-limits"
}
, retry_delay {
  seconds: 47
}
]
.
2025-06-15 08:42:12 INFO An exception occured: Traceback (most recent call last):
  File "/Users/macbook/Documents/Code/LLMdesignedEA-comp/llamea/llamea_multi_prompts.py", line 316, in evolve_solution
    evolved_individual = self.llm.sample_solution(
                         ^^^^^^^^^^^^^^^^^^^^^^^^^
  File "/Users/macbook/Documents/Code/LLMdesignedEA-comp/llamea/llm.py", line 106, in sample_solution
    message = self.query(session_messages)
              ^^^^^^^^^^^^^^^^^^^^^^^^^^^^
  File "/Users/macbook/Documents/Code/LLMdesignedEA-comp/llamea/llm.py", line 278, in query
    response = chat_session.send_message(last["content"])
               ^^^^^^^^^^^^^^^^^^^^^^^^^^^^^^^^^^^^^^^^^^
  File "/Users/macbook/miniconda3/envs/eoh/lib/python3.12/site-packages/google/generativeai/generative_models.py", line 578, in send_message
    response = self.model.generate_content(
               ^^^^^^^^^^^^^^^^^^^^^^^^^^^^
  File "/Users/macbook/miniconda3/envs/eoh/lib/python3.12/site-packages/google/generativeai/generative_models.py", line 331, in generate_content
    response = self._client.generate_content(
               ^^^^^^^^^^^^^^^^^^^^^^^^^^^^^^
  File "/Users/macbook/miniconda3/envs/eoh/lib/python3.12/site-packages/google/ai/generativelanguage_v1beta/services/generative_service/client.py", line 835, in generate_content
    response = rpc(
               ^^^^
  File "/Users/macbook/miniconda3/envs/eoh/lib/python3.12/site-packages/google/api_core/gapic_v1/method.py", line 131, in __call__
    return wrapped_func(*args, **kwargs)
           ^^^^^^^^^^^^^^^^^^^^^^^^^^^^^
  File "/Users/macbook/miniconda3/envs/eoh/lib/python3.12/site-packages/google/api_core/retry/retry_unary.py", line 294, in retry_wrapped_func
    return retry_target(
           ^^^^^^^^^^^^^
  File "/Users/macbook/miniconda3/envs/eoh/lib/python3.12/site-packages/google/api_core/retry/retry_unary.py", line 156, in retry_target
    next_sleep = _retry_error_helper(
                 ^^^^^^^^^^^^^^^^^^^^
  File "/Users/macbook/miniconda3/envs/eoh/lib/python3.12/site-packages/google/api_core/retry/retry_base.py", line 214, in _retry_error_helper
    raise final_exc from source_exc
  File "/Users/macbook/miniconda3/envs/eoh/lib/python3.12/site-packages/google/api_core/retry/retry_unary.py", line 147, in retry_target
    result = target()
             ^^^^^^^^
  File "/Users/macbook/miniconda3/envs/eoh/lib/python3.12/site-packages/google/api_core/timeout.py", line 130, in func_with_timeout
    return func(*args, **kwargs)
           ^^^^^^^^^^^^^^^^^^^^^
  File "/Users/macbook/miniconda3/envs/eoh/lib/python3.12/site-packages/google/api_core/grpc_helpers.py", line 78, in error_remapped_callable
    raise exceptions.from_grpc_error(exc) from exc
google.api_core.exceptions.ResourceExhausted: 429 You exceeded your current quota, please check your plan and billing details. For more information on this error, head to: https://ai.google.dev/gemini-api/docs/rate-limits. [violations {
  quota_metric: "generativelanguage.googleapis.com/generate_content_free_tier_requests"
  quota_id: "GenerateRequestsPerMinutePerProjectPerModel-FreeTier"
  quota_dimensions {
    key: "model"
    value: "gemini-1.5-flash"
  }
  quota_dimensions {
    key: "location"
    value: "global"
  }
  quota_value: 15
}
, links {
  description: "Learn more about Gemini API quotas"
  url: "https://ai.google.dev/gemini-api/docs/rate-limits"
}
, retry_delay {
  seconds: 47
}
]
.
2025-06-15 08:42:12 INFO An exception occured: Traceback (most recent call last):
  File "/Users/macbook/Documents/Code/LLMdesignedEA-comp/llamea/llamea_multi_prompts.py", line 316, in evolve_solution
    evolved_individual = self.llm.sample_solution(
                         ^^^^^^^^^^^^^^^^^^^^^^^^^
  File "/Users/macbook/Documents/Code/LLMdesignedEA-comp/llamea/llm.py", line 106, in sample_solution
    message = self.query(session_messages)
              ^^^^^^^^^^^^^^^^^^^^^^^^^^^^
  File "/Users/macbook/Documents/Code/LLMdesignedEA-comp/llamea/llm.py", line 278, in query
    response = chat_session.send_message(last["content"])
               ^^^^^^^^^^^^^^^^^^^^^^^^^^^^^^^^^^^^^^^^^^
  File "/Users/macbook/miniconda3/envs/eoh/lib/python3.12/site-packages/google/generativeai/generative_models.py", line 578, in send_message
    response = self.model.generate_content(
               ^^^^^^^^^^^^^^^^^^^^^^^^^^^^
  File "/Users/macbook/miniconda3/envs/eoh/lib/python3.12/site-packages/google/generativeai/generative_models.py", line 331, in generate_content
    response = self._client.generate_content(
               ^^^^^^^^^^^^^^^^^^^^^^^^^^^^^^
  File "/Users/macbook/miniconda3/envs/eoh/lib/python3.12/site-packages/google/ai/generativelanguage_v1beta/services/generative_service/client.py", line 835, in generate_content
    response = rpc(
               ^^^^
  File "/Users/macbook/miniconda3/envs/eoh/lib/python3.12/site-packages/google/api_core/gapic_v1/method.py", line 131, in __call__
    return wrapped_func(*args, **kwargs)
           ^^^^^^^^^^^^^^^^^^^^^^^^^^^^^
  File "/Users/macbook/miniconda3/envs/eoh/lib/python3.12/site-packages/google/api_core/retry/retry_unary.py", line 294, in retry_wrapped_func
    return retry_target(
           ^^^^^^^^^^^^^
  File "/Users/macbook/miniconda3/envs/eoh/lib/python3.12/site-packages/google/api_core/retry/retry_unary.py", line 156, in retry_target
    next_sleep = _retry_error_helper(
                 ^^^^^^^^^^^^^^^^^^^^
  File "/Users/macbook/miniconda3/envs/eoh/lib/python3.12/site-packages/google/api_core/retry/retry_base.py", line 214, in _retry_error_helper
    raise final_exc from source_exc
  File "/Users/macbook/miniconda3/envs/eoh/lib/python3.12/site-packages/google/api_core/retry/retry_unary.py", line 147, in retry_target
    result = target()
             ^^^^^^^^
  File "/Users/macbook/miniconda3/envs/eoh/lib/python3.12/site-packages/google/api_core/timeout.py", line 130, in func_with_timeout
    return func(*args, **kwargs)
           ^^^^^^^^^^^^^^^^^^^^^
  File "/Users/macbook/miniconda3/envs/eoh/lib/python3.12/site-packages/google/api_core/grpc_helpers.py", line 78, in error_remapped_callable
    raise exceptions.from_grpc_error(exc) from exc
google.api_core.exceptions.ResourceExhausted: 429 You exceeded your current quota, please check your plan and billing details. For more information on this error, head to: https://ai.google.dev/gemini-api/docs/rate-limits. [violations {
  quota_metric: "generativelanguage.googleapis.com/generate_content_free_tier_requests"
  quota_id: "GenerateRequestsPerMinutePerProjectPerModel-FreeTier"
  quota_dimensions {
    key: "model"
    value: "gemini-1.5-flash"
  }
  quota_dimensions {
    key: "location"
    value: "global"
  }
  quota_value: 15
}
, links {
  description: "Learn more about Gemini API quotas"
  url: "https://ai.google.dev/gemini-api/docs/rate-limits"
}
, retry_delay {
  seconds: 47
}
]
.
2025-06-15 08:42:12 INFO An exception occured: Traceback (most recent call last):
  File "/Users/macbook/Documents/Code/LLMdesignedEA-comp/llamea/llamea_multi_prompts.py", line 316, in evolve_solution
    evolved_individual = self.llm.sample_solution(
                         ^^^^^^^^^^^^^^^^^^^^^^^^^
  File "/Users/macbook/Documents/Code/LLMdesignedEA-comp/llamea/llm.py", line 106, in sample_solution
    message = self.query(session_messages)
              ^^^^^^^^^^^^^^^^^^^^^^^^^^^^
  File "/Users/macbook/Documents/Code/LLMdesignedEA-comp/llamea/llm.py", line 278, in query
    response = chat_session.send_message(last["content"])
               ^^^^^^^^^^^^^^^^^^^^^^^^^^^^^^^^^^^^^^^^^^
  File "/Users/macbook/miniconda3/envs/eoh/lib/python3.12/site-packages/google/generativeai/generative_models.py", line 578, in send_message
    response = self.model.generate_content(
               ^^^^^^^^^^^^^^^^^^^^^^^^^^^^
  File "/Users/macbook/miniconda3/envs/eoh/lib/python3.12/site-packages/google/generativeai/generative_models.py", line 331, in generate_content
    response = self._client.generate_content(
               ^^^^^^^^^^^^^^^^^^^^^^^^^^^^^^
  File "/Users/macbook/miniconda3/envs/eoh/lib/python3.12/site-packages/google/ai/generativelanguage_v1beta/services/generative_service/client.py", line 835, in generate_content
    response = rpc(
               ^^^^
  File "/Users/macbook/miniconda3/envs/eoh/lib/python3.12/site-packages/google/api_core/gapic_v1/method.py", line 131, in __call__
    return wrapped_func(*args, **kwargs)
           ^^^^^^^^^^^^^^^^^^^^^^^^^^^^^
  File "/Users/macbook/miniconda3/envs/eoh/lib/python3.12/site-packages/google/api_core/retry/retry_unary.py", line 294, in retry_wrapped_func
    return retry_target(
           ^^^^^^^^^^^^^
  File "/Users/macbook/miniconda3/envs/eoh/lib/python3.12/site-packages/google/api_core/retry/retry_unary.py", line 156, in retry_target
    next_sleep = _retry_error_helper(
                 ^^^^^^^^^^^^^^^^^^^^
  File "/Users/macbook/miniconda3/envs/eoh/lib/python3.12/site-packages/google/api_core/retry/retry_base.py", line 214, in _retry_error_helper
    raise final_exc from source_exc
  File "/Users/macbook/miniconda3/envs/eoh/lib/python3.12/site-packages/google/api_core/retry/retry_unary.py", line 147, in retry_target
    result = target()
             ^^^^^^^^
  File "/Users/macbook/miniconda3/envs/eoh/lib/python3.12/site-packages/google/api_core/timeout.py", line 130, in func_with_timeout
    return func(*args, **kwargs)
           ^^^^^^^^^^^^^^^^^^^^^
  File "/Users/macbook/miniconda3/envs/eoh/lib/python3.12/site-packages/google/api_core/grpc_helpers.py", line 78, in error_remapped_callable
    raise exceptions.from_grpc_error(exc) from exc
google.api_core.exceptions.ResourceExhausted: 429 You exceeded your current quota, please check your plan and billing details. For more information on this error, head to: https://ai.google.dev/gemini-api/docs/rate-limits. [violations {
  quota_metric: "generativelanguage.googleapis.com/generate_content_free_tier_requests"
  quota_id: "GenerateRequestsPerMinutePerProjectPerModel-FreeTier"
  quota_dimensions {
    key: "model"
    value: "gemini-1.5-flash"
  }
  quota_dimensions {
    key: "location"
    value: "global"
  }
  quota_value: 15
}
, links {
  description: "Learn more about Gemini API quotas"
  url: "https://ai.google.dev/gemini-api/docs/rate-limits"
}
, retry_delay {
  seconds: 47
}
]
.
2025-06-15 08:42:12 INFO An exception occured: Traceback (most recent call last):
  File "/Users/macbook/Documents/Code/LLMdesignedEA-comp/llamea/llamea_multi_prompts.py", line 316, in evolve_solution
    evolved_individual = self.llm.sample_solution(
                         ^^^^^^^^^^^^^^^^^^^^^^^^^
  File "/Users/macbook/Documents/Code/LLMdesignedEA-comp/llamea/llm.py", line 106, in sample_solution
    message = self.query(session_messages)
              ^^^^^^^^^^^^^^^^^^^^^^^^^^^^
  File "/Users/macbook/Documents/Code/LLMdesignedEA-comp/llamea/llm.py", line 278, in query
    response = chat_session.send_message(last["content"])
               ^^^^^^^^^^^^^^^^^^^^^^^^^^^^^^^^^^^^^^^^^^
  File "/Users/macbook/miniconda3/envs/eoh/lib/python3.12/site-packages/google/generativeai/generative_models.py", line 578, in send_message
    response = self.model.generate_content(
               ^^^^^^^^^^^^^^^^^^^^^^^^^^^^
  File "/Users/macbook/miniconda3/envs/eoh/lib/python3.12/site-packages/google/generativeai/generative_models.py", line 331, in generate_content
    response = self._client.generate_content(
               ^^^^^^^^^^^^^^^^^^^^^^^^^^^^^^
  File "/Users/macbook/miniconda3/envs/eoh/lib/python3.12/site-packages/google/ai/generativelanguage_v1beta/services/generative_service/client.py", line 835, in generate_content
    response = rpc(
               ^^^^
  File "/Users/macbook/miniconda3/envs/eoh/lib/python3.12/site-packages/google/api_core/gapic_v1/method.py", line 131, in __call__
    return wrapped_func(*args, **kwargs)
           ^^^^^^^^^^^^^^^^^^^^^^^^^^^^^
  File "/Users/macbook/miniconda3/envs/eoh/lib/python3.12/site-packages/google/api_core/retry/retry_unary.py", line 294, in retry_wrapped_func
    return retry_target(
           ^^^^^^^^^^^^^
  File "/Users/macbook/miniconda3/envs/eoh/lib/python3.12/site-packages/google/api_core/retry/retry_unary.py", line 156, in retry_target
    next_sleep = _retry_error_helper(
                 ^^^^^^^^^^^^^^^^^^^^
  File "/Users/macbook/miniconda3/envs/eoh/lib/python3.12/site-packages/google/api_core/retry/retry_base.py", line 214, in _retry_error_helper
    raise final_exc from source_exc
  File "/Users/macbook/miniconda3/envs/eoh/lib/python3.12/site-packages/google/api_core/retry/retry_unary.py", line 147, in retry_target
    result = target()
             ^^^^^^^^
  File "/Users/macbook/miniconda3/envs/eoh/lib/python3.12/site-packages/google/api_core/timeout.py", line 130, in func_with_timeout
    return func(*args, **kwargs)
           ^^^^^^^^^^^^^^^^^^^^^
  File "/Users/macbook/miniconda3/envs/eoh/lib/python3.12/site-packages/google/api_core/grpc_helpers.py", line 78, in error_remapped_callable
    raise exceptions.from_grpc_error(exc) from exc
google.api_core.exceptions.ResourceExhausted: 429 You exceeded your current quota, please check your plan and billing details. For more information on this error, head to: https://ai.google.dev/gemini-api/docs/rate-limits. [violations {
  quota_metric: "generativelanguage.googleapis.com/generate_content_free_tier_requests"
  quota_id: "GenerateRequestsPerMinutePerProjectPerModel-FreeTier"
  quota_dimensions {
    key: "model"
    value: "gemini-1.5-flash"
  }
  quota_dimensions {
    key: "location"
    value: "global"
  }
  quota_value: 15
}
, links {
  description: "Learn more about Gemini API quotas"
  url: "https://ai.google.dev/gemini-api/docs/rate-limits"
}
, retry_delay {
  seconds: 47
}
]
.
2025-06-15 08:42:12 INFO An exception occured: Traceback (most recent call last):
  File "/Users/macbook/Documents/Code/LLMdesignedEA-comp/llamea/llamea_multi_prompts.py", line 316, in evolve_solution
    evolved_individual = self.llm.sample_solution(
                         ^^^^^^^^^^^^^^^^^^^^^^^^^
  File "/Users/macbook/Documents/Code/LLMdesignedEA-comp/llamea/llm.py", line 106, in sample_solution
    message = self.query(session_messages)
              ^^^^^^^^^^^^^^^^^^^^^^^^^^^^
  File "/Users/macbook/Documents/Code/LLMdesignedEA-comp/llamea/llm.py", line 278, in query
    response = chat_session.send_message(last["content"])
               ^^^^^^^^^^^^^^^^^^^^^^^^^^^^^^^^^^^^^^^^^^
  File "/Users/macbook/miniconda3/envs/eoh/lib/python3.12/site-packages/google/generativeai/generative_models.py", line 578, in send_message
    response = self.model.generate_content(
               ^^^^^^^^^^^^^^^^^^^^^^^^^^^^
  File "/Users/macbook/miniconda3/envs/eoh/lib/python3.12/site-packages/google/generativeai/generative_models.py", line 331, in generate_content
    response = self._client.generate_content(
               ^^^^^^^^^^^^^^^^^^^^^^^^^^^^^^
  File "/Users/macbook/miniconda3/envs/eoh/lib/python3.12/site-packages/google/ai/generativelanguage_v1beta/services/generative_service/client.py", line 835, in generate_content
    response = rpc(
               ^^^^
  File "/Users/macbook/miniconda3/envs/eoh/lib/python3.12/site-packages/google/api_core/gapic_v1/method.py", line 131, in __call__
    return wrapped_func(*args, **kwargs)
           ^^^^^^^^^^^^^^^^^^^^^^^^^^^^^
  File "/Users/macbook/miniconda3/envs/eoh/lib/python3.12/site-packages/google/api_core/retry/retry_unary.py", line 294, in retry_wrapped_func
    return retry_target(
           ^^^^^^^^^^^^^
  File "/Users/macbook/miniconda3/envs/eoh/lib/python3.12/site-packages/google/api_core/retry/retry_unary.py", line 156, in retry_target
    next_sleep = _retry_error_helper(
                 ^^^^^^^^^^^^^^^^^^^^
  File "/Users/macbook/miniconda3/envs/eoh/lib/python3.12/site-packages/google/api_core/retry/retry_base.py", line 214, in _retry_error_helper
    raise final_exc from source_exc
  File "/Users/macbook/miniconda3/envs/eoh/lib/python3.12/site-packages/google/api_core/retry/retry_unary.py", line 147, in retry_target
    result = target()
             ^^^^^^^^
  File "/Users/macbook/miniconda3/envs/eoh/lib/python3.12/site-packages/google/api_core/timeout.py", line 130, in func_with_timeout
    return func(*args, **kwargs)
           ^^^^^^^^^^^^^^^^^^^^^
  File "/Users/macbook/miniconda3/envs/eoh/lib/python3.12/site-packages/google/api_core/grpc_helpers.py", line 78, in error_remapped_callable
    raise exceptions.from_grpc_error(exc) from exc
google.api_core.exceptions.ResourceExhausted: 429 You exceeded your current quota, please check your plan and billing details. For more information on this error, head to: https://ai.google.dev/gemini-api/docs/rate-limits. [violations {
  quota_metric: "generativelanguage.googleapis.com/generate_content_free_tier_requests"
  quota_id: "GenerateRequestsPerMinutePerProjectPerModel-FreeTier"
  quota_dimensions {
    key: "model"
    value: "gemini-1.5-flash"
  }
  quota_dimensions {
    key: "location"
    value: "global"
  }
  quota_value: 15
}
, links {
  description: "Learn more about Gemini API quotas"
  url: "https://ai.google.dev/gemini-api/docs/rate-limits"
}
, retry_delay {
  seconds: 47
}
]
.
2025-06-15 08:42:12 INFO An exception occured: Traceback (most recent call last):
  File "/Users/macbook/Documents/Code/LLMdesignedEA-comp/llamea/llamea_multi_prompts.py", line 316, in evolve_solution
    evolved_individual = self.llm.sample_solution(
                         ^^^^^^^^^^^^^^^^^^^^^^^^^
  File "/Users/macbook/Documents/Code/LLMdesignedEA-comp/llamea/llm.py", line 106, in sample_solution
    message = self.query(session_messages)
              ^^^^^^^^^^^^^^^^^^^^^^^^^^^^
  File "/Users/macbook/Documents/Code/LLMdesignedEA-comp/llamea/llm.py", line 278, in query
    response = chat_session.send_message(last["content"])
               ^^^^^^^^^^^^^^^^^^^^^^^^^^^^^^^^^^^^^^^^^^
  File "/Users/macbook/miniconda3/envs/eoh/lib/python3.12/site-packages/google/generativeai/generative_models.py", line 578, in send_message
    response = self.model.generate_content(
               ^^^^^^^^^^^^^^^^^^^^^^^^^^^^
  File "/Users/macbook/miniconda3/envs/eoh/lib/python3.12/site-packages/google/generativeai/generative_models.py", line 331, in generate_content
    response = self._client.generate_content(
               ^^^^^^^^^^^^^^^^^^^^^^^^^^^^^^
  File "/Users/macbook/miniconda3/envs/eoh/lib/python3.12/site-packages/google/ai/generativelanguage_v1beta/services/generative_service/client.py", line 835, in generate_content
    response = rpc(
               ^^^^
  File "/Users/macbook/miniconda3/envs/eoh/lib/python3.12/site-packages/google/api_core/gapic_v1/method.py", line 131, in __call__
    return wrapped_func(*args, **kwargs)
           ^^^^^^^^^^^^^^^^^^^^^^^^^^^^^
  File "/Users/macbook/miniconda3/envs/eoh/lib/python3.12/site-packages/google/api_core/retry/retry_unary.py", line 294, in retry_wrapped_func
    return retry_target(
           ^^^^^^^^^^^^^
  File "/Users/macbook/miniconda3/envs/eoh/lib/python3.12/site-packages/google/api_core/retry/retry_unary.py", line 156, in retry_target
    next_sleep = _retry_error_helper(
                 ^^^^^^^^^^^^^^^^^^^^
  File "/Users/macbook/miniconda3/envs/eoh/lib/python3.12/site-packages/google/api_core/retry/retry_base.py", line 214, in _retry_error_helper
    raise final_exc from source_exc
  File "/Users/macbook/miniconda3/envs/eoh/lib/python3.12/site-packages/google/api_core/retry/retry_unary.py", line 147, in retry_target
    result = target()
             ^^^^^^^^
  File "/Users/macbook/miniconda3/envs/eoh/lib/python3.12/site-packages/google/api_core/timeout.py", line 130, in func_with_timeout
    return func(*args, **kwargs)
           ^^^^^^^^^^^^^^^^^^^^^
  File "/Users/macbook/miniconda3/envs/eoh/lib/python3.12/site-packages/google/api_core/grpc_helpers.py", line 78, in error_remapped_callable
    raise exceptions.from_grpc_error(exc) from exc
google.api_core.exceptions.ResourceExhausted: 429 You exceeded your current quota, please check your plan and billing details. For more information on this error, head to: https://ai.google.dev/gemini-api/docs/rate-limits. [violations {
  quota_metric: "generativelanguage.googleapis.com/generate_content_free_tier_requests"
  quota_id: "GenerateRequestsPerMinutePerProjectPerModel-FreeTier"
  quota_dimensions {
    key: "model"
    value: "gemini-1.5-flash"
  }
  quota_dimensions {
    key: "location"
    value: "global"
  }
  quota_value: 15
}
, links {
  description: "Learn more about Gemini API quotas"
  url: "https://ai.google.dev/gemini-api/docs/rate-limits"
}
, retry_delay {
  seconds: 47
}
]
.
2025-06-15 08:42:13 INFO An exception occured: Traceback (most recent call last):
  File "/Users/macbook/Documents/Code/LLMdesignedEA-comp/llamea/llamea_multi_prompts.py", line 316, in evolve_solution
    evolved_individual = self.llm.sample_solution(
                         ^^^^^^^^^^^^^^^^^^^^^^^^^
  File "/Users/macbook/Documents/Code/LLMdesignedEA-comp/llamea/llm.py", line 106, in sample_solution
    message = self.query(session_messages)
              ^^^^^^^^^^^^^^^^^^^^^^^^^^^^
  File "/Users/macbook/Documents/Code/LLMdesignedEA-comp/llamea/llm.py", line 278, in query
    response = chat_session.send_message(last["content"])
               ^^^^^^^^^^^^^^^^^^^^^^^^^^^^^^^^^^^^^^^^^^
  File "/Users/macbook/miniconda3/envs/eoh/lib/python3.12/site-packages/google/generativeai/generative_models.py", line 578, in send_message
    response = self.model.generate_content(
               ^^^^^^^^^^^^^^^^^^^^^^^^^^^^
  File "/Users/macbook/miniconda3/envs/eoh/lib/python3.12/site-packages/google/generativeai/generative_models.py", line 331, in generate_content
    response = self._client.generate_content(
               ^^^^^^^^^^^^^^^^^^^^^^^^^^^^^^
  File "/Users/macbook/miniconda3/envs/eoh/lib/python3.12/site-packages/google/ai/generativelanguage_v1beta/services/generative_service/client.py", line 835, in generate_content
    response = rpc(
               ^^^^
  File "/Users/macbook/miniconda3/envs/eoh/lib/python3.12/site-packages/google/api_core/gapic_v1/method.py", line 131, in __call__
    return wrapped_func(*args, **kwargs)
           ^^^^^^^^^^^^^^^^^^^^^^^^^^^^^
  File "/Users/macbook/miniconda3/envs/eoh/lib/python3.12/site-packages/google/api_core/retry/retry_unary.py", line 294, in retry_wrapped_func
    return retry_target(
           ^^^^^^^^^^^^^
  File "/Users/macbook/miniconda3/envs/eoh/lib/python3.12/site-packages/google/api_core/retry/retry_unary.py", line 156, in retry_target
    next_sleep = _retry_error_helper(
                 ^^^^^^^^^^^^^^^^^^^^
  File "/Users/macbook/miniconda3/envs/eoh/lib/python3.12/site-packages/google/api_core/retry/retry_base.py", line 214, in _retry_error_helper
    raise final_exc from source_exc
  File "/Users/macbook/miniconda3/envs/eoh/lib/python3.12/site-packages/google/api_core/retry/retry_unary.py", line 147, in retry_target
    result = target()
             ^^^^^^^^
  File "/Users/macbook/miniconda3/envs/eoh/lib/python3.12/site-packages/google/api_core/timeout.py", line 130, in func_with_timeout
    return func(*args, **kwargs)
           ^^^^^^^^^^^^^^^^^^^^^
  File "/Users/macbook/miniconda3/envs/eoh/lib/python3.12/site-packages/google/api_core/grpc_helpers.py", line 78, in error_remapped_callable
    raise exceptions.from_grpc_error(exc) from exc
google.api_core.exceptions.ResourceExhausted: 429 You exceeded your current quota, please check your plan and billing details. For more information on this error, head to: https://ai.google.dev/gemini-api/docs/rate-limits. [violations {
  quota_metric: "generativelanguage.googleapis.com/generate_content_free_tier_requests"
  quota_id: "GenerateRequestsPerMinutePerProjectPerModel-FreeTier"
  quota_dimensions {
    key: "model"
    value: "gemini-1.5-flash"
  }
  quota_dimensions {
    key: "location"
    value: "global"
  }
  quota_value: 15
}
, links {
  description: "Learn more about Gemini API quotas"
  url: "https://ai.google.dev/gemini-api/docs/rate-limits"
}
, retry_delay {
  seconds: 47
}
]
.
2025-06-15 08:42:13 INFO An exception occured: Traceback (most recent call last):
  File "/Users/macbook/Documents/Code/LLMdesignedEA-comp/llamea/llamea_multi_prompts.py", line 316, in evolve_solution
    evolved_individual = self.llm.sample_solution(
                         ^^^^^^^^^^^^^^^^^^^^^^^^^
  File "/Users/macbook/Documents/Code/LLMdesignedEA-comp/llamea/llm.py", line 106, in sample_solution
    message = self.query(session_messages)
              ^^^^^^^^^^^^^^^^^^^^^^^^^^^^
  File "/Users/macbook/Documents/Code/LLMdesignedEA-comp/llamea/llm.py", line 278, in query
    response = chat_session.send_message(last["content"])
               ^^^^^^^^^^^^^^^^^^^^^^^^^^^^^^^^^^^^^^^^^^
  File "/Users/macbook/miniconda3/envs/eoh/lib/python3.12/site-packages/google/generativeai/generative_models.py", line 578, in send_message
    response = self.model.generate_content(
               ^^^^^^^^^^^^^^^^^^^^^^^^^^^^
  File "/Users/macbook/miniconda3/envs/eoh/lib/python3.12/site-packages/google/generativeai/generative_models.py", line 331, in generate_content
    response = self._client.generate_content(
               ^^^^^^^^^^^^^^^^^^^^^^^^^^^^^^
  File "/Users/macbook/miniconda3/envs/eoh/lib/python3.12/site-packages/google/ai/generativelanguage_v1beta/services/generative_service/client.py", line 835, in generate_content
    response = rpc(
               ^^^^
  File "/Users/macbook/miniconda3/envs/eoh/lib/python3.12/site-packages/google/api_core/gapic_v1/method.py", line 131, in __call__
    return wrapped_func(*args, **kwargs)
           ^^^^^^^^^^^^^^^^^^^^^^^^^^^^^
  File "/Users/macbook/miniconda3/envs/eoh/lib/python3.12/site-packages/google/api_core/retry/retry_unary.py", line 294, in retry_wrapped_func
    return retry_target(
           ^^^^^^^^^^^^^
  File "/Users/macbook/miniconda3/envs/eoh/lib/python3.12/site-packages/google/api_core/retry/retry_unary.py", line 156, in retry_target
    next_sleep = _retry_error_helper(
                 ^^^^^^^^^^^^^^^^^^^^
  File "/Users/macbook/miniconda3/envs/eoh/lib/python3.12/site-packages/google/api_core/retry/retry_base.py", line 214, in _retry_error_helper
    raise final_exc from source_exc
  File "/Users/macbook/miniconda3/envs/eoh/lib/python3.12/site-packages/google/api_core/retry/retry_unary.py", line 147, in retry_target
    result = target()
             ^^^^^^^^
  File "/Users/macbook/miniconda3/envs/eoh/lib/python3.12/site-packages/google/api_core/timeout.py", line 130, in func_with_timeout
    return func(*args, **kwargs)
           ^^^^^^^^^^^^^^^^^^^^^
  File "/Users/macbook/miniconda3/envs/eoh/lib/python3.12/site-packages/google/api_core/grpc_helpers.py", line 78, in error_remapped_callable
    raise exceptions.from_grpc_error(exc) from exc
google.api_core.exceptions.ResourceExhausted: 429 You exceeded your current quota, please check your plan and billing details. For more information on this error, head to: https://ai.google.dev/gemini-api/docs/rate-limits. [violations {
  quota_metric: "generativelanguage.googleapis.com/generate_content_free_tier_requests"
  quota_id: "GenerateRequestsPerMinutePerProjectPerModel-FreeTier"
  quota_dimensions {
    key: "model"
    value: "gemini-1.5-flash"
  }
  quota_dimensions {
    key: "location"
    value: "global"
  }
  quota_value: 15
}
, links {
  description: "Learn more about Gemini API quotas"
  url: "https://ai.google.dev/gemini-api/docs/rate-limits"
}
, retry_delay {
  seconds: 47
}
]
.
2025-06-15 08:42:13 INFO An exception occured: Traceback (most recent call last):
  File "/Users/macbook/Documents/Code/LLMdesignedEA-comp/llamea/llamea_multi_prompts.py", line 316, in evolve_solution
    evolved_individual = self.llm.sample_solution(
                         ^^^^^^^^^^^^^^^^^^^^^^^^^
  File "/Users/macbook/Documents/Code/LLMdesignedEA-comp/llamea/llm.py", line 106, in sample_solution
    message = self.query(session_messages)
              ^^^^^^^^^^^^^^^^^^^^^^^^^^^^
  File "/Users/macbook/Documents/Code/LLMdesignedEA-comp/llamea/llm.py", line 278, in query
    response = chat_session.send_message(last["content"])
               ^^^^^^^^^^^^^^^^^^^^^^^^^^^^^^^^^^^^^^^^^^
  File "/Users/macbook/miniconda3/envs/eoh/lib/python3.12/site-packages/google/generativeai/generative_models.py", line 578, in send_message
    response = self.model.generate_content(
               ^^^^^^^^^^^^^^^^^^^^^^^^^^^^
  File "/Users/macbook/miniconda3/envs/eoh/lib/python3.12/site-packages/google/generativeai/generative_models.py", line 331, in generate_content
    response = self._client.generate_content(
               ^^^^^^^^^^^^^^^^^^^^^^^^^^^^^^
  File "/Users/macbook/miniconda3/envs/eoh/lib/python3.12/site-packages/google/ai/generativelanguage_v1beta/services/generative_service/client.py", line 835, in generate_content
    response = rpc(
               ^^^^
  File "/Users/macbook/miniconda3/envs/eoh/lib/python3.12/site-packages/google/api_core/gapic_v1/method.py", line 131, in __call__
    return wrapped_func(*args, **kwargs)
           ^^^^^^^^^^^^^^^^^^^^^^^^^^^^^
  File "/Users/macbook/miniconda3/envs/eoh/lib/python3.12/site-packages/google/api_core/retry/retry_unary.py", line 294, in retry_wrapped_func
    return retry_target(
           ^^^^^^^^^^^^^
  File "/Users/macbook/miniconda3/envs/eoh/lib/python3.12/site-packages/google/api_core/retry/retry_unary.py", line 156, in retry_target
    next_sleep = _retry_error_helper(
                 ^^^^^^^^^^^^^^^^^^^^
  File "/Users/macbook/miniconda3/envs/eoh/lib/python3.12/site-packages/google/api_core/retry/retry_base.py", line 214, in _retry_error_helper
    raise final_exc from source_exc
  File "/Users/macbook/miniconda3/envs/eoh/lib/python3.12/site-packages/google/api_core/retry/retry_unary.py", line 147, in retry_target
    result = target()
             ^^^^^^^^
  File "/Users/macbook/miniconda3/envs/eoh/lib/python3.12/site-packages/google/api_core/timeout.py", line 130, in func_with_timeout
    return func(*args, **kwargs)
           ^^^^^^^^^^^^^^^^^^^^^
  File "/Users/macbook/miniconda3/envs/eoh/lib/python3.12/site-packages/google/api_core/grpc_helpers.py", line 78, in error_remapped_callable
    raise exceptions.from_grpc_error(exc) from exc
google.api_core.exceptions.ResourceExhausted: 429 You exceeded your current quota, please check your plan and billing details. For more information on this error, head to: https://ai.google.dev/gemini-api/docs/rate-limits. [violations {
  quota_metric: "generativelanguage.googleapis.com/generate_content_free_tier_requests"
  quota_id: "GenerateRequestsPerMinutePerProjectPerModel-FreeTier"
  quota_dimensions {
    key: "model"
    value: "gemini-1.5-flash"
  }
  quota_dimensions {
    key: "location"
    value: "global"
  }
  quota_value: 15
}
, links {
  description: "Learn more about Gemini API quotas"
  url: "https://ai.google.dev/gemini-api/docs/rate-limits"
}
, retry_delay {
  seconds: 47
}
]
.
