2025-06-12 07:43:03 INFO An exception occured: Traceback (most recent call last):
  File "/Users/macbook/Documents/Code/LLMdesignedEA-comp/llamea/llamea.py", line 365, in evolve_solution
    evolved_individual = self.llm.sample_solution(
                         ^^^^^^^^^^^^^^^^^^^^^^^^^
  File "/Users/macbook/Documents/Code/LLMdesignedEA-comp/llamea/llm.py", line 106, in sample_solution
    message = self.query(session_messages)
              ^^^^^^^^^^^^^^^^^^^^^^^^^^^^
  File "/Users/macbook/Documents/Code/LLMdesignedEA-comp/llamea/llm.py", line 308, in query
    response = ollama.chat(
               ^^^^^^^^^^^^
  File "/Users/macbook/miniconda3/envs/eoh/lib/python3.12/site-packages/ollama/_client.py", line 333, in chat
    return self._request(
           ^^^^^^^^^^^^^^
  File "/Users/macbook/miniconda3/envs/eoh/lib/python3.12/site-packages/ollama/_client.py", line 178, in _request
    return cls(**self._request_raw(*args, **kwargs).json())
                 ^^^^^^^^^^^^^^^^^^^^^^^^^^^^^^^^^^
  File "/Users/macbook/miniconda3/envs/eoh/lib/python3.12/site-packages/ollama/_client.py", line 124, in _request_raw
    raise ConnectionError(CONNECTION_ERROR_MESSAGE) from None
ConnectionError: Failed to connect to Ollama. Please check that Ollama is downloaded, running and accessible. https://ollama.com/download
.
