2025-06-15 09:19:59 INFO --- GNBG Problem Parameters for f8 ---
  Dimension: 30, MaxEvals: 500000
  Search Bounds: [-100, 100]
  Number of Components: 1
  Known Optimum Value: -656.788998
  Lambda (Curvature): [1]
  Mu (Asymmetry/Depth): [0.2 0.2]
----------------------------------------
2025-06-15 09:19:59 INFO --- GNBG Problem Parameters for f8 ---
  Dimension: 30, MaxEvals: 500000
  Search Bounds: [-100, 100]
  Number of Components: 1
  Known Optimum Value: -656.788998
  Lambda (Curvature): [1]
  Mu (Asymmetry/Depth): [0.2 0.2]
----------------------------------------
2025-06-15 09:19:59 ERROR Can not run the algorithm
2025-06-15 09:19:59 INFO --- GNBG Problem Parameters for f8 ---
  Dimension: 30, MaxEvals: 500000
  Search Bounds: [-100, 100]
  Number of Components: 1
  Known Optimum Value: -656.788998
  Lambda (Curvature): [1]
  Mu (Asymmetry/Depth): [0.2 0.2]
----------------------------------------
2025-06-15 09:19:59 INFO Run function 8 complete. FEHistory len: 35, AOCC: 0.0000
2025-06-15 09:19:59 INFO FeHistory: [200533.98306855 200533.98251284 200533.98370202 200533.98213451
 200533.98306284 200533.98250499 200533.98423608 200533.98428491
 200533.98202876 200533.97633026 200533.97968261 200533.98303676
 200533.98307444 200533.98374027 200533.98141369 200533.98240658
 200533.98133364 200533.98670854 200533.97944885 200533.98239331
 200533.98323191 200533.98696654 200533.98308664 200533.98312583
 200533.97779283 200533.98358288 200533.98245969 200533.98319952
 200533.98516529 200533.98086709 200533.98180967 308092.49150282
 256237.2897248  230943.59280631 161104.91854605]
2025-06-15 09:19:59 INFO Expected Optimum FE: -656.7889979935655
2025-06-15 09:19:59 INFO Multimodal (single component) AOCC mean: 0.0000
2025-06-15 09:19:59 INFO AOCC mean: 0.0000
2025-06-15 09:19:59 INFO --- GNBG Problem Parameters for f8 ---
  Dimension: 30, MaxEvals: 500000
  Search Bounds: [-100, 100]
  Number of Components: 1
  Known Optimum Value: -656.788998
  Lambda (Curvature): [1]
  Mu (Asymmetry/Depth): [0.2 0.2]
----------------------------------------
2025-06-15 09:20:00 INFO --- GNBG Problem Parameters for f8 ---
  Dimension: 30, MaxEvals: 500000
  Search Bounds: [-100, 100]
  Number of Components: 1
  Known Optimum Value: -656.788998
  Lambda (Curvature): [1]
  Mu (Asymmetry/Depth): [0.2 0.2]
----------------------------------------
2025-06-15 09:20:04 INFO Run function 8 complete. FEHistory len: 50000, AOCC: 0.0086
2025-06-15 09:20:04 INFO FeHistory: [207361.59846877 192125.28424531 155759.51103589 ...   -549.21669867
   -581.03125805   -563.77323844]
2025-06-15 09:20:04 INFO Expected Optimum FE: -656.7889979935655
2025-06-15 09:20:04 INFO Multimodal (single component) AOCC mean: 0.0086
2025-06-15 09:20:04 INFO AOCC mean: 0.0086
2025-06-15 09:20:05 INFO Run function 8 complete. FEHistory len: 50000, AOCC: 0.0000
2025-06-15 09:20:05 INFO FeHistory: [228738.50049924 282459.59163629 187408.78711586 ... 376028.98237968
 251309.57354106 128006.42567063]
2025-06-15 09:20:05 INFO Expected Optimum FE: -656.7889979935655
2025-06-15 09:20:05 INFO Multimodal (single component) AOCC mean: 0.0000
2025-06-15 09:20:05 INFO AOCC mean: 0.0000
2025-06-15 09:20:05 INFO Run function 8 complete. FEHistory len: 50000, AOCC: 0.0000
2025-06-15 09:20:05 INFO FeHistory: [126660.25230146 135268.97687872 202654.25492786 ...  54242.35160164
  91364.60209699  85524.52985966]
2025-06-15 09:20:05 INFO Expected Optimum FE: -656.7889979935655
2025-06-15 09:20:05 INFO Multimodal (single component) AOCC mean: 0.0000
2025-06-15 09:20:05 INFO AOCC mean: 0.0000
2025-06-15 09:20:21 INFO Run function 8 complete. FEHistory len: 50000, AOCC: 0.0000
2025-06-15 09:20:21 INFO FeHistory: [195839.56280837 192660.4684058  132192.92371842 ...  41816.94589296
  37945.99844569  39641.96890899]
2025-06-15 09:20:21 INFO Expected Optimum FE: -656.7889979935655
2025-06-15 09:20:21 INFO Multimodal (single component) AOCC mean: 0.0000
2025-06-15 09:20:21 INFO AOCC mean: 0.0000
2025-06-15 09:20:29 INFO --- GNBG Problem Parameters for f8 ---
  Dimension: 30, MaxEvals: 500000
  Search Bounds: [-100, 100]
  Number of Components: 1
  Known Optimum Value: -656.788998
  Lambda (Curvature): [1]
  Mu (Asymmetry/Depth): [0.2 0.2]
----------------------------------------
2025-06-15 09:20:29 INFO --- GNBG Problem Parameters for f8 ---
  Dimension: 30, MaxEvals: 500000
  Search Bounds: [-100, 100]
  Number of Components: 1
  Known Optimum Value: -656.788998
  Lambda (Curvature): [1]
  Mu (Asymmetry/Depth): [0.2 0.2]
----------------------------------------
2025-06-15 09:20:29 ERROR Can not run the algorithm
2025-06-15 09:20:29 INFO --- GNBG Problem Parameters for f8 ---
  Dimension: 30, MaxEvals: 500000
  Search Bounds: [-100, 100]
  Number of Components: 1
  Known Optimum Value: -656.788998
  Lambda (Curvature): [1]
  Mu (Asymmetry/Depth): [0.2 0.2]
----------------------------------------
2025-06-15 09:20:29 INFO Run function 8 complete. FEHistory len: 32, AOCC: 0.0000
2025-06-15 09:20:29 INFO FeHistory: [210076.719469   210076.71973017 210076.71940488 210076.72357038
 210076.72033252 210076.71980256 210076.72083941 210076.72036036
 210076.71922911 210076.71933923 210076.717863   210076.71949115
 210076.71976873 210076.71493415 210076.71920268 210076.718607
 210076.72227025 210076.7194976  210076.72398001 210076.71989098
 210076.71937349 210076.72164    210076.71639281 210076.72035953
 210076.72023621 210076.71589371 210076.71998644 210076.72235247
 210076.71948813 210076.71614979 210076.71941981 163711.19706183]
2025-06-15 09:20:29 INFO Expected Optimum FE: -656.7889979935655
2025-06-15 09:20:29 INFO Multimodal (single component) AOCC mean: 0.0000
2025-06-15 09:20:29 INFO AOCC mean: 0.0000
2025-06-15 09:20:29 INFO --- GNBG Problem Parameters for f8 ---
  Dimension: 30, MaxEvals: 500000
  Search Bounds: [-100, 100]
  Number of Components: 1
  Known Optimum Value: -656.788998
  Lambda (Curvature): [1]
  Mu (Asymmetry/Depth): [0.2 0.2]
----------------------------------------
2025-06-15 09:20:29 INFO --- GNBG Problem Parameters for f8 ---
  Dimension: 30, MaxEvals: 500000
  Search Bounds: [-100, 100]
  Number of Components: 1
  Known Optimum Value: -656.788998
  Lambda (Curvature): [1]
  Mu (Asymmetry/Depth): [0.2 0.2]
----------------------------------------
2025-06-15 09:20:34 INFO Run function 8 complete. FEHistory len: 50000, AOCC: 0.0037
2025-06-15 09:20:34 INFO FeHistory: [269566.95168771 171078.03803917 172638.22874715 ...   -525.69338927
   -366.25885314   -435.05373273]
2025-06-15 09:20:34 INFO Expected Optimum FE: -656.7889979935655
2025-06-15 09:20:34 INFO Multimodal (single component) AOCC mean: 0.0037
2025-06-15 09:20:34 INFO AOCC mean: 0.0037
2025-06-15 09:20:36 INFO Run function 8 complete. FEHistory len: 50000, AOCC: 0.0000
2025-06-15 09:20:36 INFO FeHistory: [174962.35552844 207701.59273377 164385.17120683 ... 200779.17965113
 154136.50934357 131660.56690003]
2025-06-15 09:20:36 INFO Expected Optimum FE: -656.7889979935655
2025-06-15 09:20:36 INFO Multimodal (single component) AOCC mean: 0.0000
2025-06-15 09:20:36 INFO AOCC mean: 0.0000
2025-06-15 09:20:43 INFO Run function 8 complete. FEHistory len: 50000, AOCC: 0.0000
2025-06-15 09:20:43 INFO FeHistory: [231505.12923797 243531.3784685  193111.30356634 ...  28308.65916726
  28308.74428612  28308.54248739]
2025-06-15 09:20:43 INFO Expected Optimum FE: -656.7889979935655
2025-06-15 09:20:43 INFO Multimodal (single component) AOCC mean: 0.0000
2025-06-15 09:20:43 INFO AOCC mean: 0.0000
2025-06-15 09:20:45 INFO Run function 8 complete. FEHistory len: 50000, AOCC: 0.0000
2025-06-15 09:20:45 INFO FeHistory: [114969.89658738 154616.81391064 247245.68898167 ...  21483.13049622
  21484.38879969  21485.842775  ]
2025-06-15 09:20:45 INFO Expected Optimum FE: -656.7889979935655
2025-06-15 09:20:45 INFO Multimodal (single component) AOCC mean: 0.0000
2025-06-15 09:20:45 INFO AOCC mean: 0.0000
2025-06-15 09:20:48 INFO An exception occured: Traceback (most recent call last):
  File "/Users/macbook/Documents/Code/LLMdesignedEA-comp/llamea/llamea_api_rotations.py", line 326, in evolve_solution
    evolved_individual = chosen_llm.sample_solution(
                         ^^^^^^^^^^^^^^^^^^^^^^^^^^^
  File "/Users/macbook/Documents/Code/LLMdesignedEA-comp/llamea/llm.py", line 106, in sample_solution
    message = self.query(session_messages)
              ^^^^^^^^^^^^^^^^^^^^^^^^^^^^
  File "/Users/macbook/Documents/Code/LLMdesignedEA-comp/llamea/llm.py", line 278, in query
    response = chat_session.send_message(last["content"])
               ^^^^^^^^^^^^^^^^^^^^^^^^^^^^^^^^^^^^^^^^^^
  File "/Users/macbook/miniconda3/envs/eoh/lib/python3.12/site-packages/google/generativeai/generative_models.py", line 578, in send_message
    response = self.model.generate_content(
               ^^^^^^^^^^^^^^^^^^^^^^^^^^^^
  File "/Users/macbook/miniconda3/envs/eoh/lib/python3.12/site-packages/google/generativeai/generative_models.py", line 331, in generate_content
    response = self._client.generate_content(
               ^^^^^^^^^^^^^^^^^^^^^^^^^^^^^^
  File "/Users/macbook/miniconda3/envs/eoh/lib/python3.12/site-packages/google/ai/generativelanguage_v1beta/services/generative_service/client.py", line 835, in generate_content
    response = rpc(
               ^^^^
  File "/Users/macbook/miniconda3/envs/eoh/lib/python3.12/site-packages/google/api_core/gapic_v1/method.py", line 131, in __call__
    return wrapped_func(*args, **kwargs)
           ^^^^^^^^^^^^^^^^^^^^^^^^^^^^^
  File "/Users/macbook/miniconda3/envs/eoh/lib/python3.12/site-packages/google/api_core/retry/retry_unary.py", line 294, in retry_wrapped_func
    return retry_target(
           ^^^^^^^^^^^^^
  File "/Users/macbook/miniconda3/envs/eoh/lib/python3.12/site-packages/google/api_core/retry/retry_unary.py", line 156, in retry_target
    next_sleep = _retry_error_helper(
                 ^^^^^^^^^^^^^^^^^^^^
  File "/Users/macbook/miniconda3/envs/eoh/lib/python3.12/site-packages/google/api_core/retry/retry_base.py", line 214, in _retry_error_helper
    raise final_exc from source_exc
  File "/Users/macbook/miniconda3/envs/eoh/lib/python3.12/site-packages/google/api_core/retry/retry_unary.py", line 147, in retry_target
    result = target()
             ^^^^^^^^
  File "/Users/macbook/miniconda3/envs/eoh/lib/python3.12/site-packages/google/api_core/timeout.py", line 130, in func_with_timeout
    return func(*args, **kwargs)
           ^^^^^^^^^^^^^^^^^^^^^
  File "/Users/macbook/miniconda3/envs/eoh/lib/python3.12/site-packages/google/api_core/grpc_helpers.py", line 78, in error_remapped_callable
    raise exceptions.from_grpc_error(exc) from exc
google.api_core.exceptions.ResourceExhausted: 429 You exceeded your current quota, please check your plan and billing details. For more information on this error, head to: https://ai.google.dev/gemini-api/docs/rate-limits. [violations {
  quota_metric: "generativelanguage.googleapis.com/generate_content_free_tier_requests"
  quota_id: "GenerateRequestsPerMinutePerProjectPerModel-FreeTier"
  quota_dimensions {
    key: "model"
    value: "gemini-1.5-flash"
  }
  quota_dimensions {
    key: "location"
    value: "global"
  }
  quota_value: 15
}
, links {
  description: "Learn more about Gemini API quotas"
  url: "https://ai.google.dev/gemini-api/docs/rate-limits"
}
, retry_delay {
  seconds: 11
}
]
.
2025-06-15 09:20:49 INFO An exception occured: Traceback (most recent call last):
  File "/Users/macbook/Documents/Code/LLMdesignedEA-comp/llamea/llamea_api_rotations.py", line 326, in evolve_solution
    evolved_individual = chosen_llm.sample_solution(
                         ^^^^^^^^^^^^^^^^^^^^^^^^^^^
  File "/Users/macbook/Documents/Code/LLMdesignedEA-comp/llamea/llm.py", line 106, in sample_solution
    message = self.query(session_messages)
              ^^^^^^^^^^^^^^^^^^^^^^^^^^^^
  File "/Users/macbook/Documents/Code/LLMdesignedEA-comp/llamea/llm.py", line 278, in query
    response = chat_session.send_message(last["content"])
               ^^^^^^^^^^^^^^^^^^^^^^^^^^^^^^^^^^^^^^^^^^
  File "/Users/macbook/miniconda3/envs/eoh/lib/python3.12/site-packages/google/generativeai/generative_models.py", line 578, in send_message
    response = self.model.generate_content(
               ^^^^^^^^^^^^^^^^^^^^^^^^^^^^
  File "/Users/macbook/miniconda3/envs/eoh/lib/python3.12/site-packages/google/generativeai/generative_models.py", line 331, in generate_content
    response = self._client.generate_content(
               ^^^^^^^^^^^^^^^^^^^^^^^^^^^^^^
  File "/Users/macbook/miniconda3/envs/eoh/lib/python3.12/site-packages/google/ai/generativelanguage_v1beta/services/generative_service/client.py", line 835, in generate_content
    response = rpc(
               ^^^^
  File "/Users/macbook/miniconda3/envs/eoh/lib/python3.12/site-packages/google/api_core/gapic_v1/method.py", line 131, in __call__
    return wrapped_func(*args, **kwargs)
           ^^^^^^^^^^^^^^^^^^^^^^^^^^^^^
  File "/Users/macbook/miniconda3/envs/eoh/lib/python3.12/site-packages/google/api_core/retry/retry_unary.py", line 294, in retry_wrapped_func
    return retry_target(
           ^^^^^^^^^^^^^
  File "/Users/macbook/miniconda3/envs/eoh/lib/python3.12/site-packages/google/api_core/retry/retry_unary.py", line 156, in retry_target
    next_sleep = _retry_error_helper(
                 ^^^^^^^^^^^^^^^^^^^^
  File "/Users/macbook/miniconda3/envs/eoh/lib/python3.12/site-packages/google/api_core/retry/retry_base.py", line 214, in _retry_error_helper
    raise final_exc from source_exc
  File "/Users/macbook/miniconda3/envs/eoh/lib/python3.12/site-packages/google/api_core/retry/retry_unary.py", line 147, in retry_target
    result = target()
             ^^^^^^^^
  File "/Users/macbook/miniconda3/envs/eoh/lib/python3.12/site-packages/google/api_core/timeout.py", line 130, in func_with_timeout
    return func(*args, **kwargs)
           ^^^^^^^^^^^^^^^^^^^^^
  File "/Users/macbook/miniconda3/envs/eoh/lib/python3.12/site-packages/google/api_core/grpc_helpers.py", line 78, in error_remapped_callable
    raise exceptions.from_grpc_error(exc) from exc
google.api_core.exceptions.ResourceExhausted: 429 You exceeded your current quota, please check your plan and billing details. For more information on this error, head to: https://ai.google.dev/gemini-api/docs/rate-limits. [violations {
  quota_metric: "generativelanguage.googleapis.com/generate_content_free_tier_requests"
  quota_id: "GenerateRequestsPerMinutePerProjectPerModel-FreeTier"
  quota_dimensions {
    key: "model"
    value: "gemini-1.5-flash"
  }
  quota_dimensions {
    key: "location"
    value: "global"
  }
  quota_value: 15
}
, links {
  description: "Learn more about Gemini API quotas"
  url: "https://ai.google.dev/gemini-api/docs/rate-limits"
}
, retry_delay {
  seconds: 10
}
]
.
2025-06-15 09:20:54 INFO --- GNBG Problem Parameters for f8 ---
  Dimension: 30, MaxEvals: 500000
  Search Bounds: [-100, 100]
  Number of Components: 1
  Known Optimum Value: -656.788998
  Lambda (Curvature): [1]
  Mu (Asymmetry/Depth): [0.2 0.2]
----------------------------------------
2025-06-15 09:20:56 INFO --- GNBG Problem Parameters for f8 ---
  Dimension: 30, MaxEvals: 500000
  Search Bounds: [-100, 100]
  Number of Components: 1
  Known Optimum Value: -656.788998
  Lambda (Curvature): [1]
  Mu (Asymmetry/Depth): [0.2 0.2]
----------------------------------------
2025-06-15 09:20:57 INFO --- GNBG Problem Parameters for f8 ---
  Dimension: 30, MaxEvals: 500000
  Search Bounds: [-100, 100]
  Number of Components: 1
  Known Optimum Value: -656.788998
  Lambda (Curvature): [1]
  Mu (Asymmetry/Depth): [0.2 0.2]
----------------------------------------
2025-06-15 09:20:58 INFO Run function 8 complete. FEHistory len: 50000, AOCC: 0.0000
2025-06-15 09:20:58 INFO FeHistory: [160867.6243642  282677.55218376 149323.67162022 ... 129308.42112324
 190639.63008383 116830.14314649]
2025-06-15 09:20:58 INFO Expected Optimum FE: -656.7889979935655
2025-06-15 09:20:58 INFO Multimodal (single component) AOCC mean: 0.0000
2025-06-15 09:20:58 INFO AOCC mean: 0.0000
2025-06-15 09:21:01 INFO Run function 8 complete. FEHistory len: 50000, AOCC: 0.0386
2025-06-15 09:21:01 INFO FeHistory: [187397.63246945 210374.01034929 156620.64354479 ...   -654.66069226
   -654.09302437   -654.15324201]
2025-06-15 09:21:01 INFO Expected Optimum FE: -656.7889979935655
2025-06-15 09:21:01 INFO Multimodal (single component) AOCC mean: 0.0386
2025-06-15 09:21:01 INFO AOCC mean: 0.0386
2025-06-15 09:21:02 INFO Run function 8 complete. FEHistory len: 50000, AOCC: 0.0000
2025-06-15 09:21:02 INFO FeHistory: [227240.33096843 240013.05298399 185745.23305427 ...  43652.11500829
  73480.37037179  21228.96409496]
2025-06-15 09:21:02 INFO Expected Optimum FE: -656.7889979935655
2025-06-15 09:21:02 INFO Multimodal (single component) AOCC mean: 0.0000
2025-06-15 09:21:02 INFO AOCC mean: 0.0000
2025-06-15 09:21:02 INFO An exception occured: Traceback (most recent call last):
  File "/Users/macbook/Documents/Code/LLMdesignedEA-comp/llamea/llamea_api_rotations.py", line 326, in evolve_solution
    evolved_individual = chosen_llm.sample_solution(
                         ^^^^^^^^^^^^^^^^^^^^^^^^^^^
  File "/Users/macbook/Documents/Code/LLMdesignedEA-comp/llamea/llm.py", line 106, in sample_solution
    message = self.query(session_messages)
              ^^^^^^^^^^^^^^^^^^^^^^^^^^^^
  File "/Users/macbook/Documents/Code/LLMdesignedEA-comp/llamea/llm.py", line 278, in query
    response = chat_session.send_message(last["content"])
               ^^^^^^^^^^^^^^^^^^^^^^^^^^^^^^^^^^^^^^^^^^
  File "/Users/macbook/miniconda3/envs/eoh/lib/python3.12/site-packages/google/generativeai/generative_models.py", line 578, in send_message
    response = self.model.generate_content(
               ^^^^^^^^^^^^^^^^^^^^^^^^^^^^
  File "/Users/macbook/miniconda3/envs/eoh/lib/python3.12/site-packages/google/generativeai/generative_models.py", line 331, in generate_content
    response = self._client.generate_content(
               ^^^^^^^^^^^^^^^^^^^^^^^^^^^^^^
  File "/Users/macbook/miniconda3/envs/eoh/lib/python3.12/site-packages/google/ai/generativelanguage_v1beta/services/generative_service/client.py", line 835, in generate_content
    response = rpc(
               ^^^^
  File "/Users/macbook/miniconda3/envs/eoh/lib/python3.12/site-packages/google/api_core/gapic_v1/method.py", line 131, in __call__
    return wrapped_func(*args, **kwargs)
           ^^^^^^^^^^^^^^^^^^^^^^^^^^^^^
  File "/Users/macbook/miniconda3/envs/eoh/lib/python3.12/site-packages/google/api_core/retry/retry_unary.py", line 294, in retry_wrapped_func
    return retry_target(
           ^^^^^^^^^^^^^
  File "/Users/macbook/miniconda3/envs/eoh/lib/python3.12/site-packages/google/api_core/retry/retry_unary.py", line 156, in retry_target
    next_sleep = _retry_error_helper(
                 ^^^^^^^^^^^^^^^^^^^^
  File "/Users/macbook/miniconda3/envs/eoh/lib/python3.12/site-packages/google/api_core/retry/retry_base.py", line 214, in _retry_error_helper
    raise final_exc from source_exc
  File "/Users/macbook/miniconda3/envs/eoh/lib/python3.12/site-packages/google/api_core/retry/retry_unary.py", line 147, in retry_target
    result = target()
             ^^^^^^^^
  File "/Users/macbook/miniconda3/envs/eoh/lib/python3.12/site-packages/google/api_core/timeout.py", line 130, in func_with_timeout
    return func(*args, **kwargs)
           ^^^^^^^^^^^^^^^^^^^^^
  File "/Users/macbook/miniconda3/envs/eoh/lib/python3.12/site-packages/google/api_core/grpc_helpers.py", line 78, in error_remapped_callable
    raise exceptions.from_grpc_error(exc) from exc
google.api_core.exceptions.ResourceExhausted: 429 You exceeded your current quota, please check your plan and billing details. For more information on this error, head to: https://ai.google.dev/gemini-api/docs/rate-limits. [violations {
  quota_metric: "generativelanguage.googleapis.com/generate_content_free_tier_requests"
  quota_id: "GenerateRequestsPerMinutePerProjectPerModel-FreeTier"
  quota_dimensions {
    key: "model"
    value: "gemini-1.5-flash"
  }
  quota_dimensions {
    key: "location"
    value: "global"
  }
  quota_value: 15
}
, links {
  description: "Learn more about Gemini API quotas"
  url: "https://ai.google.dev/gemini-api/docs/rate-limits"
}
, retry_delay {
  seconds: 57
}
]
.
2025-06-15 09:21:02 INFO An exception occured: Traceback (most recent call last):
  File "/Users/macbook/Documents/Code/LLMdesignedEA-comp/llamea/llamea_api_rotations.py", line 326, in evolve_solution
    evolved_individual = chosen_llm.sample_solution(
                         ^^^^^^^^^^^^^^^^^^^^^^^^^^^
  File "/Users/macbook/Documents/Code/LLMdesignedEA-comp/llamea/llm.py", line 106, in sample_solution
    message = self.query(session_messages)
              ^^^^^^^^^^^^^^^^^^^^^^^^^^^^
  File "/Users/macbook/Documents/Code/LLMdesignedEA-comp/llamea/llm.py", line 278, in query
    response = chat_session.send_message(last["content"])
               ^^^^^^^^^^^^^^^^^^^^^^^^^^^^^^^^^^^^^^^^^^
  File "/Users/macbook/miniconda3/envs/eoh/lib/python3.12/site-packages/google/generativeai/generative_models.py", line 578, in send_message
    response = self.model.generate_content(
               ^^^^^^^^^^^^^^^^^^^^^^^^^^^^
  File "/Users/macbook/miniconda3/envs/eoh/lib/python3.12/site-packages/google/generativeai/generative_models.py", line 331, in generate_content
    response = self._client.generate_content(
               ^^^^^^^^^^^^^^^^^^^^^^^^^^^^^^
  File "/Users/macbook/miniconda3/envs/eoh/lib/python3.12/site-packages/google/ai/generativelanguage_v1beta/services/generative_service/client.py", line 835, in generate_content
    response = rpc(
               ^^^^
  File "/Users/macbook/miniconda3/envs/eoh/lib/python3.12/site-packages/google/api_core/gapic_v1/method.py", line 131, in __call__
    return wrapped_func(*args, **kwargs)
           ^^^^^^^^^^^^^^^^^^^^^^^^^^^^^
  File "/Users/macbook/miniconda3/envs/eoh/lib/python3.12/site-packages/google/api_core/retry/retry_unary.py", line 294, in retry_wrapped_func
    return retry_target(
           ^^^^^^^^^^^^^
  File "/Users/macbook/miniconda3/envs/eoh/lib/python3.12/site-packages/google/api_core/retry/retry_unary.py", line 156, in retry_target
    next_sleep = _retry_error_helper(
                 ^^^^^^^^^^^^^^^^^^^^
  File "/Users/macbook/miniconda3/envs/eoh/lib/python3.12/site-packages/google/api_core/retry/retry_base.py", line 214, in _retry_error_helper
    raise final_exc from source_exc
  File "/Users/macbook/miniconda3/envs/eoh/lib/python3.12/site-packages/google/api_core/retry/retry_unary.py", line 147, in retry_target
    result = target()
             ^^^^^^^^
  File "/Users/macbook/miniconda3/envs/eoh/lib/python3.12/site-packages/google/api_core/timeout.py", line 130, in func_with_timeout
    return func(*args, **kwargs)
           ^^^^^^^^^^^^^^^^^^^^^
  File "/Users/macbook/miniconda3/envs/eoh/lib/python3.12/site-packages/google/api_core/grpc_helpers.py", line 78, in error_remapped_callable
    raise exceptions.from_grpc_error(exc) from exc
google.api_core.exceptions.ResourceExhausted: 429 You exceeded your current quota, please check your plan and billing details. For more information on this error, head to: https://ai.google.dev/gemini-api/docs/rate-limits. [violations {
  quota_metric: "generativelanguage.googleapis.com/generate_content_free_tier_requests"
  quota_id: "GenerateRequestsPerMinutePerProjectPerModel-FreeTier"
  quota_dimensions {
    key: "model"
    value: "gemini-1.5-flash"
  }
  quota_dimensions {
    key: "location"
    value: "global"
  }
  quota_value: 15
}
, links {
  description: "Learn more about Gemini API quotas"
  url: "https://ai.google.dev/gemini-api/docs/rate-limits"
}
, retry_delay {
  seconds: 57
}
]
.
2025-06-15 09:21:02 INFO An exception occured: Traceback (most recent call last):
  File "/Users/macbook/Documents/Code/LLMdesignedEA-comp/llamea/llamea_api_rotations.py", line 326, in evolve_solution
    evolved_individual = chosen_llm.sample_solution(
                         ^^^^^^^^^^^^^^^^^^^^^^^^^^^
  File "/Users/macbook/Documents/Code/LLMdesignedEA-comp/llamea/llm.py", line 106, in sample_solution
    message = self.query(session_messages)
              ^^^^^^^^^^^^^^^^^^^^^^^^^^^^
  File "/Users/macbook/Documents/Code/LLMdesignedEA-comp/llamea/llm.py", line 278, in query
    response = chat_session.send_message(last["content"])
               ^^^^^^^^^^^^^^^^^^^^^^^^^^^^^^^^^^^^^^^^^^
  File "/Users/macbook/miniconda3/envs/eoh/lib/python3.12/site-packages/google/generativeai/generative_models.py", line 578, in send_message
    response = self.model.generate_content(
               ^^^^^^^^^^^^^^^^^^^^^^^^^^^^
  File "/Users/macbook/miniconda3/envs/eoh/lib/python3.12/site-packages/google/generativeai/generative_models.py", line 331, in generate_content
    response = self._client.generate_content(
               ^^^^^^^^^^^^^^^^^^^^^^^^^^^^^^
  File "/Users/macbook/miniconda3/envs/eoh/lib/python3.12/site-packages/google/ai/generativelanguage_v1beta/services/generative_service/client.py", line 835, in generate_content
    response = rpc(
               ^^^^
  File "/Users/macbook/miniconda3/envs/eoh/lib/python3.12/site-packages/google/api_core/gapic_v1/method.py", line 131, in __call__
    return wrapped_func(*args, **kwargs)
           ^^^^^^^^^^^^^^^^^^^^^^^^^^^^^
  File "/Users/macbook/miniconda3/envs/eoh/lib/python3.12/site-packages/google/api_core/retry/retry_unary.py", line 294, in retry_wrapped_func
    return retry_target(
           ^^^^^^^^^^^^^
  File "/Users/macbook/miniconda3/envs/eoh/lib/python3.12/site-packages/google/api_core/retry/retry_unary.py", line 156, in retry_target
    next_sleep = _retry_error_helper(
                 ^^^^^^^^^^^^^^^^^^^^
  File "/Users/macbook/miniconda3/envs/eoh/lib/python3.12/site-packages/google/api_core/retry/retry_base.py", line 214, in _retry_error_helper
    raise final_exc from source_exc
  File "/Users/macbook/miniconda3/envs/eoh/lib/python3.12/site-packages/google/api_core/retry/retry_unary.py", line 147, in retry_target
    result = target()
             ^^^^^^^^
  File "/Users/macbook/miniconda3/envs/eoh/lib/python3.12/site-packages/google/api_core/timeout.py", line 130, in func_with_timeout
    return func(*args, **kwargs)
           ^^^^^^^^^^^^^^^^^^^^^
  File "/Users/macbook/miniconda3/envs/eoh/lib/python3.12/site-packages/google/api_core/grpc_helpers.py", line 78, in error_remapped_callable
    raise exceptions.from_grpc_error(exc) from exc
google.api_core.exceptions.ResourceExhausted: 429 You exceeded your current quota, please check your plan and billing details. For more information on this error, head to: https://ai.google.dev/gemini-api/docs/rate-limits. [violations {
  quota_metric: "generativelanguage.googleapis.com/generate_content_free_tier_requests"
  quota_id: "GenerateRequestsPerMinutePerProjectPerModel-FreeTier"
  quota_dimensions {
    key: "model"
    value: "gemini-1.5-flash"
  }
  quota_dimensions {
    key: "location"
    value: "global"
  }
  quota_value: 15
}
, links {
  description: "Learn more about Gemini API quotas"
  url: "https://ai.google.dev/gemini-api/docs/rate-limits"
}
, retry_delay {
  seconds: 57
}
]
.
2025-06-15 09:21:02 INFO An exception occured: Traceback (most recent call last):
  File "/Users/macbook/Documents/Code/LLMdesignedEA-comp/llamea/llamea_api_rotations.py", line 326, in evolve_solution
    evolved_individual = chosen_llm.sample_solution(
                         ^^^^^^^^^^^^^^^^^^^^^^^^^^^
  File "/Users/macbook/Documents/Code/LLMdesignedEA-comp/llamea/llm.py", line 106, in sample_solution
    message = self.query(session_messages)
              ^^^^^^^^^^^^^^^^^^^^^^^^^^^^
  File "/Users/macbook/Documents/Code/LLMdesignedEA-comp/llamea/llm.py", line 278, in query
    response = chat_session.send_message(last["content"])
               ^^^^^^^^^^^^^^^^^^^^^^^^^^^^^^^^^^^^^^^^^^
  File "/Users/macbook/miniconda3/envs/eoh/lib/python3.12/site-packages/google/generativeai/generative_models.py", line 578, in send_message
    response = self.model.generate_content(
               ^^^^^^^^^^^^^^^^^^^^^^^^^^^^
  File "/Users/macbook/miniconda3/envs/eoh/lib/python3.12/site-packages/google/generativeai/generative_models.py", line 331, in generate_content
    response = self._client.generate_content(
               ^^^^^^^^^^^^^^^^^^^^^^^^^^^^^^
  File "/Users/macbook/miniconda3/envs/eoh/lib/python3.12/site-packages/google/ai/generativelanguage_v1beta/services/generative_service/client.py", line 835, in generate_content
    response = rpc(
               ^^^^
  File "/Users/macbook/miniconda3/envs/eoh/lib/python3.12/site-packages/google/api_core/gapic_v1/method.py", line 131, in __call__
    return wrapped_func(*args, **kwargs)
           ^^^^^^^^^^^^^^^^^^^^^^^^^^^^^
  File "/Users/macbook/miniconda3/envs/eoh/lib/python3.12/site-packages/google/api_core/retry/retry_unary.py", line 294, in retry_wrapped_func
    return retry_target(
           ^^^^^^^^^^^^^
  File "/Users/macbook/miniconda3/envs/eoh/lib/python3.12/site-packages/google/api_core/retry/retry_unary.py", line 156, in retry_target
    next_sleep = _retry_error_helper(
                 ^^^^^^^^^^^^^^^^^^^^
  File "/Users/macbook/miniconda3/envs/eoh/lib/python3.12/site-packages/google/api_core/retry/retry_base.py", line 214, in _retry_error_helper
    raise final_exc from source_exc
  File "/Users/macbook/miniconda3/envs/eoh/lib/python3.12/site-packages/google/api_core/retry/retry_unary.py", line 147, in retry_target
    result = target()
             ^^^^^^^^
  File "/Users/macbook/miniconda3/envs/eoh/lib/python3.12/site-packages/google/api_core/timeout.py", line 130, in func_with_timeout
    return func(*args, **kwargs)
           ^^^^^^^^^^^^^^^^^^^^^
  File "/Users/macbook/miniconda3/envs/eoh/lib/python3.12/site-packages/google/api_core/grpc_helpers.py", line 78, in error_remapped_callable
    raise exceptions.from_grpc_error(exc) from exc
google.api_core.exceptions.ResourceExhausted: 429 You exceeded your current quota, please check your plan and billing details. For more information on this error, head to: https://ai.google.dev/gemini-api/docs/rate-limits. [violations {
  quota_metric: "generativelanguage.googleapis.com/generate_content_free_tier_requests"
  quota_id: "GenerateRequestsPerMinutePerProjectPerModel-FreeTier"
  quota_dimensions {
    key: "model"
    value: "gemini-1.5-flash"
  }
  quota_dimensions {
    key: "location"
    value: "global"
  }
  quota_value: 15
}
, links {
  description: "Learn more about Gemini API quotas"
  url: "https://ai.google.dev/gemini-api/docs/rate-limits"
}
, retry_delay {
  seconds: 57
}
]
.
2025-06-15 09:21:02 INFO An exception occured: Traceback (most recent call last):
  File "/Users/macbook/Documents/Code/LLMdesignedEA-comp/llamea/llamea_api_rotations.py", line 326, in evolve_solution
    evolved_individual = chosen_llm.sample_solution(
                         ^^^^^^^^^^^^^^^^^^^^^^^^^^^
  File "/Users/macbook/Documents/Code/LLMdesignedEA-comp/llamea/llm.py", line 106, in sample_solution
    message = self.query(session_messages)
              ^^^^^^^^^^^^^^^^^^^^^^^^^^^^
  File "/Users/macbook/Documents/Code/LLMdesignedEA-comp/llamea/llm.py", line 278, in query
    response = chat_session.send_message(last["content"])
               ^^^^^^^^^^^^^^^^^^^^^^^^^^^^^^^^^^^^^^^^^^
  File "/Users/macbook/miniconda3/envs/eoh/lib/python3.12/site-packages/google/generativeai/generative_models.py", line 578, in send_message
    response = self.model.generate_content(
               ^^^^^^^^^^^^^^^^^^^^^^^^^^^^
  File "/Users/macbook/miniconda3/envs/eoh/lib/python3.12/site-packages/google/generativeai/generative_models.py", line 331, in generate_content
    response = self._client.generate_content(
               ^^^^^^^^^^^^^^^^^^^^^^^^^^^^^^
  File "/Users/macbook/miniconda3/envs/eoh/lib/python3.12/site-packages/google/ai/generativelanguage_v1beta/services/generative_service/client.py", line 835, in generate_content
    response = rpc(
               ^^^^
  File "/Users/macbook/miniconda3/envs/eoh/lib/python3.12/site-packages/google/api_core/gapic_v1/method.py", line 131, in __call__
    return wrapped_func(*args, **kwargs)
           ^^^^^^^^^^^^^^^^^^^^^^^^^^^^^
  File "/Users/macbook/miniconda3/envs/eoh/lib/python3.12/site-packages/google/api_core/retry/retry_unary.py", line 294, in retry_wrapped_func
    return retry_target(
           ^^^^^^^^^^^^^
  File "/Users/macbook/miniconda3/envs/eoh/lib/python3.12/site-packages/google/api_core/retry/retry_unary.py", line 156, in retry_target
    next_sleep = _retry_error_helper(
                 ^^^^^^^^^^^^^^^^^^^^
  File "/Users/macbook/miniconda3/envs/eoh/lib/python3.12/site-packages/google/api_core/retry/retry_base.py", line 214, in _retry_error_helper
    raise final_exc from source_exc
  File "/Users/macbook/miniconda3/envs/eoh/lib/python3.12/site-packages/google/api_core/retry/retry_unary.py", line 147, in retry_target
    result = target()
             ^^^^^^^^
  File "/Users/macbook/miniconda3/envs/eoh/lib/python3.12/site-packages/google/api_core/timeout.py", line 130, in func_with_timeout
    return func(*args, **kwargs)
           ^^^^^^^^^^^^^^^^^^^^^
  File "/Users/macbook/miniconda3/envs/eoh/lib/python3.12/site-packages/google/api_core/grpc_helpers.py", line 78, in error_remapped_callable
    raise exceptions.from_grpc_error(exc) from exc
google.api_core.exceptions.ResourceExhausted: 429 You exceeded your current quota, please check your plan and billing details. For more information on this error, head to: https://ai.google.dev/gemini-api/docs/rate-limits. [violations {
  quota_metric: "generativelanguage.googleapis.com/generate_content_free_tier_requests"
  quota_id: "GenerateRequestsPerMinutePerProjectPerModel-FreeTier"
  quota_dimensions {
    key: "model"
    value: "gemini-1.5-flash"
  }
  quota_dimensions {
    key: "location"
    value: "global"
  }
  quota_value: 15
}
, links {
  description: "Learn more about Gemini API quotas"
  url: "https://ai.google.dev/gemini-api/docs/rate-limits"
}
, retry_delay {
  seconds: 57
}
]
.
2025-06-15 09:21:03 INFO An exception occured: Traceback (most recent call last):
  File "/Users/macbook/Documents/Code/LLMdesignedEA-comp/llamea/llamea_api_rotations.py", line 326, in evolve_solution
    evolved_individual = chosen_llm.sample_solution(
                         ^^^^^^^^^^^^^^^^^^^^^^^^^^^
  File "/Users/macbook/Documents/Code/LLMdesignedEA-comp/llamea/llm.py", line 106, in sample_solution
    message = self.query(session_messages)
              ^^^^^^^^^^^^^^^^^^^^^^^^^^^^
  File "/Users/macbook/Documents/Code/LLMdesignedEA-comp/llamea/llm.py", line 278, in query
    response = chat_session.send_message(last["content"])
               ^^^^^^^^^^^^^^^^^^^^^^^^^^^^^^^^^^^^^^^^^^
  File "/Users/macbook/miniconda3/envs/eoh/lib/python3.12/site-packages/google/generativeai/generative_models.py", line 578, in send_message
    response = self.model.generate_content(
               ^^^^^^^^^^^^^^^^^^^^^^^^^^^^
  File "/Users/macbook/miniconda3/envs/eoh/lib/python3.12/site-packages/google/generativeai/generative_models.py", line 331, in generate_content
    response = self._client.generate_content(
               ^^^^^^^^^^^^^^^^^^^^^^^^^^^^^^
  File "/Users/macbook/miniconda3/envs/eoh/lib/python3.12/site-packages/google/ai/generativelanguage_v1beta/services/generative_service/client.py", line 835, in generate_content
    response = rpc(
               ^^^^
  File "/Users/macbook/miniconda3/envs/eoh/lib/python3.12/site-packages/google/api_core/gapic_v1/method.py", line 131, in __call__
    return wrapped_func(*args, **kwargs)
           ^^^^^^^^^^^^^^^^^^^^^^^^^^^^^
  File "/Users/macbook/miniconda3/envs/eoh/lib/python3.12/site-packages/google/api_core/retry/retry_unary.py", line 294, in retry_wrapped_func
    return retry_target(
           ^^^^^^^^^^^^^
  File "/Users/macbook/miniconda3/envs/eoh/lib/python3.12/site-packages/google/api_core/retry/retry_unary.py", line 156, in retry_target
    next_sleep = _retry_error_helper(
                 ^^^^^^^^^^^^^^^^^^^^
  File "/Users/macbook/miniconda3/envs/eoh/lib/python3.12/site-packages/google/api_core/retry/retry_base.py", line 214, in _retry_error_helper
    raise final_exc from source_exc
  File "/Users/macbook/miniconda3/envs/eoh/lib/python3.12/site-packages/google/api_core/retry/retry_unary.py", line 147, in retry_target
    result = target()
             ^^^^^^^^
  File "/Users/macbook/miniconda3/envs/eoh/lib/python3.12/site-packages/google/api_core/timeout.py", line 130, in func_with_timeout
    return func(*args, **kwargs)
           ^^^^^^^^^^^^^^^^^^^^^
  File "/Users/macbook/miniconda3/envs/eoh/lib/python3.12/site-packages/google/api_core/grpc_helpers.py", line 78, in error_remapped_callable
    raise exceptions.from_grpc_error(exc) from exc
google.api_core.exceptions.ResourceExhausted: 429 You exceeded your current quota, please check your plan and billing details. For more information on this error, head to: https://ai.google.dev/gemini-api/docs/rate-limits. [violations {
  quota_metric: "generativelanguage.googleapis.com/generate_content_free_tier_requests"
  quota_id: "GenerateRequestsPerMinutePerProjectPerModel-FreeTier"
  quota_dimensions {
    key: "model"
    value: "gemini-1.5-flash"
  }
  quota_dimensions {
    key: "location"
    value: "global"
  }
  quota_value: 15
}
, links {
  description: "Learn more about Gemini API quotas"
  url: "https://ai.google.dev/gemini-api/docs/rate-limits"
}
, retry_delay {
  seconds: 56
}
]
.
2025-06-15 09:21:03 INFO An exception occured: Traceback (most recent call last):
  File "/Users/macbook/Documents/Code/LLMdesignedEA-comp/llamea/llamea_api_rotations.py", line 326, in evolve_solution
    evolved_individual = chosen_llm.sample_solution(
                         ^^^^^^^^^^^^^^^^^^^^^^^^^^^
  File "/Users/macbook/Documents/Code/LLMdesignedEA-comp/llamea/llm.py", line 106, in sample_solution
    message = self.query(session_messages)
              ^^^^^^^^^^^^^^^^^^^^^^^^^^^^
  File "/Users/macbook/Documents/Code/LLMdesignedEA-comp/llamea/llm.py", line 278, in query
    response = chat_session.send_message(last["content"])
               ^^^^^^^^^^^^^^^^^^^^^^^^^^^^^^^^^^^^^^^^^^
  File "/Users/macbook/miniconda3/envs/eoh/lib/python3.12/site-packages/google/generativeai/generative_models.py", line 578, in send_message
    response = self.model.generate_content(
               ^^^^^^^^^^^^^^^^^^^^^^^^^^^^
  File "/Users/macbook/miniconda3/envs/eoh/lib/python3.12/site-packages/google/generativeai/generative_models.py", line 331, in generate_content
    response = self._client.generate_content(
               ^^^^^^^^^^^^^^^^^^^^^^^^^^^^^^
  File "/Users/macbook/miniconda3/envs/eoh/lib/python3.12/site-packages/google/ai/generativelanguage_v1beta/services/generative_service/client.py", line 835, in generate_content
    response = rpc(
               ^^^^
  File "/Users/macbook/miniconda3/envs/eoh/lib/python3.12/site-packages/google/api_core/gapic_v1/method.py", line 131, in __call__
    return wrapped_func(*args, **kwargs)
           ^^^^^^^^^^^^^^^^^^^^^^^^^^^^^
  File "/Users/macbook/miniconda3/envs/eoh/lib/python3.12/site-packages/google/api_core/retry/retry_unary.py", line 294, in retry_wrapped_func
    return retry_target(
           ^^^^^^^^^^^^^
  File "/Users/macbook/miniconda3/envs/eoh/lib/python3.12/site-packages/google/api_core/retry/retry_unary.py", line 156, in retry_target
    next_sleep = _retry_error_helper(
                 ^^^^^^^^^^^^^^^^^^^^
  File "/Users/macbook/miniconda3/envs/eoh/lib/python3.12/site-packages/google/api_core/retry/retry_base.py", line 214, in _retry_error_helper
    raise final_exc from source_exc
  File "/Users/macbook/miniconda3/envs/eoh/lib/python3.12/site-packages/google/api_core/retry/retry_unary.py", line 147, in retry_target
    result = target()
             ^^^^^^^^
  File "/Users/macbook/miniconda3/envs/eoh/lib/python3.12/site-packages/google/api_core/timeout.py", line 130, in func_with_timeout
    return func(*args, **kwargs)
           ^^^^^^^^^^^^^^^^^^^^^
  File "/Users/macbook/miniconda3/envs/eoh/lib/python3.12/site-packages/google/api_core/grpc_helpers.py", line 78, in error_remapped_callable
    raise exceptions.from_grpc_error(exc) from exc
google.api_core.exceptions.ResourceExhausted: 429 You exceeded your current quota, please check your plan and billing details. For more information on this error, head to: https://ai.google.dev/gemini-api/docs/rate-limits. [violations {
  quota_metric: "generativelanguage.googleapis.com/generate_content_free_tier_requests"
  quota_id: "GenerateRequestsPerMinutePerProjectPerModel-FreeTier"
  quota_dimensions {
    key: "model"
    value: "gemini-1.5-flash"
  }
  quota_dimensions {
    key: "location"
    value: "global"
  }
  quota_value: 15
}
, links {
  description: "Learn more about Gemini API quotas"
  url: "https://ai.google.dev/gemini-api/docs/rate-limits"
}
, retry_delay {
  seconds: 56
}
]
.
2025-06-15 09:21:03 INFO An exception occured: Traceback (most recent call last):
  File "/Users/macbook/Documents/Code/LLMdesignedEA-comp/llamea/llamea_api_rotations.py", line 326, in evolve_solution
    evolved_individual = chosen_llm.sample_solution(
                         ^^^^^^^^^^^^^^^^^^^^^^^^^^^
  File "/Users/macbook/Documents/Code/LLMdesignedEA-comp/llamea/llm.py", line 106, in sample_solution
    message = self.query(session_messages)
              ^^^^^^^^^^^^^^^^^^^^^^^^^^^^
  File "/Users/macbook/Documents/Code/LLMdesignedEA-comp/llamea/llm.py", line 278, in query
    response = chat_session.send_message(last["content"])
               ^^^^^^^^^^^^^^^^^^^^^^^^^^^^^^^^^^^^^^^^^^
  File "/Users/macbook/miniconda3/envs/eoh/lib/python3.12/site-packages/google/generativeai/generative_models.py", line 578, in send_message
    response = self.model.generate_content(
               ^^^^^^^^^^^^^^^^^^^^^^^^^^^^
  File "/Users/macbook/miniconda3/envs/eoh/lib/python3.12/site-packages/google/generativeai/generative_models.py", line 331, in generate_content
    response = self._client.generate_content(
               ^^^^^^^^^^^^^^^^^^^^^^^^^^^^^^
  File "/Users/macbook/miniconda3/envs/eoh/lib/python3.12/site-packages/google/ai/generativelanguage_v1beta/services/generative_service/client.py", line 835, in generate_content
    response = rpc(
               ^^^^
  File "/Users/macbook/miniconda3/envs/eoh/lib/python3.12/site-packages/google/api_core/gapic_v1/method.py", line 131, in __call__
    return wrapped_func(*args, **kwargs)
           ^^^^^^^^^^^^^^^^^^^^^^^^^^^^^
  File "/Users/macbook/miniconda3/envs/eoh/lib/python3.12/site-packages/google/api_core/retry/retry_unary.py", line 294, in retry_wrapped_func
    return retry_target(
           ^^^^^^^^^^^^^
  File "/Users/macbook/miniconda3/envs/eoh/lib/python3.12/site-packages/google/api_core/retry/retry_unary.py", line 156, in retry_target
    next_sleep = _retry_error_helper(
                 ^^^^^^^^^^^^^^^^^^^^
  File "/Users/macbook/miniconda3/envs/eoh/lib/python3.12/site-packages/google/api_core/retry/retry_base.py", line 214, in _retry_error_helper
    raise final_exc from source_exc
  File "/Users/macbook/miniconda3/envs/eoh/lib/python3.12/site-packages/google/api_core/retry/retry_unary.py", line 147, in retry_target
    result = target()
             ^^^^^^^^
  File "/Users/macbook/miniconda3/envs/eoh/lib/python3.12/site-packages/google/api_core/timeout.py", line 130, in func_with_timeout
    return func(*args, **kwargs)
           ^^^^^^^^^^^^^^^^^^^^^
  File "/Users/macbook/miniconda3/envs/eoh/lib/python3.12/site-packages/google/api_core/grpc_helpers.py", line 78, in error_remapped_callable
    raise exceptions.from_grpc_error(exc) from exc
google.api_core.exceptions.ResourceExhausted: 429 You exceeded your current quota, please check your plan and billing details. For more information on this error, head to: https://ai.google.dev/gemini-api/docs/rate-limits. [violations {
  quota_metric: "generativelanguage.googleapis.com/generate_content_free_tier_requests"
  quota_id: "GenerateRequestsPerMinutePerProjectPerModel-FreeTier"
  quota_dimensions {
    key: "model"
    value: "gemini-1.5-flash"
  }
  quota_dimensions {
    key: "location"
    value: "global"
  }
  quota_value: 15
}
, links {
  description: "Learn more about Gemini API quotas"
  url: "https://ai.google.dev/gemini-api/docs/rate-limits"
}
, retry_delay {
  seconds: 56
}
]
.
2025-06-15 09:21:03 INFO An exception occured: Traceback (most recent call last):
  File "/Users/macbook/Documents/Code/LLMdesignedEA-comp/llamea/llamea_api_rotations.py", line 326, in evolve_solution
    evolved_individual = chosen_llm.sample_solution(
                         ^^^^^^^^^^^^^^^^^^^^^^^^^^^
  File "/Users/macbook/Documents/Code/LLMdesignedEA-comp/llamea/llm.py", line 106, in sample_solution
    message = self.query(session_messages)
              ^^^^^^^^^^^^^^^^^^^^^^^^^^^^
  File "/Users/macbook/Documents/Code/LLMdesignedEA-comp/llamea/llm.py", line 278, in query
    response = chat_session.send_message(last["content"])
               ^^^^^^^^^^^^^^^^^^^^^^^^^^^^^^^^^^^^^^^^^^
  File "/Users/macbook/miniconda3/envs/eoh/lib/python3.12/site-packages/google/generativeai/generative_models.py", line 578, in send_message
    response = self.model.generate_content(
               ^^^^^^^^^^^^^^^^^^^^^^^^^^^^
  File "/Users/macbook/miniconda3/envs/eoh/lib/python3.12/site-packages/google/generativeai/generative_models.py", line 331, in generate_content
    response = self._client.generate_content(
               ^^^^^^^^^^^^^^^^^^^^^^^^^^^^^^
  File "/Users/macbook/miniconda3/envs/eoh/lib/python3.12/site-packages/google/ai/generativelanguage_v1beta/services/generative_service/client.py", line 835, in generate_content
    response = rpc(
               ^^^^
  File "/Users/macbook/miniconda3/envs/eoh/lib/python3.12/site-packages/google/api_core/gapic_v1/method.py", line 131, in __call__
    return wrapped_func(*args, **kwargs)
           ^^^^^^^^^^^^^^^^^^^^^^^^^^^^^
  File "/Users/macbook/miniconda3/envs/eoh/lib/python3.12/site-packages/google/api_core/retry/retry_unary.py", line 294, in retry_wrapped_func
    return retry_target(
           ^^^^^^^^^^^^^
  File "/Users/macbook/miniconda3/envs/eoh/lib/python3.12/site-packages/google/api_core/retry/retry_unary.py", line 156, in retry_target
    next_sleep = _retry_error_helper(
                 ^^^^^^^^^^^^^^^^^^^^
  File "/Users/macbook/miniconda3/envs/eoh/lib/python3.12/site-packages/google/api_core/retry/retry_base.py", line 214, in _retry_error_helper
    raise final_exc from source_exc
  File "/Users/macbook/miniconda3/envs/eoh/lib/python3.12/site-packages/google/api_core/retry/retry_unary.py", line 147, in retry_target
    result = target()
             ^^^^^^^^
  File "/Users/macbook/miniconda3/envs/eoh/lib/python3.12/site-packages/google/api_core/timeout.py", line 130, in func_with_timeout
    return func(*args, **kwargs)
           ^^^^^^^^^^^^^^^^^^^^^
  File "/Users/macbook/miniconda3/envs/eoh/lib/python3.12/site-packages/google/api_core/grpc_helpers.py", line 78, in error_remapped_callable
    raise exceptions.from_grpc_error(exc) from exc
google.api_core.exceptions.ResourceExhausted: 429 You exceeded your current quota, please check your plan and billing details. For more information on this error, head to: https://ai.google.dev/gemini-api/docs/rate-limits. [violations {
  quota_metric: "generativelanguage.googleapis.com/generate_content_free_tier_requests"
  quota_id: "GenerateRequestsPerMinutePerProjectPerModel-FreeTier"
  quota_dimensions {
    key: "model"
    value: "gemini-1.5-flash"
  }
  quota_dimensions {
    key: "location"
    value: "global"
  }
  quota_value: 15
}
, links {
  description: "Learn more about Gemini API quotas"
  url: "https://ai.google.dev/gemini-api/docs/rate-limits"
}
, retry_delay {
  seconds: 56
}
]
.
2025-06-15 09:21:03 INFO An exception occured: Traceback (most recent call last):
  File "/Users/macbook/Documents/Code/LLMdesignedEA-comp/llamea/llamea_api_rotations.py", line 326, in evolve_solution
    evolved_individual = chosen_llm.sample_solution(
                         ^^^^^^^^^^^^^^^^^^^^^^^^^^^
  File "/Users/macbook/Documents/Code/LLMdesignedEA-comp/llamea/llm.py", line 106, in sample_solution
    message = self.query(session_messages)
              ^^^^^^^^^^^^^^^^^^^^^^^^^^^^
  File "/Users/macbook/Documents/Code/LLMdesignedEA-comp/llamea/llm.py", line 278, in query
    response = chat_session.send_message(last["content"])
               ^^^^^^^^^^^^^^^^^^^^^^^^^^^^^^^^^^^^^^^^^^
  File "/Users/macbook/miniconda3/envs/eoh/lib/python3.12/site-packages/google/generativeai/generative_models.py", line 578, in send_message
    response = self.model.generate_content(
               ^^^^^^^^^^^^^^^^^^^^^^^^^^^^
  File "/Users/macbook/miniconda3/envs/eoh/lib/python3.12/site-packages/google/generativeai/generative_models.py", line 331, in generate_content
    response = self._client.generate_content(
               ^^^^^^^^^^^^^^^^^^^^^^^^^^^^^^
  File "/Users/macbook/miniconda3/envs/eoh/lib/python3.12/site-packages/google/ai/generativelanguage_v1beta/services/generative_service/client.py", line 835, in generate_content
    response = rpc(
               ^^^^
  File "/Users/macbook/miniconda3/envs/eoh/lib/python3.12/site-packages/google/api_core/gapic_v1/method.py", line 131, in __call__
    return wrapped_func(*args, **kwargs)
           ^^^^^^^^^^^^^^^^^^^^^^^^^^^^^
  File "/Users/macbook/miniconda3/envs/eoh/lib/python3.12/site-packages/google/api_core/retry/retry_unary.py", line 294, in retry_wrapped_func
    return retry_target(
           ^^^^^^^^^^^^^
  File "/Users/macbook/miniconda3/envs/eoh/lib/python3.12/site-packages/google/api_core/retry/retry_unary.py", line 156, in retry_target
    next_sleep = _retry_error_helper(
                 ^^^^^^^^^^^^^^^^^^^^
  File "/Users/macbook/miniconda3/envs/eoh/lib/python3.12/site-packages/google/api_core/retry/retry_base.py", line 214, in _retry_error_helper
    raise final_exc from source_exc
  File "/Users/macbook/miniconda3/envs/eoh/lib/python3.12/site-packages/google/api_core/retry/retry_unary.py", line 147, in retry_target
    result = target()
             ^^^^^^^^
  File "/Users/macbook/miniconda3/envs/eoh/lib/python3.12/site-packages/google/api_core/timeout.py", line 130, in func_with_timeout
    return func(*args, **kwargs)
           ^^^^^^^^^^^^^^^^^^^^^
  File "/Users/macbook/miniconda3/envs/eoh/lib/python3.12/site-packages/google/api_core/grpc_helpers.py", line 78, in error_remapped_callable
    raise exceptions.from_grpc_error(exc) from exc
google.api_core.exceptions.ResourceExhausted: 429 You exceeded your current quota, please check your plan and billing details. For more information on this error, head to: https://ai.google.dev/gemini-api/docs/rate-limits. [violations {
  quota_metric: "generativelanguage.googleapis.com/generate_content_free_tier_requests"
  quota_id: "GenerateRequestsPerMinutePerProjectPerModel-FreeTier"
  quota_dimensions {
    key: "model"
    value: "gemini-1.5-flash"
  }
  quota_dimensions {
    key: "location"
    value: "global"
  }
  quota_value: 15
}
, links {
  description: "Learn more about Gemini API quotas"
  url: "https://ai.google.dev/gemini-api/docs/rate-limits"
}
, retry_delay {
  seconds: 56
}
]
.
2025-06-15 09:21:03 INFO An exception occured: Traceback (most recent call last):
  File "/Users/macbook/Documents/Code/LLMdesignedEA-comp/llamea/llamea_api_rotations.py", line 326, in evolve_solution
    evolved_individual = chosen_llm.sample_solution(
                         ^^^^^^^^^^^^^^^^^^^^^^^^^^^
  File "/Users/macbook/Documents/Code/LLMdesignedEA-comp/llamea/llm.py", line 106, in sample_solution
    message = self.query(session_messages)
              ^^^^^^^^^^^^^^^^^^^^^^^^^^^^
  File "/Users/macbook/Documents/Code/LLMdesignedEA-comp/llamea/llm.py", line 278, in query
    response = chat_session.send_message(last["content"])
               ^^^^^^^^^^^^^^^^^^^^^^^^^^^^^^^^^^^^^^^^^^
  File "/Users/macbook/miniconda3/envs/eoh/lib/python3.12/site-packages/google/generativeai/generative_models.py", line 578, in send_message
    response = self.model.generate_content(
               ^^^^^^^^^^^^^^^^^^^^^^^^^^^^
  File "/Users/macbook/miniconda3/envs/eoh/lib/python3.12/site-packages/google/generativeai/generative_models.py", line 331, in generate_content
    response = self._client.generate_content(
               ^^^^^^^^^^^^^^^^^^^^^^^^^^^^^^
  File "/Users/macbook/miniconda3/envs/eoh/lib/python3.12/site-packages/google/ai/generativelanguage_v1beta/services/generative_service/client.py", line 835, in generate_content
    response = rpc(
               ^^^^
  File "/Users/macbook/miniconda3/envs/eoh/lib/python3.12/site-packages/google/api_core/gapic_v1/method.py", line 131, in __call__
    return wrapped_func(*args, **kwargs)
           ^^^^^^^^^^^^^^^^^^^^^^^^^^^^^
  File "/Users/macbook/miniconda3/envs/eoh/lib/python3.12/site-packages/google/api_core/retry/retry_unary.py", line 294, in retry_wrapped_func
    return retry_target(
           ^^^^^^^^^^^^^
  File "/Users/macbook/miniconda3/envs/eoh/lib/python3.12/site-packages/google/api_core/retry/retry_unary.py", line 156, in retry_target
    next_sleep = _retry_error_helper(
                 ^^^^^^^^^^^^^^^^^^^^
  File "/Users/macbook/miniconda3/envs/eoh/lib/python3.12/site-packages/google/api_core/retry/retry_base.py", line 214, in _retry_error_helper
    raise final_exc from source_exc
  File "/Users/macbook/miniconda3/envs/eoh/lib/python3.12/site-packages/google/api_core/retry/retry_unary.py", line 147, in retry_target
    result = target()
             ^^^^^^^^
  File "/Users/macbook/miniconda3/envs/eoh/lib/python3.12/site-packages/google/api_core/timeout.py", line 130, in func_with_timeout
    return func(*args, **kwargs)
           ^^^^^^^^^^^^^^^^^^^^^
  File "/Users/macbook/miniconda3/envs/eoh/lib/python3.12/site-packages/google/api_core/grpc_helpers.py", line 78, in error_remapped_callable
    raise exceptions.from_grpc_error(exc) from exc
google.api_core.exceptions.ResourceExhausted: 429 You exceeded your current quota, please check your plan and billing details. For more information on this error, head to: https://ai.google.dev/gemini-api/docs/rate-limits. [violations {
  quota_metric: "generativelanguage.googleapis.com/generate_content_free_tier_requests"
  quota_id: "GenerateRequestsPerMinutePerProjectPerModel-FreeTier"
  quota_dimensions {
    key: "model"
    value: "gemini-1.5-flash"
  }
  quota_dimensions {
    key: "location"
    value: "global"
  }
  quota_value: 15
}
, links {
  description: "Learn more about Gemini API quotas"
  url: "https://ai.google.dev/gemini-api/docs/rate-limits"
}
, retry_delay {
  seconds: 56
}
]
.
2025-06-15 09:21:03 INFO An exception occured: Traceback (most recent call last):
  File "/Users/macbook/Documents/Code/LLMdesignedEA-comp/llamea/llamea_api_rotations.py", line 326, in evolve_solution
    evolved_individual = chosen_llm.sample_solution(
                         ^^^^^^^^^^^^^^^^^^^^^^^^^^^
  File "/Users/macbook/Documents/Code/LLMdesignedEA-comp/llamea/llm.py", line 106, in sample_solution
    message = self.query(session_messages)
              ^^^^^^^^^^^^^^^^^^^^^^^^^^^^
  File "/Users/macbook/Documents/Code/LLMdesignedEA-comp/llamea/llm.py", line 278, in query
    response = chat_session.send_message(last["content"])
               ^^^^^^^^^^^^^^^^^^^^^^^^^^^^^^^^^^^^^^^^^^
  File "/Users/macbook/miniconda3/envs/eoh/lib/python3.12/site-packages/google/generativeai/generative_models.py", line 578, in send_message
    response = self.model.generate_content(
               ^^^^^^^^^^^^^^^^^^^^^^^^^^^^
  File "/Users/macbook/miniconda3/envs/eoh/lib/python3.12/site-packages/google/generativeai/generative_models.py", line 331, in generate_content
    response = self._client.generate_content(
               ^^^^^^^^^^^^^^^^^^^^^^^^^^^^^^
  File "/Users/macbook/miniconda3/envs/eoh/lib/python3.12/site-packages/google/ai/generativelanguage_v1beta/services/generative_service/client.py", line 835, in generate_content
    response = rpc(
               ^^^^
  File "/Users/macbook/miniconda3/envs/eoh/lib/python3.12/site-packages/google/api_core/gapic_v1/method.py", line 131, in __call__
    return wrapped_func(*args, **kwargs)
           ^^^^^^^^^^^^^^^^^^^^^^^^^^^^^
  File "/Users/macbook/miniconda3/envs/eoh/lib/python3.12/site-packages/google/api_core/retry/retry_unary.py", line 294, in retry_wrapped_func
    return retry_target(
           ^^^^^^^^^^^^^
  File "/Users/macbook/miniconda3/envs/eoh/lib/python3.12/site-packages/google/api_core/retry/retry_unary.py", line 156, in retry_target
    next_sleep = _retry_error_helper(
                 ^^^^^^^^^^^^^^^^^^^^
  File "/Users/macbook/miniconda3/envs/eoh/lib/python3.12/site-packages/google/api_core/retry/retry_base.py", line 214, in _retry_error_helper
    raise final_exc from source_exc
  File "/Users/macbook/miniconda3/envs/eoh/lib/python3.12/site-packages/google/api_core/retry/retry_unary.py", line 147, in retry_target
    result = target()
             ^^^^^^^^
  File "/Users/macbook/miniconda3/envs/eoh/lib/python3.12/site-packages/google/api_core/timeout.py", line 130, in func_with_timeout
    return func(*args, **kwargs)
           ^^^^^^^^^^^^^^^^^^^^^
  File "/Users/macbook/miniconda3/envs/eoh/lib/python3.12/site-packages/google/api_core/grpc_helpers.py", line 78, in error_remapped_callable
    raise exceptions.from_grpc_error(exc) from exc
google.api_core.exceptions.ResourceExhausted: 429 You exceeded your current quota, please check your plan and billing details. For more information on this error, head to: https://ai.google.dev/gemini-api/docs/rate-limits. [violations {
  quota_metric: "generativelanguage.googleapis.com/generate_content_free_tier_requests"
  quota_id: "GenerateRequestsPerMinutePerProjectPerModel-FreeTier"
  quota_dimensions {
    key: "model"
    value: "gemini-1.5-flash"
  }
  quota_dimensions {
    key: "location"
    value: "global"
  }
  quota_value: 15
}
, links {
  description: "Learn more about Gemini API quotas"
  url: "https://ai.google.dev/gemini-api/docs/rate-limits"
}
, retry_delay {
  seconds: 56
}
]
.
2025-06-15 09:21:03 INFO An exception occured: Traceback (most recent call last):
  File "/Users/macbook/Documents/Code/LLMdesignedEA-comp/llamea/llamea_api_rotations.py", line 326, in evolve_solution
    evolved_individual = chosen_llm.sample_solution(
                         ^^^^^^^^^^^^^^^^^^^^^^^^^^^
  File "/Users/macbook/Documents/Code/LLMdesignedEA-comp/llamea/llm.py", line 106, in sample_solution
    message = self.query(session_messages)
              ^^^^^^^^^^^^^^^^^^^^^^^^^^^^
  File "/Users/macbook/Documents/Code/LLMdesignedEA-comp/llamea/llm.py", line 278, in query
    response = chat_session.send_message(last["content"])
               ^^^^^^^^^^^^^^^^^^^^^^^^^^^^^^^^^^^^^^^^^^
  File "/Users/macbook/miniconda3/envs/eoh/lib/python3.12/site-packages/google/generativeai/generative_models.py", line 578, in send_message
    response = self.model.generate_content(
               ^^^^^^^^^^^^^^^^^^^^^^^^^^^^
  File "/Users/macbook/miniconda3/envs/eoh/lib/python3.12/site-packages/google/generativeai/generative_models.py", line 331, in generate_content
    response = self._client.generate_content(
               ^^^^^^^^^^^^^^^^^^^^^^^^^^^^^^
  File "/Users/macbook/miniconda3/envs/eoh/lib/python3.12/site-packages/google/ai/generativelanguage_v1beta/services/generative_service/client.py", line 835, in generate_content
    response = rpc(
               ^^^^
  File "/Users/macbook/miniconda3/envs/eoh/lib/python3.12/site-packages/google/api_core/gapic_v1/method.py", line 131, in __call__
    return wrapped_func(*args, **kwargs)
           ^^^^^^^^^^^^^^^^^^^^^^^^^^^^^
  File "/Users/macbook/miniconda3/envs/eoh/lib/python3.12/site-packages/google/api_core/retry/retry_unary.py", line 294, in retry_wrapped_func
    return retry_target(
           ^^^^^^^^^^^^^
  File "/Users/macbook/miniconda3/envs/eoh/lib/python3.12/site-packages/google/api_core/retry/retry_unary.py", line 156, in retry_target
    next_sleep = _retry_error_helper(
                 ^^^^^^^^^^^^^^^^^^^^
  File "/Users/macbook/miniconda3/envs/eoh/lib/python3.12/site-packages/google/api_core/retry/retry_base.py", line 214, in _retry_error_helper
    raise final_exc from source_exc
  File "/Users/macbook/miniconda3/envs/eoh/lib/python3.12/site-packages/google/api_core/retry/retry_unary.py", line 147, in retry_target
    result = target()
             ^^^^^^^^
  File "/Users/macbook/miniconda3/envs/eoh/lib/python3.12/site-packages/google/api_core/timeout.py", line 130, in func_with_timeout
    return func(*args, **kwargs)
           ^^^^^^^^^^^^^^^^^^^^^
  File "/Users/macbook/miniconda3/envs/eoh/lib/python3.12/site-packages/google/api_core/grpc_helpers.py", line 78, in error_remapped_callable
    raise exceptions.from_grpc_error(exc) from exc
google.api_core.exceptions.ResourceExhausted: 429 You exceeded your current quota, please check your plan and billing details. For more information on this error, head to: https://ai.google.dev/gemini-api/docs/rate-limits. [violations {
  quota_metric: "generativelanguage.googleapis.com/generate_content_free_tier_requests"
  quota_id: "GenerateRequestsPerMinutePerProjectPerModel-FreeTier"
  quota_dimensions {
    key: "model"
    value: "gemini-1.5-flash"
  }
  quota_dimensions {
    key: "location"
    value: "global"
  }
  quota_value: 15
}
, links {
  description: "Learn more about Gemini API quotas"
  url: "https://ai.google.dev/gemini-api/docs/rate-limits"
}
, retry_delay {
  seconds: 56
}
]
.
2025-06-15 09:21:03 INFO An exception occured: Traceback (most recent call last):
  File "/Users/macbook/Documents/Code/LLMdesignedEA-comp/llamea/llamea_api_rotations.py", line 326, in evolve_solution
    evolved_individual = chosen_llm.sample_solution(
                         ^^^^^^^^^^^^^^^^^^^^^^^^^^^
  File "/Users/macbook/Documents/Code/LLMdesignedEA-comp/llamea/llm.py", line 106, in sample_solution
    message = self.query(session_messages)
              ^^^^^^^^^^^^^^^^^^^^^^^^^^^^
  File "/Users/macbook/Documents/Code/LLMdesignedEA-comp/llamea/llm.py", line 278, in query
    response = chat_session.send_message(last["content"])
               ^^^^^^^^^^^^^^^^^^^^^^^^^^^^^^^^^^^^^^^^^^
  File "/Users/macbook/miniconda3/envs/eoh/lib/python3.12/site-packages/google/generativeai/generative_models.py", line 578, in send_message
    response = self.model.generate_content(
               ^^^^^^^^^^^^^^^^^^^^^^^^^^^^
  File "/Users/macbook/miniconda3/envs/eoh/lib/python3.12/site-packages/google/generativeai/generative_models.py", line 331, in generate_content
    response = self._client.generate_content(
               ^^^^^^^^^^^^^^^^^^^^^^^^^^^^^^
  File "/Users/macbook/miniconda3/envs/eoh/lib/python3.12/site-packages/google/ai/generativelanguage_v1beta/services/generative_service/client.py", line 835, in generate_content
    response = rpc(
               ^^^^
  File "/Users/macbook/miniconda3/envs/eoh/lib/python3.12/site-packages/google/api_core/gapic_v1/method.py", line 131, in __call__
    return wrapped_func(*args, **kwargs)
           ^^^^^^^^^^^^^^^^^^^^^^^^^^^^^
  File "/Users/macbook/miniconda3/envs/eoh/lib/python3.12/site-packages/google/api_core/retry/retry_unary.py", line 294, in retry_wrapped_func
    return retry_target(
           ^^^^^^^^^^^^^
  File "/Users/macbook/miniconda3/envs/eoh/lib/python3.12/site-packages/google/api_core/retry/retry_unary.py", line 156, in retry_target
    next_sleep = _retry_error_helper(
                 ^^^^^^^^^^^^^^^^^^^^
  File "/Users/macbook/miniconda3/envs/eoh/lib/python3.12/site-packages/google/api_core/retry/retry_base.py", line 214, in _retry_error_helper
    raise final_exc from source_exc
  File "/Users/macbook/miniconda3/envs/eoh/lib/python3.12/site-packages/google/api_core/retry/retry_unary.py", line 147, in retry_target
    result = target()
             ^^^^^^^^
  File "/Users/macbook/miniconda3/envs/eoh/lib/python3.12/site-packages/google/api_core/timeout.py", line 130, in func_with_timeout
    return func(*args, **kwargs)
           ^^^^^^^^^^^^^^^^^^^^^
  File "/Users/macbook/miniconda3/envs/eoh/lib/python3.12/site-packages/google/api_core/grpc_helpers.py", line 78, in error_remapped_callable
    raise exceptions.from_grpc_error(exc) from exc
google.api_core.exceptions.ResourceExhausted: 429 You exceeded your current quota, please check your plan and billing details. For more information on this error, head to: https://ai.google.dev/gemini-api/docs/rate-limits. [violations {
  quota_metric: "generativelanguage.googleapis.com/generate_content_free_tier_requests"
  quota_id: "GenerateRequestsPerMinutePerProjectPerModel-FreeTier"
  quota_dimensions {
    key: "model"
    value: "gemini-1.5-flash"
  }
  quota_dimensions {
    key: "location"
    value: "global"
  }
  quota_value: 15
}
, links {
  description: "Learn more about Gemini API quotas"
  url: "https://ai.google.dev/gemini-api/docs/rate-limits"
}
, retry_delay {
  seconds: 56
}
]
.
2025-06-15 09:21:03 INFO An exception occured: Traceback (most recent call last):
  File "/Users/macbook/Documents/Code/LLMdesignedEA-comp/llamea/llamea_api_rotations.py", line 326, in evolve_solution
    evolved_individual = chosen_llm.sample_solution(
                         ^^^^^^^^^^^^^^^^^^^^^^^^^^^
  File "/Users/macbook/Documents/Code/LLMdesignedEA-comp/llamea/llm.py", line 106, in sample_solution
    message = self.query(session_messages)
              ^^^^^^^^^^^^^^^^^^^^^^^^^^^^
  File "/Users/macbook/Documents/Code/LLMdesignedEA-comp/llamea/llm.py", line 278, in query
    response = chat_session.send_message(last["content"])
               ^^^^^^^^^^^^^^^^^^^^^^^^^^^^^^^^^^^^^^^^^^
  File "/Users/macbook/miniconda3/envs/eoh/lib/python3.12/site-packages/google/generativeai/generative_models.py", line 578, in send_message
    response = self.model.generate_content(
               ^^^^^^^^^^^^^^^^^^^^^^^^^^^^
  File "/Users/macbook/miniconda3/envs/eoh/lib/python3.12/site-packages/google/generativeai/generative_models.py", line 331, in generate_content
    response = self._client.generate_content(
               ^^^^^^^^^^^^^^^^^^^^^^^^^^^^^^
  File "/Users/macbook/miniconda3/envs/eoh/lib/python3.12/site-packages/google/ai/generativelanguage_v1beta/services/generative_service/client.py", line 835, in generate_content
    response = rpc(
               ^^^^
  File "/Users/macbook/miniconda3/envs/eoh/lib/python3.12/site-packages/google/api_core/gapic_v1/method.py", line 131, in __call__
    return wrapped_func(*args, **kwargs)
           ^^^^^^^^^^^^^^^^^^^^^^^^^^^^^
  File "/Users/macbook/miniconda3/envs/eoh/lib/python3.12/site-packages/google/api_core/retry/retry_unary.py", line 294, in retry_wrapped_func
    return retry_target(
           ^^^^^^^^^^^^^
  File "/Users/macbook/miniconda3/envs/eoh/lib/python3.12/site-packages/google/api_core/retry/retry_unary.py", line 156, in retry_target
    next_sleep = _retry_error_helper(
                 ^^^^^^^^^^^^^^^^^^^^
  File "/Users/macbook/miniconda3/envs/eoh/lib/python3.12/site-packages/google/api_core/retry/retry_base.py", line 214, in _retry_error_helper
    raise final_exc from source_exc
  File "/Users/macbook/miniconda3/envs/eoh/lib/python3.12/site-packages/google/api_core/retry/retry_unary.py", line 147, in retry_target
    result = target()
             ^^^^^^^^
  File "/Users/macbook/miniconda3/envs/eoh/lib/python3.12/site-packages/google/api_core/timeout.py", line 130, in func_with_timeout
    return func(*args, **kwargs)
           ^^^^^^^^^^^^^^^^^^^^^
  File "/Users/macbook/miniconda3/envs/eoh/lib/python3.12/site-packages/google/api_core/grpc_helpers.py", line 78, in error_remapped_callable
    raise exceptions.from_grpc_error(exc) from exc
google.api_core.exceptions.ResourceExhausted: 429 You exceeded your current quota, please check your plan and billing details. For more information on this error, head to: https://ai.google.dev/gemini-api/docs/rate-limits. [violations {
  quota_metric: "generativelanguage.googleapis.com/generate_content_free_tier_requests"
  quota_id: "GenerateRequestsPerMinutePerProjectPerModel-FreeTier"
  quota_dimensions {
    key: "model"
    value: "gemini-1.5-flash"
  }
  quota_dimensions {
    key: "location"
    value: "global"
  }
  quota_value: 15
}
, links {
  description: "Learn more about Gemini API quotas"
  url: "https://ai.google.dev/gemini-api/docs/rate-limits"
}
, retry_delay {
  seconds: 56
}
]
.
2025-06-15 09:21:04 INFO An exception occured: Traceback (most recent call last):
  File "/Users/macbook/Documents/Code/LLMdesignedEA-comp/llamea/llamea_api_rotations.py", line 326, in evolve_solution
    evolved_individual = chosen_llm.sample_solution(
                         ^^^^^^^^^^^^^^^^^^^^^^^^^^^
  File "/Users/macbook/Documents/Code/LLMdesignedEA-comp/llamea/llm.py", line 106, in sample_solution
    message = self.query(session_messages)
              ^^^^^^^^^^^^^^^^^^^^^^^^^^^^
  File "/Users/macbook/Documents/Code/LLMdesignedEA-comp/llamea/llm.py", line 278, in query
    response = chat_session.send_message(last["content"])
               ^^^^^^^^^^^^^^^^^^^^^^^^^^^^^^^^^^^^^^^^^^
  File "/Users/macbook/miniconda3/envs/eoh/lib/python3.12/site-packages/google/generativeai/generative_models.py", line 578, in send_message
    response = self.model.generate_content(
               ^^^^^^^^^^^^^^^^^^^^^^^^^^^^
  File "/Users/macbook/miniconda3/envs/eoh/lib/python3.12/site-packages/google/generativeai/generative_models.py", line 331, in generate_content
    response = self._client.generate_content(
               ^^^^^^^^^^^^^^^^^^^^^^^^^^^^^^
  File "/Users/macbook/miniconda3/envs/eoh/lib/python3.12/site-packages/google/ai/generativelanguage_v1beta/services/generative_service/client.py", line 835, in generate_content
    response = rpc(
               ^^^^
  File "/Users/macbook/miniconda3/envs/eoh/lib/python3.12/site-packages/google/api_core/gapic_v1/method.py", line 131, in __call__
    return wrapped_func(*args, **kwargs)
           ^^^^^^^^^^^^^^^^^^^^^^^^^^^^^
  File "/Users/macbook/miniconda3/envs/eoh/lib/python3.12/site-packages/google/api_core/retry/retry_unary.py", line 294, in retry_wrapped_func
    return retry_target(
           ^^^^^^^^^^^^^
  File "/Users/macbook/miniconda3/envs/eoh/lib/python3.12/site-packages/google/api_core/retry/retry_unary.py", line 156, in retry_target
    next_sleep = _retry_error_helper(
                 ^^^^^^^^^^^^^^^^^^^^
  File "/Users/macbook/miniconda3/envs/eoh/lib/python3.12/site-packages/google/api_core/retry/retry_base.py", line 214, in _retry_error_helper
    raise final_exc from source_exc
  File "/Users/macbook/miniconda3/envs/eoh/lib/python3.12/site-packages/google/api_core/retry/retry_unary.py", line 147, in retry_target
    result = target()
             ^^^^^^^^
  File "/Users/macbook/miniconda3/envs/eoh/lib/python3.12/site-packages/google/api_core/timeout.py", line 130, in func_with_timeout
    return func(*args, **kwargs)
           ^^^^^^^^^^^^^^^^^^^^^
  File "/Users/macbook/miniconda3/envs/eoh/lib/python3.12/site-packages/google/api_core/grpc_helpers.py", line 78, in error_remapped_callable
    raise exceptions.from_grpc_error(exc) from exc
google.api_core.exceptions.ResourceExhausted: 429 You exceeded your current quota, please check your plan and billing details. For more information on this error, head to: https://ai.google.dev/gemini-api/docs/rate-limits. [violations {
  quota_metric: "generativelanguage.googleapis.com/generate_content_free_tier_requests"
  quota_id: "GenerateRequestsPerMinutePerProjectPerModel-FreeTier"
  quota_dimensions {
    key: "model"
    value: "gemini-1.5-flash"
  }
  quota_dimensions {
    key: "location"
    value: "global"
  }
  quota_value: 15
}
, links {
  description: "Learn more about Gemini API quotas"
  url: "https://ai.google.dev/gemini-api/docs/rate-limits"
}
, retry_delay {
  seconds: 55
}
]
.
2025-06-15 09:21:04 INFO An exception occured: Traceback (most recent call last):
  File "/Users/macbook/Documents/Code/LLMdesignedEA-comp/llamea/llamea_api_rotations.py", line 326, in evolve_solution
    evolved_individual = chosen_llm.sample_solution(
                         ^^^^^^^^^^^^^^^^^^^^^^^^^^^
  File "/Users/macbook/Documents/Code/LLMdesignedEA-comp/llamea/llm.py", line 106, in sample_solution
    message = self.query(session_messages)
              ^^^^^^^^^^^^^^^^^^^^^^^^^^^^
  File "/Users/macbook/Documents/Code/LLMdesignedEA-comp/llamea/llm.py", line 278, in query
    response = chat_session.send_message(last["content"])
               ^^^^^^^^^^^^^^^^^^^^^^^^^^^^^^^^^^^^^^^^^^
  File "/Users/macbook/miniconda3/envs/eoh/lib/python3.12/site-packages/google/generativeai/generative_models.py", line 578, in send_message
    response = self.model.generate_content(
               ^^^^^^^^^^^^^^^^^^^^^^^^^^^^
  File "/Users/macbook/miniconda3/envs/eoh/lib/python3.12/site-packages/google/generativeai/generative_models.py", line 331, in generate_content
    response = self._client.generate_content(
               ^^^^^^^^^^^^^^^^^^^^^^^^^^^^^^
  File "/Users/macbook/miniconda3/envs/eoh/lib/python3.12/site-packages/google/ai/generativelanguage_v1beta/services/generative_service/client.py", line 835, in generate_content
    response = rpc(
               ^^^^
  File "/Users/macbook/miniconda3/envs/eoh/lib/python3.12/site-packages/google/api_core/gapic_v1/method.py", line 131, in __call__
    return wrapped_func(*args, **kwargs)
           ^^^^^^^^^^^^^^^^^^^^^^^^^^^^^
  File "/Users/macbook/miniconda3/envs/eoh/lib/python3.12/site-packages/google/api_core/retry/retry_unary.py", line 294, in retry_wrapped_func
    return retry_target(
           ^^^^^^^^^^^^^
  File "/Users/macbook/miniconda3/envs/eoh/lib/python3.12/site-packages/google/api_core/retry/retry_unary.py", line 156, in retry_target
    next_sleep = _retry_error_helper(
                 ^^^^^^^^^^^^^^^^^^^^
  File "/Users/macbook/miniconda3/envs/eoh/lib/python3.12/site-packages/google/api_core/retry/retry_base.py", line 214, in _retry_error_helper
    raise final_exc from source_exc
  File "/Users/macbook/miniconda3/envs/eoh/lib/python3.12/site-packages/google/api_core/retry/retry_unary.py", line 147, in retry_target
    result = target()
             ^^^^^^^^
  File "/Users/macbook/miniconda3/envs/eoh/lib/python3.12/site-packages/google/api_core/timeout.py", line 130, in func_with_timeout
    return func(*args, **kwargs)
           ^^^^^^^^^^^^^^^^^^^^^
  File "/Users/macbook/miniconda3/envs/eoh/lib/python3.12/site-packages/google/api_core/grpc_helpers.py", line 78, in error_remapped_callable
    raise exceptions.from_grpc_error(exc) from exc
google.api_core.exceptions.ResourceExhausted: 429 You exceeded your current quota, please check your plan and billing details. For more information on this error, head to: https://ai.google.dev/gemini-api/docs/rate-limits. [violations {
  quota_metric: "generativelanguage.googleapis.com/generate_content_free_tier_requests"
  quota_id: "GenerateRequestsPerMinutePerProjectPerModel-FreeTier"
  quota_dimensions {
    key: "model"
    value: "gemini-1.5-flash"
  }
  quota_dimensions {
    key: "location"
    value: "global"
  }
  quota_value: 15
}
, links {
  description: "Learn more about Gemini API quotas"
  url: "https://ai.google.dev/gemini-api/docs/rate-limits"
}
, retry_delay {
  seconds: 55
}
]
.
2025-06-15 09:21:04 INFO An exception occured: Traceback (most recent call last):
  File "/Users/macbook/Documents/Code/LLMdesignedEA-comp/llamea/llamea_api_rotations.py", line 326, in evolve_solution
    evolved_individual = chosen_llm.sample_solution(
                         ^^^^^^^^^^^^^^^^^^^^^^^^^^^
  File "/Users/macbook/Documents/Code/LLMdesignedEA-comp/llamea/llm.py", line 106, in sample_solution
    message = self.query(session_messages)
              ^^^^^^^^^^^^^^^^^^^^^^^^^^^^
  File "/Users/macbook/Documents/Code/LLMdesignedEA-comp/llamea/llm.py", line 278, in query
    response = chat_session.send_message(last["content"])
               ^^^^^^^^^^^^^^^^^^^^^^^^^^^^^^^^^^^^^^^^^^
  File "/Users/macbook/miniconda3/envs/eoh/lib/python3.12/site-packages/google/generativeai/generative_models.py", line 578, in send_message
    response = self.model.generate_content(
               ^^^^^^^^^^^^^^^^^^^^^^^^^^^^
  File "/Users/macbook/miniconda3/envs/eoh/lib/python3.12/site-packages/google/generativeai/generative_models.py", line 331, in generate_content
    response = self._client.generate_content(
               ^^^^^^^^^^^^^^^^^^^^^^^^^^^^^^
  File "/Users/macbook/miniconda3/envs/eoh/lib/python3.12/site-packages/google/ai/generativelanguage_v1beta/services/generative_service/client.py", line 835, in generate_content
    response = rpc(
               ^^^^
  File "/Users/macbook/miniconda3/envs/eoh/lib/python3.12/site-packages/google/api_core/gapic_v1/method.py", line 131, in __call__
    return wrapped_func(*args, **kwargs)
           ^^^^^^^^^^^^^^^^^^^^^^^^^^^^^
  File "/Users/macbook/miniconda3/envs/eoh/lib/python3.12/site-packages/google/api_core/retry/retry_unary.py", line 294, in retry_wrapped_func
    return retry_target(
           ^^^^^^^^^^^^^
  File "/Users/macbook/miniconda3/envs/eoh/lib/python3.12/site-packages/google/api_core/retry/retry_unary.py", line 156, in retry_target
    next_sleep = _retry_error_helper(
                 ^^^^^^^^^^^^^^^^^^^^
  File "/Users/macbook/miniconda3/envs/eoh/lib/python3.12/site-packages/google/api_core/retry/retry_base.py", line 214, in _retry_error_helper
    raise final_exc from source_exc
  File "/Users/macbook/miniconda3/envs/eoh/lib/python3.12/site-packages/google/api_core/retry/retry_unary.py", line 147, in retry_target
    result = target()
             ^^^^^^^^
  File "/Users/macbook/miniconda3/envs/eoh/lib/python3.12/site-packages/google/api_core/timeout.py", line 130, in func_with_timeout
    return func(*args, **kwargs)
           ^^^^^^^^^^^^^^^^^^^^^
  File "/Users/macbook/miniconda3/envs/eoh/lib/python3.12/site-packages/google/api_core/grpc_helpers.py", line 78, in error_remapped_callable
    raise exceptions.from_grpc_error(exc) from exc
google.api_core.exceptions.ResourceExhausted: 429 You exceeded your current quota, please check your plan and billing details. For more information on this error, head to: https://ai.google.dev/gemini-api/docs/rate-limits. [violations {
  quota_metric: "generativelanguage.googleapis.com/generate_content_free_tier_requests"
  quota_id: "GenerateRequestsPerMinutePerProjectPerModel-FreeTier"
  quota_dimensions {
    key: "model"
    value: "gemini-1.5-flash"
  }
  quota_dimensions {
    key: "location"
    value: "global"
  }
  quota_value: 15
}
, links {
  description: "Learn more about Gemini API quotas"
  url: "https://ai.google.dev/gemini-api/docs/rate-limits"
}
, retry_delay {
  seconds: 55
}
]
.
2025-06-15 09:21:04 INFO An exception occured: Traceback (most recent call last):
  File "/Users/macbook/Documents/Code/LLMdesignedEA-comp/llamea/llamea_api_rotations.py", line 326, in evolve_solution
    evolved_individual = chosen_llm.sample_solution(
                         ^^^^^^^^^^^^^^^^^^^^^^^^^^^
  File "/Users/macbook/Documents/Code/LLMdesignedEA-comp/llamea/llm.py", line 106, in sample_solution
    message = self.query(session_messages)
              ^^^^^^^^^^^^^^^^^^^^^^^^^^^^
  File "/Users/macbook/Documents/Code/LLMdesignedEA-comp/llamea/llm.py", line 278, in query
    response = chat_session.send_message(last["content"])
               ^^^^^^^^^^^^^^^^^^^^^^^^^^^^^^^^^^^^^^^^^^
  File "/Users/macbook/miniconda3/envs/eoh/lib/python3.12/site-packages/google/generativeai/generative_models.py", line 578, in send_message
    response = self.model.generate_content(
               ^^^^^^^^^^^^^^^^^^^^^^^^^^^^
  File "/Users/macbook/miniconda3/envs/eoh/lib/python3.12/site-packages/google/generativeai/generative_models.py", line 331, in generate_content
    response = self._client.generate_content(
               ^^^^^^^^^^^^^^^^^^^^^^^^^^^^^^
  File "/Users/macbook/miniconda3/envs/eoh/lib/python3.12/site-packages/google/ai/generativelanguage_v1beta/services/generative_service/client.py", line 835, in generate_content
    response = rpc(
               ^^^^
  File "/Users/macbook/miniconda3/envs/eoh/lib/python3.12/site-packages/google/api_core/gapic_v1/method.py", line 131, in __call__
    return wrapped_func(*args, **kwargs)
           ^^^^^^^^^^^^^^^^^^^^^^^^^^^^^
  File "/Users/macbook/miniconda3/envs/eoh/lib/python3.12/site-packages/google/api_core/retry/retry_unary.py", line 294, in retry_wrapped_func
    return retry_target(
           ^^^^^^^^^^^^^
  File "/Users/macbook/miniconda3/envs/eoh/lib/python3.12/site-packages/google/api_core/retry/retry_unary.py", line 156, in retry_target
    next_sleep = _retry_error_helper(
                 ^^^^^^^^^^^^^^^^^^^^
  File "/Users/macbook/miniconda3/envs/eoh/lib/python3.12/site-packages/google/api_core/retry/retry_base.py", line 214, in _retry_error_helper
    raise final_exc from source_exc
  File "/Users/macbook/miniconda3/envs/eoh/lib/python3.12/site-packages/google/api_core/retry/retry_unary.py", line 147, in retry_target
    result = target()
             ^^^^^^^^
  File "/Users/macbook/miniconda3/envs/eoh/lib/python3.12/site-packages/google/api_core/timeout.py", line 130, in func_with_timeout
    return func(*args, **kwargs)
           ^^^^^^^^^^^^^^^^^^^^^
  File "/Users/macbook/miniconda3/envs/eoh/lib/python3.12/site-packages/google/api_core/grpc_helpers.py", line 78, in error_remapped_callable
    raise exceptions.from_grpc_error(exc) from exc
google.api_core.exceptions.ResourceExhausted: 429 You exceeded your current quota, please check your plan and billing details. For more information on this error, head to: https://ai.google.dev/gemini-api/docs/rate-limits. [violations {
  quota_metric: "generativelanguage.googleapis.com/generate_content_free_tier_requests"
  quota_id: "GenerateRequestsPerMinutePerProjectPerModel-FreeTier"
  quota_dimensions {
    key: "model"
    value: "gemini-1.5-flash"
  }
  quota_dimensions {
    key: "location"
    value: "global"
  }
  quota_value: 15
}
, links {
  description: "Learn more about Gemini API quotas"
  url: "https://ai.google.dev/gemini-api/docs/rate-limits"
}
, retry_delay {
  seconds: 55
}
]
.
2025-06-15 09:21:04 INFO An exception occured: Traceback (most recent call last):
  File "/Users/macbook/Documents/Code/LLMdesignedEA-comp/llamea/llamea_api_rotations.py", line 326, in evolve_solution
    evolved_individual = chosen_llm.sample_solution(
                         ^^^^^^^^^^^^^^^^^^^^^^^^^^^
  File "/Users/macbook/Documents/Code/LLMdesignedEA-comp/llamea/llm.py", line 106, in sample_solution
    message = self.query(session_messages)
              ^^^^^^^^^^^^^^^^^^^^^^^^^^^^
  File "/Users/macbook/Documents/Code/LLMdesignedEA-comp/llamea/llm.py", line 278, in query
    response = chat_session.send_message(last["content"])
               ^^^^^^^^^^^^^^^^^^^^^^^^^^^^^^^^^^^^^^^^^^
  File "/Users/macbook/miniconda3/envs/eoh/lib/python3.12/site-packages/google/generativeai/generative_models.py", line 578, in send_message
    response = self.model.generate_content(
               ^^^^^^^^^^^^^^^^^^^^^^^^^^^^
  File "/Users/macbook/miniconda3/envs/eoh/lib/python3.12/site-packages/google/generativeai/generative_models.py", line 331, in generate_content
    response = self._client.generate_content(
               ^^^^^^^^^^^^^^^^^^^^^^^^^^^^^^
  File "/Users/macbook/miniconda3/envs/eoh/lib/python3.12/site-packages/google/ai/generativelanguage_v1beta/services/generative_service/client.py", line 835, in generate_content
    response = rpc(
               ^^^^
  File "/Users/macbook/miniconda3/envs/eoh/lib/python3.12/site-packages/google/api_core/gapic_v1/method.py", line 131, in __call__
    return wrapped_func(*args, **kwargs)
           ^^^^^^^^^^^^^^^^^^^^^^^^^^^^^
  File "/Users/macbook/miniconda3/envs/eoh/lib/python3.12/site-packages/google/api_core/retry/retry_unary.py", line 294, in retry_wrapped_func
    return retry_target(
           ^^^^^^^^^^^^^
  File "/Users/macbook/miniconda3/envs/eoh/lib/python3.12/site-packages/google/api_core/retry/retry_unary.py", line 156, in retry_target
    next_sleep = _retry_error_helper(
                 ^^^^^^^^^^^^^^^^^^^^
  File "/Users/macbook/miniconda3/envs/eoh/lib/python3.12/site-packages/google/api_core/retry/retry_base.py", line 214, in _retry_error_helper
    raise final_exc from source_exc
  File "/Users/macbook/miniconda3/envs/eoh/lib/python3.12/site-packages/google/api_core/retry/retry_unary.py", line 147, in retry_target
    result = target()
             ^^^^^^^^
  File "/Users/macbook/miniconda3/envs/eoh/lib/python3.12/site-packages/google/api_core/timeout.py", line 130, in func_with_timeout
    return func(*args, **kwargs)
           ^^^^^^^^^^^^^^^^^^^^^
  File "/Users/macbook/miniconda3/envs/eoh/lib/python3.12/site-packages/google/api_core/grpc_helpers.py", line 78, in error_remapped_callable
    raise exceptions.from_grpc_error(exc) from exc
google.api_core.exceptions.ResourceExhausted: 429 You exceeded your current quota, please check your plan and billing details. For more information on this error, head to: https://ai.google.dev/gemini-api/docs/rate-limits. [violations {
  quota_metric: "generativelanguage.googleapis.com/generate_content_free_tier_requests"
  quota_id: "GenerateRequestsPerMinutePerProjectPerModel-FreeTier"
  quota_dimensions {
    key: "model"
    value: "gemini-1.5-flash"
  }
  quota_dimensions {
    key: "location"
    value: "global"
  }
  quota_value: 15
}
, links {
  description: "Learn more about Gemini API quotas"
  url: "https://ai.google.dev/gemini-api/docs/rate-limits"
}
, retry_delay {
  seconds: 55
}
]
.
2025-06-15 09:21:04 INFO An exception occured: Traceback (most recent call last):
  File "/Users/macbook/Documents/Code/LLMdesignedEA-comp/llamea/llamea_api_rotations.py", line 326, in evolve_solution
    evolved_individual = chosen_llm.sample_solution(
                         ^^^^^^^^^^^^^^^^^^^^^^^^^^^
  File "/Users/macbook/Documents/Code/LLMdesignedEA-comp/llamea/llm.py", line 106, in sample_solution
    message = self.query(session_messages)
              ^^^^^^^^^^^^^^^^^^^^^^^^^^^^
  File "/Users/macbook/Documents/Code/LLMdesignedEA-comp/llamea/llm.py", line 278, in query
    response = chat_session.send_message(last["content"])
               ^^^^^^^^^^^^^^^^^^^^^^^^^^^^^^^^^^^^^^^^^^
  File "/Users/macbook/miniconda3/envs/eoh/lib/python3.12/site-packages/google/generativeai/generative_models.py", line 578, in send_message
    response = self.model.generate_content(
               ^^^^^^^^^^^^^^^^^^^^^^^^^^^^
  File "/Users/macbook/miniconda3/envs/eoh/lib/python3.12/site-packages/google/generativeai/generative_models.py", line 331, in generate_content
    response = self._client.generate_content(
               ^^^^^^^^^^^^^^^^^^^^^^^^^^^^^^
  File "/Users/macbook/miniconda3/envs/eoh/lib/python3.12/site-packages/google/ai/generativelanguage_v1beta/services/generative_service/client.py", line 835, in generate_content
    response = rpc(
               ^^^^
  File "/Users/macbook/miniconda3/envs/eoh/lib/python3.12/site-packages/google/api_core/gapic_v1/method.py", line 131, in __call__
    return wrapped_func(*args, **kwargs)
           ^^^^^^^^^^^^^^^^^^^^^^^^^^^^^
  File "/Users/macbook/miniconda3/envs/eoh/lib/python3.12/site-packages/google/api_core/retry/retry_unary.py", line 294, in retry_wrapped_func
    return retry_target(
           ^^^^^^^^^^^^^
  File "/Users/macbook/miniconda3/envs/eoh/lib/python3.12/site-packages/google/api_core/retry/retry_unary.py", line 156, in retry_target
    next_sleep = _retry_error_helper(
                 ^^^^^^^^^^^^^^^^^^^^
  File "/Users/macbook/miniconda3/envs/eoh/lib/python3.12/site-packages/google/api_core/retry/retry_base.py", line 214, in _retry_error_helper
    raise final_exc from source_exc
  File "/Users/macbook/miniconda3/envs/eoh/lib/python3.12/site-packages/google/api_core/retry/retry_unary.py", line 147, in retry_target
    result = target()
             ^^^^^^^^
  File "/Users/macbook/miniconda3/envs/eoh/lib/python3.12/site-packages/google/api_core/timeout.py", line 130, in func_with_timeout
    return func(*args, **kwargs)
           ^^^^^^^^^^^^^^^^^^^^^
  File "/Users/macbook/miniconda3/envs/eoh/lib/python3.12/site-packages/google/api_core/grpc_helpers.py", line 78, in error_remapped_callable
    raise exceptions.from_grpc_error(exc) from exc
google.api_core.exceptions.ResourceExhausted: 429 You exceeded your current quota, please check your plan and billing details. For more information on this error, head to: https://ai.google.dev/gemini-api/docs/rate-limits. [violations {
  quota_metric: "generativelanguage.googleapis.com/generate_content_free_tier_requests"
  quota_id: "GenerateRequestsPerMinutePerProjectPerModel-FreeTier"
  quota_dimensions {
    key: "model"
    value: "gemini-1.5-flash"
  }
  quota_dimensions {
    key: "location"
    value: "global"
  }
  quota_value: 15
}
, links {
  description: "Learn more about Gemini API quotas"
  url: "https://ai.google.dev/gemini-api/docs/rate-limits"
}
, retry_delay {
  seconds: 55
}
]
.
2025-06-15 09:21:04 INFO An exception occured: Traceback (most recent call last):
  File "/Users/macbook/Documents/Code/LLMdesignedEA-comp/llamea/llamea_api_rotations.py", line 326, in evolve_solution
    evolved_individual = chosen_llm.sample_solution(
                         ^^^^^^^^^^^^^^^^^^^^^^^^^^^
  File "/Users/macbook/Documents/Code/LLMdesignedEA-comp/llamea/llm.py", line 106, in sample_solution
    message = self.query(session_messages)
              ^^^^^^^^^^^^^^^^^^^^^^^^^^^^
  File "/Users/macbook/Documents/Code/LLMdesignedEA-comp/llamea/llm.py", line 278, in query
    response = chat_session.send_message(last["content"])
               ^^^^^^^^^^^^^^^^^^^^^^^^^^^^^^^^^^^^^^^^^^
  File "/Users/macbook/miniconda3/envs/eoh/lib/python3.12/site-packages/google/generativeai/generative_models.py", line 578, in send_message
    response = self.model.generate_content(
               ^^^^^^^^^^^^^^^^^^^^^^^^^^^^
  File "/Users/macbook/miniconda3/envs/eoh/lib/python3.12/site-packages/google/generativeai/generative_models.py", line 331, in generate_content
    response = self._client.generate_content(
               ^^^^^^^^^^^^^^^^^^^^^^^^^^^^^^
  File "/Users/macbook/miniconda3/envs/eoh/lib/python3.12/site-packages/google/ai/generativelanguage_v1beta/services/generative_service/client.py", line 835, in generate_content
    response = rpc(
               ^^^^
  File "/Users/macbook/miniconda3/envs/eoh/lib/python3.12/site-packages/google/api_core/gapic_v1/method.py", line 131, in __call__
    return wrapped_func(*args, **kwargs)
           ^^^^^^^^^^^^^^^^^^^^^^^^^^^^^
  File "/Users/macbook/miniconda3/envs/eoh/lib/python3.12/site-packages/google/api_core/retry/retry_unary.py", line 294, in retry_wrapped_func
    return retry_target(
           ^^^^^^^^^^^^^
  File "/Users/macbook/miniconda3/envs/eoh/lib/python3.12/site-packages/google/api_core/retry/retry_unary.py", line 156, in retry_target
    next_sleep = _retry_error_helper(
                 ^^^^^^^^^^^^^^^^^^^^
  File "/Users/macbook/miniconda3/envs/eoh/lib/python3.12/site-packages/google/api_core/retry/retry_base.py", line 214, in _retry_error_helper
    raise final_exc from source_exc
  File "/Users/macbook/miniconda3/envs/eoh/lib/python3.12/site-packages/google/api_core/retry/retry_unary.py", line 147, in retry_target
    result = target()
             ^^^^^^^^
  File "/Users/macbook/miniconda3/envs/eoh/lib/python3.12/site-packages/google/api_core/timeout.py", line 130, in func_with_timeout
    return func(*args, **kwargs)
           ^^^^^^^^^^^^^^^^^^^^^
  File "/Users/macbook/miniconda3/envs/eoh/lib/python3.12/site-packages/google/api_core/grpc_helpers.py", line 78, in error_remapped_callable
    raise exceptions.from_grpc_error(exc) from exc
google.api_core.exceptions.ResourceExhausted: 429 You exceeded your current quota, please check your plan and billing details. For more information on this error, head to: https://ai.google.dev/gemini-api/docs/rate-limits. [violations {
  quota_metric: "generativelanguage.googleapis.com/generate_content_free_tier_requests"
  quota_id: "GenerateRequestsPerMinutePerProjectPerModel-FreeTier"
  quota_dimensions {
    key: "model"
    value: "gemini-1.5-flash"
  }
  quota_dimensions {
    key: "location"
    value: "global"
  }
  quota_value: 15
}
, links {
  description: "Learn more about Gemini API quotas"
  url: "https://ai.google.dev/gemini-api/docs/rate-limits"
}
, retry_delay {
  seconds: 55
}
]
.
2025-06-15 09:21:04 INFO An exception occured: Traceback (most recent call last):
  File "/Users/macbook/Documents/Code/LLMdesignedEA-comp/llamea/llamea_api_rotations.py", line 326, in evolve_solution
    evolved_individual = chosen_llm.sample_solution(
                         ^^^^^^^^^^^^^^^^^^^^^^^^^^^
  File "/Users/macbook/Documents/Code/LLMdesignedEA-comp/llamea/llm.py", line 106, in sample_solution
    message = self.query(session_messages)
              ^^^^^^^^^^^^^^^^^^^^^^^^^^^^
  File "/Users/macbook/Documents/Code/LLMdesignedEA-comp/llamea/llm.py", line 278, in query
    response = chat_session.send_message(last["content"])
               ^^^^^^^^^^^^^^^^^^^^^^^^^^^^^^^^^^^^^^^^^^
  File "/Users/macbook/miniconda3/envs/eoh/lib/python3.12/site-packages/google/generativeai/generative_models.py", line 578, in send_message
    response = self.model.generate_content(
               ^^^^^^^^^^^^^^^^^^^^^^^^^^^^
  File "/Users/macbook/miniconda3/envs/eoh/lib/python3.12/site-packages/google/generativeai/generative_models.py", line 331, in generate_content
    response = self._client.generate_content(
               ^^^^^^^^^^^^^^^^^^^^^^^^^^^^^^
  File "/Users/macbook/miniconda3/envs/eoh/lib/python3.12/site-packages/google/ai/generativelanguage_v1beta/services/generative_service/client.py", line 835, in generate_content
    response = rpc(
               ^^^^
  File "/Users/macbook/miniconda3/envs/eoh/lib/python3.12/site-packages/google/api_core/gapic_v1/method.py", line 131, in __call__
    return wrapped_func(*args, **kwargs)
           ^^^^^^^^^^^^^^^^^^^^^^^^^^^^^
  File "/Users/macbook/miniconda3/envs/eoh/lib/python3.12/site-packages/google/api_core/retry/retry_unary.py", line 294, in retry_wrapped_func
    return retry_target(
           ^^^^^^^^^^^^^
  File "/Users/macbook/miniconda3/envs/eoh/lib/python3.12/site-packages/google/api_core/retry/retry_unary.py", line 156, in retry_target
    next_sleep = _retry_error_helper(
                 ^^^^^^^^^^^^^^^^^^^^
  File "/Users/macbook/miniconda3/envs/eoh/lib/python3.12/site-packages/google/api_core/retry/retry_base.py", line 214, in _retry_error_helper
    raise final_exc from source_exc
  File "/Users/macbook/miniconda3/envs/eoh/lib/python3.12/site-packages/google/api_core/retry/retry_unary.py", line 147, in retry_target
    result = target()
             ^^^^^^^^
  File "/Users/macbook/miniconda3/envs/eoh/lib/python3.12/site-packages/google/api_core/timeout.py", line 130, in func_with_timeout
    return func(*args, **kwargs)
           ^^^^^^^^^^^^^^^^^^^^^
  File "/Users/macbook/miniconda3/envs/eoh/lib/python3.12/site-packages/google/api_core/grpc_helpers.py", line 78, in error_remapped_callable
    raise exceptions.from_grpc_error(exc) from exc
google.api_core.exceptions.ResourceExhausted: 429 You exceeded your current quota, please check your plan and billing details. For more information on this error, head to: https://ai.google.dev/gemini-api/docs/rate-limits. [violations {
  quota_metric: "generativelanguage.googleapis.com/generate_content_free_tier_requests"
  quota_id: "GenerateRequestsPerMinutePerProjectPerModel-FreeTier"
  quota_dimensions {
    key: "model"
    value: "gemini-1.5-flash"
  }
  quota_dimensions {
    key: "location"
    value: "global"
  }
  quota_value: 15
}
, links {
  description: "Learn more about Gemini API quotas"
  url: "https://ai.google.dev/gemini-api/docs/rate-limits"
}
, retry_delay {
  seconds: 55
}
]
.
2025-06-15 09:21:04 INFO An exception occured: Traceback (most recent call last):
  File "/Users/macbook/Documents/Code/LLMdesignedEA-comp/llamea/llamea_api_rotations.py", line 326, in evolve_solution
    evolved_individual = chosen_llm.sample_solution(
                         ^^^^^^^^^^^^^^^^^^^^^^^^^^^
  File "/Users/macbook/Documents/Code/LLMdesignedEA-comp/llamea/llm.py", line 106, in sample_solution
    message = self.query(session_messages)
              ^^^^^^^^^^^^^^^^^^^^^^^^^^^^
  File "/Users/macbook/Documents/Code/LLMdesignedEA-comp/llamea/llm.py", line 278, in query
    response = chat_session.send_message(last["content"])
               ^^^^^^^^^^^^^^^^^^^^^^^^^^^^^^^^^^^^^^^^^^
  File "/Users/macbook/miniconda3/envs/eoh/lib/python3.12/site-packages/google/generativeai/generative_models.py", line 578, in send_message
    response = self.model.generate_content(
               ^^^^^^^^^^^^^^^^^^^^^^^^^^^^
  File "/Users/macbook/miniconda3/envs/eoh/lib/python3.12/site-packages/google/generativeai/generative_models.py", line 331, in generate_content
    response = self._client.generate_content(
               ^^^^^^^^^^^^^^^^^^^^^^^^^^^^^^
  File "/Users/macbook/miniconda3/envs/eoh/lib/python3.12/site-packages/google/ai/generativelanguage_v1beta/services/generative_service/client.py", line 835, in generate_content
    response = rpc(
               ^^^^
  File "/Users/macbook/miniconda3/envs/eoh/lib/python3.12/site-packages/google/api_core/gapic_v1/method.py", line 131, in __call__
    return wrapped_func(*args, **kwargs)
           ^^^^^^^^^^^^^^^^^^^^^^^^^^^^^
  File "/Users/macbook/miniconda3/envs/eoh/lib/python3.12/site-packages/google/api_core/retry/retry_unary.py", line 294, in retry_wrapped_func
    return retry_target(
           ^^^^^^^^^^^^^
  File "/Users/macbook/miniconda3/envs/eoh/lib/python3.12/site-packages/google/api_core/retry/retry_unary.py", line 156, in retry_target
    next_sleep = _retry_error_helper(
                 ^^^^^^^^^^^^^^^^^^^^
  File "/Users/macbook/miniconda3/envs/eoh/lib/python3.12/site-packages/google/api_core/retry/retry_base.py", line 214, in _retry_error_helper
    raise final_exc from source_exc
  File "/Users/macbook/miniconda3/envs/eoh/lib/python3.12/site-packages/google/api_core/retry/retry_unary.py", line 147, in retry_target
    result = target()
             ^^^^^^^^
  File "/Users/macbook/miniconda3/envs/eoh/lib/python3.12/site-packages/google/api_core/timeout.py", line 130, in func_with_timeout
    return func(*args, **kwargs)
           ^^^^^^^^^^^^^^^^^^^^^
  File "/Users/macbook/miniconda3/envs/eoh/lib/python3.12/site-packages/google/api_core/grpc_helpers.py", line 78, in error_remapped_callable
    raise exceptions.from_grpc_error(exc) from exc
google.api_core.exceptions.ResourceExhausted: 429 You exceeded your current quota, please check your plan and billing details. For more information on this error, head to: https://ai.google.dev/gemini-api/docs/rate-limits. [violations {
  quota_metric: "generativelanguage.googleapis.com/generate_content_free_tier_requests"
  quota_id: "GenerateRequestsPerMinutePerProjectPerModel-FreeTier"
  quota_dimensions {
    key: "model"
    value: "gemini-1.5-flash"
  }
  quota_dimensions {
    key: "location"
    value: "global"
  }
  quota_value: 15
}
, links {
  description: "Learn more about Gemini API quotas"
  url: "https://ai.google.dev/gemini-api/docs/rate-limits"
}
, retry_delay {
  seconds: 55
}
]
.
2025-06-15 09:21:04 INFO An exception occured: Traceback (most recent call last):
  File "/Users/macbook/Documents/Code/LLMdesignedEA-comp/llamea/llamea_api_rotations.py", line 326, in evolve_solution
    evolved_individual = chosen_llm.sample_solution(
                         ^^^^^^^^^^^^^^^^^^^^^^^^^^^
  File "/Users/macbook/Documents/Code/LLMdesignedEA-comp/llamea/llm.py", line 106, in sample_solution
    message = self.query(session_messages)
              ^^^^^^^^^^^^^^^^^^^^^^^^^^^^
  File "/Users/macbook/Documents/Code/LLMdesignedEA-comp/llamea/llm.py", line 278, in query
    response = chat_session.send_message(last["content"])
               ^^^^^^^^^^^^^^^^^^^^^^^^^^^^^^^^^^^^^^^^^^
  File "/Users/macbook/miniconda3/envs/eoh/lib/python3.12/site-packages/google/generativeai/generative_models.py", line 578, in send_message
    response = self.model.generate_content(
               ^^^^^^^^^^^^^^^^^^^^^^^^^^^^
  File "/Users/macbook/miniconda3/envs/eoh/lib/python3.12/site-packages/google/generativeai/generative_models.py", line 331, in generate_content
    response = self._client.generate_content(
               ^^^^^^^^^^^^^^^^^^^^^^^^^^^^^^
  File "/Users/macbook/miniconda3/envs/eoh/lib/python3.12/site-packages/google/ai/generativelanguage_v1beta/services/generative_service/client.py", line 835, in generate_content
    response = rpc(
               ^^^^
  File "/Users/macbook/miniconda3/envs/eoh/lib/python3.12/site-packages/google/api_core/gapic_v1/method.py", line 131, in __call__
    return wrapped_func(*args, **kwargs)
           ^^^^^^^^^^^^^^^^^^^^^^^^^^^^^
  File "/Users/macbook/miniconda3/envs/eoh/lib/python3.12/site-packages/google/api_core/retry/retry_unary.py", line 294, in retry_wrapped_func
    return retry_target(
           ^^^^^^^^^^^^^
  File "/Users/macbook/miniconda3/envs/eoh/lib/python3.12/site-packages/google/api_core/retry/retry_unary.py", line 156, in retry_target
    next_sleep = _retry_error_helper(
                 ^^^^^^^^^^^^^^^^^^^^
  File "/Users/macbook/miniconda3/envs/eoh/lib/python3.12/site-packages/google/api_core/retry/retry_base.py", line 214, in _retry_error_helper
    raise final_exc from source_exc
  File "/Users/macbook/miniconda3/envs/eoh/lib/python3.12/site-packages/google/api_core/retry/retry_unary.py", line 147, in retry_target
    result = target()
             ^^^^^^^^
  File "/Users/macbook/miniconda3/envs/eoh/lib/python3.12/site-packages/google/api_core/timeout.py", line 130, in func_with_timeout
    return func(*args, **kwargs)
           ^^^^^^^^^^^^^^^^^^^^^
  File "/Users/macbook/miniconda3/envs/eoh/lib/python3.12/site-packages/google/api_core/grpc_helpers.py", line 78, in error_remapped_callable
    raise exceptions.from_grpc_error(exc) from exc
google.api_core.exceptions.ResourceExhausted: 429 You exceeded your current quota, please check your plan and billing details. For more information on this error, head to: https://ai.google.dev/gemini-api/docs/rate-limits. [violations {
  quota_metric: "generativelanguage.googleapis.com/generate_content_free_tier_requests"
  quota_id: "GenerateRequestsPerMinutePerProjectPerModel-FreeTier"
  quota_dimensions {
    key: "model"
    value: "gemini-1.5-flash"
  }
  quota_dimensions {
    key: "location"
    value: "global"
  }
  quota_value: 15
}
, links {
  description: "Learn more about Gemini API quotas"
  url: "https://ai.google.dev/gemini-api/docs/rate-limits"
}
, retry_delay {
  seconds: 55
}
]
.
2025-06-15 09:21:16 INFO An exception occured: Traceback (most recent call last):
  File "/Users/macbook/Documents/Code/LLMdesignedEA-comp/llamea/llamea_api_rotations.py", line 326, in evolve_solution
    evolved_individual = chosen_llm.sample_solution(
                         ^^^^^^^^^^^^^^^^^^^^^^^^^^^
  File "/Users/macbook/Documents/Code/LLMdesignedEA-comp/llamea/llm.py", line 106, in sample_solution
    message = self.query(session_messages)
              ^^^^^^^^^^^^^^^^^^^^^^^^^^^^
  File "/Users/macbook/Documents/Code/LLMdesignedEA-comp/llamea/llm.py", line 278, in query
    response = chat_session.send_message(last["content"])
               ^^^^^^^^^^^^^^^^^^^^^^^^^^^^^^^^^^^^^^^^^^
  File "/Users/macbook/miniconda3/envs/eoh/lib/python3.12/site-packages/google/generativeai/generative_models.py", line 578, in send_message
    response = self.model.generate_content(
               ^^^^^^^^^^^^^^^^^^^^^^^^^^^^
  File "/Users/macbook/miniconda3/envs/eoh/lib/python3.12/site-packages/google/generativeai/generative_models.py", line 331, in generate_content
    response = self._client.generate_content(
               ^^^^^^^^^^^^^^^^^^^^^^^^^^^^^^
  File "/Users/macbook/miniconda3/envs/eoh/lib/python3.12/site-packages/google/ai/generativelanguage_v1beta/services/generative_service/client.py", line 835, in generate_content
    response = rpc(
               ^^^^
  File "/Users/macbook/miniconda3/envs/eoh/lib/python3.12/site-packages/google/api_core/gapic_v1/method.py", line 131, in __call__
    return wrapped_func(*args, **kwargs)
           ^^^^^^^^^^^^^^^^^^^^^^^^^^^^^
  File "/Users/macbook/miniconda3/envs/eoh/lib/python3.12/site-packages/google/api_core/retry/retry_unary.py", line 294, in retry_wrapped_func
    return retry_target(
           ^^^^^^^^^^^^^
  File "/Users/macbook/miniconda3/envs/eoh/lib/python3.12/site-packages/google/api_core/retry/retry_unary.py", line 156, in retry_target
    next_sleep = _retry_error_helper(
                 ^^^^^^^^^^^^^^^^^^^^
  File "/Users/macbook/miniconda3/envs/eoh/lib/python3.12/site-packages/google/api_core/retry/retry_base.py", line 214, in _retry_error_helper
    raise final_exc from source_exc
  File "/Users/macbook/miniconda3/envs/eoh/lib/python3.12/site-packages/google/api_core/retry/retry_unary.py", line 147, in retry_target
    result = target()
             ^^^^^^^^
  File "/Users/macbook/miniconda3/envs/eoh/lib/python3.12/site-packages/google/api_core/timeout.py", line 130, in func_with_timeout
    return func(*args, **kwargs)
           ^^^^^^^^^^^^^^^^^^^^^
  File "/Users/macbook/miniconda3/envs/eoh/lib/python3.12/site-packages/google/api_core/grpc_helpers.py", line 78, in error_remapped_callable
    raise exceptions.from_grpc_error(exc) from exc
google.api_core.exceptions.ResourceExhausted: 429 You exceeded your current quota, please check your plan and billing details. For more information on this error, head to: https://ai.google.dev/gemini-api/docs/rate-limits. [violations {
  quota_metric: "generativelanguage.googleapis.com/generate_content_free_tier_requests"
  quota_id: "GenerateRequestsPerMinutePerProjectPerModel-FreeTier"
  quota_dimensions {
    key: "model"
    value: "gemini-1.5-flash"
  }
  quota_dimensions {
    key: "location"
    value: "global"
  }
  quota_value: 15
}
, links {
  description: "Learn more about Gemini API quotas"
  url: "https://ai.google.dev/gemini-api/docs/rate-limits"
}
, retry_delay {
  seconds: 43
}
]
.
2025-06-15 09:21:16 INFO An exception occured: Traceback (most recent call last):
  File "/Users/macbook/Documents/Code/LLMdesignedEA-comp/llamea/llamea_api_rotations.py", line 326, in evolve_solution
    evolved_individual = chosen_llm.sample_solution(
                         ^^^^^^^^^^^^^^^^^^^^^^^^^^^
  File "/Users/macbook/Documents/Code/LLMdesignedEA-comp/llamea/llm.py", line 106, in sample_solution
    message = self.query(session_messages)
              ^^^^^^^^^^^^^^^^^^^^^^^^^^^^
  File "/Users/macbook/Documents/Code/LLMdesignedEA-comp/llamea/llm.py", line 278, in query
    response = chat_session.send_message(last["content"])
               ^^^^^^^^^^^^^^^^^^^^^^^^^^^^^^^^^^^^^^^^^^
  File "/Users/macbook/miniconda3/envs/eoh/lib/python3.12/site-packages/google/generativeai/generative_models.py", line 578, in send_message
    response = self.model.generate_content(
               ^^^^^^^^^^^^^^^^^^^^^^^^^^^^
  File "/Users/macbook/miniconda3/envs/eoh/lib/python3.12/site-packages/google/generativeai/generative_models.py", line 331, in generate_content
    response = self._client.generate_content(
               ^^^^^^^^^^^^^^^^^^^^^^^^^^^^^^
  File "/Users/macbook/miniconda3/envs/eoh/lib/python3.12/site-packages/google/ai/generativelanguage_v1beta/services/generative_service/client.py", line 835, in generate_content
    response = rpc(
               ^^^^
  File "/Users/macbook/miniconda3/envs/eoh/lib/python3.12/site-packages/google/api_core/gapic_v1/method.py", line 131, in __call__
    return wrapped_func(*args, **kwargs)
           ^^^^^^^^^^^^^^^^^^^^^^^^^^^^^
  File "/Users/macbook/miniconda3/envs/eoh/lib/python3.12/site-packages/google/api_core/retry/retry_unary.py", line 294, in retry_wrapped_func
    return retry_target(
           ^^^^^^^^^^^^^
  File "/Users/macbook/miniconda3/envs/eoh/lib/python3.12/site-packages/google/api_core/retry/retry_unary.py", line 156, in retry_target
    next_sleep = _retry_error_helper(
                 ^^^^^^^^^^^^^^^^^^^^
  File "/Users/macbook/miniconda3/envs/eoh/lib/python3.12/site-packages/google/api_core/retry/retry_base.py", line 214, in _retry_error_helper
    raise final_exc from source_exc
  File "/Users/macbook/miniconda3/envs/eoh/lib/python3.12/site-packages/google/api_core/retry/retry_unary.py", line 147, in retry_target
    result = target()
             ^^^^^^^^
  File "/Users/macbook/miniconda3/envs/eoh/lib/python3.12/site-packages/google/api_core/timeout.py", line 130, in func_with_timeout
    return func(*args, **kwargs)
           ^^^^^^^^^^^^^^^^^^^^^
  File "/Users/macbook/miniconda3/envs/eoh/lib/python3.12/site-packages/google/api_core/grpc_helpers.py", line 78, in error_remapped_callable
    raise exceptions.from_grpc_error(exc) from exc
google.api_core.exceptions.ResourceExhausted: 429 You exceeded your current quota, please check your plan and billing details. For more information on this error, head to: https://ai.google.dev/gemini-api/docs/rate-limits. [violations {
  quota_metric: "generativelanguage.googleapis.com/generate_content_free_tier_requests"
  quota_id: "GenerateRequestsPerMinutePerProjectPerModel-FreeTier"
  quota_dimensions {
    key: "model"
    value: "gemini-1.5-flash"
  }
  quota_dimensions {
    key: "location"
    value: "global"
  }
  quota_value: 15
}
, links {
  description: "Learn more about Gemini API quotas"
  url: "https://ai.google.dev/gemini-api/docs/rate-limits"
}
, retry_delay {
  seconds: 43
}
]
.
2025-06-15 09:21:16 INFO An exception occured: Traceback (most recent call last):
  File "/Users/macbook/Documents/Code/LLMdesignedEA-comp/llamea/llamea_api_rotations.py", line 326, in evolve_solution
    evolved_individual = chosen_llm.sample_solution(
                         ^^^^^^^^^^^^^^^^^^^^^^^^^^^
  File "/Users/macbook/Documents/Code/LLMdesignedEA-comp/llamea/llm.py", line 106, in sample_solution
    message = self.query(session_messages)
              ^^^^^^^^^^^^^^^^^^^^^^^^^^^^
  File "/Users/macbook/Documents/Code/LLMdesignedEA-comp/llamea/llm.py", line 278, in query
    response = chat_session.send_message(last["content"])
               ^^^^^^^^^^^^^^^^^^^^^^^^^^^^^^^^^^^^^^^^^^
  File "/Users/macbook/miniconda3/envs/eoh/lib/python3.12/site-packages/google/generativeai/generative_models.py", line 578, in send_message
    response = self.model.generate_content(
               ^^^^^^^^^^^^^^^^^^^^^^^^^^^^
  File "/Users/macbook/miniconda3/envs/eoh/lib/python3.12/site-packages/google/generativeai/generative_models.py", line 331, in generate_content
    response = self._client.generate_content(
               ^^^^^^^^^^^^^^^^^^^^^^^^^^^^^^
  File "/Users/macbook/miniconda3/envs/eoh/lib/python3.12/site-packages/google/ai/generativelanguage_v1beta/services/generative_service/client.py", line 835, in generate_content
    response = rpc(
               ^^^^
  File "/Users/macbook/miniconda3/envs/eoh/lib/python3.12/site-packages/google/api_core/gapic_v1/method.py", line 131, in __call__
    return wrapped_func(*args, **kwargs)
           ^^^^^^^^^^^^^^^^^^^^^^^^^^^^^
  File "/Users/macbook/miniconda3/envs/eoh/lib/python3.12/site-packages/google/api_core/retry/retry_unary.py", line 294, in retry_wrapped_func
    return retry_target(
           ^^^^^^^^^^^^^
  File "/Users/macbook/miniconda3/envs/eoh/lib/python3.12/site-packages/google/api_core/retry/retry_unary.py", line 156, in retry_target
    next_sleep = _retry_error_helper(
                 ^^^^^^^^^^^^^^^^^^^^
  File "/Users/macbook/miniconda3/envs/eoh/lib/python3.12/site-packages/google/api_core/retry/retry_base.py", line 214, in _retry_error_helper
    raise final_exc from source_exc
  File "/Users/macbook/miniconda3/envs/eoh/lib/python3.12/site-packages/google/api_core/retry/retry_unary.py", line 147, in retry_target
    result = target()
             ^^^^^^^^
  File "/Users/macbook/miniconda3/envs/eoh/lib/python3.12/site-packages/google/api_core/timeout.py", line 130, in func_with_timeout
    return func(*args, **kwargs)
           ^^^^^^^^^^^^^^^^^^^^^
  File "/Users/macbook/miniconda3/envs/eoh/lib/python3.12/site-packages/google/api_core/grpc_helpers.py", line 78, in error_remapped_callable
    raise exceptions.from_grpc_error(exc) from exc
google.api_core.exceptions.ResourceExhausted: 429 You exceeded your current quota, please check your plan and billing details. For more information on this error, head to: https://ai.google.dev/gemini-api/docs/rate-limits. [violations {
  quota_metric: "generativelanguage.googleapis.com/generate_content_free_tier_requests"
  quota_id: "GenerateRequestsPerMinutePerProjectPerModel-FreeTier"
  quota_dimensions {
    key: "model"
    value: "gemini-1.5-flash"
  }
  quota_dimensions {
    key: "location"
    value: "global"
  }
  quota_value: 15
}
, links {
  description: "Learn more about Gemini API quotas"
  url: "https://ai.google.dev/gemini-api/docs/rate-limits"
}
, retry_delay {
  seconds: 43
}
]
.
2025-06-15 09:21:16 INFO An exception occured: Traceback (most recent call last):
  File "/Users/macbook/Documents/Code/LLMdesignedEA-comp/llamea/llamea_api_rotations.py", line 326, in evolve_solution
    evolved_individual = chosen_llm.sample_solution(
                         ^^^^^^^^^^^^^^^^^^^^^^^^^^^
  File "/Users/macbook/Documents/Code/LLMdesignedEA-comp/llamea/llm.py", line 106, in sample_solution
    message = self.query(session_messages)
              ^^^^^^^^^^^^^^^^^^^^^^^^^^^^
  File "/Users/macbook/Documents/Code/LLMdesignedEA-comp/llamea/llm.py", line 278, in query
    response = chat_session.send_message(last["content"])
               ^^^^^^^^^^^^^^^^^^^^^^^^^^^^^^^^^^^^^^^^^^
  File "/Users/macbook/miniconda3/envs/eoh/lib/python3.12/site-packages/google/generativeai/generative_models.py", line 578, in send_message
    response = self.model.generate_content(
               ^^^^^^^^^^^^^^^^^^^^^^^^^^^^
  File "/Users/macbook/miniconda3/envs/eoh/lib/python3.12/site-packages/google/generativeai/generative_models.py", line 331, in generate_content
    response = self._client.generate_content(
               ^^^^^^^^^^^^^^^^^^^^^^^^^^^^^^
  File "/Users/macbook/miniconda3/envs/eoh/lib/python3.12/site-packages/google/ai/generativelanguage_v1beta/services/generative_service/client.py", line 835, in generate_content
    response = rpc(
               ^^^^
  File "/Users/macbook/miniconda3/envs/eoh/lib/python3.12/site-packages/google/api_core/gapic_v1/method.py", line 131, in __call__
    return wrapped_func(*args, **kwargs)
           ^^^^^^^^^^^^^^^^^^^^^^^^^^^^^
  File "/Users/macbook/miniconda3/envs/eoh/lib/python3.12/site-packages/google/api_core/retry/retry_unary.py", line 294, in retry_wrapped_func
    return retry_target(
           ^^^^^^^^^^^^^
  File "/Users/macbook/miniconda3/envs/eoh/lib/python3.12/site-packages/google/api_core/retry/retry_unary.py", line 156, in retry_target
    next_sleep = _retry_error_helper(
                 ^^^^^^^^^^^^^^^^^^^^
  File "/Users/macbook/miniconda3/envs/eoh/lib/python3.12/site-packages/google/api_core/retry/retry_base.py", line 214, in _retry_error_helper
    raise final_exc from source_exc
  File "/Users/macbook/miniconda3/envs/eoh/lib/python3.12/site-packages/google/api_core/retry/retry_unary.py", line 147, in retry_target
    result = target()
             ^^^^^^^^
  File "/Users/macbook/miniconda3/envs/eoh/lib/python3.12/site-packages/google/api_core/timeout.py", line 130, in func_with_timeout
    return func(*args, **kwargs)
           ^^^^^^^^^^^^^^^^^^^^^
  File "/Users/macbook/miniconda3/envs/eoh/lib/python3.12/site-packages/google/api_core/grpc_helpers.py", line 78, in error_remapped_callable
    raise exceptions.from_grpc_error(exc) from exc
google.api_core.exceptions.ResourceExhausted: 429 You exceeded your current quota, please check your plan and billing details. For more information on this error, head to: https://ai.google.dev/gemini-api/docs/rate-limits. [violations {
  quota_metric: "generativelanguage.googleapis.com/generate_content_free_tier_requests"
  quota_id: "GenerateRequestsPerMinutePerProjectPerModel-FreeTier"
  quota_dimensions {
    key: "model"
    value: "gemini-1.5-flash"
  }
  quota_dimensions {
    key: "location"
    value: "global"
  }
  quota_value: 15
}
, links {
  description: "Learn more about Gemini API quotas"
  url: "https://ai.google.dev/gemini-api/docs/rate-limits"
}
, retry_delay {
  seconds: 43
}
]
.
2025-06-15 09:21:16 INFO An exception occured: Traceback (most recent call last):
  File "/Users/macbook/Documents/Code/LLMdesignedEA-comp/llamea/llamea_api_rotations.py", line 326, in evolve_solution
    evolved_individual = chosen_llm.sample_solution(
                         ^^^^^^^^^^^^^^^^^^^^^^^^^^^
  File "/Users/macbook/Documents/Code/LLMdesignedEA-comp/llamea/llm.py", line 106, in sample_solution
    message = self.query(session_messages)
              ^^^^^^^^^^^^^^^^^^^^^^^^^^^^
  File "/Users/macbook/Documents/Code/LLMdesignedEA-comp/llamea/llm.py", line 278, in query
    response = chat_session.send_message(last["content"])
               ^^^^^^^^^^^^^^^^^^^^^^^^^^^^^^^^^^^^^^^^^^
  File "/Users/macbook/miniconda3/envs/eoh/lib/python3.12/site-packages/google/generativeai/generative_models.py", line 578, in send_message
    response = self.model.generate_content(
               ^^^^^^^^^^^^^^^^^^^^^^^^^^^^
  File "/Users/macbook/miniconda3/envs/eoh/lib/python3.12/site-packages/google/generativeai/generative_models.py", line 331, in generate_content
    response = self._client.generate_content(
               ^^^^^^^^^^^^^^^^^^^^^^^^^^^^^^
  File "/Users/macbook/miniconda3/envs/eoh/lib/python3.12/site-packages/google/ai/generativelanguage_v1beta/services/generative_service/client.py", line 835, in generate_content
    response = rpc(
               ^^^^
  File "/Users/macbook/miniconda3/envs/eoh/lib/python3.12/site-packages/google/api_core/gapic_v1/method.py", line 131, in __call__
    return wrapped_func(*args, **kwargs)
           ^^^^^^^^^^^^^^^^^^^^^^^^^^^^^
  File "/Users/macbook/miniconda3/envs/eoh/lib/python3.12/site-packages/google/api_core/retry/retry_unary.py", line 294, in retry_wrapped_func
    return retry_target(
           ^^^^^^^^^^^^^
  File "/Users/macbook/miniconda3/envs/eoh/lib/python3.12/site-packages/google/api_core/retry/retry_unary.py", line 156, in retry_target
    next_sleep = _retry_error_helper(
                 ^^^^^^^^^^^^^^^^^^^^
  File "/Users/macbook/miniconda3/envs/eoh/lib/python3.12/site-packages/google/api_core/retry/retry_base.py", line 214, in _retry_error_helper
    raise final_exc from source_exc
  File "/Users/macbook/miniconda3/envs/eoh/lib/python3.12/site-packages/google/api_core/retry/retry_unary.py", line 147, in retry_target
    result = target()
             ^^^^^^^^
  File "/Users/macbook/miniconda3/envs/eoh/lib/python3.12/site-packages/google/api_core/timeout.py", line 130, in func_with_timeout
    return func(*args, **kwargs)
           ^^^^^^^^^^^^^^^^^^^^^
  File "/Users/macbook/miniconda3/envs/eoh/lib/python3.12/site-packages/google/api_core/grpc_helpers.py", line 78, in error_remapped_callable
    raise exceptions.from_grpc_error(exc) from exc
google.api_core.exceptions.ResourceExhausted: 429 You exceeded your current quota, please check your plan and billing details. For more information on this error, head to: https://ai.google.dev/gemini-api/docs/rate-limits. [violations {
  quota_metric: "generativelanguage.googleapis.com/generate_content_free_tier_requests"
  quota_id: "GenerateRequestsPerMinutePerProjectPerModel-FreeTier"
  quota_dimensions {
    key: "model"
    value: "gemini-1.5-flash"
  }
  quota_dimensions {
    key: "location"
    value: "global"
  }
  quota_value: 15
}
, links {
  description: "Learn more about Gemini API quotas"
  url: "https://ai.google.dev/gemini-api/docs/rate-limits"
}
, retry_delay {
  seconds: 43
}
]
.
2025-06-15 09:21:16 INFO An exception occured: Traceback (most recent call last):
  File "/Users/macbook/Documents/Code/LLMdesignedEA-comp/llamea/llamea_api_rotations.py", line 326, in evolve_solution
    evolved_individual = chosen_llm.sample_solution(
                         ^^^^^^^^^^^^^^^^^^^^^^^^^^^
  File "/Users/macbook/Documents/Code/LLMdesignedEA-comp/llamea/llm.py", line 106, in sample_solution
    message = self.query(session_messages)
              ^^^^^^^^^^^^^^^^^^^^^^^^^^^^
  File "/Users/macbook/Documents/Code/LLMdesignedEA-comp/llamea/llm.py", line 278, in query
    response = chat_session.send_message(last["content"])
               ^^^^^^^^^^^^^^^^^^^^^^^^^^^^^^^^^^^^^^^^^^
  File "/Users/macbook/miniconda3/envs/eoh/lib/python3.12/site-packages/google/generativeai/generative_models.py", line 578, in send_message
    response = self.model.generate_content(
               ^^^^^^^^^^^^^^^^^^^^^^^^^^^^
  File "/Users/macbook/miniconda3/envs/eoh/lib/python3.12/site-packages/google/generativeai/generative_models.py", line 331, in generate_content
    response = self._client.generate_content(
               ^^^^^^^^^^^^^^^^^^^^^^^^^^^^^^
  File "/Users/macbook/miniconda3/envs/eoh/lib/python3.12/site-packages/google/ai/generativelanguage_v1beta/services/generative_service/client.py", line 835, in generate_content
    response = rpc(
               ^^^^
  File "/Users/macbook/miniconda3/envs/eoh/lib/python3.12/site-packages/google/api_core/gapic_v1/method.py", line 131, in __call__
    return wrapped_func(*args, **kwargs)
           ^^^^^^^^^^^^^^^^^^^^^^^^^^^^^
  File "/Users/macbook/miniconda3/envs/eoh/lib/python3.12/site-packages/google/api_core/retry/retry_unary.py", line 294, in retry_wrapped_func
    return retry_target(
           ^^^^^^^^^^^^^
  File "/Users/macbook/miniconda3/envs/eoh/lib/python3.12/site-packages/google/api_core/retry/retry_unary.py", line 156, in retry_target
    next_sleep = _retry_error_helper(
                 ^^^^^^^^^^^^^^^^^^^^
  File "/Users/macbook/miniconda3/envs/eoh/lib/python3.12/site-packages/google/api_core/retry/retry_base.py", line 214, in _retry_error_helper
    raise final_exc from source_exc
  File "/Users/macbook/miniconda3/envs/eoh/lib/python3.12/site-packages/google/api_core/retry/retry_unary.py", line 147, in retry_target
    result = target()
             ^^^^^^^^
  File "/Users/macbook/miniconda3/envs/eoh/lib/python3.12/site-packages/google/api_core/timeout.py", line 130, in func_with_timeout
    return func(*args, **kwargs)
           ^^^^^^^^^^^^^^^^^^^^^
  File "/Users/macbook/miniconda3/envs/eoh/lib/python3.12/site-packages/google/api_core/grpc_helpers.py", line 78, in error_remapped_callable
    raise exceptions.from_grpc_error(exc) from exc
google.api_core.exceptions.ResourceExhausted: 429 You exceeded your current quota, please check your plan and billing details. For more information on this error, head to: https://ai.google.dev/gemini-api/docs/rate-limits. [violations {
  quota_metric: "generativelanguage.googleapis.com/generate_content_free_tier_requests"
  quota_id: "GenerateRequestsPerMinutePerProjectPerModel-FreeTier"
  quota_dimensions {
    key: "model"
    value: "gemini-1.5-flash"
  }
  quota_dimensions {
    key: "location"
    value: "global"
  }
  quota_value: 15
}
, links {
  description: "Learn more about Gemini API quotas"
  url: "https://ai.google.dev/gemini-api/docs/rate-limits"
}
, retry_delay {
  seconds: 43
}
]
.
2025-06-15 09:21:16 INFO An exception occured: Traceback (most recent call last):
  File "/Users/macbook/Documents/Code/LLMdesignedEA-comp/llamea/llamea_api_rotations.py", line 326, in evolve_solution
    evolved_individual = chosen_llm.sample_solution(
                         ^^^^^^^^^^^^^^^^^^^^^^^^^^^
  File "/Users/macbook/Documents/Code/LLMdesignedEA-comp/llamea/llm.py", line 106, in sample_solution
    message = self.query(session_messages)
              ^^^^^^^^^^^^^^^^^^^^^^^^^^^^
  File "/Users/macbook/Documents/Code/LLMdesignedEA-comp/llamea/llm.py", line 278, in query
    response = chat_session.send_message(last["content"])
               ^^^^^^^^^^^^^^^^^^^^^^^^^^^^^^^^^^^^^^^^^^
  File "/Users/macbook/miniconda3/envs/eoh/lib/python3.12/site-packages/google/generativeai/generative_models.py", line 578, in send_message
    response = self.model.generate_content(
               ^^^^^^^^^^^^^^^^^^^^^^^^^^^^
  File "/Users/macbook/miniconda3/envs/eoh/lib/python3.12/site-packages/google/generativeai/generative_models.py", line 331, in generate_content
    response = self._client.generate_content(
               ^^^^^^^^^^^^^^^^^^^^^^^^^^^^^^
  File "/Users/macbook/miniconda3/envs/eoh/lib/python3.12/site-packages/google/ai/generativelanguage_v1beta/services/generative_service/client.py", line 835, in generate_content
    response = rpc(
               ^^^^
  File "/Users/macbook/miniconda3/envs/eoh/lib/python3.12/site-packages/google/api_core/gapic_v1/method.py", line 131, in __call__
    return wrapped_func(*args, **kwargs)
           ^^^^^^^^^^^^^^^^^^^^^^^^^^^^^
  File "/Users/macbook/miniconda3/envs/eoh/lib/python3.12/site-packages/google/api_core/retry/retry_unary.py", line 294, in retry_wrapped_func
    return retry_target(
           ^^^^^^^^^^^^^
  File "/Users/macbook/miniconda3/envs/eoh/lib/python3.12/site-packages/google/api_core/retry/retry_unary.py", line 156, in retry_target
    next_sleep = _retry_error_helper(
                 ^^^^^^^^^^^^^^^^^^^^
  File "/Users/macbook/miniconda3/envs/eoh/lib/python3.12/site-packages/google/api_core/retry/retry_base.py", line 214, in _retry_error_helper
    raise final_exc from source_exc
  File "/Users/macbook/miniconda3/envs/eoh/lib/python3.12/site-packages/google/api_core/retry/retry_unary.py", line 147, in retry_target
    result = target()
             ^^^^^^^^
  File "/Users/macbook/miniconda3/envs/eoh/lib/python3.12/site-packages/google/api_core/timeout.py", line 130, in func_with_timeout
    return func(*args, **kwargs)
           ^^^^^^^^^^^^^^^^^^^^^
  File "/Users/macbook/miniconda3/envs/eoh/lib/python3.12/site-packages/google/api_core/grpc_helpers.py", line 78, in error_remapped_callable
    raise exceptions.from_grpc_error(exc) from exc
google.api_core.exceptions.ResourceExhausted: 429 You exceeded your current quota, please check your plan and billing details. For more information on this error, head to: https://ai.google.dev/gemini-api/docs/rate-limits. [violations {
  quota_metric: "generativelanguage.googleapis.com/generate_content_free_tier_requests"
  quota_id: "GenerateRequestsPerMinutePerProjectPerModel-FreeTier"
  quota_dimensions {
    key: "model"
    value: "gemini-1.5-flash"
  }
  quota_dimensions {
    key: "location"
    value: "global"
  }
  quota_value: 15
}
, links {
  description: "Learn more about Gemini API quotas"
  url: "https://ai.google.dev/gemini-api/docs/rate-limits"
}
, retry_delay {
  seconds: 43
}
]
.
2025-06-15 09:21:16 INFO An exception occured: Traceback (most recent call last):
  File "/Users/macbook/Documents/Code/LLMdesignedEA-comp/llamea/llamea_api_rotations.py", line 326, in evolve_solution
    evolved_individual = chosen_llm.sample_solution(
                         ^^^^^^^^^^^^^^^^^^^^^^^^^^^
  File "/Users/macbook/Documents/Code/LLMdesignedEA-comp/llamea/llm.py", line 106, in sample_solution
    message = self.query(session_messages)
              ^^^^^^^^^^^^^^^^^^^^^^^^^^^^
  File "/Users/macbook/Documents/Code/LLMdesignedEA-comp/llamea/llm.py", line 278, in query
    response = chat_session.send_message(last["content"])
               ^^^^^^^^^^^^^^^^^^^^^^^^^^^^^^^^^^^^^^^^^^
  File "/Users/macbook/miniconda3/envs/eoh/lib/python3.12/site-packages/google/generativeai/generative_models.py", line 578, in send_message
    response = self.model.generate_content(
               ^^^^^^^^^^^^^^^^^^^^^^^^^^^^
  File "/Users/macbook/miniconda3/envs/eoh/lib/python3.12/site-packages/google/generativeai/generative_models.py", line 331, in generate_content
    response = self._client.generate_content(
               ^^^^^^^^^^^^^^^^^^^^^^^^^^^^^^
  File "/Users/macbook/miniconda3/envs/eoh/lib/python3.12/site-packages/google/ai/generativelanguage_v1beta/services/generative_service/client.py", line 835, in generate_content
    response = rpc(
               ^^^^
  File "/Users/macbook/miniconda3/envs/eoh/lib/python3.12/site-packages/google/api_core/gapic_v1/method.py", line 131, in __call__
    return wrapped_func(*args, **kwargs)
           ^^^^^^^^^^^^^^^^^^^^^^^^^^^^^
  File "/Users/macbook/miniconda3/envs/eoh/lib/python3.12/site-packages/google/api_core/retry/retry_unary.py", line 294, in retry_wrapped_func
    return retry_target(
           ^^^^^^^^^^^^^
  File "/Users/macbook/miniconda3/envs/eoh/lib/python3.12/site-packages/google/api_core/retry/retry_unary.py", line 156, in retry_target
    next_sleep = _retry_error_helper(
                 ^^^^^^^^^^^^^^^^^^^^
  File "/Users/macbook/miniconda3/envs/eoh/lib/python3.12/site-packages/google/api_core/retry/retry_base.py", line 214, in _retry_error_helper
    raise final_exc from source_exc
  File "/Users/macbook/miniconda3/envs/eoh/lib/python3.12/site-packages/google/api_core/retry/retry_unary.py", line 147, in retry_target
    result = target()
             ^^^^^^^^
  File "/Users/macbook/miniconda3/envs/eoh/lib/python3.12/site-packages/google/api_core/timeout.py", line 130, in func_with_timeout
    return func(*args, **kwargs)
           ^^^^^^^^^^^^^^^^^^^^^
  File "/Users/macbook/miniconda3/envs/eoh/lib/python3.12/site-packages/google/api_core/grpc_helpers.py", line 78, in error_remapped_callable
    raise exceptions.from_grpc_error(exc) from exc
google.api_core.exceptions.ResourceExhausted: 429 You exceeded your current quota, please check your plan and billing details. For more information on this error, head to: https://ai.google.dev/gemini-api/docs/rate-limits. [violations {
  quota_metric: "generativelanguage.googleapis.com/generate_content_free_tier_requests"
  quota_id: "GenerateRequestsPerMinutePerProjectPerModel-FreeTier"
  quota_dimensions {
    key: "model"
    value: "gemini-1.5-flash"
  }
  quota_dimensions {
    key: "location"
    value: "global"
  }
  quota_value: 15
}
, links {
  description: "Learn more about Gemini API quotas"
  url: "https://ai.google.dev/gemini-api/docs/rate-limits"
}
, retry_delay {
  seconds: 43
}
]
.
2025-06-15 09:21:16 INFO An exception occured: Traceback (most recent call last):
  File "/Users/macbook/Documents/Code/LLMdesignedEA-comp/llamea/llamea_api_rotations.py", line 326, in evolve_solution
    evolved_individual = chosen_llm.sample_solution(
                         ^^^^^^^^^^^^^^^^^^^^^^^^^^^
  File "/Users/macbook/Documents/Code/LLMdesignedEA-comp/llamea/llm.py", line 106, in sample_solution
    message = self.query(session_messages)
              ^^^^^^^^^^^^^^^^^^^^^^^^^^^^
  File "/Users/macbook/Documents/Code/LLMdesignedEA-comp/llamea/llm.py", line 278, in query
    response = chat_session.send_message(last["content"])
               ^^^^^^^^^^^^^^^^^^^^^^^^^^^^^^^^^^^^^^^^^^
  File "/Users/macbook/miniconda3/envs/eoh/lib/python3.12/site-packages/google/generativeai/generative_models.py", line 578, in send_message
    response = self.model.generate_content(
               ^^^^^^^^^^^^^^^^^^^^^^^^^^^^
  File "/Users/macbook/miniconda3/envs/eoh/lib/python3.12/site-packages/google/generativeai/generative_models.py", line 331, in generate_content
    response = self._client.generate_content(
               ^^^^^^^^^^^^^^^^^^^^^^^^^^^^^^
  File "/Users/macbook/miniconda3/envs/eoh/lib/python3.12/site-packages/google/ai/generativelanguage_v1beta/services/generative_service/client.py", line 835, in generate_content
    response = rpc(
               ^^^^
  File "/Users/macbook/miniconda3/envs/eoh/lib/python3.12/site-packages/google/api_core/gapic_v1/method.py", line 131, in __call__
    return wrapped_func(*args, **kwargs)
           ^^^^^^^^^^^^^^^^^^^^^^^^^^^^^
  File "/Users/macbook/miniconda3/envs/eoh/lib/python3.12/site-packages/google/api_core/retry/retry_unary.py", line 294, in retry_wrapped_func
    return retry_target(
           ^^^^^^^^^^^^^
  File "/Users/macbook/miniconda3/envs/eoh/lib/python3.12/site-packages/google/api_core/retry/retry_unary.py", line 156, in retry_target
    next_sleep = _retry_error_helper(
                 ^^^^^^^^^^^^^^^^^^^^
  File "/Users/macbook/miniconda3/envs/eoh/lib/python3.12/site-packages/google/api_core/retry/retry_base.py", line 214, in _retry_error_helper
    raise final_exc from source_exc
  File "/Users/macbook/miniconda3/envs/eoh/lib/python3.12/site-packages/google/api_core/retry/retry_unary.py", line 147, in retry_target
    result = target()
             ^^^^^^^^
  File "/Users/macbook/miniconda3/envs/eoh/lib/python3.12/site-packages/google/api_core/timeout.py", line 130, in func_with_timeout
    return func(*args, **kwargs)
           ^^^^^^^^^^^^^^^^^^^^^
  File "/Users/macbook/miniconda3/envs/eoh/lib/python3.12/site-packages/google/api_core/grpc_helpers.py", line 78, in error_remapped_callable
    raise exceptions.from_grpc_error(exc) from exc
google.api_core.exceptions.ResourceExhausted: 429 You exceeded your current quota, please check your plan and billing details. For more information on this error, head to: https://ai.google.dev/gemini-api/docs/rate-limits. [violations {
  quota_metric: "generativelanguage.googleapis.com/generate_content_free_tier_requests"
  quota_id: "GenerateRequestsPerMinutePerProjectPerModel-FreeTier"
  quota_dimensions {
    key: "model"
    value: "gemini-1.5-flash"
  }
  quota_dimensions {
    key: "location"
    value: "global"
  }
  quota_value: 15
}
, links {
  description: "Learn more about Gemini API quotas"
  url: "https://ai.google.dev/gemini-api/docs/rate-limits"
}
, retry_delay {
  seconds: 43
}
]
.
2025-06-15 09:21:16 INFO An exception occured: Traceback (most recent call last):
  File "/Users/macbook/Documents/Code/LLMdesignedEA-comp/llamea/llamea_api_rotations.py", line 326, in evolve_solution
    evolved_individual = chosen_llm.sample_solution(
                         ^^^^^^^^^^^^^^^^^^^^^^^^^^^
  File "/Users/macbook/Documents/Code/LLMdesignedEA-comp/llamea/llm.py", line 106, in sample_solution
    message = self.query(session_messages)
              ^^^^^^^^^^^^^^^^^^^^^^^^^^^^
  File "/Users/macbook/Documents/Code/LLMdesignedEA-comp/llamea/llm.py", line 278, in query
    response = chat_session.send_message(last["content"])
               ^^^^^^^^^^^^^^^^^^^^^^^^^^^^^^^^^^^^^^^^^^
  File "/Users/macbook/miniconda3/envs/eoh/lib/python3.12/site-packages/google/generativeai/generative_models.py", line 578, in send_message
    response = self.model.generate_content(
               ^^^^^^^^^^^^^^^^^^^^^^^^^^^^
  File "/Users/macbook/miniconda3/envs/eoh/lib/python3.12/site-packages/google/generativeai/generative_models.py", line 331, in generate_content
    response = self._client.generate_content(
               ^^^^^^^^^^^^^^^^^^^^^^^^^^^^^^
  File "/Users/macbook/miniconda3/envs/eoh/lib/python3.12/site-packages/google/ai/generativelanguage_v1beta/services/generative_service/client.py", line 835, in generate_content
    response = rpc(
               ^^^^
  File "/Users/macbook/miniconda3/envs/eoh/lib/python3.12/site-packages/google/api_core/gapic_v1/method.py", line 131, in __call__
    return wrapped_func(*args, **kwargs)
           ^^^^^^^^^^^^^^^^^^^^^^^^^^^^^
  File "/Users/macbook/miniconda3/envs/eoh/lib/python3.12/site-packages/google/api_core/retry/retry_unary.py", line 294, in retry_wrapped_func
    return retry_target(
           ^^^^^^^^^^^^^
  File "/Users/macbook/miniconda3/envs/eoh/lib/python3.12/site-packages/google/api_core/retry/retry_unary.py", line 156, in retry_target
    next_sleep = _retry_error_helper(
                 ^^^^^^^^^^^^^^^^^^^^
  File "/Users/macbook/miniconda3/envs/eoh/lib/python3.12/site-packages/google/api_core/retry/retry_base.py", line 214, in _retry_error_helper
    raise final_exc from source_exc
  File "/Users/macbook/miniconda3/envs/eoh/lib/python3.12/site-packages/google/api_core/retry/retry_unary.py", line 147, in retry_target
    result = target()
             ^^^^^^^^
  File "/Users/macbook/miniconda3/envs/eoh/lib/python3.12/site-packages/google/api_core/timeout.py", line 130, in func_with_timeout
    return func(*args, **kwargs)
           ^^^^^^^^^^^^^^^^^^^^^
  File "/Users/macbook/miniconda3/envs/eoh/lib/python3.12/site-packages/google/api_core/grpc_helpers.py", line 78, in error_remapped_callable
    raise exceptions.from_grpc_error(exc) from exc
google.api_core.exceptions.ResourceExhausted: 429 You exceeded your current quota, please check your plan and billing details. For more information on this error, head to: https://ai.google.dev/gemini-api/docs/rate-limits. [violations {
  quota_metric: "generativelanguage.googleapis.com/generate_content_free_tier_requests"
  quota_id: "GenerateRequestsPerMinutePerProjectPerModel-FreeTier"
  quota_dimensions {
    key: "model"
    value: "gemini-1.5-flash"
  }
  quota_dimensions {
    key: "location"
    value: "global"
  }
  quota_value: 15
}
, links {
  description: "Learn more about Gemini API quotas"
  url: "https://ai.google.dev/gemini-api/docs/rate-limits"
}
, retry_delay {
  seconds: 43
}
]
.
2025-06-15 09:21:17 INFO An exception occured: Traceback (most recent call last):
  File "/Users/macbook/Documents/Code/LLMdesignedEA-comp/llamea/llamea_api_rotations.py", line 326, in evolve_solution
    evolved_individual = chosen_llm.sample_solution(
                         ^^^^^^^^^^^^^^^^^^^^^^^^^^^
  File "/Users/macbook/Documents/Code/LLMdesignedEA-comp/llamea/llm.py", line 106, in sample_solution
    message = self.query(session_messages)
              ^^^^^^^^^^^^^^^^^^^^^^^^^^^^
  File "/Users/macbook/Documents/Code/LLMdesignedEA-comp/llamea/llm.py", line 278, in query
    response = chat_session.send_message(last["content"])
               ^^^^^^^^^^^^^^^^^^^^^^^^^^^^^^^^^^^^^^^^^^
  File "/Users/macbook/miniconda3/envs/eoh/lib/python3.12/site-packages/google/generativeai/generative_models.py", line 578, in send_message
    response = self.model.generate_content(
               ^^^^^^^^^^^^^^^^^^^^^^^^^^^^
  File "/Users/macbook/miniconda3/envs/eoh/lib/python3.12/site-packages/google/generativeai/generative_models.py", line 331, in generate_content
    response = self._client.generate_content(
               ^^^^^^^^^^^^^^^^^^^^^^^^^^^^^^
  File "/Users/macbook/miniconda3/envs/eoh/lib/python3.12/site-packages/google/ai/generativelanguage_v1beta/services/generative_service/client.py", line 835, in generate_content
    response = rpc(
               ^^^^
  File "/Users/macbook/miniconda3/envs/eoh/lib/python3.12/site-packages/google/api_core/gapic_v1/method.py", line 131, in __call__
    return wrapped_func(*args, **kwargs)
           ^^^^^^^^^^^^^^^^^^^^^^^^^^^^^
  File "/Users/macbook/miniconda3/envs/eoh/lib/python3.12/site-packages/google/api_core/retry/retry_unary.py", line 294, in retry_wrapped_func
    return retry_target(
           ^^^^^^^^^^^^^
  File "/Users/macbook/miniconda3/envs/eoh/lib/python3.12/site-packages/google/api_core/retry/retry_unary.py", line 156, in retry_target
    next_sleep = _retry_error_helper(
                 ^^^^^^^^^^^^^^^^^^^^
  File "/Users/macbook/miniconda3/envs/eoh/lib/python3.12/site-packages/google/api_core/retry/retry_base.py", line 214, in _retry_error_helper
    raise final_exc from source_exc
  File "/Users/macbook/miniconda3/envs/eoh/lib/python3.12/site-packages/google/api_core/retry/retry_unary.py", line 147, in retry_target
    result = target()
             ^^^^^^^^
  File "/Users/macbook/miniconda3/envs/eoh/lib/python3.12/site-packages/google/api_core/timeout.py", line 130, in func_with_timeout
    return func(*args, **kwargs)
           ^^^^^^^^^^^^^^^^^^^^^
  File "/Users/macbook/miniconda3/envs/eoh/lib/python3.12/site-packages/google/api_core/grpc_helpers.py", line 78, in error_remapped_callable
    raise exceptions.from_grpc_error(exc) from exc
google.api_core.exceptions.ResourceExhausted: 429 You exceeded your current quota, please check your plan and billing details. For more information on this error, head to: https://ai.google.dev/gemini-api/docs/rate-limits. [violations {
  quota_metric: "generativelanguage.googleapis.com/generate_content_free_tier_requests"
  quota_id: "GenerateRequestsPerMinutePerProjectPerModel-FreeTier"
  quota_dimensions {
    key: "model"
    value: "gemini-1.5-flash"
  }
  quota_dimensions {
    key: "location"
    value: "global"
  }
  quota_value: 15
}
, links {
  description: "Learn more about Gemini API quotas"
  url: "https://ai.google.dev/gemini-api/docs/rate-limits"
}
, retry_delay {
  seconds: 42
}
]
.
2025-06-15 09:21:17 INFO An exception occured: Traceback (most recent call last):
  File "/Users/macbook/Documents/Code/LLMdesignedEA-comp/llamea/llamea_api_rotations.py", line 326, in evolve_solution
    evolved_individual = chosen_llm.sample_solution(
                         ^^^^^^^^^^^^^^^^^^^^^^^^^^^
  File "/Users/macbook/Documents/Code/LLMdesignedEA-comp/llamea/llm.py", line 106, in sample_solution
    message = self.query(session_messages)
              ^^^^^^^^^^^^^^^^^^^^^^^^^^^^
  File "/Users/macbook/Documents/Code/LLMdesignedEA-comp/llamea/llm.py", line 278, in query
    response = chat_session.send_message(last["content"])
               ^^^^^^^^^^^^^^^^^^^^^^^^^^^^^^^^^^^^^^^^^^
  File "/Users/macbook/miniconda3/envs/eoh/lib/python3.12/site-packages/google/generativeai/generative_models.py", line 578, in send_message
    response = self.model.generate_content(
               ^^^^^^^^^^^^^^^^^^^^^^^^^^^^
  File "/Users/macbook/miniconda3/envs/eoh/lib/python3.12/site-packages/google/generativeai/generative_models.py", line 331, in generate_content
    response = self._client.generate_content(
               ^^^^^^^^^^^^^^^^^^^^^^^^^^^^^^
  File "/Users/macbook/miniconda3/envs/eoh/lib/python3.12/site-packages/google/ai/generativelanguage_v1beta/services/generative_service/client.py", line 835, in generate_content
    response = rpc(
               ^^^^
  File "/Users/macbook/miniconda3/envs/eoh/lib/python3.12/site-packages/google/api_core/gapic_v1/method.py", line 131, in __call__
    return wrapped_func(*args, **kwargs)
           ^^^^^^^^^^^^^^^^^^^^^^^^^^^^^
  File "/Users/macbook/miniconda3/envs/eoh/lib/python3.12/site-packages/google/api_core/retry/retry_unary.py", line 294, in retry_wrapped_func
    return retry_target(
           ^^^^^^^^^^^^^
  File "/Users/macbook/miniconda3/envs/eoh/lib/python3.12/site-packages/google/api_core/retry/retry_unary.py", line 156, in retry_target
    next_sleep = _retry_error_helper(
                 ^^^^^^^^^^^^^^^^^^^^
  File "/Users/macbook/miniconda3/envs/eoh/lib/python3.12/site-packages/google/api_core/retry/retry_base.py", line 214, in _retry_error_helper
    raise final_exc from source_exc
  File "/Users/macbook/miniconda3/envs/eoh/lib/python3.12/site-packages/google/api_core/retry/retry_unary.py", line 147, in retry_target
    result = target()
             ^^^^^^^^
  File "/Users/macbook/miniconda3/envs/eoh/lib/python3.12/site-packages/google/api_core/timeout.py", line 130, in func_with_timeout
    return func(*args, **kwargs)
           ^^^^^^^^^^^^^^^^^^^^^
  File "/Users/macbook/miniconda3/envs/eoh/lib/python3.12/site-packages/google/api_core/grpc_helpers.py", line 78, in error_remapped_callable
    raise exceptions.from_grpc_error(exc) from exc
google.api_core.exceptions.ResourceExhausted: 429 You exceeded your current quota, please check your plan and billing details. For more information on this error, head to: https://ai.google.dev/gemini-api/docs/rate-limits. [violations {
  quota_metric: "generativelanguage.googleapis.com/generate_content_free_tier_requests"
  quota_id: "GenerateRequestsPerMinutePerProjectPerModel-FreeTier"
  quota_dimensions {
    key: "model"
    value: "gemini-1.5-flash"
  }
  quota_dimensions {
    key: "location"
    value: "global"
  }
  quota_value: 15
}
, links {
  description: "Learn more about Gemini API quotas"
  url: "https://ai.google.dev/gemini-api/docs/rate-limits"
}
, retry_delay {
  seconds: 42
}
]
.
2025-06-15 09:21:17 INFO An exception occured: Traceback (most recent call last):
  File "/Users/macbook/Documents/Code/LLMdesignedEA-comp/llamea/llamea_api_rotations.py", line 326, in evolve_solution
    evolved_individual = chosen_llm.sample_solution(
                         ^^^^^^^^^^^^^^^^^^^^^^^^^^^
  File "/Users/macbook/Documents/Code/LLMdesignedEA-comp/llamea/llm.py", line 106, in sample_solution
    message = self.query(session_messages)
              ^^^^^^^^^^^^^^^^^^^^^^^^^^^^
  File "/Users/macbook/Documents/Code/LLMdesignedEA-comp/llamea/llm.py", line 278, in query
    response = chat_session.send_message(last["content"])
               ^^^^^^^^^^^^^^^^^^^^^^^^^^^^^^^^^^^^^^^^^^
  File "/Users/macbook/miniconda3/envs/eoh/lib/python3.12/site-packages/google/generativeai/generative_models.py", line 578, in send_message
    response = self.model.generate_content(
               ^^^^^^^^^^^^^^^^^^^^^^^^^^^^
  File "/Users/macbook/miniconda3/envs/eoh/lib/python3.12/site-packages/google/generativeai/generative_models.py", line 331, in generate_content
    response = self._client.generate_content(
               ^^^^^^^^^^^^^^^^^^^^^^^^^^^^^^
  File "/Users/macbook/miniconda3/envs/eoh/lib/python3.12/site-packages/google/ai/generativelanguage_v1beta/services/generative_service/client.py", line 835, in generate_content
    response = rpc(
               ^^^^
  File "/Users/macbook/miniconda3/envs/eoh/lib/python3.12/site-packages/google/api_core/gapic_v1/method.py", line 131, in __call__
    return wrapped_func(*args, **kwargs)
           ^^^^^^^^^^^^^^^^^^^^^^^^^^^^^
  File "/Users/macbook/miniconda3/envs/eoh/lib/python3.12/site-packages/google/api_core/retry/retry_unary.py", line 294, in retry_wrapped_func
    return retry_target(
           ^^^^^^^^^^^^^
  File "/Users/macbook/miniconda3/envs/eoh/lib/python3.12/site-packages/google/api_core/retry/retry_unary.py", line 156, in retry_target
    next_sleep = _retry_error_helper(
                 ^^^^^^^^^^^^^^^^^^^^
  File "/Users/macbook/miniconda3/envs/eoh/lib/python3.12/site-packages/google/api_core/retry/retry_base.py", line 214, in _retry_error_helper
    raise final_exc from source_exc
  File "/Users/macbook/miniconda3/envs/eoh/lib/python3.12/site-packages/google/api_core/retry/retry_unary.py", line 147, in retry_target
    result = target()
             ^^^^^^^^
  File "/Users/macbook/miniconda3/envs/eoh/lib/python3.12/site-packages/google/api_core/timeout.py", line 130, in func_with_timeout
    return func(*args, **kwargs)
           ^^^^^^^^^^^^^^^^^^^^^
  File "/Users/macbook/miniconda3/envs/eoh/lib/python3.12/site-packages/google/api_core/grpc_helpers.py", line 78, in error_remapped_callable
    raise exceptions.from_grpc_error(exc) from exc
google.api_core.exceptions.ResourceExhausted: 429 You exceeded your current quota, please check your plan and billing details. For more information on this error, head to: https://ai.google.dev/gemini-api/docs/rate-limits. [violations {
  quota_metric: "generativelanguage.googleapis.com/generate_content_free_tier_requests"
  quota_id: "GenerateRequestsPerMinutePerProjectPerModel-FreeTier"
  quota_dimensions {
    key: "model"
    value: "gemini-1.5-flash"
  }
  quota_dimensions {
    key: "location"
    value: "global"
  }
  quota_value: 15
}
, links {
  description: "Learn more about Gemini API quotas"
  url: "https://ai.google.dev/gemini-api/docs/rate-limits"
}
, retry_delay {
  seconds: 42
}
]
.
2025-06-15 09:21:17 INFO An exception occured: Traceback (most recent call last):
  File "/Users/macbook/Documents/Code/LLMdesignedEA-comp/llamea/llamea_api_rotations.py", line 326, in evolve_solution
    evolved_individual = chosen_llm.sample_solution(
                         ^^^^^^^^^^^^^^^^^^^^^^^^^^^
  File "/Users/macbook/Documents/Code/LLMdesignedEA-comp/llamea/llm.py", line 106, in sample_solution
    message = self.query(session_messages)
              ^^^^^^^^^^^^^^^^^^^^^^^^^^^^
  File "/Users/macbook/Documents/Code/LLMdesignedEA-comp/llamea/llm.py", line 278, in query
    response = chat_session.send_message(last["content"])
               ^^^^^^^^^^^^^^^^^^^^^^^^^^^^^^^^^^^^^^^^^^
  File "/Users/macbook/miniconda3/envs/eoh/lib/python3.12/site-packages/google/generativeai/generative_models.py", line 578, in send_message
    response = self.model.generate_content(
               ^^^^^^^^^^^^^^^^^^^^^^^^^^^^
  File "/Users/macbook/miniconda3/envs/eoh/lib/python3.12/site-packages/google/generativeai/generative_models.py", line 331, in generate_content
    response = self._client.generate_content(
               ^^^^^^^^^^^^^^^^^^^^^^^^^^^^^^
  File "/Users/macbook/miniconda3/envs/eoh/lib/python3.12/site-packages/google/ai/generativelanguage_v1beta/services/generative_service/client.py", line 835, in generate_content
    response = rpc(
               ^^^^
  File "/Users/macbook/miniconda3/envs/eoh/lib/python3.12/site-packages/google/api_core/gapic_v1/method.py", line 131, in __call__
    return wrapped_func(*args, **kwargs)
           ^^^^^^^^^^^^^^^^^^^^^^^^^^^^^
  File "/Users/macbook/miniconda3/envs/eoh/lib/python3.12/site-packages/google/api_core/retry/retry_unary.py", line 294, in retry_wrapped_func
    return retry_target(
           ^^^^^^^^^^^^^
  File "/Users/macbook/miniconda3/envs/eoh/lib/python3.12/site-packages/google/api_core/retry/retry_unary.py", line 156, in retry_target
    next_sleep = _retry_error_helper(
                 ^^^^^^^^^^^^^^^^^^^^
  File "/Users/macbook/miniconda3/envs/eoh/lib/python3.12/site-packages/google/api_core/retry/retry_base.py", line 214, in _retry_error_helper
    raise final_exc from source_exc
  File "/Users/macbook/miniconda3/envs/eoh/lib/python3.12/site-packages/google/api_core/retry/retry_unary.py", line 147, in retry_target
    result = target()
             ^^^^^^^^
  File "/Users/macbook/miniconda3/envs/eoh/lib/python3.12/site-packages/google/api_core/timeout.py", line 130, in func_with_timeout
    return func(*args, **kwargs)
           ^^^^^^^^^^^^^^^^^^^^^
  File "/Users/macbook/miniconda3/envs/eoh/lib/python3.12/site-packages/google/api_core/grpc_helpers.py", line 78, in error_remapped_callable
    raise exceptions.from_grpc_error(exc) from exc
google.api_core.exceptions.ResourceExhausted: 429 You exceeded your current quota, please check your plan and billing details. For more information on this error, head to: https://ai.google.dev/gemini-api/docs/rate-limits. [violations {
  quota_metric: "generativelanguage.googleapis.com/generate_content_free_tier_requests"
  quota_id: "GenerateRequestsPerMinutePerProjectPerModel-FreeTier"
  quota_dimensions {
    key: "model"
    value: "gemini-1.5-flash"
  }
  quota_dimensions {
    key: "location"
    value: "global"
  }
  quota_value: 15
}
, links {
  description: "Learn more about Gemini API quotas"
  url: "https://ai.google.dev/gemini-api/docs/rate-limits"
}
, retry_delay {
  seconds: 42
}
]
.
2025-06-15 09:21:17 INFO An exception occured: Traceback (most recent call last):
  File "/Users/macbook/Documents/Code/LLMdesignedEA-comp/llamea/llamea_api_rotations.py", line 326, in evolve_solution
    evolved_individual = chosen_llm.sample_solution(
                         ^^^^^^^^^^^^^^^^^^^^^^^^^^^
  File "/Users/macbook/Documents/Code/LLMdesignedEA-comp/llamea/llm.py", line 106, in sample_solution
    message = self.query(session_messages)
              ^^^^^^^^^^^^^^^^^^^^^^^^^^^^
  File "/Users/macbook/Documents/Code/LLMdesignedEA-comp/llamea/llm.py", line 278, in query
    response = chat_session.send_message(last["content"])
               ^^^^^^^^^^^^^^^^^^^^^^^^^^^^^^^^^^^^^^^^^^
  File "/Users/macbook/miniconda3/envs/eoh/lib/python3.12/site-packages/google/generativeai/generative_models.py", line 578, in send_message
    response = self.model.generate_content(
               ^^^^^^^^^^^^^^^^^^^^^^^^^^^^
  File "/Users/macbook/miniconda3/envs/eoh/lib/python3.12/site-packages/google/generativeai/generative_models.py", line 331, in generate_content
    response = self._client.generate_content(
               ^^^^^^^^^^^^^^^^^^^^^^^^^^^^^^
  File "/Users/macbook/miniconda3/envs/eoh/lib/python3.12/site-packages/google/ai/generativelanguage_v1beta/services/generative_service/client.py", line 835, in generate_content
    response = rpc(
               ^^^^
  File "/Users/macbook/miniconda3/envs/eoh/lib/python3.12/site-packages/google/api_core/gapic_v1/method.py", line 131, in __call__
    return wrapped_func(*args, **kwargs)
           ^^^^^^^^^^^^^^^^^^^^^^^^^^^^^
  File "/Users/macbook/miniconda3/envs/eoh/lib/python3.12/site-packages/google/api_core/retry/retry_unary.py", line 294, in retry_wrapped_func
    return retry_target(
           ^^^^^^^^^^^^^
  File "/Users/macbook/miniconda3/envs/eoh/lib/python3.12/site-packages/google/api_core/retry/retry_unary.py", line 156, in retry_target
    next_sleep = _retry_error_helper(
                 ^^^^^^^^^^^^^^^^^^^^
  File "/Users/macbook/miniconda3/envs/eoh/lib/python3.12/site-packages/google/api_core/retry/retry_base.py", line 214, in _retry_error_helper
    raise final_exc from source_exc
  File "/Users/macbook/miniconda3/envs/eoh/lib/python3.12/site-packages/google/api_core/retry/retry_unary.py", line 147, in retry_target
    result = target()
             ^^^^^^^^
  File "/Users/macbook/miniconda3/envs/eoh/lib/python3.12/site-packages/google/api_core/timeout.py", line 130, in func_with_timeout
    return func(*args, **kwargs)
           ^^^^^^^^^^^^^^^^^^^^^
  File "/Users/macbook/miniconda3/envs/eoh/lib/python3.12/site-packages/google/api_core/grpc_helpers.py", line 78, in error_remapped_callable
    raise exceptions.from_grpc_error(exc) from exc
google.api_core.exceptions.ResourceExhausted: 429 You exceeded your current quota, please check your plan and billing details. For more information on this error, head to: https://ai.google.dev/gemini-api/docs/rate-limits. [violations {
  quota_metric: "generativelanguage.googleapis.com/generate_content_free_tier_requests"
  quota_id: "GenerateRequestsPerMinutePerProjectPerModel-FreeTier"
  quota_dimensions {
    key: "model"
    value: "gemini-1.5-flash"
  }
  quota_dimensions {
    key: "location"
    value: "global"
  }
  quota_value: 15
}
, links {
  description: "Learn more about Gemini API quotas"
  url: "https://ai.google.dev/gemini-api/docs/rate-limits"
}
, retry_delay {
  seconds: 42
}
]
.
