2025-06-15 09:24:24 INFO Using LLM api key #AIzaSyAEUmOe_NUQT_vGqRWH_9XnMDQuUe0CiKU)
2025-06-15 09:24:24 INFO Using LLM api key #AIzaSyAS4WrMPg7WNPXLpCYIOG49cIYOL7vTAl8)
2025-06-15 09:24:24 INFO Using LLM api key #AIzaSyARJfdVOsI9AKUK6gxvUszL_bn5Z_lr5Wg)
2025-06-15 09:24:24 INFO Using LLM api key #AIzaSyAEUmOe_NUQT_vGqRWH_9XnMDQuUe0CiKU)
2025-06-15 09:24:24 INFO Using LLM api key #AIzaSyAS4WrMPg7WNPXLpCYIOG49cIYOL7vTAl8)
2025-06-15 09:24:31 INFO --- GNBG Problem Parameters for f8 ---
  Dimension: 30, MaxEvals: 500000
  Search Bounds: [-100, 100]
  Number of Components: 1
  Known Optimum Value: -656.788998
  Lambda (Curvature): [1]
  Mu (Asymmetry/Depth): [0.2 0.2]
----------------------------------------
2025-06-15 09:24:31 INFO Run function 8 complete. FEHistory len: 533, AOCC: 0.0000
2025-06-15 09:24:31 INFO FeHistory: [170788.31935256 177708.99017333 169418.77849464 161287.02547792
 162273.86579101 157244.59214644 155090.77811492 144130.03241025
 145276.08702791 140569.60482837 140544.59737648 144899.85548212
 146752.09948365 139199.9297775  141961.08551673 145222.60057692
 140215.06318802 138690.50194232 143122.14373428 148205.12123451
 145297.37218398 135871.1048874  138385.16855627 143979.15001032
 138425.80100359 139050.88762621 136023.97689841 136548.50349504
 137618.69035966 144086.40614832 130041.60146044 132465.17236285
 129032.59775361 131208.46135218 129526.70387417 127557.30370729
 136688.00489839 122432.40990177 121897.21201399 121320.43443437
 117221.75793698 115534.27201609 119500.96933476 118076.24836964
 114278.23511691 118295.55792533 115613.83570722 115193.78838876
 114331.33512166 112081.84447875 115014.8161542  117251.34865534
 113636.30377384 110428.09906533 111529.32174466 111079.23627674
 112105.56739809 113183.37118197 111842.81249813 112693.03319983
 112456.22239866 108318.3531701  109228.65159825 107852.86668888
 109033.41347531 109376.23709706 107857.95541705 107766.32618086
 109221.76550299 107144.13116668 106944.89730459 107513.11362192
 106672.91600131 105811.06878218 104832.85604213 105422.91302396
 104176.78067373 103758.87130624 103459.74893546 105130.42285597
 103535.34992816 102914.00171658 102760.07993389 102407.92126854
 101709.93214121 100439.32665623 101158.16900792 100723.3379592
 100878.52496651  99862.8336495  100422.22190182  99115.40336451
  99652.42241422  99428.86029259  98067.53670147  98921.53175986
  97778.04735974  97237.31122034  97148.50790437  97095.66827131
  97292.50339499  96737.37919074  97072.12920808  96570.73501108
  96828.44397616  96649.37929254  96303.52883056  96557.82859918
  96064.98030196  96372.06936035  95573.13700457  95560.80520413
  95797.26521008  95603.7070749   95619.7882279   95794.36959353
  95512.07161537  95775.85073748  95432.88401645  95833.54018155
  95212.46875734  95568.50262792  95297.45208765  95298.18533128
  95447.71605865  95060.81573175  95345.91439793  94911.57417769
  95156.14373389  94880.3434626   95014.21028069  94940.34450061
  94683.14531025  94669.57050406  94582.70353926  94528.74947127
  94835.62992208  94464.19708956  94877.63442952  94328.65132136
  94309.14550691  94268.85667491  94196.9554293   94261.39266704
  94197.02580503  94070.76756175  94023.95553862  93946.07949628
  93850.43690052  93919.1164665   93779.28780058  93747.90102548
  93674.13126133  93670.62018689  93581.63179203  93630.12101025
  93593.7379635   93556.80396254  93514.79859708  93541.22537282
  93520.56933528  93543.20404241  93423.51338341  93345.49305869
  93487.11494194  93324.65193343  93308.14347295  93259.62355261
  93325.99807288  93337.1139339   93294.25864681  93292.46047695
  93223.2168344   93163.71820637  93225.95965619  93126.73243303
  93065.48295731  93005.427417    92973.92417116  92975.71191204
  93009.15605105  93038.59773119  92989.26037615  93032.74381121
  93010.3149476   92967.32917994  92986.15234988  93058.36369836
  92979.22154015  92977.32053166  92976.34195959  92973.18730465
  92969.53091804  92997.67693308  92972.91515769  92944.95772745
  92952.1124467   92972.50093461  92918.96597113  92923.42467806
  92898.03348265  92875.30867123  92866.98007651  92876.44288184
  92893.50012091  92867.59153993  92857.8771923   92894.23588476
  92841.02597683  92882.82334509  92846.8769114   92861.52938685
  92838.42718983  92803.4960674   92797.20677301  92822.27077366
  92789.47261866  92795.79062085  92780.13799233  92797.68826837
  92761.31859484  92764.39655718  92749.34256253  92736.79721602
  92757.5288661   92707.18917818  92724.99638873  92704.63429343
  92713.69744886  92712.09421485  92722.66812374  92698.17870398
  92716.24934156  92725.62951627  92716.62320286  92674.9070682
  92682.63976993  92673.05452013  92674.58629417  92683.98113293
  92684.85365664  92648.54854296  92626.30821886  92623.34156153
  92612.912176    92612.5743556   92628.60529248  92613.59473865
  92612.34210003  92614.3808636   92610.98104244  92613.11921698
  92607.49368134  92608.43158189  92601.78173602  92595.36081701
  92599.92402361  92587.16265021  92588.38813301  92576.67268693
  92583.31045672  92581.06036547  92571.20433337  92577.27570779
  92581.8812022   92565.50490141  92567.92020355  92561.33491763
  92559.94762525  92564.57397662  92553.75189837  92548.33391356
  92548.43097437  92545.27700351  92542.42358924  92539.85154378
  92537.91487973  92536.52818032  92536.38354168  92537.11089424
  92531.71286955  92536.201425    92530.90234781  92534.48977996
  92530.89743024  92536.85671012  92532.88377298  92532.52915841
  92534.62204811  92534.60183116  92530.83244733  92531.92954978
  92533.22262223  92531.15316049  92533.45855049  92528.73385908
  92530.80523664  92528.27197612  92524.81442479  92522.65489493
  92518.06134525  92515.74487165  92519.11892701  92517.6299513
  92509.72230989  92510.46167898  92508.8318771   92507.35787133
  92508.08840495  92507.78361585  92505.88422648  92509.54730552
  92504.30626567  92503.53824009  92506.77908851  92501.64175274
  92500.9725629   92499.54608372  92499.63724188  92499.8909745
  92498.52016257  92499.7143168   92501.43154401  92498.88842276
  92498.1760299   92498.56206622  92498.82115633  92498.40836625
  92499.45740812  92499.52268615  92500.07775424  92498.23064422
  92497.9202286   92498.54245672  92496.65893118  92494.16047172
  92495.59678031  92492.82151965  92490.37279979  92488.4054692
  92487.44145179  92488.76467931  92487.873772    92487.57462926
  92488.2258045   92487.66653258  92487.549368    92486.036055
  92484.95766973  92485.00173572  92484.81782239  92485.56185627
  92484.06106157  92483.49160405  92484.15867582  92482.82440745
  92482.64087391  92482.03319506  92482.41796735  92481.65574022
  92482.38291728  92480.96551628  92480.5288116   92480.42420582
  92481.10126768  92481.42809085  92480.27669796  92480.04753328
  92480.31527482  92479.11928579  92479.3722252   92478.57398472
  92479.04487928  92478.74198905  92478.33368836  92478.43775982
  92478.27798097  92478.26509922  92478.38671519  92478.38915129
  92477.89037999  92477.93432702  92478.23949055  92478.17740309
  92477.60281615  92477.33376958  92477.01832747  92477.22872041
  92477.26661422  92477.61456012  92477.46113252  92476.93651292
  92476.89181084  92476.82657075  92476.40735893  92476.39153175
  92476.39940047  92476.0213989   92475.83354083  92476.01228295
  92476.00912476  92475.7839343   92475.89891939  92475.9801705
  92475.71178471  92475.59263493  92475.58697073  92475.69221551
  92475.65104888  92475.54060999  92475.60850796  92475.27145833
  92475.40200735  92475.50311828  92475.04369153  92475.05826265
  92474.98887987  92474.85533054  92475.16131216  92474.8368642
  92474.66884784  92474.51218678  92474.49444341  92474.34637618
  92474.41217069  92474.48221415  92474.31311415  92474.23119995
  92474.27856002  92474.23198894  92474.21227875  92473.95883317
  92473.99417786  92473.96568465  92474.04897076  92473.9059377
  92473.98939615  92473.84142301  92473.93689117  92473.80662376
  92473.83864216  92473.80232888  92473.84616181  92473.79694287
  92473.7446874   92473.74237325  92473.82354947  92473.75465993
  92473.7145623   92473.73648938  92473.71579445  92473.71525823
  92473.67818044  92473.72516251  92473.6319758   92473.63179684
  92473.648856    92473.57111492  92473.5222397   92473.51373311
  92473.50119271  92473.50431349  92473.54488789  92473.53689463
  92473.51960667  92473.5513482   92473.52661343  92473.44917022
  92473.42598479  92473.47839698  92473.43623493  92473.51526923
  92473.37780095  92473.41006416  92473.38630008  92473.36000776
  92473.38101287  92473.35551966  92473.3848575   92473.36806953
  92473.40049487  92473.33997621  92473.31883635  92473.3412304
  92473.31362266  92473.32403207  92473.30491233  92473.32449075
  92473.2847029   92473.28132501  92473.26498058  92473.25936536
  92473.26727619  92473.2549369   92473.24104274  92473.25625594
  92473.23145476  92473.20777814  92473.21629049  92473.20803416
  92473.23665177  92473.22403382  92473.21958007  92473.20808521
  92473.20939098  92473.21481175  92473.17699464  92473.20995137
  92473.17122794  92473.15330317  92473.14780423  92473.14761042
  92473.15922445  92473.16478729  92473.1571019   92473.13280199
  92473.14050771  92473.13117715  92473.12395025  92473.11516094
  92473.10520169  92473.09869301  92473.10299802  92473.0793429
  92473.08335816  92473.0803812   92473.05864496  92473.05476683
  92473.06305053  92473.06278765  92473.04746274  92473.04668929
  92473.05610132]
2025-06-15 09:24:31 INFO Expected Optimum FE: -656.7889979935655
2025-06-15 09:24:31 INFO Multimodal (single component) AOCC mean: 0.0000
2025-06-15 09:24:31 INFO AOCC mean: 0.0000
2025-06-15 09:24:33 INFO --- GNBG Problem Parameters for f8 ---
  Dimension: 30, MaxEvals: 500000
  Search Bounds: [-100, 100]
  Number of Components: 1
  Known Optimum Value: -656.788998
  Lambda (Curvature): [1]
  Mu (Asymmetry/Depth): [0.2 0.2]
----------------------------------------
2025-06-15 09:24:33 ERROR Can not run the algorithm
2025-06-15 09:24:33 INFO Run function 8 complete. FEHistory len: 20, AOCC: 0.0000
2025-06-15 09:24:33 INFO FeHistory: [180469.12273998 183051.59072384 110636.05979971 166005.49018355
 198757.27971014 187305.32600182 175731.93904537 214641.74287226
 113520.3742718  244929.55706502 192285.61002502 193175.53033872
 107234.87810913 263988.81755301 205826.16549235 298450.44545862
 215929.34737528 320171.13431448 104961.3640048  160769.87071291]
2025-06-15 09:24:33 INFO Expected Optimum FE: -656.7889979935655
2025-06-15 09:24:33 INFO Multimodal (single component) AOCC mean: 0.0000
2025-06-15 09:24:33 INFO AOCC mean: 0.0000
2025-06-15 09:24:34 INFO --- GNBG Problem Parameters for f8 ---
  Dimension: 30, MaxEvals: 500000
  Search Bounds: [-100, 100]
  Number of Components: 1
  Known Optimum Value: -656.788998
  Lambda (Curvature): [1]
  Mu (Asymmetry/Depth): [0.2 0.2]
----------------------------------------
2025-06-15 09:24:34 ERROR Can not run the algorithm
2025-06-15 09:24:34 INFO Run function 8 complete. FEHistory len: 20, AOCC: 0.0000
2025-06-15 09:24:34 INFO FeHistory: [165718.35139636 163560.25199464 190191.65230494 204409.69682682
 234047.27610222 204217.40008613 154922.39371579 165106.3060008
 187042.10845122 243337.31146858 251873.78576984 270004.43377482
 229744.76406618 140973.13759586 250487.86928906 215264.80784508
 164903.08798184 235344.20181623 236027.49335665 252547.74643094]
2025-06-15 09:24:34 INFO Expected Optimum FE: -656.7889979935655
2025-06-15 09:24:34 INFO Multimodal (single component) AOCC mean: 0.0000
2025-06-15 09:24:34 INFO AOCC mean: 0.0000
2025-06-15 09:24:35 INFO --- GNBG Problem Parameters for f8 ---
  Dimension: 30, MaxEvals: 500000
  Search Bounds: [-100, 100]
  Number of Components: 1
  Known Optimum Value: -656.788998
  Lambda (Curvature): [1]
  Mu (Asymmetry/Depth): [0.2 0.2]
----------------------------------------
2025-06-15 09:24:35 ERROR Can not run the algorithm
2025-06-15 09:24:35 INFO Run function 8 complete. FEHistory len: 301, AOCC: 0.0000
2025-06-15 09:24:35 INFO FeHistory: [250241.52632789 192543.83848724 240503.23367283 243366.44559886
 106672.21329851 231200.24326995 152906.70104342 171499.43976138
 150725.92729587 266029.74376509 240830.37861056 151124.16557942
 103004.7491265  250115.86849482 214849.2593956  262776.17553173
 229476.85554105 106425.33712363 157015.0578222  181353.73739766
 175983.90905069 184665.34164246 162323.10876179 286035.47212102
 234326.87658001  80853.07895359 237204.82130284 271245.06060778
 230225.14047094 285481.51802413 120419.35885187 235724.84286643
 150704.47277414 196418.84943535 131769.36050534 176849.13704909
 100383.29425494 243770.54548096 127508.7423634  118214.34477891
 201084.99706913 148876.43687213 217113.42867993 250846.02298998
 227418.31469452 202046.67768587 175681.20346678 138178.23456094
 115138.01563445 139040.44946608 141051.13404769 177438.83185544
 166290.14757421 151638.81534511 204007.19519073 204982.51776248
 188543.29546454 177850.22263711 126562.00235842 134489.82594299
 190122.14268513 161028.50602524 328809.90493919 219672.3667593
 252619.82700585 178165.68092997 192916.02134017 115368.01976172
 177469.23688607 256658.79227291 223448.17815674 144700.67795146
 198464.33207109 133824.70936053 179555.30399356 185146.08939888
 141967.77432336 209829.18026105 164460.55627412 167969.64878087
 182735.17759301 170639.36738253 174803.78250678 199420.67585014
 117686.51273    236472.66908785 245514.22058588 129345.6134392
 226060.49932297 153465.50449397 193653.51567542 237395.79961556
 132841.57771799 198021.86237801 253973.01259493 133882.43598144
 138337.05827156 225255.61206955 122889.38026724 197263.38342708
 161889.64566681 148327.43235729 205414.70280058 142987.20341026
 113216.01341104 179100.09115417 178948.44160676 177801.61323209
 129381.0925195  340549.34116009 210363.09722816 203791.22759137
 147499.90404477 147300.25960496 220989.49206125 129647.13506511
 139076.36451446 159364.45261376 216414.00783138 277045.24554066
 225049.97377504 214242.49179509 177660.46426288 128028.30564242
 217623.45748902 157513.19309252 207148.99437531 192867.21982922
 148262.1419203  217267.46761242 221545.20698853 116540.69140191
 171453.28916665 220730.18408269 230177.4815967  175270.44619029
 160630.69920766 181533.50638554 285964.54377476 221976.80241918
 138660.33321888 242476.27360961 141729.3798237  200806.2327198
 230470.61340135  96610.74111351 135767.7755752  145104.5778327
 202334.19059366 172916.31505635 180598.7090783  256021.86597991
 208503.19491475 135787.70489767 239306.21943773 176243.00430723
 208423.54824039 122358.99169293 169571.84235989 221324.04156685
 164805.47279645 233633.37907996 173960.80225028 152172.96488395
 196131.30808515 228748.22902858 174920.90541942 247296.04705281
 179546.00393908 138393.23915012 133420.62650547 151043.53494943
  79819.69808793 191757.79263741 217283.87784826 109036.60112031
 199662.43207128 170961.43018607 195382.71003294 221172.96621703
 219324.90982467 203383.34048465 234668.81974099 136738.19065401
 204560.8983023  208949.95475314 192361.16521368 218533.1421044
 160947.60935892 250584.82521793 199833.95457738 189877.80520207
 171530.72916957 213364.97920229  95632.16648833 162691.35809307
 172744.49965278 212007.2951405  260202.22211835 155071.37013084
 173747.45869842 197720.2054166  161312.62005495 177862.19154523
 183057.37878764 245512.70982271 184602.76488164 149963.53549526
 193605.94936648 270190.89122324 249320.31725234 186146.18784668
 205761.8722187  227390.12324065 114311.13474173 161410.88928168
 244060.9157016  157475.20389884 214772.04111378 209575.59600558
 245640.75475852 186381.25929354 175977.3901267  170599.3236486
 232820.10482355 177023.13657287 183346.98365527 263758.19500296
 195138.03507603 147787.72791553 219262.9670272  209709.6150056
 130982.24762697 183646.23101177 182698.22898863 100761.76085865
 174109.5941473  162315.36429678 195585.50980299 146582.40566383
 193273.76329817 193948.4039045  226391.91971726 164887.25524699
 140035.71325952 134005.28006141 185016.56048639 130419.81570283
 220095.15741064 154890.79697241 128776.22455904 212986.06840902
 145430.25172775 105371.66190068 217706.94461882 175095.78556959
 200436.21329859 182355.02347314 145244.42712336 168409.16136341
 165597.80528154 156745.11695242 255806.29941749 227795.28557046
 182596.19237235 213789.08276057 143483.85567047 191173.90265274
 287713.83627612 224417.66949923 277047.58704931 225912.51832242
 222703.82004092 223297.65236656 213376.35435787 120834.41177682
 239029.56054138 143252.53224038 198430.98872642 177334.45926685
 147536.78497798 174678.07994465 200748.1913137  184453.14094185
 118903.62142667 204262.91037309 122114.86407742 229447.68286474
 190735.19206068 160538.16691017 296976.07011106 137835.43332411
 318874.44805123 179261.64892685 233276.01874306 237025.89687833
 223072.74959484 215685.96593835 100733.06562133 174233.48265354
 128921.06955113]
2025-06-15 09:24:35 INFO Expected Optimum FE: -656.7889979935655
2025-06-15 09:24:35 INFO Multimodal (single component) AOCC mean: 0.0000
2025-06-15 09:24:35 INFO AOCC mean: 0.0000
2025-06-15 09:24:35 INFO --- GNBG Problem Parameters for f8 ---
  Dimension: 30, MaxEvals: 500000
  Search Bounds: [-100, 100]
  Number of Components: 1
  Known Optimum Value: -656.788998
  Lambda (Curvature): [1]
  Mu (Asymmetry/Depth): [0.2 0.2]
----------------------------------------
2025-06-15 09:24:35 ERROR Can not run the algorithm
2025-06-15 09:24:35 INFO Run function 8 complete. FEHistory len: 20, AOCC: 0.0000
2025-06-15 09:24:35 INFO FeHistory: [224999.65185617 173967.5286254  140621.75449803 121525.68445732
 150722.52140226 279108.17892878 153602.4241807  309859.15822351
 162053.96070139 158585.15219146 215707.57232257 169403.15913193
 202522.31370212 187564.84920617 214268.43362307 247404.9088913
 233503.74217763 244057.45127903 204272.16016647 151201.74009584]
2025-06-15 09:24:35 INFO Expected Optimum FE: -656.7889979935655
2025-06-15 09:24:35 INFO Multimodal (single component) AOCC mean: 0.0000
2025-06-15 09:24:35 INFO AOCC mean: 0.0000
2025-06-15 09:24:35 INFO Using LLM api key #AIzaSyARJfdVOsI9AKUK6gxvUszL_bn5Z_lr5Wg)
2025-06-15 09:24:35 INFO Using LLM api key #AIzaSyAEUmOe_NUQT_vGqRWH_9XnMDQuUe0CiKU)
2025-06-15 09:24:35 INFO Using LLM api key #AIzaSyCbA5uIXRIIWnTv7HCUGX75WoYJ4PeZWd0)
2025-06-15 09:24:35 INFO Using LLM api key #AIzaSyAEUmOe_NUQT_vGqRWH_9XnMDQuUe0CiKU)
2025-06-15 09:24:35 INFO Using LLM api key #AIzaSyCbA5uIXRIIWnTv7HCUGX75WoYJ4PeZWd0)
2025-06-15 09:24:36 INFO An exception occured: Traceback (most recent call last):
  File "/Users/macbook/Documents/Code/LLMdesignedEA-comp/llamea/llamea_api_rotations.py", line 329, in evolve_solution
    evolved_individual = chosen_llm.sample_solution(
                         ^^^^^^^^^^^^^^^^^^^^^^^^^^^
  File "/Users/macbook/Documents/Code/LLMdesignedEA-comp/llamea/llm.py", line 106, in sample_solution
    message = self.query(session_messages)
              ^^^^^^^^^^^^^^^^^^^^^^^^^^^^
  File "/Users/macbook/Documents/Code/LLMdesignedEA-comp/llamea/llm.py", line 278, in query
    response = chat_session.send_message(last["content"])
               ^^^^^^^^^^^^^^^^^^^^^^^^^^^^^^^^^^^^^^^^^^
  File "/Users/macbook/miniconda3/envs/eoh/lib/python3.12/site-packages/google/generativeai/generative_models.py", line 578, in send_message
    response = self.model.generate_content(
               ^^^^^^^^^^^^^^^^^^^^^^^^^^^^
  File "/Users/macbook/miniconda3/envs/eoh/lib/python3.12/site-packages/google/generativeai/generative_models.py", line 331, in generate_content
    response = self._client.generate_content(
               ^^^^^^^^^^^^^^^^^^^^^^^^^^^^^^
  File "/Users/macbook/miniconda3/envs/eoh/lib/python3.12/site-packages/google/ai/generativelanguage_v1beta/services/generative_service/client.py", line 835, in generate_content
    response = rpc(
               ^^^^
  File "/Users/macbook/miniconda3/envs/eoh/lib/python3.12/site-packages/google/api_core/gapic_v1/method.py", line 131, in __call__
    return wrapped_func(*args, **kwargs)
           ^^^^^^^^^^^^^^^^^^^^^^^^^^^^^
  File "/Users/macbook/miniconda3/envs/eoh/lib/python3.12/site-packages/google/api_core/retry/retry_unary.py", line 294, in retry_wrapped_func
    return retry_target(
           ^^^^^^^^^^^^^
  File "/Users/macbook/miniconda3/envs/eoh/lib/python3.12/site-packages/google/api_core/retry/retry_unary.py", line 156, in retry_target
    next_sleep = _retry_error_helper(
                 ^^^^^^^^^^^^^^^^^^^^
  File "/Users/macbook/miniconda3/envs/eoh/lib/python3.12/site-packages/google/api_core/retry/retry_base.py", line 214, in _retry_error_helper
    raise final_exc from source_exc
  File "/Users/macbook/miniconda3/envs/eoh/lib/python3.12/site-packages/google/api_core/retry/retry_unary.py", line 147, in retry_target
    result = target()
             ^^^^^^^^
  File "/Users/macbook/miniconda3/envs/eoh/lib/python3.12/site-packages/google/api_core/timeout.py", line 130, in func_with_timeout
    return func(*args, **kwargs)
           ^^^^^^^^^^^^^^^^^^^^^
  File "/Users/macbook/miniconda3/envs/eoh/lib/python3.12/site-packages/google/api_core/grpc_helpers.py", line 78, in error_remapped_callable
    raise exceptions.from_grpc_error(exc) from exc
google.api_core.exceptions.ResourceExhausted: 429 You exceeded your current quota, please check your plan and billing details. For more information on this error, head to: https://ai.google.dev/gemini-api/docs/rate-limits. [violations {
  quota_metric: "generativelanguage.googleapis.com/generate_content_free_tier_requests"
  quota_id: "GenerateRequestsPerMinutePerProjectPerModel-FreeTier"
  quota_dimensions {
    key: "model"
    value: "gemini-1.5-flash"
  }
  quota_dimensions {
    key: "location"
    value: "global"
  }
  quota_value: 15
}
, links {
  description: "Learn more about Gemini API quotas"
  url: "https://ai.google.dev/gemini-api/docs/rate-limits"
}
, retry_delay {
  seconds: 23
}
]
.
2025-06-15 09:24:36 INFO An exception occured: Traceback (most recent call last):
  File "/Users/macbook/Documents/Code/LLMdesignedEA-comp/llamea/llamea_api_rotations.py", line 329, in evolve_solution
    evolved_individual = chosen_llm.sample_solution(
                         ^^^^^^^^^^^^^^^^^^^^^^^^^^^
  File "/Users/macbook/Documents/Code/LLMdesignedEA-comp/llamea/llm.py", line 106, in sample_solution
    message = self.query(session_messages)
              ^^^^^^^^^^^^^^^^^^^^^^^^^^^^
  File "/Users/macbook/Documents/Code/LLMdesignedEA-comp/llamea/llm.py", line 278, in query
    response = chat_session.send_message(last["content"])
               ^^^^^^^^^^^^^^^^^^^^^^^^^^^^^^^^^^^^^^^^^^
  File "/Users/macbook/miniconda3/envs/eoh/lib/python3.12/site-packages/google/generativeai/generative_models.py", line 578, in send_message
    response = self.model.generate_content(
               ^^^^^^^^^^^^^^^^^^^^^^^^^^^^
  File "/Users/macbook/miniconda3/envs/eoh/lib/python3.12/site-packages/google/generativeai/generative_models.py", line 331, in generate_content
    response = self._client.generate_content(
               ^^^^^^^^^^^^^^^^^^^^^^^^^^^^^^
  File "/Users/macbook/miniconda3/envs/eoh/lib/python3.12/site-packages/google/ai/generativelanguage_v1beta/services/generative_service/client.py", line 835, in generate_content
    response = rpc(
               ^^^^
  File "/Users/macbook/miniconda3/envs/eoh/lib/python3.12/site-packages/google/api_core/gapic_v1/method.py", line 131, in __call__
    return wrapped_func(*args, **kwargs)
           ^^^^^^^^^^^^^^^^^^^^^^^^^^^^^
  File "/Users/macbook/miniconda3/envs/eoh/lib/python3.12/site-packages/google/api_core/retry/retry_unary.py", line 294, in retry_wrapped_func
    return retry_target(
           ^^^^^^^^^^^^^
  File "/Users/macbook/miniconda3/envs/eoh/lib/python3.12/site-packages/google/api_core/retry/retry_unary.py", line 156, in retry_target
    next_sleep = _retry_error_helper(
                 ^^^^^^^^^^^^^^^^^^^^
  File "/Users/macbook/miniconda3/envs/eoh/lib/python3.12/site-packages/google/api_core/retry/retry_base.py", line 214, in _retry_error_helper
    raise final_exc from source_exc
  File "/Users/macbook/miniconda3/envs/eoh/lib/python3.12/site-packages/google/api_core/retry/retry_unary.py", line 147, in retry_target
    result = target()
             ^^^^^^^^
  File "/Users/macbook/miniconda3/envs/eoh/lib/python3.12/site-packages/google/api_core/timeout.py", line 130, in func_with_timeout
    return func(*args, **kwargs)
           ^^^^^^^^^^^^^^^^^^^^^
  File "/Users/macbook/miniconda3/envs/eoh/lib/python3.12/site-packages/google/api_core/grpc_helpers.py", line 78, in error_remapped_callable
    raise exceptions.from_grpc_error(exc) from exc
google.api_core.exceptions.ResourceExhausted: 429 You exceeded your current quota, please check your plan and billing details. For more information on this error, head to: https://ai.google.dev/gemini-api/docs/rate-limits. [violations {
  quota_metric: "generativelanguage.googleapis.com/generate_content_free_tier_requests"
  quota_id: "GenerateRequestsPerMinutePerProjectPerModel-FreeTier"
  quota_dimensions {
    key: "model"
    value: "gemini-1.5-flash"
  }
  quota_dimensions {
    key: "location"
    value: "global"
  }
  quota_value: 15
}
, links {
  description: "Learn more about Gemini API quotas"
  url: "https://ai.google.dev/gemini-api/docs/rate-limits"
}
, retry_delay {
  seconds: 23
}
]
.
2025-06-15 09:24:42 INFO --- GNBG Problem Parameters for f8 ---
  Dimension: 30, MaxEvals: 500000
  Search Bounds: [-100, 100]
  Number of Components: 1
  Known Optimum Value: -656.788998
  Lambda (Curvature): [1]
  Mu (Asymmetry/Depth): [0.2 0.2]
----------------------------------------
2025-06-15 09:24:42 INFO Run function 8 complete. FEHistory len: 269, AOCC: 0.0000
2025-06-15 09:24:42 INFO FeHistory: [228316.08420975 224222.42628135 221735.54356482 214781.99390541
 213905.107711   216766.67937994 211687.14843206 210428.61708299
 204343.67289915 204791.09472749 205060.05752741 207781.78094031
 201948.76963731 206222.42272367 199627.48563487 199611.65042394
 202760.27226303 200222.85341725 200229.07045066 194323.59580756
 197804.69195936 195374.43122701 193308.71264854 191310.8195011
 190848.93381075 191656.15142464 192685.42086518 188550.17052981
 188145.7612112  189283.57721518 187074.5680361  186854.51143033
 186106.17651974 185817.96565082 184095.00484925 185353.87864846
 184014.12860759 184278.56602853 183729.17059213 185167.60559342
 183733.93375582 183838.67709598 183962.98757011 184532.89934532
 183843.77048183 184456.29681744 183447.40804908 182449.91319924
 182792.06839465 181631.69740487 182023.34952439 181351.49117379
 181129.0505063  181164.85149615 181253.24655754 180959.66212964
 180801.08454086 180846.55486347 180522.92531496 180686.51037625
 180287.91074563 180306.18537737 180263.65070154 180461.9338117
 180097.21329068 180196.30241373 180032.50147239 180112.70645162
 180341.81647218 179916.91818483 179743.86700075 179708.73791416
 179655.26666152 179687.01013453 179771.49350029 179551.88482657
 179594.96697563 179509.77910743 179678.99836487 179486.95619382
 179586.33395175 179589.0255067  179290.50094835 179257.12208865
 179241.7124842  179196.97569071 179201.00269491 179187.38138415
 179264.95401607 179212.98885336 179225.42556298 179186.94698961
 179149.63584491 179086.00929339 179128.57674599 179053.99356192
 179043.27668847 179024.96201325 179043.81746034 179022.20634748
 179010.46300618 178988.52135117 179003.10285634 178968.43846057
 178961.33508986 178934.2974468  178948.25415525 178949.39229303
 178957.06158699 178942.77066836 178970.4128295  178948.19674446
 178943.03369829 178954.95451108 178924.60045552 178937.0690594
 178916.52908625 178916.88013891 178911.11329667 178918.55239048
 178915.44958836 178907.03529588 178912.86092799 178912.48329503
 178923.07058058 178902.65902478 178890.52522563 178894.84205133
 178879.73087746 178875.73271837 178878.01626153 178879.69808833
 178878.05546664 178880.53215394 178874.69083177 178864.91577177
 178865.65991019 178861.29561885 178863.32256094 178860.73559187
 178861.55539093 178855.29251249 178855.11769591 178855.34342235
 178854.45273689 178854.54480065 178856.95458101 178855.42520539
 178851.56483125 178852.32444145 178850.90894375 178851.59112951
 178850.47083109 178850.68706303 178852.66874925 178848.79382635
 178848.41188621 178844.70272497 178844.45921149 178844.44093788
 178844.80420061 178844.62926091 178844.4897359  178843.8761198
 178846.05992758 178843.66135718 178842.37244234 178843.44156786
 178841.1326305  178841.03828749 178841.17985715 178842.24849429
 178842.1098977  178841.20751341 178842.0259749  178840.61922067
 178840.96858551 178839.48010243 178839.82683073 178840.34133536
 178838.95245224 178838.76173136 178839.47600337 178838.23684872
 178838.48797386 178837.95391649 178838.24375541 178837.81900883
 178837.76400912 178837.97145992 178838.24080547 178837.81064048
 178838.11808241 178837.77200532 178837.66485725 178837.78341998
 178837.65993038 178837.9234672  178837.72703907 178837.91520491
 178838.03023625 178837.28094633 178837.67060646 178837.34660658
 178837.44382915 178837.36555134 178836.8932125  178836.7543044
 178836.89141598 178836.85932515 178836.95469772 178836.60255778
 178836.69755335 178836.35266737 178836.47474829 178836.54441255
 178836.45387485 178836.37567953 178836.54546778 178836.36462774
 178836.27805815 178836.19459037 178836.3626165  178836.14960725
 178836.24909027 178836.31212404 178836.30501228 178836.26976478
 178836.10569315 178836.03491869 178836.03647872 178836.10638027
 178835.93793343 178836.0368064  178835.89186972 178836.02273422
 178835.88434254 178835.85564225 178835.85163646 178835.87826087
 178835.88035392 178835.84427756 178835.82154924 178835.83959555
 178835.82184264 178835.86375051 178835.80499556 178835.79576611
 178835.77351451 178835.78719401 178835.74415364 178835.71582873
 178835.72307782 178835.7148584  178835.70576112 178835.70736062
 178835.72856458 178835.712552   178835.71666344 178835.71856631
 178835.73003979 178835.69831389 178835.69131438 178835.70385131
 178835.66198957 178835.64479966 178835.63969263 178835.6324431
 178835.63757876]
2025-06-15 09:24:42 INFO Expected Optimum FE: -656.7889979935655
2025-06-15 09:24:42 INFO Multimodal (single component) AOCC mean: 0.0000
2025-06-15 09:24:42 INFO AOCC mean: 0.0000
2025-06-15 09:24:44 INFO --- GNBG Problem Parameters for f8 ---
  Dimension: 30, MaxEvals: 500000
  Search Bounds: [-100, 100]
  Number of Components: 1
  Known Optimum Value: -656.788998
  Lambda (Curvature): [1]
  Mu (Asymmetry/Depth): [0.2 0.2]
----------------------------------------
2025-06-15 09:24:46 INFO --- GNBG Problem Parameters for f8 ---
  Dimension: 30, MaxEvals: 500000
  Search Bounds: [-100, 100]
  Number of Components: 1
  Known Optimum Value: -656.788998
  Lambda (Curvature): [1]
  Mu (Asymmetry/Depth): [0.2 0.2]
----------------------------------------
2025-06-15 09:24:46 ERROR Can not run the algorithm
2025-06-15 09:24:46 INFO Run function 8 complete. FEHistory len: 20, AOCC: 0.0000
2025-06-15 09:24:46 INFO FeHistory: [117221.34456797 164223.09601365 182820.03389573 263549.57837023
 121198.46563904 146435.87606043 240440.35200024 179135.12913429
 226688.45456063 183431.95929305 281946.11495776 148317.50055536
 326938.298884   259080.3651192  166962.97945054 171093.44841625
 189043.47833129 212776.8961045  225697.26016791 351396.00737684]
2025-06-15 09:24:46 INFO Expected Optimum FE: -656.7889979935655
2025-06-15 09:24:46 INFO Multimodal (single component) AOCC mean: 0.0000
2025-06-15 09:24:46 INFO AOCC mean: 0.0000
2025-06-15 09:24:54 INFO Run function 8 complete. FEHistory len: 50000, AOCC: 0.0000
2025-06-15 09:24:54 INFO FeHistory: [171134.34370333 146917.24987185 260728.73365769 ...  36565.54891164
  38105.89542556  36645.07830541]
2025-06-15 09:24:54 INFO Expected Optimum FE: -656.7889979935655
2025-06-15 09:24:54 INFO Multimodal (single component) AOCC mean: 0.0000
2025-06-15 09:24:54 INFO AOCC mean: 0.0000
2025-06-15 09:24:54 INFO Using LLM api key #AIzaSyAS4WrMPg7WNPXLpCYIOG49cIYOL7vTAl8)
2025-06-15 09:24:54 INFO Using LLM api key #AIzaSyAS4WrMPg7WNPXLpCYIOG49cIYOL7vTAl8)
2025-06-15 09:24:54 INFO Using LLM api key #AIzaSyARJfdVOsI9AKUK6gxvUszL_bn5Z_lr5Wg)
2025-06-15 09:24:54 INFO Using LLM api key #AIzaSyAS4WrMPg7WNPXLpCYIOG49cIYOL7vTAl8)
2025-06-15 09:24:54 INFO Using LLM api key #AIzaSyARJfdVOsI9AKUK6gxvUszL_bn5Z_lr5Wg)
2025-06-15 09:24:55 INFO An exception occured: Traceback (most recent call last):
  File "/Users/macbook/Documents/Code/LLMdesignedEA-comp/llamea/llamea_api_rotations.py", line 329, in evolve_solution
    evolved_individual = chosen_llm.sample_solution(
                         ^^^^^^^^^^^^^^^^^^^^^^^^^^^
  File "/Users/macbook/Documents/Code/LLMdesignedEA-comp/llamea/llm.py", line 106, in sample_solution
    message = self.query(session_messages)
              ^^^^^^^^^^^^^^^^^^^^^^^^^^^^
  File "/Users/macbook/Documents/Code/LLMdesignedEA-comp/llamea/llm.py", line 278, in query
    response = chat_session.send_message(last["content"])
               ^^^^^^^^^^^^^^^^^^^^^^^^^^^^^^^^^^^^^^^^^^
  File "/Users/macbook/miniconda3/envs/eoh/lib/python3.12/site-packages/google/generativeai/generative_models.py", line 578, in send_message
    response = self.model.generate_content(
               ^^^^^^^^^^^^^^^^^^^^^^^^^^^^
  File "/Users/macbook/miniconda3/envs/eoh/lib/python3.12/site-packages/google/generativeai/generative_models.py", line 331, in generate_content
    response = self._client.generate_content(
               ^^^^^^^^^^^^^^^^^^^^^^^^^^^^^^
  File "/Users/macbook/miniconda3/envs/eoh/lib/python3.12/site-packages/google/ai/generativelanguage_v1beta/services/generative_service/client.py", line 835, in generate_content
    response = rpc(
               ^^^^
  File "/Users/macbook/miniconda3/envs/eoh/lib/python3.12/site-packages/google/api_core/gapic_v1/method.py", line 131, in __call__
    return wrapped_func(*args, **kwargs)
           ^^^^^^^^^^^^^^^^^^^^^^^^^^^^^
  File "/Users/macbook/miniconda3/envs/eoh/lib/python3.12/site-packages/google/api_core/retry/retry_unary.py", line 294, in retry_wrapped_func
    return retry_target(
           ^^^^^^^^^^^^^
  File "/Users/macbook/miniconda3/envs/eoh/lib/python3.12/site-packages/google/api_core/retry/retry_unary.py", line 156, in retry_target
    next_sleep = _retry_error_helper(
                 ^^^^^^^^^^^^^^^^^^^^
  File "/Users/macbook/miniconda3/envs/eoh/lib/python3.12/site-packages/google/api_core/retry/retry_base.py", line 214, in _retry_error_helper
    raise final_exc from source_exc
  File "/Users/macbook/miniconda3/envs/eoh/lib/python3.12/site-packages/google/api_core/retry/retry_unary.py", line 147, in retry_target
    result = target()
             ^^^^^^^^
  File "/Users/macbook/miniconda3/envs/eoh/lib/python3.12/site-packages/google/api_core/timeout.py", line 130, in func_with_timeout
    return func(*args, **kwargs)
           ^^^^^^^^^^^^^^^^^^^^^
  File "/Users/macbook/miniconda3/envs/eoh/lib/python3.12/site-packages/google/api_core/grpc_helpers.py", line 78, in error_remapped_callable
    raise exceptions.from_grpc_error(exc) from exc
google.api_core.exceptions.ResourceExhausted: 429 You exceeded your current quota, please check your plan and billing details. For more information on this error, head to: https://ai.google.dev/gemini-api/docs/rate-limits. [violations {
  quota_metric: "generativelanguage.googleapis.com/generate_content_free_tier_requests"
  quota_id: "GenerateRequestsPerMinutePerProjectPerModel-FreeTier"
  quota_dimensions {
    key: "model"
    value: "gemini-1.5-flash"
  }
  quota_dimensions {
    key: "location"
    value: "global"
  }
  quota_value: 15
}
, links {
  description: "Learn more about Gemini API quotas"
  url: "https://ai.google.dev/gemini-api/docs/rate-limits"
}
, retry_delay {
  seconds: 4
}
]
.
2025-06-15 09:24:55 INFO An exception occured: Traceback (most recent call last):
  File "/Users/macbook/Documents/Code/LLMdesignedEA-comp/llamea/llamea_api_rotations.py", line 329, in evolve_solution
    evolved_individual = chosen_llm.sample_solution(
                         ^^^^^^^^^^^^^^^^^^^^^^^^^^^
  File "/Users/macbook/Documents/Code/LLMdesignedEA-comp/llamea/llm.py", line 106, in sample_solution
    message = self.query(session_messages)
              ^^^^^^^^^^^^^^^^^^^^^^^^^^^^
  File "/Users/macbook/Documents/Code/LLMdesignedEA-comp/llamea/llm.py", line 278, in query
    response = chat_session.send_message(last["content"])
               ^^^^^^^^^^^^^^^^^^^^^^^^^^^^^^^^^^^^^^^^^^
  File "/Users/macbook/miniconda3/envs/eoh/lib/python3.12/site-packages/google/generativeai/generative_models.py", line 578, in send_message
    response = self.model.generate_content(
               ^^^^^^^^^^^^^^^^^^^^^^^^^^^^
  File "/Users/macbook/miniconda3/envs/eoh/lib/python3.12/site-packages/google/generativeai/generative_models.py", line 331, in generate_content
    response = self._client.generate_content(
               ^^^^^^^^^^^^^^^^^^^^^^^^^^^^^^
  File "/Users/macbook/miniconda3/envs/eoh/lib/python3.12/site-packages/google/ai/generativelanguage_v1beta/services/generative_service/client.py", line 835, in generate_content
    response = rpc(
               ^^^^
  File "/Users/macbook/miniconda3/envs/eoh/lib/python3.12/site-packages/google/api_core/gapic_v1/method.py", line 131, in __call__
    return wrapped_func(*args, **kwargs)
           ^^^^^^^^^^^^^^^^^^^^^^^^^^^^^
  File "/Users/macbook/miniconda3/envs/eoh/lib/python3.12/site-packages/google/api_core/retry/retry_unary.py", line 294, in retry_wrapped_func
    return retry_target(
           ^^^^^^^^^^^^^
  File "/Users/macbook/miniconda3/envs/eoh/lib/python3.12/site-packages/google/api_core/retry/retry_unary.py", line 156, in retry_target
    next_sleep = _retry_error_helper(
                 ^^^^^^^^^^^^^^^^^^^^
  File "/Users/macbook/miniconda3/envs/eoh/lib/python3.12/site-packages/google/api_core/retry/retry_base.py", line 214, in _retry_error_helper
    raise final_exc from source_exc
  File "/Users/macbook/miniconda3/envs/eoh/lib/python3.12/site-packages/google/api_core/retry/retry_unary.py", line 147, in retry_target
    result = target()
             ^^^^^^^^
  File "/Users/macbook/miniconda3/envs/eoh/lib/python3.12/site-packages/google/api_core/timeout.py", line 130, in func_with_timeout
    return func(*args, **kwargs)
           ^^^^^^^^^^^^^^^^^^^^^
  File "/Users/macbook/miniconda3/envs/eoh/lib/python3.12/site-packages/google/api_core/grpc_helpers.py", line 78, in error_remapped_callable
    raise exceptions.from_grpc_error(exc) from exc
google.api_core.exceptions.ResourceExhausted: 429 You exceeded your current quota, please check your plan and billing details. For more information on this error, head to: https://ai.google.dev/gemini-api/docs/rate-limits. [violations {
  quota_metric: "generativelanguage.googleapis.com/generate_content_free_tier_requests"
  quota_id: "GenerateRequestsPerMinutePerProjectPerModel-FreeTier"
  quota_dimensions {
    key: "model"
    value: "gemini-1.5-flash"
  }
  quota_dimensions {
    key: "location"
    value: "global"
  }
  quota_value: 15
}
, links {
  description: "Learn more about Gemini API quotas"
  url: "https://ai.google.dev/gemini-api/docs/rate-limits"
}
, retry_delay {
  seconds: 4
}
]
.
2025-06-15 09:24:55 INFO An exception occured: Traceback (most recent call last):
  File "/Users/macbook/Documents/Code/LLMdesignedEA-comp/llamea/llamea_api_rotations.py", line 329, in evolve_solution
    evolved_individual = chosen_llm.sample_solution(
                         ^^^^^^^^^^^^^^^^^^^^^^^^^^^
  File "/Users/macbook/Documents/Code/LLMdesignedEA-comp/llamea/llm.py", line 106, in sample_solution
    message = self.query(session_messages)
              ^^^^^^^^^^^^^^^^^^^^^^^^^^^^
  File "/Users/macbook/Documents/Code/LLMdesignedEA-comp/llamea/llm.py", line 278, in query
    response = chat_session.send_message(last["content"])
               ^^^^^^^^^^^^^^^^^^^^^^^^^^^^^^^^^^^^^^^^^^
  File "/Users/macbook/miniconda3/envs/eoh/lib/python3.12/site-packages/google/generativeai/generative_models.py", line 578, in send_message
    response = self.model.generate_content(
               ^^^^^^^^^^^^^^^^^^^^^^^^^^^^
  File "/Users/macbook/miniconda3/envs/eoh/lib/python3.12/site-packages/google/generativeai/generative_models.py", line 331, in generate_content
    response = self._client.generate_content(
               ^^^^^^^^^^^^^^^^^^^^^^^^^^^^^^
  File "/Users/macbook/miniconda3/envs/eoh/lib/python3.12/site-packages/google/ai/generativelanguage_v1beta/services/generative_service/client.py", line 835, in generate_content
    response = rpc(
               ^^^^
  File "/Users/macbook/miniconda3/envs/eoh/lib/python3.12/site-packages/google/api_core/gapic_v1/method.py", line 131, in __call__
    return wrapped_func(*args, **kwargs)
           ^^^^^^^^^^^^^^^^^^^^^^^^^^^^^
  File "/Users/macbook/miniconda3/envs/eoh/lib/python3.12/site-packages/google/api_core/retry/retry_unary.py", line 294, in retry_wrapped_func
    return retry_target(
           ^^^^^^^^^^^^^
  File "/Users/macbook/miniconda3/envs/eoh/lib/python3.12/site-packages/google/api_core/retry/retry_unary.py", line 156, in retry_target
    next_sleep = _retry_error_helper(
                 ^^^^^^^^^^^^^^^^^^^^
  File "/Users/macbook/miniconda3/envs/eoh/lib/python3.12/site-packages/google/api_core/retry/retry_base.py", line 214, in _retry_error_helper
    raise final_exc from source_exc
  File "/Users/macbook/miniconda3/envs/eoh/lib/python3.12/site-packages/google/api_core/retry/retry_unary.py", line 147, in retry_target
    result = target()
             ^^^^^^^^
  File "/Users/macbook/miniconda3/envs/eoh/lib/python3.12/site-packages/google/api_core/timeout.py", line 130, in func_with_timeout
    return func(*args, **kwargs)
           ^^^^^^^^^^^^^^^^^^^^^
  File "/Users/macbook/miniconda3/envs/eoh/lib/python3.12/site-packages/google/api_core/grpc_helpers.py", line 78, in error_remapped_callable
    raise exceptions.from_grpc_error(exc) from exc
google.api_core.exceptions.ResourceExhausted: 429 You exceeded your current quota, please check your plan and billing details. For more information on this error, head to: https://ai.google.dev/gemini-api/docs/rate-limits. [violations {
  quota_metric: "generativelanguage.googleapis.com/generate_content_free_tier_requests"
  quota_id: "GenerateRequestsPerMinutePerProjectPerModel-FreeTier"
  quota_dimensions {
    key: "model"
    value: "gemini-1.5-flash"
  }
  quota_dimensions {
    key: "location"
    value: "global"
  }
  quota_value: 15
}
, links {
  description: "Learn more about Gemini API quotas"
  url: "https://ai.google.dev/gemini-api/docs/rate-limits"
}
, retry_delay {
  seconds: 4
}
]
.
2025-06-15 09:24:55 INFO An exception occured: Traceback (most recent call last):
  File "/Users/macbook/Documents/Code/LLMdesignedEA-comp/llamea/llamea_api_rotations.py", line 329, in evolve_solution
    evolved_individual = chosen_llm.sample_solution(
                         ^^^^^^^^^^^^^^^^^^^^^^^^^^^
  File "/Users/macbook/Documents/Code/LLMdesignedEA-comp/llamea/llm.py", line 106, in sample_solution
    message = self.query(session_messages)
              ^^^^^^^^^^^^^^^^^^^^^^^^^^^^
  File "/Users/macbook/Documents/Code/LLMdesignedEA-comp/llamea/llm.py", line 278, in query
    response = chat_session.send_message(last["content"])
               ^^^^^^^^^^^^^^^^^^^^^^^^^^^^^^^^^^^^^^^^^^
  File "/Users/macbook/miniconda3/envs/eoh/lib/python3.12/site-packages/google/generativeai/generative_models.py", line 578, in send_message
    response = self.model.generate_content(
               ^^^^^^^^^^^^^^^^^^^^^^^^^^^^
  File "/Users/macbook/miniconda3/envs/eoh/lib/python3.12/site-packages/google/generativeai/generative_models.py", line 331, in generate_content
    response = self._client.generate_content(
               ^^^^^^^^^^^^^^^^^^^^^^^^^^^^^^
  File "/Users/macbook/miniconda3/envs/eoh/lib/python3.12/site-packages/google/ai/generativelanguage_v1beta/services/generative_service/client.py", line 835, in generate_content
    response = rpc(
               ^^^^
  File "/Users/macbook/miniconda3/envs/eoh/lib/python3.12/site-packages/google/api_core/gapic_v1/method.py", line 131, in __call__
    return wrapped_func(*args, **kwargs)
           ^^^^^^^^^^^^^^^^^^^^^^^^^^^^^
  File "/Users/macbook/miniconda3/envs/eoh/lib/python3.12/site-packages/google/api_core/retry/retry_unary.py", line 294, in retry_wrapped_func
    return retry_target(
           ^^^^^^^^^^^^^
  File "/Users/macbook/miniconda3/envs/eoh/lib/python3.12/site-packages/google/api_core/retry/retry_unary.py", line 156, in retry_target
    next_sleep = _retry_error_helper(
                 ^^^^^^^^^^^^^^^^^^^^
  File "/Users/macbook/miniconda3/envs/eoh/lib/python3.12/site-packages/google/api_core/retry/retry_base.py", line 214, in _retry_error_helper
    raise final_exc from source_exc
  File "/Users/macbook/miniconda3/envs/eoh/lib/python3.12/site-packages/google/api_core/retry/retry_unary.py", line 147, in retry_target
    result = target()
             ^^^^^^^^
  File "/Users/macbook/miniconda3/envs/eoh/lib/python3.12/site-packages/google/api_core/timeout.py", line 130, in func_with_timeout
    return func(*args, **kwargs)
           ^^^^^^^^^^^^^^^^^^^^^
  File "/Users/macbook/miniconda3/envs/eoh/lib/python3.12/site-packages/google/api_core/grpc_helpers.py", line 78, in error_remapped_callable
    raise exceptions.from_grpc_error(exc) from exc
google.api_core.exceptions.ResourceExhausted: 429 You exceeded your current quota, please check your plan and billing details. For more information on this error, head to: https://ai.google.dev/gemini-api/docs/rate-limits. [violations {
  quota_metric: "generativelanguage.googleapis.com/generate_content_free_tier_requests"
  quota_id: "GenerateRequestsPerMinutePerProjectPerModel-FreeTier"
  quota_dimensions {
    key: "model"
    value: "gemini-1.5-flash"
  }
  quota_dimensions {
    key: "location"
    value: "global"
  }
  quota_value: 15
}
, links {
  description: "Learn more about Gemini API quotas"
  url: "https://ai.google.dev/gemini-api/docs/rate-limits"
}
, retry_delay {
  seconds: 4
}
]
.
2025-06-15 09:24:55 INFO An exception occured: Traceback (most recent call last):
  File "/Users/macbook/Documents/Code/LLMdesignedEA-comp/llamea/llamea_api_rotations.py", line 329, in evolve_solution
    evolved_individual = chosen_llm.sample_solution(
                         ^^^^^^^^^^^^^^^^^^^^^^^^^^^
  File "/Users/macbook/Documents/Code/LLMdesignedEA-comp/llamea/llm.py", line 106, in sample_solution
    message = self.query(session_messages)
              ^^^^^^^^^^^^^^^^^^^^^^^^^^^^
  File "/Users/macbook/Documents/Code/LLMdesignedEA-comp/llamea/llm.py", line 278, in query
    response = chat_session.send_message(last["content"])
               ^^^^^^^^^^^^^^^^^^^^^^^^^^^^^^^^^^^^^^^^^^
  File "/Users/macbook/miniconda3/envs/eoh/lib/python3.12/site-packages/google/generativeai/generative_models.py", line 578, in send_message
    response = self.model.generate_content(
               ^^^^^^^^^^^^^^^^^^^^^^^^^^^^
  File "/Users/macbook/miniconda3/envs/eoh/lib/python3.12/site-packages/google/generativeai/generative_models.py", line 331, in generate_content
    response = self._client.generate_content(
               ^^^^^^^^^^^^^^^^^^^^^^^^^^^^^^
  File "/Users/macbook/miniconda3/envs/eoh/lib/python3.12/site-packages/google/ai/generativelanguage_v1beta/services/generative_service/client.py", line 835, in generate_content
    response = rpc(
               ^^^^
  File "/Users/macbook/miniconda3/envs/eoh/lib/python3.12/site-packages/google/api_core/gapic_v1/method.py", line 131, in __call__
    return wrapped_func(*args, **kwargs)
           ^^^^^^^^^^^^^^^^^^^^^^^^^^^^^
  File "/Users/macbook/miniconda3/envs/eoh/lib/python3.12/site-packages/google/api_core/retry/retry_unary.py", line 294, in retry_wrapped_func
    return retry_target(
           ^^^^^^^^^^^^^
  File "/Users/macbook/miniconda3/envs/eoh/lib/python3.12/site-packages/google/api_core/retry/retry_unary.py", line 156, in retry_target
    next_sleep = _retry_error_helper(
                 ^^^^^^^^^^^^^^^^^^^^
  File "/Users/macbook/miniconda3/envs/eoh/lib/python3.12/site-packages/google/api_core/retry/retry_base.py", line 214, in _retry_error_helper
    raise final_exc from source_exc
  File "/Users/macbook/miniconda3/envs/eoh/lib/python3.12/site-packages/google/api_core/retry/retry_unary.py", line 147, in retry_target
    result = target()
             ^^^^^^^^
  File "/Users/macbook/miniconda3/envs/eoh/lib/python3.12/site-packages/google/api_core/timeout.py", line 130, in func_with_timeout
    return func(*args, **kwargs)
           ^^^^^^^^^^^^^^^^^^^^^
  File "/Users/macbook/miniconda3/envs/eoh/lib/python3.12/site-packages/google/api_core/grpc_helpers.py", line 78, in error_remapped_callable
    raise exceptions.from_grpc_error(exc) from exc
google.api_core.exceptions.ResourceExhausted: 429 You exceeded your current quota, please check your plan and billing details. For more information on this error, head to: https://ai.google.dev/gemini-api/docs/rate-limits. [violations {
  quota_metric: "generativelanguage.googleapis.com/generate_content_free_tier_requests"
  quota_id: "GenerateRequestsPerMinutePerProjectPerModel-FreeTier"
  quota_dimensions {
    key: "model"
    value: "gemini-1.5-flash"
  }
  quota_dimensions {
    key: "location"
    value: "global"
  }
  quota_value: 15
}
, links {
  description: "Learn more about Gemini API quotas"
  url: "https://ai.google.dev/gemini-api/docs/rate-limits"
}
, retry_delay {
  seconds: 4
}
]
.
2025-06-15 09:24:55 INFO Using LLM api key #AIzaSyAS4WrMPg7WNPXLpCYIOG49cIYOL7vTAl8)
2025-06-15 09:24:55 INFO Using LLM api key #AIzaSyARJfdVOsI9AKUK6gxvUszL_bn5Z_lr5Wg)
2025-06-15 09:24:55 INFO Using LLM api key #AIzaSyAEUmOe_NUQT_vGqRWH_9XnMDQuUe0CiKU)
2025-06-15 09:24:55 INFO Using LLM api key #AIzaSyAS4WrMPg7WNPXLpCYIOG49cIYOL7vTAl8)
2025-06-15 09:24:55 INFO Using LLM api key #AIzaSyARJfdVOsI9AKUK6gxvUszL_bn5Z_lr5Wg)
2025-06-15 09:24:55 INFO An exception occured: Traceback (most recent call last):
  File "/Users/macbook/Documents/Code/LLMdesignedEA-comp/llamea/llamea_api_rotations.py", line 329, in evolve_solution
    evolved_individual = chosen_llm.sample_solution(
                         ^^^^^^^^^^^^^^^^^^^^^^^^^^^
  File "/Users/macbook/Documents/Code/LLMdesignedEA-comp/llamea/llm.py", line 106, in sample_solution
    message = self.query(session_messages)
              ^^^^^^^^^^^^^^^^^^^^^^^^^^^^
  File "/Users/macbook/Documents/Code/LLMdesignedEA-comp/llamea/llm.py", line 278, in query
    response = chat_session.send_message(last["content"])
               ^^^^^^^^^^^^^^^^^^^^^^^^^^^^^^^^^^^^^^^^^^
  File "/Users/macbook/miniconda3/envs/eoh/lib/python3.12/site-packages/google/generativeai/generative_models.py", line 578, in send_message
    response = self.model.generate_content(
               ^^^^^^^^^^^^^^^^^^^^^^^^^^^^
  File "/Users/macbook/miniconda3/envs/eoh/lib/python3.12/site-packages/google/generativeai/generative_models.py", line 331, in generate_content
    response = self._client.generate_content(
               ^^^^^^^^^^^^^^^^^^^^^^^^^^^^^^
  File "/Users/macbook/miniconda3/envs/eoh/lib/python3.12/site-packages/google/ai/generativelanguage_v1beta/services/generative_service/client.py", line 835, in generate_content
    response = rpc(
               ^^^^
  File "/Users/macbook/miniconda3/envs/eoh/lib/python3.12/site-packages/google/api_core/gapic_v1/method.py", line 131, in __call__
    return wrapped_func(*args, **kwargs)
           ^^^^^^^^^^^^^^^^^^^^^^^^^^^^^
  File "/Users/macbook/miniconda3/envs/eoh/lib/python3.12/site-packages/google/api_core/retry/retry_unary.py", line 294, in retry_wrapped_func
    return retry_target(
           ^^^^^^^^^^^^^
  File "/Users/macbook/miniconda3/envs/eoh/lib/python3.12/site-packages/google/api_core/retry/retry_unary.py", line 156, in retry_target
    next_sleep = _retry_error_helper(
                 ^^^^^^^^^^^^^^^^^^^^
  File "/Users/macbook/miniconda3/envs/eoh/lib/python3.12/site-packages/google/api_core/retry/retry_base.py", line 214, in _retry_error_helper
    raise final_exc from source_exc
  File "/Users/macbook/miniconda3/envs/eoh/lib/python3.12/site-packages/google/api_core/retry/retry_unary.py", line 147, in retry_target
    result = target()
             ^^^^^^^^
  File "/Users/macbook/miniconda3/envs/eoh/lib/python3.12/site-packages/google/api_core/timeout.py", line 130, in func_with_timeout
    return func(*args, **kwargs)
           ^^^^^^^^^^^^^^^^^^^^^
  File "/Users/macbook/miniconda3/envs/eoh/lib/python3.12/site-packages/google/api_core/grpc_helpers.py", line 78, in error_remapped_callable
    raise exceptions.from_grpc_error(exc) from exc
google.api_core.exceptions.ResourceExhausted: 429 You exceeded your current quota, please check your plan and billing details. For more information on this error, head to: https://ai.google.dev/gemini-api/docs/rate-limits. [violations {
  quota_metric: "generativelanguage.googleapis.com/generate_content_free_tier_requests"
  quota_id: "GenerateRequestsPerMinutePerProjectPerModel-FreeTier"
  quota_dimensions {
    key: "model"
    value: "gemini-1.5-flash"
  }
  quota_dimensions {
    key: "location"
    value: "global"
  }
  quota_value: 15
}
, links {
  description: "Learn more about Gemini API quotas"
  url: "https://ai.google.dev/gemini-api/docs/rate-limits"
}
, retry_delay {
  seconds: 4
}
]
.
2025-06-15 09:24:55 INFO An exception occured: Traceback (most recent call last):
  File "/Users/macbook/Documents/Code/LLMdesignedEA-comp/llamea/llamea_api_rotations.py", line 329, in evolve_solution
    evolved_individual = chosen_llm.sample_solution(
                         ^^^^^^^^^^^^^^^^^^^^^^^^^^^
  File "/Users/macbook/Documents/Code/LLMdesignedEA-comp/llamea/llm.py", line 106, in sample_solution
    message = self.query(session_messages)
              ^^^^^^^^^^^^^^^^^^^^^^^^^^^^
  File "/Users/macbook/Documents/Code/LLMdesignedEA-comp/llamea/llm.py", line 278, in query
    response = chat_session.send_message(last["content"])
               ^^^^^^^^^^^^^^^^^^^^^^^^^^^^^^^^^^^^^^^^^^
  File "/Users/macbook/miniconda3/envs/eoh/lib/python3.12/site-packages/google/generativeai/generative_models.py", line 578, in send_message
    response = self.model.generate_content(
               ^^^^^^^^^^^^^^^^^^^^^^^^^^^^
  File "/Users/macbook/miniconda3/envs/eoh/lib/python3.12/site-packages/google/generativeai/generative_models.py", line 331, in generate_content
    response = self._client.generate_content(
               ^^^^^^^^^^^^^^^^^^^^^^^^^^^^^^
  File "/Users/macbook/miniconda3/envs/eoh/lib/python3.12/site-packages/google/ai/generativelanguage_v1beta/services/generative_service/client.py", line 835, in generate_content
    response = rpc(
               ^^^^
  File "/Users/macbook/miniconda3/envs/eoh/lib/python3.12/site-packages/google/api_core/gapic_v1/method.py", line 131, in __call__
    return wrapped_func(*args, **kwargs)
           ^^^^^^^^^^^^^^^^^^^^^^^^^^^^^
  File "/Users/macbook/miniconda3/envs/eoh/lib/python3.12/site-packages/google/api_core/retry/retry_unary.py", line 294, in retry_wrapped_func
    return retry_target(
           ^^^^^^^^^^^^^
  File "/Users/macbook/miniconda3/envs/eoh/lib/python3.12/site-packages/google/api_core/retry/retry_unary.py", line 156, in retry_target
    next_sleep = _retry_error_helper(
                 ^^^^^^^^^^^^^^^^^^^^
  File "/Users/macbook/miniconda3/envs/eoh/lib/python3.12/site-packages/google/api_core/retry/retry_base.py", line 214, in _retry_error_helper
    raise final_exc from source_exc
  File "/Users/macbook/miniconda3/envs/eoh/lib/python3.12/site-packages/google/api_core/retry/retry_unary.py", line 147, in retry_target
    result = target()
             ^^^^^^^^
  File "/Users/macbook/miniconda3/envs/eoh/lib/python3.12/site-packages/google/api_core/timeout.py", line 130, in func_with_timeout
    return func(*args, **kwargs)
           ^^^^^^^^^^^^^^^^^^^^^
  File "/Users/macbook/miniconda3/envs/eoh/lib/python3.12/site-packages/google/api_core/grpc_helpers.py", line 78, in error_remapped_callable
    raise exceptions.from_grpc_error(exc) from exc
google.api_core.exceptions.ResourceExhausted: 429 You exceeded your current quota, please check your plan and billing details. For more information on this error, head to: https://ai.google.dev/gemini-api/docs/rate-limits. [violations {
  quota_metric: "generativelanguage.googleapis.com/generate_content_free_tier_requests"
  quota_id: "GenerateRequestsPerMinutePerProjectPerModel-FreeTier"
  quota_dimensions {
    key: "model"
    value: "gemini-1.5-flash"
  }
  quota_dimensions {
    key: "location"
    value: "global"
  }
  quota_value: 15
}
, links {
  description: "Learn more about Gemini API quotas"
  url: "https://ai.google.dev/gemini-api/docs/rate-limits"
}
, retry_delay {
  seconds: 4
}
]
.
2025-06-15 09:24:55 INFO An exception occured: Traceback (most recent call last):
  File "/Users/macbook/Documents/Code/LLMdesignedEA-comp/llamea/llamea_api_rotations.py", line 329, in evolve_solution
    evolved_individual = chosen_llm.sample_solution(
                         ^^^^^^^^^^^^^^^^^^^^^^^^^^^
  File "/Users/macbook/Documents/Code/LLMdesignedEA-comp/llamea/llm.py", line 106, in sample_solution
    message = self.query(session_messages)
              ^^^^^^^^^^^^^^^^^^^^^^^^^^^^
  File "/Users/macbook/Documents/Code/LLMdesignedEA-comp/llamea/llm.py", line 278, in query
    response = chat_session.send_message(last["content"])
               ^^^^^^^^^^^^^^^^^^^^^^^^^^^^^^^^^^^^^^^^^^
  File "/Users/macbook/miniconda3/envs/eoh/lib/python3.12/site-packages/google/generativeai/generative_models.py", line 578, in send_message
    response = self.model.generate_content(
               ^^^^^^^^^^^^^^^^^^^^^^^^^^^^
  File "/Users/macbook/miniconda3/envs/eoh/lib/python3.12/site-packages/google/generativeai/generative_models.py", line 331, in generate_content
    response = self._client.generate_content(
               ^^^^^^^^^^^^^^^^^^^^^^^^^^^^^^
  File "/Users/macbook/miniconda3/envs/eoh/lib/python3.12/site-packages/google/ai/generativelanguage_v1beta/services/generative_service/client.py", line 835, in generate_content
    response = rpc(
               ^^^^
  File "/Users/macbook/miniconda3/envs/eoh/lib/python3.12/site-packages/google/api_core/gapic_v1/method.py", line 131, in __call__
    return wrapped_func(*args, **kwargs)
           ^^^^^^^^^^^^^^^^^^^^^^^^^^^^^
  File "/Users/macbook/miniconda3/envs/eoh/lib/python3.12/site-packages/google/api_core/retry/retry_unary.py", line 294, in retry_wrapped_func
    return retry_target(
           ^^^^^^^^^^^^^
  File "/Users/macbook/miniconda3/envs/eoh/lib/python3.12/site-packages/google/api_core/retry/retry_unary.py", line 156, in retry_target
    next_sleep = _retry_error_helper(
                 ^^^^^^^^^^^^^^^^^^^^
  File "/Users/macbook/miniconda3/envs/eoh/lib/python3.12/site-packages/google/api_core/retry/retry_base.py", line 214, in _retry_error_helper
    raise final_exc from source_exc
  File "/Users/macbook/miniconda3/envs/eoh/lib/python3.12/site-packages/google/api_core/retry/retry_unary.py", line 147, in retry_target
    result = target()
             ^^^^^^^^
  File "/Users/macbook/miniconda3/envs/eoh/lib/python3.12/site-packages/google/api_core/timeout.py", line 130, in func_with_timeout
    return func(*args, **kwargs)
           ^^^^^^^^^^^^^^^^^^^^^
  File "/Users/macbook/miniconda3/envs/eoh/lib/python3.12/site-packages/google/api_core/grpc_helpers.py", line 78, in error_remapped_callable
    raise exceptions.from_grpc_error(exc) from exc
google.api_core.exceptions.ResourceExhausted: 429 You exceeded your current quota, please check your plan and billing details. For more information on this error, head to: https://ai.google.dev/gemini-api/docs/rate-limits. [violations {
  quota_metric: "generativelanguage.googleapis.com/generate_content_free_tier_requests"
  quota_id: "GenerateRequestsPerMinutePerProjectPerModel-FreeTier"
  quota_dimensions {
    key: "model"
    value: "gemini-1.5-flash"
  }
  quota_dimensions {
    key: "location"
    value: "global"
  }
  quota_value: 15
}
, links {
  description: "Learn more about Gemini API quotas"
  url: "https://ai.google.dev/gemini-api/docs/rate-limits"
}
, retry_delay {
  seconds: 4
}
]
.
2025-06-15 09:24:55 INFO An exception occured: Traceback (most recent call last):
  File "/Users/macbook/Documents/Code/LLMdesignedEA-comp/llamea/llamea_api_rotations.py", line 329, in evolve_solution
    evolved_individual = chosen_llm.sample_solution(
                         ^^^^^^^^^^^^^^^^^^^^^^^^^^^
  File "/Users/macbook/Documents/Code/LLMdesignedEA-comp/llamea/llm.py", line 106, in sample_solution
    message = self.query(session_messages)
              ^^^^^^^^^^^^^^^^^^^^^^^^^^^^
  File "/Users/macbook/Documents/Code/LLMdesignedEA-comp/llamea/llm.py", line 278, in query
    response = chat_session.send_message(last["content"])
               ^^^^^^^^^^^^^^^^^^^^^^^^^^^^^^^^^^^^^^^^^^
  File "/Users/macbook/miniconda3/envs/eoh/lib/python3.12/site-packages/google/generativeai/generative_models.py", line 578, in send_message
    response = self.model.generate_content(
               ^^^^^^^^^^^^^^^^^^^^^^^^^^^^
  File "/Users/macbook/miniconda3/envs/eoh/lib/python3.12/site-packages/google/generativeai/generative_models.py", line 331, in generate_content
    response = self._client.generate_content(
               ^^^^^^^^^^^^^^^^^^^^^^^^^^^^^^
  File "/Users/macbook/miniconda3/envs/eoh/lib/python3.12/site-packages/google/ai/generativelanguage_v1beta/services/generative_service/client.py", line 835, in generate_content
    response = rpc(
               ^^^^
  File "/Users/macbook/miniconda3/envs/eoh/lib/python3.12/site-packages/google/api_core/gapic_v1/method.py", line 131, in __call__
    return wrapped_func(*args, **kwargs)
           ^^^^^^^^^^^^^^^^^^^^^^^^^^^^^
  File "/Users/macbook/miniconda3/envs/eoh/lib/python3.12/site-packages/google/api_core/retry/retry_unary.py", line 294, in retry_wrapped_func
    return retry_target(
           ^^^^^^^^^^^^^
  File "/Users/macbook/miniconda3/envs/eoh/lib/python3.12/site-packages/google/api_core/retry/retry_unary.py", line 156, in retry_target
    next_sleep = _retry_error_helper(
                 ^^^^^^^^^^^^^^^^^^^^
  File "/Users/macbook/miniconda3/envs/eoh/lib/python3.12/site-packages/google/api_core/retry/retry_base.py", line 214, in _retry_error_helper
    raise final_exc from source_exc
  File "/Users/macbook/miniconda3/envs/eoh/lib/python3.12/site-packages/google/api_core/retry/retry_unary.py", line 147, in retry_target
    result = target()
             ^^^^^^^^
  File "/Users/macbook/miniconda3/envs/eoh/lib/python3.12/site-packages/google/api_core/timeout.py", line 130, in func_with_timeout
    return func(*args, **kwargs)
           ^^^^^^^^^^^^^^^^^^^^^
  File "/Users/macbook/miniconda3/envs/eoh/lib/python3.12/site-packages/google/api_core/grpc_helpers.py", line 78, in error_remapped_callable
    raise exceptions.from_grpc_error(exc) from exc
google.api_core.exceptions.ResourceExhausted: 429 You exceeded your current quota, please check your plan and billing details. For more information on this error, head to: https://ai.google.dev/gemini-api/docs/rate-limits. [violations {
  quota_metric: "generativelanguage.googleapis.com/generate_content_free_tier_requests"
  quota_id: "GenerateRequestsPerMinutePerProjectPerModel-FreeTier"
  quota_dimensions {
    key: "model"
    value: "gemini-1.5-flash"
  }
  quota_dimensions {
    key: "location"
    value: "global"
  }
  quota_value: 15
}
, links {
  description: "Learn more about Gemini API quotas"
  url: "https://ai.google.dev/gemini-api/docs/rate-limits"
}
, retry_delay {
  seconds: 4
}
]
.
2025-06-15 09:24:55 INFO An exception occured: Traceback (most recent call last):
  File "/Users/macbook/Documents/Code/LLMdesignedEA-comp/llamea/llamea_api_rotations.py", line 329, in evolve_solution
    evolved_individual = chosen_llm.sample_solution(
                         ^^^^^^^^^^^^^^^^^^^^^^^^^^^
  File "/Users/macbook/Documents/Code/LLMdesignedEA-comp/llamea/llm.py", line 106, in sample_solution
    message = self.query(session_messages)
              ^^^^^^^^^^^^^^^^^^^^^^^^^^^^
  File "/Users/macbook/Documents/Code/LLMdesignedEA-comp/llamea/llm.py", line 278, in query
    response = chat_session.send_message(last["content"])
               ^^^^^^^^^^^^^^^^^^^^^^^^^^^^^^^^^^^^^^^^^^
  File "/Users/macbook/miniconda3/envs/eoh/lib/python3.12/site-packages/google/generativeai/generative_models.py", line 578, in send_message
    response = self.model.generate_content(
               ^^^^^^^^^^^^^^^^^^^^^^^^^^^^
  File "/Users/macbook/miniconda3/envs/eoh/lib/python3.12/site-packages/google/generativeai/generative_models.py", line 331, in generate_content
    response = self._client.generate_content(
               ^^^^^^^^^^^^^^^^^^^^^^^^^^^^^^
  File "/Users/macbook/miniconda3/envs/eoh/lib/python3.12/site-packages/google/ai/generativelanguage_v1beta/services/generative_service/client.py", line 835, in generate_content
    response = rpc(
               ^^^^
  File "/Users/macbook/miniconda3/envs/eoh/lib/python3.12/site-packages/google/api_core/gapic_v1/method.py", line 131, in __call__
    return wrapped_func(*args, **kwargs)
           ^^^^^^^^^^^^^^^^^^^^^^^^^^^^^
  File "/Users/macbook/miniconda3/envs/eoh/lib/python3.12/site-packages/google/api_core/retry/retry_unary.py", line 294, in retry_wrapped_func
    return retry_target(
           ^^^^^^^^^^^^^
  File "/Users/macbook/miniconda3/envs/eoh/lib/python3.12/site-packages/google/api_core/retry/retry_unary.py", line 156, in retry_target
    next_sleep = _retry_error_helper(
                 ^^^^^^^^^^^^^^^^^^^^
  File "/Users/macbook/miniconda3/envs/eoh/lib/python3.12/site-packages/google/api_core/retry/retry_base.py", line 214, in _retry_error_helper
    raise final_exc from source_exc
  File "/Users/macbook/miniconda3/envs/eoh/lib/python3.12/site-packages/google/api_core/retry/retry_unary.py", line 147, in retry_target
    result = target()
             ^^^^^^^^
  File "/Users/macbook/miniconda3/envs/eoh/lib/python3.12/site-packages/google/api_core/timeout.py", line 130, in func_with_timeout
    return func(*args, **kwargs)
           ^^^^^^^^^^^^^^^^^^^^^
  File "/Users/macbook/miniconda3/envs/eoh/lib/python3.12/site-packages/google/api_core/grpc_helpers.py", line 78, in error_remapped_callable
    raise exceptions.from_grpc_error(exc) from exc
google.api_core.exceptions.ResourceExhausted: 429 You exceeded your current quota, please check your plan and billing details. For more information on this error, head to: https://ai.google.dev/gemini-api/docs/rate-limits. [violations {
  quota_metric: "generativelanguage.googleapis.com/generate_content_free_tier_requests"
  quota_id: "GenerateRequestsPerMinutePerProjectPerModel-FreeTier"
  quota_dimensions {
    key: "model"
    value: "gemini-1.5-flash"
  }
  quota_dimensions {
    key: "location"
    value: "global"
  }
  quota_value: 15
}
, links {
  description: "Learn more about Gemini API quotas"
  url: "https://ai.google.dev/gemini-api/docs/rate-limits"
}
, retry_delay {
  seconds: 4
}
]
.
2025-06-15 09:24:55 INFO Using LLM api key #AIzaSyAS4WrMPg7WNPXLpCYIOG49cIYOL7vTAl8)
2025-06-15 09:24:55 INFO Using LLM api key #AIzaSyARJfdVOsI9AKUK6gxvUszL_bn5Z_lr5Wg)
2025-06-15 09:24:55 INFO Using LLM api key #AIzaSyCbA5uIXRIIWnTv7HCUGX75WoYJ4PeZWd0)
2025-06-15 09:24:56 INFO Using LLM api key #AIzaSyARJfdVOsI9AKUK6gxvUszL_bn5Z_lr5Wg)
2025-06-15 09:24:56 INFO Using LLM api key #AIzaSyAEUmOe_NUQT_vGqRWH_9XnMDQuUe0CiKU)
2025-06-15 09:24:56 INFO An exception occured: Traceback (most recent call last):
  File "/Users/macbook/Documents/Code/LLMdesignedEA-comp/llamea/llamea_api_rotations.py", line 329, in evolve_solution
    evolved_individual = chosen_llm.sample_solution(
                         ^^^^^^^^^^^^^^^^^^^^^^^^^^^
  File "/Users/macbook/Documents/Code/LLMdesignedEA-comp/llamea/llm.py", line 106, in sample_solution
    message = self.query(session_messages)
              ^^^^^^^^^^^^^^^^^^^^^^^^^^^^
  File "/Users/macbook/Documents/Code/LLMdesignedEA-comp/llamea/llm.py", line 278, in query
    response = chat_session.send_message(last["content"])
               ^^^^^^^^^^^^^^^^^^^^^^^^^^^^^^^^^^^^^^^^^^
  File "/Users/macbook/miniconda3/envs/eoh/lib/python3.12/site-packages/google/generativeai/generative_models.py", line 578, in send_message
    response = self.model.generate_content(
               ^^^^^^^^^^^^^^^^^^^^^^^^^^^^
  File "/Users/macbook/miniconda3/envs/eoh/lib/python3.12/site-packages/google/generativeai/generative_models.py", line 331, in generate_content
    response = self._client.generate_content(
               ^^^^^^^^^^^^^^^^^^^^^^^^^^^^^^
  File "/Users/macbook/miniconda3/envs/eoh/lib/python3.12/site-packages/google/ai/generativelanguage_v1beta/services/generative_service/client.py", line 835, in generate_content
    response = rpc(
               ^^^^
  File "/Users/macbook/miniconda3/envs/eoh/lib/python3.12/site-packages/google/api_core/gapic_v1/method.py", line 131, in __call__
    return wrapped_func(*args, **kwargs)
           ^^^^^^^^^^^^^^^^^^^^^^^^^^^^^
  File "/Users/macbook/miniconda3/envs/eoh/lib/python3.12/site-packages/google/api_core/retry/retry_unary.py", line 294, in retry_wrapped_func
    return retry_target(
           ^^^^^^^^^^^^^
  File "/Users/macbook/miniconda3/envs/eoh/lib/python3.12/site-packages/google/api_core/retry/retry_unary.py", line 156, in retry_target
    next_sleep = _retry_error_helper(
                 ^^^^^^^^^^^^^^^^^^^^
  File "/Users/macbook/miniconda3/envs/eoh/lib/python3.12/site-packages/google/api_core/retry/retry_base.py", line 214, in _retry_error_helper
    raise final_exc from source_exc
  File "/Users/macbook/miniconda3/envs/eoh/lib/python3.12/site-packages/google/api_core/retry/retry_unary.py", line 147, in retry_target
    result = target()
             ^^^^^^^^
  File "/Users/macbook/miniconda3/envs/eoh/lib/python3.12/site-packages/google/api_core/timeout.py", line 130, in func_with_timeout
    return func(*args, **kwargs)
           ^^^^^^^^^^^^^^^^^^^^^
  File "/Users/macbook/miniconda3/envs/eoh/lib/python3.12/site-packages/google/api_core/grpc_helpers.py", line 78, in error_remapped_callable
    raise exceptions.from_grpc_error(exc) from exc
google.api_core.exceptions.ResourceExhausted: 429 You exceeded your current quota, please check your plan and billing details. For more information on this error, head to: https://ai.google.dev/gemini-api/docs/rate-limits. [violations {
  quota_metric: "generativelanguage.googleapis.com/generate_content_free_tier_requests"
  quota_id: "GenerateRequestsPerMinutePerProjectPerModel-FreeTier"
  quota_dimensions {
    key: "model"
    value: "gemini-1.5-flash"
  }
  quota_dimensions {
    key: "location"
    value: "global"
  }
  quota_value: 15
}
, links {
  description: "Learn more about Gemini API quotas"
  url: "https://ai.google.dev/gemini-api/docs/rate-limits"
}
, retry_delay {
  seconds: 3
}
]
.
2025-06-15 09:24:56 INFO An exception occured: Traceback (most recent call last):
  File "/Users/macbook/Documents/Code/LLMdesignedEA-comp/llamea/llamea_api_rotations.py", line 329, in evolve_solution
    evolved_individual = chosen_llm.sample_solution(
                         ^^^^^^^^^^^^^^^^^^^^^^^^^^^
  File "/Users/macbook/Documents/Code/LLMdesignedEA-comp/llamea/llm.py", line 106, in sample_solution
    message = self.query(session_messages)
              ^^^^^^^^^^^^^^^^^^^^^^^^^^^^
  File "/Users/macbook/Documents/Code/LLMdesignedEA-comp/llamea/llm.py", line 278, in query
    response = chat_session.send_message(last["content"])
               ^^^^^^^^^^^^^^^^^^^^^^^^^^^^^^^^^^^^^^^^^^
  File "/Users/macbook/miniconda3/envs/eoh/lib/python3.12/site-packages/google/generativeai/generative_models.py", line 578, in send_message
    response = self.model.generate_content(
               ^^^^^^^^^^^^^^^^^^^^^^^^^^^^
  File "/Users/macbook/miniconda3/envs/eoh/lib/python3.12/site-packages/google/generativeai/generative_models.py", line 331, in generate_content
    response = self._client.generate_content(
               ^^^^^^^^^^^^^^^^^^^^^^^^^^^^^^
  File "/Users/macbook/miniconda3/envs/eoh/lib/python3.12/site-packages/google/ai/generativelanguage_v1beta/services/generative_service/client.py", line 835, in generate_content
    response = rpc(
               ^^^^
  File "/Users/macbook/miniconda3/envs/eoh/lib/python3.12/site-packages/google/api_core/gapic_v1/method.py", line 131, in __call__
    return wrapped_func(*args, **kwargs)
           ^^^^^^^^^^^^^^^^^^^^^^^^^^^^^
  File "/Users/macbook/miniconda3/envs/eoh/lib/python3.12/site-packages/google/api_core/retry/retry_unary.py", line 294, in retry_wrapped_func
    return retry_target(
           ^^^^^^^^^^^^^
  File "/Users/macbook/miniconda3/envs/eoh/lib/python3.12/site-packages/google/api_core/retry/retry_unary.py", line 156, in retry_target
    next_sleep = _retry_error_helper(
                 ^^^^^^^^^^^^^^^^^^^^
  File "/Users/macbook/miniconda3/envs/eoh/lib/python3.12/site-packages/google/api_core/retry/retry_base.py", line 214, in _retry_error_helper
    raise final_exc from source_exc
  File "/Users/macbook/miniconda3/envs/eoh/lib/python3.12/site-packages/google/api_core/retry/retry_unary.py", line 147, in retry_target
    result = target()
             ^^^^^^^^
  File "/Users/macbook/miniconda3/envs/eoh/lib/python3.12/site-packages/google/api_core/timeout.py", line 130, in func_with_timeout
    return func(*args, **kwargs)
           ^^^^^^^^^^^^^^^^^^^^^
  File "/Users/macbook/miniconda3/envs/eoh/lib/python3.12/site-packages/google/api_core/grpc_helpers.py", line 78, in error_remapped_callable
    raise exceptions.from_grpc_error(exc) from exc
google.api_core.exceptions.ResourceExhausted: 429 You exceeded your current quota, please check your plan and billing details. For more information on this error, head to: https://ai.google.dev/gemini-api/docs/rate-limits. [violations {
  quota_metric: "generativelanguage.googleapis.com/generate_content_free_tier_requests"
  quota_id: "GenerateRequestsPerMinutePerProjectPerModel-FreeTier"
  quota_dimensions {
    key: "model"
    value: "gemini-1.5-flash"
  }
  quota_dimensions {
    key: "location"
    value: "global"
  }
  quota_value: 15
}
, links {
  description: "Learn more about Gemini API quotas"
  url: "https://ai.google.dev/gemini-api/docs/rate-limits"
}
, retry_delay {
  seconds: 3
}
]
.
2025-06-15 09:24:56 INFO An exception occured: Traceback (most recent call last):
  File "/Users/macbook/Documents/Code/LLMdesignedEA-comp/llamea/llamea_api_rotations.py", line 329, in evolve_solution
    evolved_individual = chosen_llm.sample_solution(
                         ^^^^^^^^^^^^^^^^^^^^^^^^^^^
  File "/Users/macbook/Documents/Code/LLMdesignedEA-comp/llamea/llm.py", line 106, in sample_solution
    message = self.query(session_messages)
              ^^^^^^^^^^^^^^^^^^^^^^^^^^^^
  File "/Users/macbook/Documents/Code/LLMdesignedEA-comp/llamea/llm.py", line 278, in query
    response = chat_session.send_message(last["content"])
               ^^^^^^^^^^^^^^^^^^^^^^^^^^^^^^^^^^^^^^^^^^
  File "/Users/macbook/miniconda3/envs/eoh/lib/python3.12/site-packages/google/generativeai/generative_models.py", line 578, in send_message
    response = self.model.generate_content(
               ^^^^^^^^^^^^^^^^^^^^^^^^^^^^
  File "/Users/macbook/miniconda3/envs/eoh/lib/python3.12/site-packages/google/generativeai/generative_models.py", line 331, in generate_content
    response = self._client.generate_content(
               ^^^^^^^^^^^^^^^^^^^^^^^^^^^^^^
  File "/Users/macbook/miniconda3/envs/eoh/lib/python3.12/site-packages/google/ai/generativelanguage_v1beta/services/generative_service/client.py", line 835, in generate_content
    response = rpc(
               ^^^^
  File "/Users/macbook/miniconda3/envs/eoh/lib/python3.12/site-packages/google/api_core/gapic_v1/method.py", line 131, in __call__
    return wrapped_func(*args, **kwargs)
           ^^^^^^^^^^^^^^^^^^^^^^^^^^^^^
  File "/Users/macbook/miniconda3/envs/eoh/lib/python3.12/site-packages/google/api_core/retry/retry_unary.py", line 294, in retry_wrapped_func
    return retry_target(
           ^^^^^^^^^^^^^
  File "/Users/macbook/miniconda3/envs/eoh/lib/python3.12/site-packages/google/api_core/retry/retry_unary.py", line 156, in retry_target
    next_sleep = _retry_error_helper(
                 ^^^^^^^^^^^^^^^^^^^^
  File "/Users/macbook/miniconda3/envs/eoh/lib/python3.12/site-packages/google/api_core/retry/retry_base.py", line 214, in _retry_error_helper
    raise final_exc from source_exc
  File "/Users/macbook/miniconda3/envs/eoh/lib/python3.12/site-packages/google/api_core/retry/retry_unary.py", line 147, in retry_target
    result = target()
             ^^^^^^^^
  File "/Users/macbook/miniconda3/envs/eoh/lib/python3.12/site-packages/google/api_core/timeout.py", line 130, in func_with_timeout
    return func(*args, **kwargs)
           ^^^^^^^^^^^^^^^^^^^^^
  File "/Users/macbook/miniconda3/envs/eoh/lib/python3.12/site-packages/google/api_core/grpc_helpers.py", line 78, in error_remapped_callable
    raise exceptions.from_grpc_error(exc) from exc
google.api_core.exceptions.ResourceExhausted: 429 You exceeded your current quota, please check your plan and billing details. For more information on this error, head to: https://ai.google.dev/gemini-api/docs/rate-limits. [violations {
  quota_metric: "generativelanguage.googleapis.com/generate_content_free_tier_requests"
  quota_id: "GenerateRequestsPerMinutePerProjectPerModel-FreeTier"
  quota_dimensions {
    key: "model"
    value: "gemini-1.5-flash"
  }
  quota_dimensions {
    key: "location"
    value: "global"
  }
  quota_value: 15
}
, links {
  description: "Learn more about Gemini API quotas"
  url: "https://ai.google.dev/gemini-api/docs/rate-limits"
}
, retry_delay {
  seconds: 3
}
]
.
2025-06-15 09:24:56 INFO An exception occured: Traceback (most recent call last):
  File "/Users/macbook/Documents/Code/LLMdesignedEA-comp/llamea/llamea_api_rotations.py", line 329, in evolve_solution
    evolved_individual = chosen_llm.sample_solution(
                         ^^^^^^^^^^^^^^^^^^^^^^^^^^^
  File "/Users/macbook/Documents/Code/LLMdesignedEA-comp/llamea/llm.py", line 106, in sample_solution
    message = self.query(session_messages)
              ^^^^^^^^^^^^^^^^^^^^^^^^^^^^
  File "/Users/macbook/Documents/Code/LLMdesignedEA-comp/llamea/llm.py", line 278, in query
    response = chat_session.send_message(last["content"])
               ^^^^^^^^^^^^^^^^^^^^^^^^^^^^^^^^^^^^^^^^^^
  File "/Users/macbook/miniconda3/envs/eoh/lib/python3.12/site-packages/google/generativeai/generative_models.py", line 578, in send_message
    response = self.model.generate_content(
               ^^^^^^^^^^^^^^^^^^^^^^^^^^^^
  File "/Users/macbook/miniconda3/envs/eoh/lib/python3.12/site-packages/google/generativeai/generative_models.py", line 331, in generate_content
    response = self._client.generate_content(
               ^^^^^^^^^^^^^^^^^^^^^^^^^^^^^^
  File "/Users/macbook/miniconda3/envs/eoh/lib/python3.12/site-packages/google/ai/generativelanguage_v1beta/services/generative_service/client.py", line 835, in generate_content
    response = rpc(
               ^^^^
  File "/Users/macbook/miniconda3/envs/eoh/lib/python3.12/site-packages/google/api_core/gapic_v1/method.py", line 131, in __call__
    return wrapped_func(*args, **kwargs)
           ^^^^^^^^^^^^^^^^^^^^^^^^^^^^^
  File "/Users/macbook/miniconda3/envs/eoh/lib/python3.12/site-packages/google/api_core/retry/retry_unary.py", line 294, in retry_wrapped_func
    return retry_target(
           ^^^^^^^^^^^^^
  File "/Users/macbook/miniconda3/envs/eoh/lib/python3.12/site-packages/google/api_core/retry/retry_unary.py", line 156, in retry_target
    next_sleep = _retry_error_helper(
                 ^^^^^^^^^^^^^^^^^^^^
  File "/Users/macbook/miniconda3/envs/eoh/lib/python3.12/site-packages/google/api_core/retry/retry_base.py", line 214, in _retry_error_helper
    raise final_exc from source_exc
  File "/Users/macbook/miniconda3/envs/eoh/lib/python3.12/site-packages/google/api_core/retry/retry_unary.py", line 147, in retry_target
    result = target()
             ^^^^^^^^
  File "/Users/macbook/miniconda3/envs/eoh/lib/python3.12/site-packages/google/api_core/timeout.py", line 130, in func_with_timeout
    return func(*args, **kwargs)
           ^^^^^^^^^^^^^^^^^^^^^
  File "/Users/macbook/miniconda3/envs/eoh/lib/python3.12/site-packages/google/api_core/grpc_helpers.py", line 78, in error_remapped_callable
    raise exceptions.from_grpc_error(exc) from exc
google.api_core.exceptions.ResourceExhausted: 429 You exceeded your current quota, please check your plan and billing details. For more information on this error, head to: https://ai.google.dev/gemini-api/docs/rate-limits. [violations {
  quota_metric: "generativelanguage.googleapis.com/generate_content_free_tier_requests"
  quota_id: "GenerateRequestsPerMinutePerProjectPerModel-FreeTier"
  quota_dimensions {
    key: "model"
    value: "gemini-1.5-flash"
  }
  quota_dimensions {
    key: "location"
    value: "global"
  }
  quota_value: 15
}
, links {
  description: "Learn more about Gemini API quotas"
  url: "https://ai.google.dev/gemini-api/docs/rate-limits"
}
, retry_delay {
  seconds: 3
}
]
.
2025-06-15 09:24:56 INFO An exception occured: Traceback (most recent call last):
  File "/Users/macbook/Documents/Code/LLMdesignedEA-comp/llamea/llamea_api_rotations.py", line 329, in evolve_solution
    evolved_individual = chosen_llm.sample_solution(
                         ^^^^^^^^^^^^^^^^^^^^^^^^^^^
  File "/Users/macbook/Documents/Code/LLMdesignedEA-comp/llamea/llm.py", line 106, in sample_solution
    message = self.query(session_messages)
              ^^^^^^^^^^^^^^^^^^^^^^^^^^^^
  File "/Users/macbook/Documents/Code/LLMdesignedEA-comp/llamea/llm.py", line 278, in query
    response = chat_session.send_message(last["content"])
               ^^^^^^^^^^^^^^^^^^^^^^^^^^^^^^^^^^^^^^^^^^
  File "/Users/macbook/miniconda3/envs/eoh/lib/python3.12/site-packages/google/generativeai/generative_models.py", line 578, in send_message
    response = self.model.generate_content(
               ^^^^^^^^^^^^^^^^^^^^^^^^^^^^
  File "/Users/macbook/miniconda3/envs/eoh/lib/python3.12/site-packages/google/generativeai/generative_models.py", line 331, in generate_content
    response = self._client.generate_content(
               ^^^^^^^^^^^^^^^^^^^^^^^^^^^^^^
  File "/Users/macbook/miniconda3/envs/eoh/lib/python3.12/site-packages/google/ai/generativelanguage_v1beta/services/generative_service/client.py", line 835, in generate_content
    response = rpc(
               ^^^^
  File "/Users/macbook/miniconda3/envs/eoh/lib/python3.12/site-packages/google/api_core/gapic_v1/method.py", line 131, in __call__
    return wrapped_func(*args, **kwargs)
           ^^^^^^^^^^^^^^^^^^^^^^^^^^^^^
  File "/Users/macbook/miniconda3/envs/eoh/lib/python3.12/site-packages/google/api_core/retry/retry_unary.py", line 294, in retry_wrapped_func
    return retry_target(
           ^^^^^^^^^^^^^
  File "/Users/macbook/miniconda3/envs/eoh/lib/python3.12/site-packages/google/api_core/retry/retry_unary.py", line 156, in retry_target
    next_sleep = _retry_error_helper(
                 ^^^^^^^^^^^^^^^^^^^^
  File "/Users/macbook/miniconda3/envs/eoh/lib/python3.12/site-packages/google/api_core/retry/retry_base.py", line 214, in _retry_error_helper
    raise final_exc from source_exc
  File "/Users/macbook/miniconda3/envs/eoh/lib/python3.12/site-packages/google/api_core/retry/retry_unary.py", line 147, in retry_target
    result = target()
             ^^^^^^^^
  File "/Users/macbook/miniconda3/envs/eoh/lib/python3.12/site-packages/google/api_core/timeout.py", line 130, in func_with_timeout
    return func(*args, **kwargs)
           ^^^^^^^^^^^^^^^^^^^^^
  File "/Users/macbook/miniconda3/envs/eoh/lib/python3.12/site-packages/google/api_core/grpc_helpers.py", line 78, in error_remapped_callable
    raise exceptions.from_grpc_error(exc) from exc
google.api_core.exceptions.ResourceExhausted: 429 You exceeded your current quota, please check your plan and billing details. For more information on this error, head to: https://ai.google.dev/gemini-api/docs/rate-limits. [violations {
  quota_metric: "generativelanguage.googleapis.com/generate_content_free_tier_requests"
  quota_id: "GenerateRequestsPerMinutePerProjectPerModel-FreeTier"
  quota_dimensions {
    key: "model"
    value: "gemini-1.5-flash"
  }
  quota_dimensions {
    key: "location"
    value: "global"
  }
  quota_value: 15
}
, links {
  description: "Learn more about Gemini API quotas"
  url: "https://ai.google.dev/gemini-api/docs/rate-limits"
}
, retry_delay {
  seconds: 3
}
]
.
2025-06-15 09:24:56 INFO Using LLM api key #AIzaSyARJfdVOsI9AKUK6gxvUszL_bn5Z_lr5Wg)
2025-06-15 09:24:56 INFO Using LLM api key #AIzaSyAEUmOe_NUQT_vGqRWH_9XnMDQuUe0CiKU)
2025-06-15 09:24:56 INFO Using LLM api key #AIzaSyCbA5uIXRIIWnTv7HCUGX75WoYJ4PeZWd0)
2025-06-15 09:24:56 INFO Using LLM api key #AIzaSyAS4WrMPg7WNPXLpCYIOG49cIYOL7vTAl8)
2025-06-15 09:24:56 INFO Using LLM api key #AIzaSyAS4WrMPg7WNPXLpCYIOG49cIYOL7vTAl8)
2025-06-15 09:24:57 INFO An exception occured: Traceback (most recent call last):
  File "/Users/macbook/Documents/Code/LLMdesignedEA-comp/llamea/llamea_api_rotations.py", line 329, in evolve_solution
    evolved_individual = chosen_llm.sample_solution(
                         ^^^^^^^^^^^^^^^^^^^^^^^^^^^
  File "/Users/macbook/Documents/Code/LLMdesignedEA-comp/llamea/llm.py", line 106, in sample_solution
    message = self.query(session_messages)
              ^^^^^^^^^^^^^^^^^^^^^^^^^^^^
  File "/Users/macbook/Documents/Code/LLMdesignedEA-comp/llamea/llm.py", line 278, in query
    response = chat_session.send_message(last["content"])
               ^^^^^^^^^^^^^^^^^^^^^^^^^^^^^^^^^^^^^^^^^^
  File "/Users/macbook/miniconda3/envs/eoh/lib/python3.12/site-packages/google/generativeai/generative_models.py", line 578, in send_message
    response = self.model.generate_content(
               ^^^^^^^^^^^^^^^^^^^^^^^^^^^^
  File "/Users/macbook/miniconda3/envs/eoh/lib/python3.12/site-packages/google/generativeai/generative_models.py", line 331, in generate_content
    response = self._client.generate_content(
               ^^^^^^^^^^^^^^^^^^^^^^^^^^^^^^
  File "/Users/macbook/miniconda3/envs/eoh/lib/python3.12/site-packages/google/ai/generativelanguage_v1beta/services/generative_service/client.py", line 835, in generate_content
    response = rpc(
               ^^^^
  File "/Users/macbook/miniconda3/envs/eoh/lib/python3.12/site-packages/google/api_core/gapic_v1/method.py", line 131, in __call__
    return wrapped_func(*args, **kwargs)
           ^^^^^^^^^^^^^^^^^^^^^^^^^^^^^
  File "/Users/macbook/miniconda3/envs/eoh/lib/python3.12/site-packages/google/api_core/retry/retry_unary.py", line 294, in retry_wrapped_func
    return retry_target(
           ^^^^^^^^^^^^^
  File "/Users/macbook/miniconda3/envs/eoh/lib/python3.12/site-packages/google/api_core/retry/retry_unary.py", line 156, in retry_target
    next_sleep = _retry_error_helper(
                 ^^^^^^^^^^^^^^^^^^^^
  File "/Users/macbook/miniconda3/envs/eoh/lib/python3.12/site-packages/google/api_core/retry/retry_base.py", line 214, in _retry_error_helper
    raise final_exc from source_exc
  File "/Users/macbook/miniconda3/envs/eoh/lib/python3.12/site-packages/google/api_core/retry/retry_unary.py", line 147, in retry_target
    result = target()
             ^^^^^^^^
  File "/Users/macbook/miniconda3/envs/eoh/lib/python3.12/site-packages/google/api_core/timeout.py", line 130, in func_with_timeout
    return func(*args, **kwargs)
           ^^^^^^^^^^^^^^^^^^^^^
  File "/Users/macbook/miniconda3/envs/eoh/lib/python3.12/site-packages/google/api_core/grpc_helpers.py", line 78, in error_remapped_callable
    raise exceptions.from_grpc_error(exc) from exc
google.api_core.exceptions.ResourceExhausted: 429 You exceeded your current quota, please check your plan and billing details. For more information on this error, head to: https://ai.google.dev/gemini-api/docs/rate-limits. [violations {
  quota_metric: "generativelanguage.googleapis.com/generate_content_free_tier_requests"
  quota_id: "GenerateRequestsPerMinutePerProjectPerModel-FreeTier"
  quota_dimensions {
    key: "model"
    value: "gemini-1.5-flash"
  }
  quota_dimensions {
    key: "location"
    value: "global"
  }
  quota_value: 15
}
, links {
  description: "Learn more about Gemini API quotas"
  url: "https://ai.google.dev/gemini-api/docs/rate-limits"
}
, retry_delay {
  seconds: 2
}
]
.
2025-06-15 09:24:57 INFO An exception occured: Traceback (most recent call last):
  File "/Users/macbook/Documents/Code/LLMdesignedEA-comp/llamea/llamea_api_rotations.py", line 329, in evolve_solution
    evolved_individual = chosen_llm.sample_solution(
                         ^^^^^^^^^^^^^^^^^^^^^^^^^^^
  File "/Users/macbook/Documents/Code/LLMdesignedEA-comp/llamea/llm.py", line 106, in sample_solution
    message = self.query(session_messages)
              ^^^^^^^^^^^^^^^^^^^^^^^^^^^^
  File "/Users/macbook/Documents/Code/LLMdesignedEA-comp/llamea/llm.py", line 278, in query
    response = chat_session.send_message(last["content"])
               ^^^^^^^^^^^^^^^^^^^^^^^^^^^^^^^^^^^^^^^^^^
  File "/Users/macbook/miniconda3/envs/eoh/lib/python3.12/site-packages/google/generativeai/generative_models.py", line 578, in send_message
    response = self.model.generate_content(
               ^^^^^^^^^^^^^^^^^^^^^^^^^^^^
  File "/Users/macbook/miniconda3/envs/eoh/lib/python3.12/site-packages/google/generativeai/generative_models.py", line 331, in generate_content
    response = self._client.generate_content(
               ^^^^^^^^^^^^^^^^^^^^^^^^^^^^^^
  File "/Users/macbook/miniconda3/envs/eoh/lib/python3.12/site-packages/google/ai/generativelanguage_v1beta/services/generative_service/client.py", line 835, in generate_content
    response = rpc(
               ^^^^
  File "/Users/macbook/miniconda3/envs/eoh/lib/python3.12/site-packages/google/api_core/gapic_v1/method.py", line 131, in __call__
    return wrapped_func(*args, **kwargs)
           ^^^^^^^^^^^^^^^^^^^^^^^^^^^^^
  File "/Users/macbook/miniconda3/envs/eoh/lib/python3.12/site-packages/google/api_core/retry/retry_unary.py", line 294, in retry_wrapped_func
    return retry_target(
           ^^^^^^^^^^^^^
  File "/Users/macbook/miniconda3/envs/eoh/lib/python3.12/site-packages/google/api_core/retry/retry_unary.py", line 156, in retry_target
    next_sleep = _retry_error_helper(
                 ^^^^^^^^^^^^^^^^^^^^
  File "/Users/macbook/miniconda3/envs/eoh/lib/python3.12/site-packages/google/api_core/retry/retry_base.py", line 214, in _retry_error_helper
    raise final_exc from source_exc
  File "/Users/macbook/miniconda3/envs/eoh/lib/python3.12/site-packages/google/api_core/retry/retry_unary.py", line 147, in retry_target
    result = target()
             ^^^^^^^^
  File "/Users/macbook/miniconda3/envs/eoh/lib/python3.12/site-packages/google/api_core/timeout.py", line 130, in func_with_timeout
    return func(*args, **kwargs)
           ^^^^^^^^^^^^^^^^^^^^^
  File "/Users/macbook/miniconda3/envs/eoh/lib/python3.12/site-packages/google/api_core/grpc_helpers.py", line 78, in error_remapped_callable
    raise exceptions.from_grpc_error(exc) from exc
google.api_core.exceptions.ResourceExhausted: 429 You exceeded your current quota, please check your plan and billing details. For more information on this error, head to: https://ai.google.dev/gemini-api/docs/rate-limits. [violations {
  quota_metric: "generativelanguage.googleapis.com/generate_content_free_tier_requests"
  quota_id: "GenerateRequestsPerMinutePerProjectPerModel-FreeTier"
  quota_dimensions {
    key: "model"
    value: "gemini-1.5-flash"
  }
  quota_dimensions {
    key: "location"
    value: "global"
  }
  quota_value: 15
}
, links {
  description: "Learn more about Gemini API quotas"
  url: "https://ai.google.dev/gemini-api/docs/rate-limits"
}
, retry_delay {
  seconds: 2
}
]
.
2025-06-15 09:24:57 INFO An exception occured: Traceback (most recent call last):
  File "/Users/macbook/Documents/Code/LLMdesignedEA-comp/llamea/llamea_api_rotations.py", line 329, in evolve_solution
    evolved_individual = chosen_llm.sample_solution(
                         ^^^^^^^^^^^^^^^^^^^^^^^^^^^
  File "/Users/macbook/Documents/Code/LLMdesignedEA-comp/llamea/llm.py", line 106, in sample_solution
    message = self.query(session_messages)
              ^^^^^^^^^^^^^^^^^^^^^^^^^^^^
  File "/Users/macbook/Documents/Code/LLMdesignedEA-comp/llamea/llm.py", line 278, in query
    response = chat_session.send_message(last["content"])
               ^^^^^^^^^^^^^^^^^^^^^^^^^^^^^^^^^^^^^^^^^^
  File "/Users/macbook/miniconda3/envs/eoh/lib/python3.12/site-packages/google/generativeai/generative_models.py", line 578, in send_message
    response = self.model.generate_content(
               ^^^^^^^^^^^^^^^^^^^^^^^^^^^^
  File "/Users/macbook/miniconda3/envs/eoh/lib/python3.12/site-packages/google/generativeai/generative_models.py", line 331, in generate_content
    response = self._client.generate_content(
               ^^^^^^^^^^^^^^^^^^^^^^^^^^^^^^
  File "/Users/macbook/miniconda3/envs/eoh/lib/python3.12/site-packages/google/ai/generativelanguage_v1beta/services/generative_service/client.py", line 835, in generate_content
    response = rpc(
               ^^^^
  File "/Users/macbook/miniconda3/envs/eoh/lib/python3.12/site-packages/google/api_core/gapic_v1/method.py", line 131, in __call__
    return wrapped_func(*args, **kwargs)
           ^^^^^^^^^^^^^^^^^^^^^^^^^^^^^
  File "/Users/macbook/miniconda3/envs/eoh/lib/python3.12/site-packages/google/api_core/retry/retry_unary.py", line 294, in retry_wrapped_func
    return retry_target(
           ^^^^^^^^^^^^^
  File "/Users/macbook/miniconda3/envs/eoh/lib/python3.12/site-packages/google/api_core/retry/retry_unary.py", line 156, in retry_target
    next_sleep = _retry_error_helper(
                 ^^^^^^^^^^^^^^^^^^^^
  File "/Users/macbook/miniconda3/envs/eoh/lib/python3.12/site-packages/google/api_core/retry/retry_base.py", line 214, in _retry_error_helper
    raise final_exc from source_exc
  File "/Users/macbook/miniconda3/envs/eoh/lib/python3.12/site-packages/google/api_core/retry/retry_unary.py", line 147, in retry_target
    result = target()
             ^^^^^^^^
  File "/Users/macbook/miniconda3/envs/eoh/lib/python3.12/site-packages/google/api_core/timeout.py", line 130, in func_with_timeout
    return func(*args, **kwargs)
           ^^^^^^^^^^^^^^^^^^^^^
  File "/Users/macbook/miniconda3/envs/eoh/lib/python3.12/site-packages/google/api_core/grpc_helpers.py", line 78, in error_remapped_callable
    raise exceptions.from_grpc_error(exc) from exc
google.api_core.exceptions.ResourceExhausted: 429 You exceeded your current quota, please check your plan and billing details. For more information on this error, head to: https://ai.google.dev/gemini-api/docs/rate-limits. [violations {
  quota_metric: "generativelanguage.googleapis.com/generate_content_free_tier_requests"
  quota_id: "GenerateRequestsPerMinutePerProjectPerModel-FreeTier"
  quota_dimensions {
    key: "model"
    value: "gemini-1.5-flash"
  }
  quota_dimensions {
    key: "location"
    value: "global"
  }
  quota_value: 15
}
, links {
  description: "Learn more about Gemini API quotas"
  url: "https://ai.google.dev/gemini-api/docs/rate-limits"
}
, retry_delay {
  seconds: 2
}
]
.
2025-06-15 09:24:57 INFO An exception occured: Traceback (most recent call last):
  File "/Users/macbook/Documents/Code/LLMdesignedEA-comp/llamea/llamea_api_rotations.py", line 329, in evolve_solution
    evolved_individual = chosen_llm.sample_solution(
                         ^^^^^^^^^^^^^^^^^^^^^^^^^^^
  File "/Users/macbook/Documents/Code/LLMdesignedEA-comp/llamea/llm.py", line 106, in sample_solution
    message = self.query(session_messages)
              ^^^^^^^^^^^^^^^^^^^^^^^^^^^^
  File "/Users/macbook/Documents/Code/LLMdesignedEA-comp/llamea/llm.py", line 278, in query
    response = chat_session.send_message(last["content"])
               ^^^^^^^^^^^^^^^^^^^^^^^^^^^^^^^^^^^^^^^^^^
  File "/Users/macbook/miniconda3/envs/eoh/lib/python3.12/site-packages/google/generativeai/generative_models.py", line 578, in send_message
    response = self.model.generate_content(
               ^^^^^^^^^^^^^^^^^^^^^^^^^^^^
  File "/Users/macbook/miniconda3/envs/eoh/lib/python3.12/site-packages/google/generativeai/generative_models.py", line 331, in generate_content
    response = self._client.generate_content(
               ^^^^^^^^^^^^^^^^^^^^^^^^^^^^^^
  File "/Users/macbook/miniconda3/envs/eoh/lib/python3.12/site-packages/google/ai/generativelanguage_v1beta/services/generative_service/client.py", line 835, in generate_content
    response = rpc(
               ^^^^
  File "/Users/macbook/miniconda3/envs/eoh/lib/python3.12/site-packages/google/api_core/gapic_v1/method.py", line 131, in __call__
    return wrapped_func(*args, **kwargs)
           ^^^^^^^^^^^^^^^^^^^^^^^^^^^^^
  File "/Users/macbook/miniconda3/envs/eoh/lib/python3.12/site-packages/google/api_core/retry/retry_unary.py", line 294, in retry_wrapped_func
    return retry_target(
           ^^^^^^^^^^^^^
  File "/Users/macbook/miniconda3/envs/eoh/lib/python3.12/site-packages/google/api_core/retry/retry_unary.py", line 156, in retry_target
    next_sleep = _retry_error_helper(
                 ^^^^^^^^^^^^^^^^^^^^
  File "/Users/macbook/miniconda3/envs/eoh/lib/python3.12/site-packages/google/api_core/retry/retry_base.py", line 214, in _retry_error_helper
    raise final_exc from source_exc
  File "/Users/macbook/miniconda3/envs/eoh/lib/python3.12/site-packages/google/api_core/retry/retry_unary.py", line 147, in retry_target
    result = target()
             ^^^^^^^^
  File "/Users/macbook/miniconda3/envs/eoh/lib/python3.12/site-packages/google/api_core/timeout.py", line 130, in func_with_timeout
    return func(*args, **kwargs)
           ^^^^^^^^^^^^^^^^^^^^^
  File "/Users/macbook/miniconda3/envs/eoh/lib/python3.12/site-packages/google/api_core/grpc_helpers.py", line 78, in error_remapped_callable
    raise exceptions.from_grpc_error(exc) from exc
google.api_core.exceptions.ResourceExhausted: 429 You exceeded your current quota, please check your plan and billing details. For more information on this error, head to: https://ai.google.dev/gemini-api/docs/rate-limits. [violations {
  quota_metric: "generativelanguage.googleapis.com/generate_content_free_tier_requests"
  quota_id: "GenerateRequestsPerMinutePerProjectPerModel-FreeTier"
  quota_dimensions {
    key: "model"
    value: "gemini-1.5-flash"
  }
  quota_dimensions {
    key: "location"
    value: "global"
  }
  quota_value: 15
}
, links {
  description: "Learn more about Gemini API quotas"
  url: "https://ai.google.dev/gemini-api/docs/rate-limits"
}
, retry_delay {
  seconds: 2
}
]
.
2025-06-15 09:24:57 INFO An exception occured: Traceback (most recent call last):
  File "/Users/macbook/Documents/Code/LLMdesignedEA-comp/llamea/llamea_api_rotations.py", line 329, in evolve_solution
    evolved_individual = chosen_llm.sample_solution(
                         ^^^^^^^^^^^^^^^^^^^^^^^^^^^
  File "/Users/macbook/Documents/Code/LLMdesignedEA-comp/llamea/llm.py", line 106, in sample_solution
    message = self.query(session_messages)
              ^^^^^^^^^^^^^^^^^^^^^^^^^^^^
  File "/Users/macbook/Documents/Code/LLMdesignedEA-comp/llamea/llm.py", line 278, in query
    response = chat_session.send_message(last["content"])
               ^^^^^^^^^^^^^^^^^^^^^^^^^^^^^^^^^^^^^^^^^^
  File "/Users/macbook/miniconda3/envs/eoh/lib/python3.12/site-packages/google/generativeai/generative_models.py", line 578, in send_message
    response = self.model.generate_content(
               ^^^^^^^^^^^^^^^^^^^^^^^^^^^^
  File "/Users/macbook/miniconda3/envs/eoh/lib/python3.12/site-packages/google/generativeai/generative_models.py", line 331, in generate_content
    response = self._client.generate_content(
               ^^^^^^^^^^^^^^^^^^^^^^^^^^^^^^
  File "/Users/macbook/miniconda3/envs/eoh/lib/python3.12/site-packages/google/ai/generativelanguage_v1beta/services/generative_service/client.py", line 835, in generate_content
    response = rpc(
               ^^^^
  File "/Users/macbook/miniconda3/envs/eoh/lib/python3.12/site-packages/google/api_core/gapic_v1/method.py", line 131, in __call__
    return wrapped_func(*args, **kwargs)
           ^^^^^^^^^^^^^^^^^^^^^^^^^^^^^
  File "/Users/macbook/miniconda3/envs/eoh/lib/python3.12/site-packages/google/api_core/retry/retry_unary.py", line 294, in retry_wrapped_func
    return retry_target(
           ^^^^^^^^^^^^^
  File "/Users/macbook/miniconda3/envs/eoh/lib/python3.12/site-packages/google/api_core/retry/retry_unary.py", line 156, in retry_target
    next_sleep = _retry_error_helper(
                 ^^^^^^^^^^^^^^^^^^^^
  File "/Users/macbook/miniconda3/envs/eoh/lib/python3.12/site-packages/google/api_core/retry/retry_base.py", line 214, in _retry_error_helper
    raise final_exc from source_exc
  File "/Users/macbook/miniconda3/envs/eoh/lib/python3.12/site-packages/google/api_core/retry/retry_unary.py", line 147, in retry_target
    result = target()
             ^^^^^^^^
  File "/Users/macbook/miniconda3/envs/eoh/lib/python3.12/site-packages/google/api_core/timeout.py", line 130, in func_with_timeout
    return func(*args, **kwargs)
           ^^^^^^^^^^^^^^^^^^^^^
  File "/Users/macbook/miniconda3/envs/eoh/lib/python3.12/site-packages/google/api_core/grpc_helpers.py", line 78, in error_remapped_callable
    raise exceptions.from_grpc_error(exc) from exc
google.api_core.exceptions.ResourceExhausted: 429 You exceeded your current quota, please check your plan and billing details. For more information on this error, head to: https://ai.google.dev/gemini-api/docs/rate-limits. [violations {
  quota_metric: "generativelanguage.googleapis.com/generate_content_free_tier_requests"
  quota_id: "GenerateRequestsPerMinutePerProjectPerModel-FreeTier"
  quota_dimensions {
    key: "model"
    value: "gemini-1.5-flash"
  }
  quota_dimensions {
    key: "location"
    value: "global"
  }
  quota_value: 15
}
, links {
  description: "Learn more about Gemini API quotas"
  url: "https://ai.google.dev/gemini-api/docs/rate-limits"
}
, retry_delay {
  seconds: 2
}
]
.
2025-06-15 09:25:04 INFO Using LLM api key #AIzaSyAS4WrMPg7WNPXLpCYIOG49cIYOL7vTAl8)
2025-06-15 09:25:04 INFO Using LLM api key #AIzaSyARJfdVOsI9AKUK6gxvUszL_bn5Z_lr5Wg)
2025-06-15 09:25:04 INFO Using LLM api key #AIzaSyAS4WrMPg7WNPXLpCYIOG49cIYOL7vTAl8)
2025-06-15 09:25:04 INFO Using LLM api key #AIzaSyARJfdVOsI9AKUK6gxvUszL_bn5Z_lr5Wg)
2025-06-15 09:25:04 INFO Using LLM api key #AIzaSyAS4WrMPg7WNPXLpCYIOG49cIYOL7vTAl8)
2025-06-15 09:25:04 INFO An exception occured: Traceback (most recent call last):
  File "/Users/macbook/Documents/Code/LLMdesignedEA-comp/llamea/llamea_api_rotations.py", line 329, in evolve_solution
    evolved_individual = chosen_llm.sample_solution(
                         ^^^^^^^^^^^^^^^^^^^^^^^^^^^
  File "/Users/macbook/Documents/Code/LLMdesignedEA-comp/llamea/llm.py", line 106, in sample_solution
    message = self.query(session_messages)
              ^^^^^^^^^^^^^^^^^^^^^^^^^^^^
  File "/Users/macbook/Documents/Code/LLMdesignedEA-comp/llamea/llm.py", line 278, in query
    response = chat_session.send_message(last["content"])
               ^^^^^^^^^^^^^^^^^^^^^^^^^^^^^^^^^^^^^^^^^^
  File "/Users/macbook/miniconda3/envs/eoh/lib/python3.12/site-packages/google/generativeai/generative_models.py", line 578, in send_message
    response = self.model.generate_content(
               ^^^^^^^^^^^^^^^^^^^^^^^^^^^^
  File "/Users/macbook/miniconda3/envs/eoh/lib/python3.12/site-packages/google/generativeai/generative_models.py", line 331, in generate_content
    response = self._client.generate_content(
               ^^^^^^^^^^^^^^^^^^^^^^^^^^^^^^
  File "/Users/macbook/miniconda3/envs/eoh/lib/python3.12/site-packages/google/ai/generativelanguage_v1beta/services/generative_service/client.py", line 835, in generate_content
    response = rpc(
               ^^^^
  File "/Users/macbook/miniconda3/envs/eoh/lib/python3.12/site-packages/google/api_core/gapic_v1/method.py", line 131, in __call__
    return wrapped_func(*args, **kwargs)
           ^^^^^^^^^^^^^^^^^^^^^^^^^^^^^
  File "/Users/macbook/miniconda3/envs/eoh/lib/python3.12/site-packages/google/api_core/retry/retry_unary.py", line 294, in retry_wrapped_func
    return retry_target(
           ^^^^^^^^^^^^^
  File "/Users/macbook/miniconda3/envs/eoh/lib/python3.12/site-packages/google/api_core/retry/retry_unary.py", line 156, in retry_target
    next_sleep = _retry_error_helper(
                 ^^^^^^^^^^^^^^^^^^^^
  File "/Users/macbook/miniconda3/envs/eoh/lib/python3.12/site-packages/google/api_core/retry/retry_base.py", line 214, in _retry_error_helper
    raise final_exc from source_exc
  File "/Users/macbook/miniconda3/envs/eoh/lib/python3.12/site-packages/google/api_core/retry/retry_unary.py", line 147, in retry_target
    result = target()
             ^^^^^^^^
  File "/Users/macbook/miniconda3/envs/eoh/lib/python3.12/site-packages/google/api_core/timeout.py", line 130, in func_with_timeout
    return func(*args, **kwargs)
           ^^^^^^^^^^^^^^^^^^^^^
  File "/Users/macbook/miniconda3/envs/eoh/lib/python3.12/site-packages/google/api_core/grpc_helpers.py", line 78, in error_remapped_callable
    raise exceptions.from_grpc_error(exc) from exc
google.api_core.exceptions.ResourceExhausted: 429 You exceeded your current quota, please check your plan and billing details. For more information on this error, head to: https://ai.google.dev/gemini-api/docs/rate-limits. [violations {
  quota_metric: "generativelanguage.googleapis.com/generate_content_free_tier_requests"
  quota_id: "GenerateRequestsPerMinutePerProjectPerModel-FreeTier"
  quota_dimensions {
    key: "model"
    value: "gemini-1.5-flash"
  }
  quota_dimensions {
    key: "location"
    value: "global"
  }
  quota_value: 15
}
, links {
  description: "Learn more about Gemini API quotas"
  url: "https://ai.google.dev/gemini-api/docs/rate-limits"
}
, retry_delay {
  seconds: 55
}
]
.
2025-06-15 09:25:04 INFO An exception occured: Traceback (most recent call last):
  File "/Users/macbook/Documents/Code/LLMdesignedEA-comp/llamea/llamea_api_rotations.py", line 329, in evolve_solution
    evolved_individual = chosen_llm.sample_solution(
                         ^^^^^^^^^^^^^^^^^^^^^^^^^^^
  File "/Users/macbook/Documents/Code/LLMdesignedEA-comp/llamea/llm.py", line 106, in sample_solution
    message = self.query(session_messages)
              ^^^^^^^^^^^^^^^^^^^^^^^^^^^^
  File "/Users/macbook/Documents/Code/LLMdesignedEA-comp/llamea/llm.py", line 278, in query
    response = chat_session.send_message(last["content"])
               ^^^^^^^^^^^^^^^^^^^^^^^^^^^^^^^^^^^^^^^^^^
  File "/Users/macbook/miniconda3/envs/eoh/lib/python3.12/site-packages/google/generativeai/generative_models.py", line 578, in send_message
    response = self.model.generate_content(
               ^^^^^^^^^^^^^^^^^^^^^^^^^^^^
  File "/Users/macbook/miniconda3/envs/eoh/lib/python3.12/site-packages/google/generativeai/generative_models.py", line 331, in generate_content
    response = self._client.generate_content(
               ^^^^^^^^^^^^^^^^^^^^^^^^^^^^^^
  File "/Users/macbook/miniconda3/envs/eoh/lib/python3.12/site-packages/google/ai/generativelanguage_v1beta/services/generative_service/client.py", line 835, in generate_content
    response = rpc(
               ^^^^
  File "/Users/macbook/miniconda3/envs/eoh/lib/python3.12/site-packages/google/api_core/gapic_v1/method.py", line 131, in __call__
    return wrapped_func(*args, **kwargs)
           ^^^^^^^^^^^^^^^^^^^^^^^^^^^^^
  File "/Users/macbook/miniconda3/envs/eoh/lib/python3.12/site-packages/google/api_core/retry/retry_unary.py", line 294, in retry_wrapped_func
    return retry_target(
           ^^^^^^^^^^^^^
  File "/Users/macbook/miniconda3/envs/eoh/lib/python3.12/site-packages/google/api_core/retry/retry_unary.py", line 156, in retry_target
    next_sleep = _retry_error_helper(
                 ^^^^^^^^^^^^^^^^^^^^
  File "/Users/macbook/miniconda3/envs/eoh/lib/python3.12/site-packages/google/api_core/retry/retry_base.py", line 214, in _retry_error_helper
    raise final_exc from source_exc
  File "/Users/macbook/miniconda3/envs/eoh/lib/python3.12/site-packages/google/api_core/retry/retry_unary.py", line 147, in retry_target
    result = target()
             ^^^^^^^^
  File "/Users/macbook/miniconda3/envs/eoh/lib/python3.12/site-packages/google/api_core/timeout.py", line 130, in func_with_timeout
    return func(*args, **kwargs)
           ^^^^^^^^^^^^^^^^^^^^^
  File "/Users/macbook/miniconda3/envs/eoh/lib/python3.12/site-packages/google/api_core/grpc_helpers.py", line 78, in error_remapped_callable
    raise exceptions.from_grpc_error(exc) from exc
google.api_core.exceptions.ResourceExhausted: 429 You exceeded your current quota, please check your plan and billing details. For more information on this error, head to: https://ai.google.dev/gemini-api/docs/rate-limits. [violations {
  quota_metric: "generativelanguage.googleapis.com/generate_content_free_tier_requests"
  quota_id: "GenerateRequestsPerMinutePerProjectPerModel-FreeTier"
  quota_dimensions {
    key: "model"
    value: "gemini-1.5-flash"
  }
  quota_dimensions {
    key: "location"
    value: "global"
  }
  quota_value: 15
}
, links {
  description: "Learn more about Gemini API quotas"
  url: "https://ai.google.dev/gemini-api/docs/rate-limits"
}
, retry_delay {
  seconds: 55
}
]
.
2025-06-15 09:25:04 INFO An exception occured: Traceback (most recent call last):
  File "/Users/macbook/Documents/Code/LLMdesignedEA-comp/llamea/llamea_api_rotations.py", line 329, in evolve_solution
    evolved_individual = chosen_llm.sample_solution(
                         ^^^^^^^^^^^^^^^^^^^^^^^^^^^
  File "/Users/macbook/Documents/Code/LLMdesignedEA-comp/llamea/llm.py", line 106, in sample_solution
    message = self.query(session_messages)
              ^^^^^^^^^^^^^^^^^^^^^^^^^^^^
  File "/Users/macbook/Documents/Code/LLMdesignedEA-comp/llamea/llm.py", line 278, in query
    response = chat_session.send_message(last["content"])
               ^^^^^^^^^^^^^^^^^^^^^^^^^^^^^^^^^^^^^^^^^^
  File "/Users/macbook/miniconda3/envs/eoh/lib/python3.12/site-packages/google/generativeai/generative_models.py", line 578, in send_message
    response = self.model.generate_content(
               ^^^^^^^^^^^^^^^^^^^^^^^^^^^^
  File "/Users/macbook/miniconda3/envs/eoh/lib/python3.12/site-packages/google/generativeai/generative_models.py", line 331, in generate_content
    response = self._client.generate_content(
               ^^^^^^^^^^^^^^^^^^^^^^^^^^^^^^
  File "/Users/macbook/miniconda3/envs/eoh/lib/python3.12/site-packages/google/ai/generativelanguage_v1beta/services/generative_service/client.py", line 835, in generate_content
    response = rpc(
               ^^^^
  File "/Users/macbook/miniconda3/envs/eoh/lib/python3.12/site-packages/google/api_core/gapic_v1/method.py", line 131, in __call__
    return wrapped_func(*args, **kwargs)
           ^^^^^^^^^^^^^^^^^^^^^^^^^^^^^
  File "/Users/macbook/miniconda3/envs/eoh/lib/python3.12/site-packages/google/api_core/retry/retry_unary.py", line 294, in retry_wrapped_func
    return retry_target(
           ^^^^^^^^^^^^^
  File "/Users/macbook/miniconda3/envs/eoh/lib/python3.12/site-packages/google/api_core/retry/retry_unary.py", line 156, in retry_target
    next_sleep = _retry_error_helper(
                 ^^^^^^^^^^^^^^^^^^^^
  File "/Users/macbook/miniconda3/envs/eoh/lib/python3.12/site-packages/google/api_core/retry/retry_base.py", line 214, in _retry_error_helper
    raise final_exc from source_exc
  File "/Users/macbook/miniconda3/envs/eoh/lib/python3.12/site-packages/google/api_core/retry/retry_unary.py", line 147, in retry_target
    result = target()
             ^^^^^^^^
  File "/Users/macbook/miniconda3/envs/eoh/lib/python3.12/site-packages/google/api_core/timeout.py", line 130, in func_with_timeout
    return func(*args, **kwargs)
           ^^^^^^^^^^^^^^^^^^^^^
  File "/Users/macbook/miniconda3/envs/eoh/lib/python3.12/site-packages/google/api_core/grpc_helpers.py", line 78, in error_remapped_callable
    raise exceptions.from_grpc_error(exc) from exc
google.api_core.exceptions.ResourceExhausted: 429 You exceeded your current quota, please check your plan and billing details. For more information on this error, head to: https://ai.google.dev/gemini-api/docs/rate-limits. [violations {
  quota_metric: "generativelanguage.googleapis.com/generate_content_free_tier_requests"
  quota_id: "GenerateRequestsPerMinutePerProjectPerModel-FreeTier"
  quota_dimensions {
    key: "model"
    value: "gemini-1.5-flash"
  }
  quota_dimensions {
    key: "location"
    value: "global"
  }
  quota_value: 15
}
, links {
  description: "Learn more about Gemini API quotas"
  url: "https://ai.google.dev/gemini-api/docs/rate-limits"
}
, retry_delay {
  seconds: 55
}
]
.
2025-06-15 09:25:04 INFO An exception occured: Traceback (most recent call last):
  File "/Users/macbook/Documents/Code/LLMdesignedEA-comp/llamea/llamea_api_rotations.py", line 329, in evolve_solution
    evolved_individual = chosen_llm.sample_solution(
                         ^^^^^^^^^^^^^^^^^^^^^^^^^^^
  File "/Users/macbook/Documents/Code/LLMdesignedEA-comp/llamea/llm.py", line 106, in sample_solution
    message = self.query(session_messages)
              ^^^^^^^^^^^^^^^^^^^^^^^^^^^^
  File "/Users/macbook/Documents/Code/LLMdesignedEA-comp/llamea/llm.py", line 278, in query
    response = chat_session.send_message(last["content"])
               ^^^^^^^^^^^^^^^^^^^^^^^^^^^^^^^^^^^^^^^^^^
  File "/Users/macbook/miniconda3/envs/eoh/lib/python3.12/site-packages/google/generativeai/generative_models.py", line 578, in send_message
    response = self.model.generate_content(
               ^^^^^^^^^^^^^^^^^^^^^^^^^^^^
  File "/Users/macbook/miniconda3/envs/eoh/lib/python3.12/site-packages/google/generativeai/generative_models.py", line 331, in generate_content
    response = self._client.generate_content(
               ^^^^^^^^^^^^^^^^^^^^^^^^^^^^^^
  File "/Users/macbook/miniconda3/envs/eoh/lib/python3.12/site-packages/google/ai/generativelanguage_v1beta/services/generative_service/client.py", line 835, in generate_content
    response = rpc(
               ^^^^
  File "/Users/macbook/miniconda3/envs/eoh/lib/python3.12/site-packages/google/api_core/gapic_v1/method.py", line 131, in __call__
    return wrapped_func(*args, **kwargs)
           ^^^^^^^^^^^^^^^^^^^^^^^^^^^^^
  File "/Users/macbook/miniconda3/envs/eoh/lib/python3.12/site-packages/google/api_core/retry/retry_unary.py", line 294, in retry_wrapped_func
    return retry_target(
           ^^^^^^^^^^^^^
  File "/Users/macbook/miniconda3/envs/eoh/lib/python3.12/site-packages/google/api_core/retry/retry_unary.py", line 156, in retry_target
    next_sleep = _retry_error_helper(
                 ^^^^^^^^^^^^^^^^^^^^
  File "/Users/macbook/miniconda3/envs/eoh/lib/python3.12/site-packages/google/api_core/retry/retry_base.py", line 214, in _retry_error_helper
    raise final_exc from source_exc
  File "/Users/macbook/miniconda3/envs/eoh/lib/python3.12/site-packages/google/api_core/retry/retry_unary.py", line 147, in retry_target
    result = target()
             ^^^^^^^^
  File "/Users/macbook/miniconda3/envs/eoh/lib/python3.12/site-packages/google/api_core/timeout.py", line 130, in func_with_timeout
    return func(*args, **kwargs)
           ^^^^^^^^^^^^^^^^^^^^^
  File "/Users/macbook/miniconda3/envs/eoh/lib/python3.12/site-packages/google/api_core/grpc_helpers.py", line 78, in error_remapped_callable
    raise exceptions.from_grpc_error(exc) from exc
google.api_core.exceptions.ResourceExhausted: 429 You exceeded your current quota, please check your plan and billing details. For more information on this error, head to: https://ai.google.dev/gemini-api/docs/rate-limits. [violations {
  quota_metric: "generativelanguage.googleapis.com/generate_content_free_tier_requests"
  quota_id: "GenerateRequestsPerMinutePerProjectPerModel-FreeTier"
  quota_dimensions {
    key: "model"
    value: "gemini-1.5-flash"
  }
  quota_dimensions {
    key: "location"
    value: "global"
  }
  quota_value: 15
}
, links {
  description: "Learn more about Gemini API quotas"
  url: "https://ai.google.dev/gemini-api/docs/rate-limits"
}
, retry_delay {
  seconds: 55
}
]
.
2025-06-15 09:25:04 INFO An exception occured: Traceback (most recent call last):
  File "/Users/macbook/Documents/Code/LLMdesignedEA-comp/llamea/llamea_api_rotations.py", line 329, in evolve_solution
    evolved_individual = chosen_llm.sample_solution(
                         ^^^^^^^^^^^^^^^^^^^^^^^^^^^
  File "/Users/macbook/Documents/Code/LLMdesignedEA-comp/llamea/llm.py", line 106, in sample_solution
    message = self.query(session_messages)
              ^^^^^^^^^^^^^^^^^^^^^^^^^^^^
  File "/Users/macbook/Documents/Code/LLMdesignedEA-comp/llamea/llm.py", line 278, in query
    response = chat_session.send_message(last["content"])
               ^^^^^^^^^^^^^^^^^^^^^^^^^^^^^^^^^^^^^^^^^^
  File "/Users/macbook/miniconda3/envs/eoh/lib/python3.12/site-packages/google/generativeai/generative_models.py", line 578, in send_message
    response = self.model.generate_content(
               ^^^^^^^^^^^^^^^^^^^^^^^^^^^^
  File "/Users/macbook/miniconda3/envs/eoh/lib/python3.12/site-packages/google/generativeai/generative_models.py", line 331, in generate_content
    response = self._client.generate_content(
               ^^^^^^^^^^^^^^^^^^^^^^^^^^^^^^
  File "/Users/macbook/miniconda3/envs/eoh/lib/python3.12/site-packages/google/ai/generativelanguage_v1beta/services/generative_service/client.py", line 835, in generate_content
    response = rpc(
               ^^^^
  File "/Users/macbook/miniconda3/envs/eoh/lib/python3.12/site-packages/google/api_core/gapic_v1/method.py", line 131, in __call__
    return wrapped_func(*args, **kwargs)
           ^^^^^^^^^^^^^^^^^^^^^^^^^^^^^
  File "/Users/macbook/miniconda3/envs/eoh/lib/python3.12/site-packages/google/api_core/retry/retry_unary.py", line 294, in retry_wrapped_func
    return retry_target(
           ^^^^^^^^^^^^^
  File "/Users/macbook/miniconda3/envs/eoh/lib/python3.12/site-packages/google/api_core/retry/retry_unary.py", line 156, in retry_target
    next_sleep = _retry_error_helper(
                 ^^^^^^^^^^^^^^^^^^^^
  File "/Users/macbook/miniconda3/envs/eoh/lib/python3.12/site-packages/google/api_core/retry/retry_base.py", line 214, in _retry_error_helper
    raise final_exc from source_exc
  File "/Users/macbook/miniconda3/envs/eoh/lib/python3.12/site-packages/google/api_core/retry/retry_unary.py", line 147, in retry_target
    result = target()
             ^^^^^^^^
  File "/Users/macbook/miniconda3/envs/eoh/lib/python3.12/site-packages/google/api_core/timeout.py", line 130, in func_with_timeout
    return func(*args, **kwargs)
           ^^^^^^^^^^^^^^^^^^^^^
  File "/Users/macbook/miniconda3/envs/eoh/lib/python3.12/site-packages/google/api_core/grpc_helpers.py", line 78, in error_remapped_callable
    raise exceptions.from_grpc_error(exc) from exc
google.api_core.exceptions.ResourceExhausted: 429 You exceeded your current quota, please check your plan and billing details. For more information on this error, head to: https://ai.google.dev/gemini-api/docs/rate-limits. [violations {
  quota_metric: "generativelanguage.googleapis.com/generate_content_free_tier_requests"
  quota_id: "GenerateRequestsPerMinutePerProjectPerModel-FreeTier"
  quota_dimensions {
    key: "model"
    value: "gemini-1.5-flash"
  }
  quota_dimensions {
    key: "location"
    value: "global"
  }
  quota_value: 15
}
, links {
  description: "Learn more about Gemini API quotas"
  url: "https://ai.google.dev/gemini-api/docs/rate-limits"
}
, retry_delay {
  seconds: 55
}
]
.
2025-06-15 09:25:04 INFO Using LLM api key #AIzaSyAS4WrMPg7WNPXLpCYIOG49cIYOL7vTAl8)
2025-06-15 09:25:04 INFO Using LLM api key #AIzaSyARJfdVOsI9AKUK6gxvUszL_bn5Z_lr5Wg)
2025-06-15 09:25:04 INFO Using LLM api key #AIzaSyCbA5uIXRIIWnTv7HCUGX75WoYJ4PeZWd0)
2025-06-15 09:25:04 INFO Using LLM api key #AIzaSyAS4WrMPg7WNPXLpCYIOG49cIYOL7vTAl8)
2025-06-15 09:25:04 INFO Using LLM api key #AIzaSyARJfdVOsI9AKUK6gxvUszL_bn5Z_lr5Wg)
2025-06-15 09:25:05 INFO An exception occured: Traceback (most recent call last):
  File "/Users/macbook/Documents/Code/LLMdesignedEA-comp/llamea/llamea_api_rotations.py", line 329, in evolve_solution
    evolved_individual = chosen_llm.sample_solution(
                         ^^^^^^^^^^^^^^^^^^^^^^^^^^^
  File "/Users/macbook/Documents/Code/LLMdesignedEA-comp/llamea/llm.py", line 106, in sample_solution
    message = self.query(session_messages)
              ^^^^^^^^^^^^^^^^^^^^^^^^^^^^
  File "/Users/macbook/Documents/Code/LLMdesignedEA-comp/llamea/llm.py", line 278, in query
    response = chat_session.send_message(last["content"])
               ^^^^^^^^^^^^^^^^^^^^^^^^^^^^^^^^^^^^^^^^^^
  File "/Users/macbook/miniconda3/envs/eoh/lib/python3.12/site-packages/google/generativeai/generative_models.py", line 578, in send_message
    response = self.model.generate_content(
               ^^^^^^^^^^^^^^^^^^^^^^^^^^^^
  File "/Users/macbook/miniconda3/envs/eoh/lib/python3.12/site-packages/google/generativeai/generative_models.py", line 331, in generate_content
    response = self._client.generate_content(
               ^^^^^^^^^^^^^^^^^^^^^^^^^^^^^^
  File "/Users/macbook/miniconda3/envs/eoh/lib/python3.12/site-packages/google/ai/generativelanguage_v1beta/services/generative_service/client.py", line 835, in generate_content
    response = rpc(
               ^^^^
  File "/Users/macbook/miniconda3/envs/eoh/lib/python3.12/site-packages/google/api_core/gapic_v1/method.py", line 131, in __call__
    return wrapped_func(*args, **kwargs)
           ^^^^^^^^^^^^^^^^^^^^^^^^^^^^^
  File "/Users/macbook/miniconda3/envs/eoh/lib/python3.12/site-packages/google/api_core/retry/retry_unary.py", line 294, in retry_wrapped_func
    return retry_target(
           ^^^^^^^^^^^^^
  File "/Users/macbook/miniconda3/envs/eoh/lib/python3.12/site-packages/google/api_core/retry/retry_unary.py", line 156, in retry_target
    next_sleep = _retry_error_helper(
                 ^^^^^^^^^^^^^^^^^^^^
  File "/Users/macbook/miniconda3/envs/eoh/lib/python3.12/site-packages/google/api_core/retry/retry_base.py", line 214, in _retry_error_helper
    raise final_exc from source_exc
  File "/Users/macbook/miniconda3/envs/eoh/lib/python3.12/site-packages/google/api_core/retry/retry_unary.py", line 147, in retry_target
    result = target()
             ^^^^^^^^
  File "/Users/macbook/miniconda3/envs/eoh/lib/python3.12/site-packages/google/api_core/timeout.py", line 130, in func_with_timeout
    return func(*args, **kwargs)
           ^^^^^^^^^^^^^^^^^^^^^
  File "/Users/macbook/miniconda3/envs/eoh/lib/python3.12/site-packages/google/api_core/grpc_helpers.py", line 78, in error_remapped_callable
    raise exceptions.from_grpc_error(exc) from exc
google.api_core.exceptions.ResourceExhausted: 429 You exceeded your current quota, please check your plan and billing details. For more information on this error, head to: https://ai.google.dev/gemini-api/docs/rate-limits. [violations {
  quota_metric: "generativelanguage.googleapis.com/generate_content_free_tier_requests"
  quota_id: "GenerateRequestsPerMinutePerProjectPerModel-FreeTier"
  quota_dimensions {
    key: "model"
    value: "gemini-1.5-flash"
  }
  quota_dimensions {
    key: "location"
    value: "global"
  }
  quota_value: 15
}
, links {
  description: "Learn more about Gemini API quotas"
  url: "https://ai.google.dev/gemini-api/docs/rate-limits"
}
, retry_delay {
  seconds: 54
}
]
.
2025-06-15 09:25:05 INFO An exception occured: Traceback (most recent call last):
  File "/Users/macbook/Documents/Code/LLMdesignedEA-comp/llamea/llamea_api_rotations.py", line 329, in evolve_solution
    evolved_individual = chosen_llm.sample_solution(
                         ^^^^^^^^^^^^^^^^^^^^^^^^^^^
  File "/Users/macbook/Documents/Code/LLMdesignedEA-comp/llamea/llm.py", line 106, in sample_solution
    message = self.query(session_messages)
              ^^^^^^^^^^^^^^^^^^^^^^^^^^^^
  File "/Users/macbook/Documents/Code/LLMdesignedEA-comp/llamea/llm.py", line 278, in query
    response = chat_session.send_message(last["content"])
               ^^^^^^^^^^^^^^^^^^^^^^^^^^^^^^^^^^^^^^^^^^
  File "/Users/macbook/miniconda3/envs/eoh/lib/python3.12/site-packages/google/generativeai/generative_models.py", line 578, in send_message
    response = self.model.generate_content(
               ^^^^^^^^^^^^^^^^^^^^^^^^^^^^
  File "/Users/macbook/miniconda3/envs/eoh/lib/python3.12/site-packages/google/generativeai/generative_models.py", line 331, in generate_content
    response = self._client.generate_content(
               ^^^^^^^^^^^^^^^^^^^^^^^^^^^^^^
  File "/Users/macbook/miniconda3/envs/eoh/lib/python3.12/site-packages/google/ai/generativelanguage_v1beta/services/generative_service/client.py", line 835, in generate_content
    response = rpc(
               ^^^^
  File "/Users/macbook/miniconda3/envs/eoh/lib/python3.12/site-packages/google/api_core/gapic_v1/method.py", line 131, in __call__
    return wrapped_func(*args, **kwargs)
           ^^^^^^^^^^^^^^^^^^^^^^^^^^^^^
  File "/Users/macbook/miniconda3/envs/eoh/lib/python3.12/site-packages/google/api_core/retry/retry_unary.py", line 294, in retry_wrapped_func
    return retry_target(
           ^^^^^^^^^^^^^
  File "/Users/macbook/miniconda3/envs/eoh/lib/python3.12/site-packages/google/api_core/retry/retry_unary.py", line 156, in retry_target
    next_sleep = _retry_error_helper(
                 ^^^^^^^^^^^^^^^^^^^^
  File "/Users/macbook/miniconda3/envs/eoh/lib/python3.12/site-packages/google/api_core/retry/retry_base.py", line 214, in _retry_error_helper
    raise final_exc from source_exc
  File "/Users/macbook/miniconda3/envs/eoh/lib/python3.12/site-packages/google/api_core/retry/retry_unary.py", line 147, in retry_target
    result = target()
             ^^^^^^^^
  File "/Users/macbook/miniconda3/envs/eoh/lib/python3.12/site-packages/google/api_core/timeout.py", line 130, in func_with_timeout
    return func(*args, **kwargs)
           ^^^^^^^^^^^^^^^^^^^^^
  File "/Users/macbook/miniconda3/envs/eoh/lib/python3.12/site-packages/google/api_core/grpc_helpers.py", line 78, in error_remapped_callable
    raise exceptions.from_grpc_error(exc) from exc
google.api_core.exceptions.ResourceExhausted: 429 You exceeded your current quota, please check your plan and billing details. For more information on this error, head to: https://ai.google.dev/gemini-api/docs/rate-limits. [violations {
  quota_metric: "generativelanguage.googleapis.com/generate_content_free_tier_requests"
  quota_id: "GenerateRequestsPerMinutePerProjectPerModel-FreeTier"
  quota_dimensions {
    key: "model"
    value: "gemini-1.5-flash"
  }
  quota_dimensions {
    key: "location"
    value: "global"
  }
  quota_value: 15
}
, links {
  description: "Learn more about Gemini API quotas"
  url: "https://ai.google.dev/gemini-api/docs/rate-limits"
}
, retry_delay {
  seconds: 54
}
]
.
2025-06-15 09:25:05 INFO An exception occured: Traceback (most recent call last):
  File "/Users/macbook/Documents/Code/LLMdesignedEA-comp/llamea/llamea_api_rotations.py", line 329, in evolve_solution
    evolved_individual = chosen_llm.sample_solution(
                         ^^^^^^^^^^^^^^^^^^^^^^^^^^^
  File "/Users/macbook/Documents/Code/LLMdesignedEA-comp/llamea/llm.py", line 106, in sample_solution
    message = self.query(session_messages)
              ^^^^^^^^^^^^^^^^^^^^^^^^^^^^
  File "/Users/macbook/Documents/Code/LLMdesignedEA-comp/llamea/llm.py", line 278, in query
    response = chat_session.send_message(last["content"])
               ^^^^^^^^^^^^^^^^^^^^^^^^^^^^^^^^^^^^^^^^^^
  File "/Users/macbook/miniconda3/envs/eoh/lib/python3.12/site-packages/google/generativeai/generative_models.py", line 578, in send_message
    response = self.model.generate_content(
               ^^^^^^^^^^^^^^^^^^^^^^^^^^^^
  File "/Users/macbook/miniconda3/envs/eoh/lib/python3.12/site-packages/google/generativeai/generative_models.py", line 331, in generate_content
    response = self._client.generate_content(
               ^^^^^^^^^^^^^^^^^^^^^^^^^^^^^^
  File "/Users/macbook/miniconda3/envs/eoh/lib/python3.12/site-packages/google/ai/generativelanguage_v1beta/services/generative_service/client.py", line 835, in generate_content
    response = rpc(
               ^^^^
  File "/Users/macbook/miniconda3/envs/eoh/lib/python3.12/site-packages/google/api_core/gapic_v1/method.py", line 131, in __call__
    return wrapped_func(*args, **kwargs)
           ^^^^^^^^^^^^^^^^^^^^^^^^^^^^^
  File "/Users/macbook/miniconda3/envs/eoh/lib/python3.12/site-packages/google/api_core/retry/retry_unary.py", line 294, in retry_wrapped_func
    return retry_target(
           ^^^^^^^^^^^^^
  File "/Users/macbook/miniconda3/envs/eoh/lib/python3.12/site-packages/google/api_core/retry/retry_unary.py", line 156, in retry_target
    next_sleep = _retry_error_helper(
                 ^^^^^^^^^^^^^^^^^^^^
  File "/Users/macbook/miniconda3/envs/eoh/lib/python3.12/site-packages/google/api_core/retry/retry_base.py", line 214, in _retry_error_helper
    raise final_exc from source_exc
  File "/Users/macbook/miniconda3/envs/eoh/lib/python3.12/site-packages/google/api_core/retry/retry_unary.py", line 147, in retry_target
    result = target()
             ^^^^^^^^
  File "/Users/macbook/miniconda3/envs/eoh/lib/python3.12/site-packages/google/api_core/timeout.py", line 130, in func_with_timeout
    return func(*args, **kwargs)
           ^^^^^^^^^^^^^^^^^^^^^
  File "/Users/macbook/miniconda3/envs/eoh/lib/python3.12/site-packages/google/api_core/grpc_helpers.py", line 78, in error_remapped_callable
    raise exceptions.from_grpc_error(exc) from exc
google.api_core.exceptions.ResourceExhausted: 429 You exceeded your current quota, please check your plan and billing details. For more information on this error, head to: https://ai.google.dev/gemini-api/docs/rate-limits. [violations {
  quota_metric: "generativelanguage.googleapis.com/generate_content_free_tier_requests"
  quota_id: "GenerateRequestsPerMinutePerProjectPerModel-FreeTier"
  quota_dimensions {
    key: "model"
    value: "gemini-1.5-flash"
  }
  quota_dimensions {
    key: "location"
    value: "global"
  }
  quota_value: 15
}
, links {
  description: "Learn more about Gemini API quotas"
  url: "https://ai.google.dev/gemini-api/docs/rate-limits"
}
, retry_delay {
  seconds: 54
}
]
.
2025-06-15 09:25:05 INFO An exception occured: Traceback (most recent call last):
  File "/Users/macbook/Documents/Code/LLMdesignedEA-comp/llamea/llamea_api_rotations.py", line 329, in evolve_solution
    evolved_individual = chosen_llm.sample_solution(
                         ^^^^^^^^^^^^^^^^^^^^^^^^^^^
  File "/Users/macbook/Documents/Code/LLMdesignedEA-comp/llamea/llm.py", line 106, in sample_solution
    message = self.query(session_messages)
              ^^^^^^^^^^^^^^^^^^^^^^^^^^^^
  File "/Users/macbook/Documents/Code/LLMdesignedEA-comp/llamea/llm.py", line 278, in query
    response = chat_session.send_message(last["content"])
               ^^^^^^^^^^^^^^^^^^^^^^^^^^^^^^^^^^^^^^^^^^
  File "/Users/macbook/miniconda3/envs/eoh/lib/python3.12/site-packages/google/generativeai/generative_models.py", line 578, in send_message
    response = self.model.generate_content(
               ^^^^^^^^^^^^^^^^^^^^^^^^^^^^
  File "/Users/macbook/miniconda3/envs/eoh/lib/python3.12/site-packages/google/generativeai/generative_models.py", line 331, in generate_content
    response = self._client.generate_content(
               ^^^^^^^^^^^^^^^^^^^^^^^^^^^^^^
  File "/Users/macbook/miniconda3/envs/eoh/lib/python3.12/site-packages/google/ai/generativelanguage_v1beta/services/generative_service/client.py", line 835, in generate_content
    response = rpc(
               ^^^^
  File "/Users/macbook/miniconda3/envs/eoh/lib/python3.12/site-packages/google/api_core/gapic_v1/method.py", line 131, in __call__
    return wrapped_func(*args, **kwargs)
           ^^^^^^^^^^^^^^^^^^^^^^^^^^^^^
  File "/Users/macbook/miniconda3/envs/eoh/lib/python3.12/site-packages/google/api_core/retry/retry_unary.py", line 294, in retry_wrapped_func
    return retry_target(
           ^^^^^^^^^^^^^
  File "/Users/macbook/miniconda3/envs/eoh/lib/python3.12/site-packages/google/api_core/retry/retry_unary.py", line 156, in retry_target
    next_sleep = _retry_error_helper(
                 ^^^^^^^^^^^^^^^^^^^^
  File "/Users/macbook/miniconda3/envs/eoh/lib/python3.12/site-packages/google/api_core/retry/retry_base.py", line 214, in _retry_error_helper
    raise final_exc from source_exc
  File "/Users/macbook/miniconda3/envs/eoh/lib/python3.12/site-packages/google/api_core/retry/retry_unary.py", line 147, in retry_target
    result = target()
             ^^^^^^^^
  File "/Users/macbook/miniconda3/envs/eoh/lib/python3.12/site-packages/google/api_core/timeout.py", line 130, in func_with_timeout
    return func(*args, **kwargs)
           ^^^^^^^^^^^^^^^^^^^^^
  File "/Users/macbook/miniconda3/envs/eoh/lib/python3.12/site-packages/google/api_core/grpc_helpers.py", line 78, in error_remapped_callable
    raise exceptions.from_grpc_error(exc) from exc
google.api_core.exceptions.ResourceExhausted: 429 You exceeded your current quota, please check your plan and billing details. For more information on this error, head to: https://ai.google.dev/gemini-api/docs/rate-limits. [violations {
  quota_metric: "generativelanguage.googleapis.com/generate_content_free_tier_requests"
  quota_id: "GenerateRequestsPerMinutePerProjectPerModel-FreeTier"
  quota_dimensions {
    key: "model"
    value: "gemini-1.5-flash"
  }
  quota_dimensions {
    key: "location"
    value: "global"
  }
  quota_value: 15
}
, links {
  description: "Learn more about Gemini API quotas"
  url: "https://ai.google.dev/gemini-api/docs/rate-limits"
}
, retry_delay {
  seconds: 54
}
]
.
2025-06-15 09:25:05 INFO An exception occured: Traceback (most recent call last):
  File "/Users/macbook/Documents/Code/LLMdesignedEA-comp/llamea/llamea_api_rotations.py", line 329, in evolve_solution
    evolved_individual = chosen_llm.sample_solution(
                         ^^^^^^^^^^^^^^^^^^^^^^^^^^^
  File "/Users/macbook/Documents/Code/LLMdesignedEA-comp/llamea/llm.py", line 106, in sample_solution
    message = self.query(session_messages)
              ^^^^^^^^^^^^^^^^^^^^^^^^^^^^
  File "/Users/macbook/Documents/Code/LLMdesignedEA-comp/llamea/llm.py", line 278, in query
    response = chat_session.send_message(last["content"])
               ^^^^^^^^^^^^^^^^^^^^^^^^^^^^^^^^^^^^^^^^^^
  File "/Users/macbook/miniconda3/envs/eoh/lib/python3.12/site-packages/google/generativeai/generative_models.py", line 578, in send_message
    response = self.model.generate_content(
               ^^^^^^^^^^^^^^^^^^^^^^^^^^^^
  File "/Users/macbook/miniconda3/envs/eoh/lib/python3.12/site-packages/google/generativeai/generative_models.py", line 331, in generate_content
    response = self._client.generate_content(
               ^^^^^^^^^^^^^^^^^^^^^^^^^^^^^^
  File "/Users/macbook/miniconda3/envs/eoh/lib/python3.12/site-packages/google/ai/generativelanguage_v1beta/services/generative_service/client.py", line 835, in generate_content
    response = rpc(
               ^^^^
  File "/Users/macbook/miniconda3/envs/eoh/lib/python3.12/site-packages/google/api_core/gapic_v1/method.py", line 131, in __call__
    return wrapped_func(*args, **kwargs)
           ^^^^^^^^^^^^^^^^^^^^^^^^^^^^^
  File "/Users/macbook/miniconda3/envs/eoh/lib/python3.12/site-packages/google/api_core/retry/retry_unary.py", line 294, in retry_wrapped_func
    return retry_target(
           ^^^^^^^^^^^^^
  File "/Users/macbook/miniconda3/envs/eoh/lib/python3.12/site-packages/google/api_core/retry/retry_unary.py", line 156, in retry_target
    next_sleep = _retry_error_helper(
                 ^^^^^^^^^^^^^^^^^^^^
  File "/Users/macbook/miniconda3/envs/eoh/lib/python3.12/site-packages/google/api_core/retry/retry_base.py", line 214, in _retry_error_helper
    raise final_exc from source_exc
  File "/Users/macbook/miniconda3/envs/eoh/lib/python3.12/site-packages/google/api_core/retry/retry_unary.py", line 147, in retry_target
    result = target()
             ^^^^^^^^
  File "/Users/macbook/miniconda3/envs/eoh/lib/python3.12/site-packages/google/api_core/timeout.py", line 130, in func_with_timeout
    return func(*args, **kwargs)
           ^^^^^^^^^^^^^^^^^^^^^
  File "/Users/macbook/miniconda3/envs/eoh/lib/python3.12/site-packages/google/api_core/grpc_helpers.py", line 78, in error_remapped_callable
    raise exceptions.from_grpc_error(exc) from exc
google.api_core.exceptions.ResourceExhausted: 429 You exceeded your current quota, please check your plan and billing details. For more information on this error, head to: https://ai.google.dev/gemini-api/docs/rate-limits. [violations {
  quota_metric: "generativelanguage.googleapis.com/generate_content_free_tier_requests"
  quota_id: "GenerateRequestsPerMinutePerProjectPerModel-FreeTier"
  quota_dimensions {
    key: "model"
    value: "gemini-1.5-flash"
  }
  quota_dimensions {
    key: "location"
    value: "global"
  }
  quota_value: 15
}
, links {
  description: "Learn more about Gemini API quotas"
  url: "https://ai.google.dev/gemini-api/docs/rate-limits"
}
, retry_delay {
  seconds: 54
}
]
.
2025-06-15 09:25:05 INFO Using LLM api key #AIzaSyAS4WrMPg7WNPXLpCYIOG49cIYOL7vTAl8)
2025-06-15 09:25:05 INFO Using LLM api key #AIzaSyARJfdVOsI9AKUK6gxvUszL_bn5Z_lr5Wg)
2025-06-15 09:25:05 INFO Using LLM api key #AIzaSyAEUmOe_NUQT_vGqRWH_9XnMDQuUe0CiKU)
2025-06-15 09:25:05 INFO Using LLM api key #AIzaSyAEUmOe_NUQT_vGqRWH_9XnMDQuUe0CiKU)
2025-06-15 09:25:05 INFO Using LLM api key #AIzaSyCbA5uIXRIIWnTv7HCUGX75WoYJ4PeZWd0)
2025-06-15 09:25:05 INFO An exception occured: Traceback (most recent call last):
  File "/Users/macbook/Documents/Code/LLMdesignedEA-comp/llamea/llamea_api_rotations.py", line 329, in evolve_solution
    evolved_individual = chosen_llm.sample_solution(
                         ^^^^^^^^^^^^^^^^^^^^^^^^^^^
  File "/Users/macbook/Documents/Code/LLMdesignedEA-comp/llamea/llm.py", line 106, in sample_solution
    message = self.query(session_messages)
              ^^^^^^^^^^^^^^^^^^^^^^^^^^^^
  File "/Users/macbook/Documents/Code/LLMdesignedEA-comp/llamea/llm.py", line 278, in query
    response = chat_session.send_message(last["content"])
               ^^^^^^^^^^^^^^^^^^^^^^^^^^^^^^^^^^^^^^^^^^
  File "/Users/macbook/miniconda3/envs/eoh/lib/python3.12/site-packages/google/generativeai/generative_models.py", line 578, in send_message
    response = self.model.generate_content(
               ^^^^^^^^^^^^^^^^^^^^^^^^^^^^
  File "/Users/macbook/miniconda3/envs/eoh/lib/python3.12/site-packages/google/generativeai/generative_models.py", line 331, in generate_content
    response = self._client.generate_content(
               ^^^^^^^^^^^^^^^^^^^^^^^^^^^^^^
  File "/Users/macbook/miniconda3/envs/eoh/lib/python3.12/site-packages/google/ai/generativelanguage_v1beta/services/generative_service/client.py", line 835, in generate_content
    response = rpc(
               ^^^^
  File "/Users/macbook/miniconda3/envs/eoh/lib/python3.12/site-packages/google/api_core/gapic_v1/method.py", line 131, in __call__
    return wrapped_func(*args, **kwargs)
           ^^^^^^^^^^^^^^^^^^^^^^^^^^^^^
  File "/Users/macbook/miniconda3/envs/eoh/lib/python3.12/site-packages/google/api_core/retry/retry_unary.py", line 294, in retry_wrapped_func
    return retry_target(
           ^^^^^^^^^^^^^
  File "/Users/macbook/miniconda3/envs/eoh/lib/python3.12/site-packages/google/api_core/retry/retry_unary.py", line 156, in retry_target
    next_sleep = _retry_error_helper(
                 ^^^^^^^^^^^^^^^^^^^^
  File "/Users/macbook/miniconda3/envs/eoh/lib/python3.12/site-packages/google/api_core/retry/retry_base.py", line 214, in _retry_error_helper
    raise final_exc from source_exc
  File "/Users/macbook/miniconda3/envs/eoh/lib/python3.12/site-packages/google/api_core/retry/retry_unary.py", line 147, in retry_target
    result = target()
             ^^^^^^^^
  File "/Users/macbook/miniconda3/envs/eoh/lib/python3.12/site-packages/google/api_core/timeout.py", line 130, in func_with_timeout
    return func(*args, **kwargs)
           ^^^^^^^^^^^^^^^^^^^^^
  File "/Users/macbook/miniconda3/envs/eoh/lib/python3.12/site-packages/google/api_core/grpc_helpers.py", line 78, in error_remapped_callable
    raise exceptions.from_grpc_error(exc) from exc
google.api_core.exceptions.ResourceExhausted: 429 You exceeded your current quota, please check your plan and billing details. For more information on this error, head to: https://ai.google.dev/gemini-api/docs/rate-limits. [violations {
  quota_metric: "generativelanguage.googleapis.com/generate_content_free_tier_requests"
  quota_id: "GenerateRequestsPerMinutePerProjectPerModel-FreeTier"
  quota_dimensions {
    key: "model"
    value: "gemini-1.5-flash"
  }
  quota_dimensions {
    key: "location"
    value: "global"
  }
  quota_value: 15
}
, links {
  description: "Learn more about Gemini API quotas"
  url: "https://ai.google.dev/gemini-api/docs/rate-limits"
}
, retry_delay {
  seconds: 54
}
]
.
2025-06-15 09:25:05 INFO An exception occured: Traceback (most recent call last):
  File "/Users/macbook/Documents/Code/LLMdesignedEA-comp/llamea/llamea_api_rotations.py", line 329, in evolve_solution
    evolved_individual = chosen_llm.sample_solution(
                         ^^^^^^^^^^^^^^^^^^^^^^^^^^^
  File "/Users/macbook/Documents/Code/LLMdesignedEA-comp/llamea/llm.py", line 106, in sample_solution
    message = self.query(session_messages)
              ^^^^^^^^^^^^^^^^^^^^^^^^^^^^
  File "/Users/macbook/Documents/Code/LLMdesignedEA-comp/llamea/llm.py", line 278, in query
    response = chat_session.send_message(last["content"])
               ^^^^^^^^^^^^^^^^^^^^^^^^^^^^^^^^^^^^^^^^^^
  File "/Users/macbook/miniconda3/envs/eoh/lib/python3.12/site-packages/google/generativeai/generative_models.py", line 578, in send_message
    response = self.model.generate_content(
               ^^^^^^^^^^^^^^^^^^^^^^^^^^^^
  File "/Users/macbook/miniconda3/envs/eoh/lib/python3.12/site-packages/google/generativeai/generative_models.py", line 331, in generate_content
    response = self._client.generate_content(
               ^^^^^^^^^^^^^^^^^^^^^^^^^^^^^^
  File "/Users/macbook/miniconda3/envs/eoh/lib/python3.12/site-packages/google/ai/generativelanguage_v1beta/services/generative_service/client.py", line 835, in generate_content
    response = rpc(
               ^^^^
  File "/Users/macbook/miniconda3/envs/eoh/lib/python3.12/site-packages/google/api_core/gapic_v1/method.py", line 131, in __call__
    return wrapped_func(*args, **kwargs)
           ^^^^^^^^^^^^^^^^^^^^^^^^^^^^^
  File "/Users/macbook/miniconda3/envs/eoh/lib/python3.12/site-packages/google/api_core/retry/retry_unary.py", line 294, in retry_wrapped_func
    return retry_target(
           ^^^^^^^^^^^^^
  File "/Users/macbook/miniconda3/envs/eoh/lib/python3.12/site-packages/google/api_core/retry/retry_unary.py", line 156, in retry_target
    next_sleep = _retry_error_helper(
                 ^^^^^^^^^^^^^^^^^^^^
  File "/Users/macbook/miniconda3/envs/eoh/lib/python3.12/site-packages/google/api_core/retry/retry_base.py", line 214, in _retry_error_helper
    raise final_exc from source_exc
  File "/Users/macbook/miniconda3/envs/eoh/lib/python3.12/site-packages/google/api_core/retry/retry_unary.py", line 147, in retry_target
    result = target()
             ^^^^^^^^
  File "/Users/macbook/miniconda3/envs/eoh/lib/python3.12/site-packages/google/api_core/timeout.py", line 130, in func_with_timeout
    return func(*args, **kwargs)
           ^^^^^^^^^^^^^^^^^^^^^
  File "/Users/macbook/miniconda3/envs/eoh/lib/python3.12/site-packages/google/api_core/grpc_helpers.py", line 78, in error_remapped_callable
    raise exceptions.from_grpc_error(exc) from exc
google.api_core.exceptions.ResourceExhausted: 429 You exceeded your current quota, please check your plan and billing details. For more information on this error, head to: https://ai.google.dev/gemini-api/docs/rate-limits. [violations {
  quota_metric: "generativelanguage.googleapis.com/generate_content_free_tier_requests"
  quota_id: "GenerateRequestsPerMinutePerProjectPerModel-FreeTier"
  quota_dimensions {
    key: "model"
    value: "gemini-1.5-flash"
  }
  quota_dimensions {
    key: "location"
    value: "global"
  }
  quota_value: 15
}
, links {
  description: "Learn more about Gemini API quotas"
  url: "https://ai.google.dev/gemini-api/docs/rate-limits"
}
, retry_delay {
  seconds: 54
}
]
.
2025-06-15 09:25:05 INFO An exception occured: Traceback (most recent call last):
  File "/Users/macbook/Documents/Code/LLMdesignedEA-comp/llamea/llamea_api_rotations.py", line 329, in evolve_solution
    evolved_individual = chosen_llm.sample_solution(
                         ^^^^^^^^^^^^^^^^^^^^^^^^^^^
  File "/Users/macbook/Documents/Code/LLMdesignedEA-comp/llamea/llm.py", line 106, in sample_solution
    message = self.query(session_messages)
              ^^^^^^^^^^^^^^^^^^^^^^^^^^^^
  File "/Users/macbook/Documents/Code/LLMdesignedEA-comp/llamea/llm.py", line 278, in query
    response = chat_session.send_message(last["content"])
               ^^^^^^^^^^^^^^^^^^^^^^^^^^^^^^^^^^^^^^^^^^
  File "/Users/macbook/miniconda3/envs/eoh/lib/python3.12/site-packages/google/generativeai/generative_models.py", line 578, in send_message
    response = self.model.generate_content(
               ^^^^^^^^^^^^^^^^^^^^^^^^^^^^
  File "/Users/macbook/miniconda3/envs/eoh/lib/python3.12/site-packages/google/generativeai/generative_models.py", line 331, in generate_content
    response = self._client.generate_content(
               ^^^^^^^^^^^^^^^^^^^^^^^^^^^^^^
  File "/Users/macbook/miniconda3/envs/eoh/lib/python3.12/site-packages/google/ai/generativelanguage_v1beta/services/generative_service/client.py", line 835, in generate_content
    response = rpc(
               ^^^^
  File "/Users/macbook/miniconda3/envs/eoh/lib/python3.12/site-packages/google/api_core/gapic_v1/method.py", line 131, in __call__
    return wrapped_func(*args, **kwargs)
           ^^^^^^^^^^^^^^^^^^^^^^^^^^^^^
  File "/Users/macbook/miniconda3/envs/eoh/lib/python3.12/site-packages/google/api_core/retry/retry_unary.py", line 294, in retry_wrapped_func
    return retry_target(
           ^^^^^^^^^^^^^
  File "/Users/macbook/miniconda3/envs/eoh/lib/python3.12/site-packages/google/api_core/retry/retry_unary.py", line 156, in retry_target
    next_sleep = _retry_error_helper(
                 ^^^^^^^^^^^^^^^^^^^^
  File "/Users/macbook/miniconda3/envs/eoh/lib/python3.12/site-packages/google/api_core/retry/retry_base.py", line 214, in _retry_error_helper
    raise final_exc from source_exc
  File "/Users/macbook/miniconda3/envs/eoh/lib/python3.12/site-packages/google/api_core/retry/retry_unary.py", line 147, in retry_target
    result = target()
             ^^^^^^^^
  File "/Users/macbook/miniconda3/envs/eoh/lib/python3.12/site-packages/google/api_core/timeout.py", line 130, in func_with_timeout
    return func(*args, **kwargs)
           ^^^^^^^^^^^^^^^^^^^^^
  File "/Users/macbook/miniconda3/envs/eoh/lib/python3.12/site-packages/google/api_core/grpc_helpers.py", line 78, in error_remapped_callable
    raise exceptions.from_grpc_error(exc) from exc
google.api_core.exceptions.ResourceExhausted: 429 You exceeded your current quota, please check your plan and billing details. For more information on this error, head to: https://ai.google.dev/gemini-api/docs/rate-limits. [violations {
  quota_metric: "generativelanguage.googleapis.com/generate_content_free_tier_requests"
  quota_id: "GenerateRequestsPerMinutePerProjectPerModel-FreeTier"
  quota_dimensions {
    key: "model"
    value: "gemini-1.5-flash"
  }
  quota_dimensions {
    key: "location"
    value: "global"
  }
  quota_value: 15
}
, links {
  description: "Learn more about Gemini API quotas"
  url: "https://ai.google.dev/gemini-api/docs/rate-limits"
}
, retry_delay {
  seconds: 54
}
]
.
2025-06-15 09:25:05 INFO An exception occured: Traceback (most recent call last):
  File "/Users/macbook/Documents/Code/LLMdesignedEA-comp/llamea/llamea_api_rotations.py", line 329, in evolve_solution
    evolved_individual = chosen_llm.sample_solution(
                         ^^^^^^^^^^^^^^^^^^^^^^^^^^^
  File "/Users/macbook/Documents/Code/LLMdesignedEA-comp/llamea/llm.py", line 106, in sample_solution
    message = self.query(session_messages)
              ^^^^^^^^^^^^^^^^^^^^^^^^^^^^
  File "/Users/macbook/Documents/Code/LLMdesignedEA-comp/llamea/llm.py", line 278, in query
    response = chat_session.send_message(last["content"])
               ^^^^^^^^^^^^^^^^^^^^^^^^^^^^^^^^^^^^^^^^^^
  File "/Users/macbook/miniconda3/envs/eoh/lib/python3.12/site-packages/google/generativeai/generative_models.py", line 578, in send_message
    response = self.model.generate_content(
               ^^^^^^^^^^^^^^^^^^^^^^^^^^^^
  File "/Users/macbook/miniconda3/envs/eoh/lib/python3.12/site-packages/google/generativeai/generative_models.py", line 331, in generate_content
    response = self._client.generate_content(
               ^^^^^^^^^^^^^^^^^^^^^^^^^^^^^^
  File "/Users/macbook/miniconda3/envs/eoh/lib/python3.12/site-packages/google/ai/generativelanguage_v1beta/services/generative_service/client.py", line 835, in generate_content
    response = rpc(
               ^^^^
  File "/Users/macbook/miniconda3/envs/eoh/lib/python3.12/site-packages/google/api_core/gapic_v1/method.py", line 131, in __call__
    return wrapped_func(*args, **kwargs)
           ^^^^^^^^^^^^^^^^^^^^^^^^^^^^^
  File "/Users/macbook/miniconda3/envs/eoh/lib/python3.12/site-packages/google/api_core/retry/retry_unary.py", line 294, in retry_wrapped_func
    return retry_target(
           ^^^^^^^^^^^^^
  File "/Users/macbook/miniconda3/envs/eoh/lib/python3.12/site-packages/google/api_core/retry/retry_unary.py", line 156, in retry_target
    next_sleep = _retry_error_helper(
                 ^^^^^^^^^^^^^^^^^^^^
  File "/Users/macbook/miniconda3/envs/eoh/lib/python3.12/site-packages/google/api_core/retry/retry_base.py", line 214, in _retry_error_helper
    raise final_exc from source_exc
  File "/Users/macbook/miniconda3/envs/eoh/lib/python3.12/site-packages/google/api_core/retry/retry_unary.py", line 147, in retry_target
    result = target()
             ^^^^^^^^
  File "/Users/macbook/miniconda3/envs/eoh/lib/python3.12/site-packages/google/api_core/timeout.py", line 130, in func_with_timeout
    return func(*args, **kwargs)
           ^^^^^^^^^^^^^^^^^^^^^
  File "/Users/macbook/miniconda3/envs/eoh/lib/python3.12/site-packages/google/api_core/grpc_helpers.py", line 78, in error_remapped_callable
    raise exceptions.from_grpc_error(exc) from exc
google.api_core.exceptions.ResourceExhausted: 429 You exceeded your current quota, please check your plan and billing details. For more information on this error, head to: https://ai.google.dev/gemini-api/docs/rate-limits. [violations {
  quota_metric: "generativelanguage.googleapis.com/generate_content_free_tier_requests"
  quota_id: "GenerateRequestsPerMinutePerProjectPerModel-FreeTier"
  quota_dimensions {
    key: "model"
    value: "gemini-1.5-flash"
  }
  quota_dimensions {
    key: "location"
    value: "global"
  }
  quota_value: 15
}
, links {
  description: "Learn more about Gemini API quotas"
  url: "https://ai.google.dev/gemini-api/docs/rate-limits"
}
, retry_delay {
  seconds: 54
}
]
.
2025-06-15 09:25:05 INFO An exception occured: Traceback (most recent call last):
  File "/Users/macbook/Documents/Code/LLMdesignedEA-comp/llamea/llamea_api_rotations.py", line 329, in evolve_solution
    evolved_individual = chosen_llm.sample_solution(
                         ^^^^^^^^^^^^^^^^^^^^^^^^^^^
  File "/Users/macbook/Documents/Code/LLMdesignedEA-comp/llamea/llm.py", line 106, in sample_solution
    message = self.query(session_messages)
              ^^^^^^^^^^^^^^^^^^^^^^^^^^^^
  File "/Users/macbook/Documents/Code/LLMdesignedEA-comp/llamea/llm.py", line 278, in query
    response = chat_session.send_message(last["content"])
               ^^^^^^^^^^^^^^^^^^^^^^^^^^^^^^^^^^^^^^^^^^
  File "/Users/macbook/miniconda3/envs/eoh/lib/python3.12/site-packages/google/generativeai/generative_models.py", line 578, in send_message
    response = self.model.generate_content(
               ^^^^^^^^^^^^^^^^^^^^^^^^^^^^
  File "/Users/macbook/miniconda3/envs/eoh/lib/python3.12/site-packages/google/generativeai/generative_models.py", line 331, in generate_content
    response = self._client.generate_content(
               ^^^^^^^^^^^^^^^^^^^^^^^^^^^^^^
  File "/Users/macbook/miniconda3/envs/eoh/lib/python3.12/site-packages/google/ai/generativelanguage_v1beta/services/generative_service/client.py", line 835, in generate_content
    response = rpc(
               ^^^^
  File "/Users/macbook/miniconda3/envs/eoh/lib/python3.12/site-packages/google/api_core/gapic_v1/method.py", line 131, in __call__
    return wrapped_func(*args, **kwargs)
           ^^^^^^^^^^^^^^^^^^^^^^^^^^^^^
  File "/Users/macbook/miniconda3/envs/eoh/lib/python3.12/site-packages/google/api_core/retry/retry_unary.py", line 294, in retry_wrapped_func
    return retry_target(
           ^^^^^^^^^^^^^
  File "/Users/macbook/miniconda3/envs/eoh/lib/python3.12/site-packages/google/api_core/retry/retry_unary.py", line 156, in retry_target
    next_sleep = _retry_error_helper(
                 ^^^^^^^^^^^^^^^^^^^^
  File "/Users/macbook/miniconda3/envs/eoh/lib/python3.12/site-packages/google/api_core/retry/retry_base.py", line 214, in _retry_error_helper
    raise final_exc from source_exc
  File "/Users/macbook/miniconda3/envs/eoh/lib/python3.12/site-packages/google/api_core/retry/retry_unary.py", line 147, in retry_target
    result = target()
             ^^^^^^^^
  File "/Users/macbook/miniconda3/envs/eoh/lib/python3.12/site-packages/google/api_core/timeout.py", line 130, in func_with_timeout
    return func(*args, **kwargs)
           ^^^^^^^^^^^^^^^^^^^^^
  File "/Users/macbook/miniconda3/envs/eoh/lib/python3.12/site-packages/google/api_core/grpc_helpers.py", line 78, in error_remapped_callable
    raise exceptions.from_grpc_error(exc) from exc
google.api_core.exceptions.ResourceExhausted: 429 You exceeded your current quota, please check your plan and billing details. For more information on this error, head to: https://ai.google.dev/gemini-api/docs/rate-limits. [violations {
  quota_metric: "generativelanguage.googleapis.com/generate_content_free_tier_requests"
  quota_id: "GenerateRequestsPerMinutePerProjectPerModel-FreeTier"
  quota_dimensions {
    key: "model"
    value: "gemini-1.5-flash"
  }
  quota_dimensions {
    key: "location"
    value: "global"
  }
  quota_value: 15
}
, links {
  description: "Learn more about Gemini API quotas"
  url: "https://ai.google.dev/gemini-api/docs/rate-limits"
}
, retry_delay {
  seconds: 54
}
]
.
2025-06-15 09:25:05 INFO Using LLM api key #AIzaSyAS4WrMPg7WNPXLpCYIOG49cIYOL7vTAl8)
2025-06-15 09:25:05 INFO Using LLM api key #AIzaSyAEUmOe_NUQT_vGqRWH_9XnMDQuUe0CiKU)
2025-06-15 09:25:05 INFO Using LLM api key #AIzaSyAEUmOe_NUQT_vGqRWH_9XnMDQuUe0CiKU)
2025-06-15 09:25:05 INFO Using LLM api key #AIzaSyCbA5uIXRIIWnTv7HCUGX75WoYJ4PeZWd0)
2025-06-15 09:25:05 INFO Using LLM api key #AIzaSyAS4WrMPg7WNPXLpCYIOG49cIYOL7vTAl8)
2025-06-15 09:25:06 INFO An exception occured: Traceback (most recent call last):
  File "/Users/macbook/Documents/Code/LLMdesignedEA-comp/llamea/llamea_api_rotations.py", line 329, in evolve_solution
    evolved_individual = chosen_llm.sample_solution(
                         ^^^^^^^^^^^^^^^^^^^^^^^^^^^
  File "/Users/macbook/Documents/Code/LLMdesignedEA-comp/llamea/llm.py", line 106, in sample_solution
    message = self.query(session_messages)
              ^^^^^^^^^^^^^^^^^^^^^^^^^^^^
  File "/Users/macbook/Documents/Code/LLMdesignedEA-comp/llamea/llm.py", line 278, in query
    response = chat_session.send_message(last["content"])
               ^^^^^^^^^^^^^^^^^^^^^^^^^^^^^^^^^^^^^^^^^^
  File "/Users/macbook/miniconda3/envs/eoh/lib/python3.12/site-packages/google/generativeai/generative_models.py", line 578, in send_message
    response = self.model.generate_content(
               ^^^^^^^^^^^^^^^^^^^^^^^^^^^^
  File "/Users/macbook/miniconda3/envs/eoh/lib/python3.12/site-packages/google/generativeai/generative_models.py", line 331, in generate_content
    response = self._client.generate_content(
               ^^^^^^^^^^^^^^^^^^^^^^^^^^^^^^
  File "/Users/macbook/miniconda3/envs/eoh/lib/python3.12/site-packages/google/ai/generativelanguage_v1beta/services/generative_service/client.py", line 835, in generate_content
    response = rpc(
               ^^^^
  File "/Users/macbook/miniconda3/envs/eoh/lib/python3.12/site-packages/google/api_core/gapic_v1/method.py", line 131, in __call__
    return wrapped_func(*args, **kwargs)
           ^^^^^^^^^^^^^^^^^^^^^^^^^^^^^
  File "/Users/macbook/miniconda3/envs/eoh/lib/python3.12/site-packages/google/api_core/retry/retry_unary.py", line 294, in retry_wrapped_func
    return retry_target(
           ^^^^^^^^^^^^^
  File "/Users/macbook/miniconda3/envs/eoh/lib/python3.12/site-packages/google/api_core/retry/retry_unary.py", line 156, in retry_target
    next_sleep = _retry_error_helper(
                 ^^^^^^^^^^^^^^^^^^^^
  File "/Users/macbook/miniconda3/envs/eoh/lib/python3.12/site-packages/google/api_core/retry/retry_base.py", line 214, in _retry_error_helper
    raise final_exc from source_exc
  File "/Users/macbook/miniconda3/envs/eoh/lib/python3.12/site-packages/google/api_core/retry/retry_unary.py", line 147, in retry_target
    result = target()
             ^^^^^^^^
  File "/Users/macbook/miniconda3/envs/eoh/lib/python3.12/site-packages/google/api_core/timeout.py", line 130, in func_with_timeout
    return func(*args, **kwargs)
           ^^^^^^^^^^^^^^^^^^^^^
  File "/Users/macbook/miniconda3/envs/eoh/lib/python3.12/site-packages/google/api_core/grpc_helpers.py", line 78, in error_remapped_callable
    raise exceptions.from_grpc_error(exc) from exc
google.api_core.exceptions.ResourceExhausted: 429 You exceeded your current quota, please check your plan and billing details. For more information on this error, head to: https://ai.google.dev/gemini-api/docs/rate-limits. [violations {
  quota_metric: "generativelanguage.googleapis.com/generate_content_free_tier_requests"
  quota_id: "GenerateRequestsPerMinutePerProjectPerModel-FreeTier"
  quota_dimensions {
    key: "model"
    value: "gemini-1.5-flash"
  }
  quota_dimensions {
    key: "location"
    value: "global"
  }
  quota_value: 15
}
, links {
  description: "Learn more about Gemini API quotas"
  url: "https://ai.google.dev/gemini-api/docs/rate-limits"
}
, retry_delay {
  seconds: 53
}
]
.
2025-06-15 09:25:06 INFO An exception occured: Traceback (most recent call last):
  File "/Users/macbook/Documents/Code/LLMdesignedEA-comp/llamea/llamea_api_rotations.py", line 329, in evolve_solution
    evolved_individual = chosen_llm.sample_solution(
                         ^^^^^^^^^^^^^^^^^^^^^^^^^^^
  File "/Users/macbook/Documents/Code/LLMdesignedEA-comp/llamea/llm.py", line 106, in sample_solution
    message = self.query(session_messages)
              ^^^^^^^^^^^^^^^^^^^^^^^^^^^^
  File "/Users/macbook/Documents/Code/LLMdesignedEA-comp/llamea/llm.py", line 278, in query
    response = chat_session.send_message(last["content"])
               ^^^^^^^^^^^^^^^^^^^^^^^^^^^^^^^^^^^^^^^^^^
  File "/Users/macbook/miniconda3/envs/eoh/lib/python3.12/site-packages/google/generativeai/generative_models.py", line 578, in send_message
    response = self.model.generate_content(
               ^^^^^^^^^^^^^^^^^^^^^^^^^^^^
  File "/Users/macbook/miniconda3/envs/eoh/lib/python3.12/site-packages/google/generativeai/generative_models.py", line 331, in generate_content
    response = self._client.generate_content(
               ^^^^^^^^^^^^^^^^^^^^^^^^^^^^^^
  File "/Users/macbook/miniconda3/envs/eoh/lib/python3.12/site-packages/google/ai/generativelanguage_v1beta/services/generative_service/client.py", line 835, in generate_content
    response = rpc(
               ^^^^
  File "/Users/macbook/miniconda3/envs/eoh/lib/python3.12/site-packages/google/api_core/gapic_v1/method.py", line 131, in __call__
    return wrapped_func(*args, **kwargs)
           ^^^^^^^^^^^^^^^^^^^^^^^^^^^^^
  File "/Users/macbook/miniconda3/envs/eoh/lib/python3.12/site-packages/google/api_core/retry/retry_unary.py", line 294, in retry_wrapped_func
    return retry_target(
           ^^^^^^^^^^^^^
  File "/Users/macbook/miniconda3/envs/eoh/lib/python3.12/site-packages/google/api_core/retry/retry_unary.py", line 156, in retry_target
    next_sleep = _retry_error_helper(
                 ^^^^^^^^^^^^^^^^^^^^
  File "/Users/macbook/miniconda3/envs/eoh/lib/python3.12/site-packages/google/api_core/retry/retry_base.py", line 214, in _retry_error_helper
    raise final_exc from source_exc
  File "/Users/macbook/miniconda3/envs/eoh/lib/python3.12/site-packages/google/api_core/retry/retry_unary.py", line 147, in retry_target
    result = target()
             ^^^^^^^^
  File "/Users/macbook/miniconda3/envs/eoh/lib/python3.12/site-packages/google/api_core/timeout.py", line 130, in func_with_timeout
    return func(*args, **kwargs)
           ^^^^^^^^^^^^^^^^^^^^^
  File "/Users/macbook/miniconda3/envs/eoh/lib/python3.12/site-packages/google/api_core/grpc_helpers.py", line 78, in error_remapped_callable
    raise exceptions.from_grpc_error(exc) from exc
google.api_core.exceptions.ResourceExhausted: 429 You exceeded your current quota, please check your plan and billing details. For more information on this error, head to: https://ai.google.dev/gemini-api/docs/rate-limits. [violations {
  quota_metric: "generativelanguage.googleapis.com/generate_content_free_tier_requests"
  quota_id: "GenerateRequestsPerMinutePerProjectPerModel-FreeTier"
  quota_dimensions {
    key: "model"
    value: "gemini-1.5-flash"
  }
  quota_dimensions {
    key: "location"
    value: "global"
  }
  quota_value: 15
}
, links {
  description: "Learn more about Gemini API quotas"
  url: "https://ai.google.dev/gemini-api/docs/rate-limits"
}
, retry_delay {
  seconds: 53
}
]
.
2025-06-15 09:25:06 INFO An exception occured: Traceback (most recent call last):
  File "/Users/macbook/Documents/Code/LLMdesignedEA-comp/llamea/llamea_api_rotations.py", line 329, in evolve_solution
    evolved_individual = chosen_llm.sample_solution(
                         ^^^^^^^^^^^^^^^^^^^^^^^^^^^
  File "/Users/macbook/Documents/Code/LLMdesignedEA-comp/llamea/llm.py", line 106, in sample_solution
    message = self.query(session_messages)
              ^^^^^^^^^^^^^^^^^^^^^^^^^^^^
  File "/Users/macbook/Documents/Code/LLMdesignedEA-comp/llamea/llm.py", line 278, in query
    response = chat_session.send_message(last["content"])
               ^^^^^^^^^^^^^^^^^^^^^^^^^^^^^^^^^^^^^^^^^^
  File "/Users/macbook/miniconda3/envs/eoh/lib/python3.12/site-packages/google/generativeai/generative_models.py", line 578, in send_message
    response = self.model.generate_content(
               ^^^^^^^^^^^^^^^^^^^^^^^^^^^^
  File "/Users/macbook/miniconda3/envs/eoh/lib/python3.12/site-packages/google/generativeai/generative_models.py", line 331, in generate_content
    response = self._client.generate_content(
               ^^^^^^^^^^^^^^^^^^^^^^^^^^^^^^
  File "/Users/macbook/miniconda3/envs/eoh/lib/python3.12/site-packages/google/ai/generativelanguage_v1beta/services/generative_service/client.py", line 835, in generate_content
    response = rpc(
               ^^^^
  File "/Users/macbook/miniconda3/envs/eoh/lib/python3.12/site-packages/google/api_core/gapic_v1/method.py", line 131, in __call__
    return wrapped_func(*args, **kwargs)
           ^^^^^^^^^^^^^^^^^^^^^^^^^^^^^
  File "/Users/macbook/miniconda3/envs/eoh/lib/python3.12/site-packages/google/api_core/retry/retry_unary.py", line 294, in retry_wrapped_func
    return retry_target(
           ^^^^^^^^^^^^^
  File "/Users/macbook/miniconda3/envs/eoh/lib/python3.12/site-packages/google/api_core/retry/retry_unary.py", line 156, in retry_target
    next_sleep = _retry_error_helper(
                 ^^^^^^^^^^^^^^^^^^^^
  File "/Users/macbook/miniconda3/envs/eoh/lib/python3.12/site-packages/google/api_core/retry/retry_base.py", line 214, in _retry_error_helper
    raise final_exc from source_exc
  File "/Users/macbook/miniconda3/envs/eoh/lib/python3.12/site-packages/google/api_core/retry/retry_unary.py", line 147, in retry_target
    result = target()
             ^^^^^^^^
  File "/Users/macbook/miniconda3/envs/eoh/lib/python3.12/site-packages/google/api_core/timeout.py", line 130, in func_with_timeout
    return func(*args, **kwargs)
           ^^^^^^^^^^^^^^^^^^^^^
  File "/Users/macbook/miniconda3/envs/eoh/lib/python3.12/site-packages/google/api_core/grpc_helpers.py", line 78, in error_remapped_callable
    raise exceptions.from_grpc_error(exc) from exc
google.api_core.exceptions.ResourceExhausted: 429 You exceeded your current quota, please check your plan and billing details. For more information on this error, head to: https://ai.google.dev/gemini-api/docs/rate-limits. [violations {
  quota_metric: "generativelanguage.googleapis.com/generate_content_free_tier_requests"
  quota_id: "GenerateRequestsPerMinutePerProjectPerModel-FreeTier"
  quota_dimensions {
    key: "model"
    value: "gemini-1.5-flash"
  }
  quota_dimensions {
    key: "location"
    value: "global"
  }
  quota_value: 15
}
, links {
  description: "Learn more about Gemini API quotas"
  url: "https://ai.google.dev/gemini-api/docs/rate-limits"
}
, retry_delay {
  seconds: 53
}
]
.
2025-06-15 09:25:06 INFO An exception occured: Traceback (most recent call last):
  File "/Users/macbook/Documents/Code/LLMdesignedEA-comp/llamea/llamea_api_rotations.py", line 329, in evolve_solution
    evolved_individual = chosen_llm.sample_solution(
                         ^^^^^^^^^^^^^^^^^^^^^^^^^^^
  File "/Users/macbook/Documents/Code/LLMdesignedEA-comp/llamea/llm.py", line 106, in sample_solution
    message = self.query(session_messages)
              ^^^^^^^^^^^^^^^^^^^^^^^^^^^^
  File "/Users/macbook/Documents/Code/LLMdesignedEA-comp/llamea/llm.py", line 278, in query
    response = chat_session.send_message(last["content"])
               ^^^^^^^^^^^^^^^^^^^^^^^^^^^^^^^^^^^^^^^^^^
  File "/Users/macbook/miniconda3/envs/eoh/lib/python3.12/site-packages/google/generativeai/generative_models.py", line 578, in send_message
    response = self.model.generate_content(
               ^^^^^^^^^^^^^^^^^^^^^^^^^^^^
  File "/Users/macbook/miniconda3/envs/eoh/lib/python3.12/site-packages/google/generativeai/generative_models.py", line 331, in generate_content
    response = self._client.generate_content(
               ^^^^^^^^^^^^^^^^^^^^^^^^^^^^^^
  File "/Users/macbook/miniconda3/envs/eoh/lib/python3.12/site-packages/google/ai/generativelanguage_v1beta/services/generative_service/client.py", line 835, in generate_content
    response = rpc(
               ^^^^
  File "/Users/macbook/miniconda3/envs/eoh/lib/python3.12/site-packages/google/api_core/gapic_v1/method.py", line 131, in __call__
    return wrapped_func(*args, **kwargs)
           ^^^^^^^^^^^^^^^^^^^^^^^^^^^^^
  File "/Users/macbook/miniconda3/envs/eoh/lib/python3.12/site-packages/google/api_core/retry/retry_unary.py", line 294, in retry_wrapped_func
    return retry_target(
           ^^^^^^^^^^^^^
  File "/Users/macbook/miniconda3/envs/eoh/lib/python3.12/site-packages/google/api_core/retry/retry_unary.py", line 156, in retry_target
    next_sleep = _retry_error_helper(
                 ^^^^^^^^^^^^^^^^^^^^
  File "/Users/macbook/miniconda3/envs/eoh/lib/python3.12/site-packages/google/api_core/retry/retry_base.py", line 214, in _retry_error_helper
    raise final_exc from source_exc
  File "/Users/macbook/miniconda3/envs/eoh/lib/python3.12/site-packages/google/api_core/retry/retry_unary.py", line 147, in retry_target
    result = target()
             ^^^^^^^^
  File "/Users/macbook/miniconda3/envs/eoh/lib/python3.12/site-packages/google/api_core/timeout.py", line 130, in func_with_timeout
    return func(*args, **kwargs)
           ^^^^^^^^^^^^^^^^^^^^^
  File "/Users/macbook/miniconda3/envs/eoh/lib/python3.12/site-packages/google/api_core/grpc_helpers.py", line 78, in error_remapped_callable
    raise exceptions.from_grpc_error(exc) from exc
google.api_core.exceptions.ResourceExhausted: 429 You exceeded your current quota, please check your plan and billing details. For more information on this error, head to: https://ai.google.dev/gemini-api/docs/rate-limits. [violations {
  quota_metric: "generativelanguage.googleapis.com/generate_content_free_tier_requests"
  quota_id: "GenerateRequestsPerMinutePerProjectPerModel-FreeTier"
  quota_dimensions {
    key: "model"
    value: "gemini-1.5-flash"
  }
  quota_dimensions {
    key: "location"
    value: "global"
  }
  quota_value: 15
}
, links {
  description: "Learn more about Gemini API quotas"
  url: "https://ai.google.dev/gemini-api/docs/rate-limits"
}
, retry_delay {
  seconds: 53
}
]
.
2025-06-15 09:25:06 INFO An exception occured: Traceback (most recent call last):
  File "/Users/macbook/Documents/Code/LLMdesignedEA-comp/llamea/llamea_api_rotations.py", line 329, in evolve_solution
    evolved_individual = chosen_llm.sample_solution(
                         ^^^^^^^^^^^^^^^^^^^^^^^^^^^
  File "/Users/macbook/Documents/Code/LLMdesignedEA-comp/llamea/llm.py", line 106, in sample_solution
    message = self.query(session_messages)
              ^^^^^^^^^^^^^^^^^^^^^^^^^^^^
  File "/Users/macbook/Documents/Code/LLMdesignedEA-comp/llamea/llm.py", line 278, in query
    response = chat_session.send_message(last["content"])
               ^^^^^^^^^^^^^^^^^^^^^^^^^^^^^^^^^^^^^^^^^^
  File "/Users/macbook/miniconda3/envs/eoh/lib/python3.12/site-packages/google/generativeai/generative_models.py", line 578, in send_message
    response = self.model.generate_content(
               ^^^^^^^^^^^^^^^^^^^^^^^^^^^^
  File "/Users/macbook/miniconda3/envs/eoh/lib/python3.12/site-packages/google/generativeai/generative_models.py", line 331, in generate_content
    response = self._client.generate_content(
               ^^^^^^^^^^^^^^^^^^^^^^^^^^^^^^
  File "/Users/macbook/miniconda3/envs/eoh/lib/python3.12/site-packages/google/ai/generativelanguage_v1beta/services/generative_service/client.py", line 835, in generate_content
    response = rpc(
               ^^^^
  File "/Users/macbook/miniconda3/envs/eoh/lib/python3.12/site-packages/google/api_core/gapic_v1/method.py", line 131, in __call__
    return wrapped_func(*args, **kwargs)
           ^^^^^^^^^^^^^^^^^^^^^^^^^^^^^
  File "/Users/macbook/miniconda3/envs/eoh/lib/python3.12/site-packages/google/api_core/retry/retry_unary.py", line 294, in retry_wrapped_func
    return retry_target(
           ^^^^^^^^^^^^^
  File "/Users/macbook/miniconda3/envs/eoh/lib/python3.12/site-packages/google/api_core/retry/retry_unary.py", line 156, in retry_target
    next_sleep = _retry_error_helper(
                 ^^^^^^^^^^^^^^^^^^^^
  File "/Users/macbook/miniconda3/envs/eoh/lib/python3.12/site-packages/google/api_core/retry/retry_base.py", line 214, in _retry_error_helper
    raise final_exc from source_exc
  File "/Users/macbook/miniconda3/envs/eoh/lib/python3.12/site-packages/google/api_core/retry/retry_unary.py", line 147, in retry_target
    result = target()
             ^^^^^^^^
  File "/Users/macbook/miniconda3/envs/eoh/lib/python3.12/site-packages/google/api_core/timeout.py", line 130, in func_with_timeout
    return func(*args, **kwargs)
           ^^^^^^^^^^^^^^^^^^^^^
  File "/Users/macbook/miniconda3/envs/eoh/lib/python3.12/site-packages/google/api_core/grpc_helpers.py", line 78, in error_remapped_callable
    raise exceptions.from_grpc_error(exc) from exc
google.api_core.exceptions.ResourceExhausted: 429 You exceeded your current quota, please check your plan and billing details. For more information on this error, head to: https://ai.google.dev/gemini-api/docs/rate-limits. [violations {
  quota_metric: "generativelanguage.googleapis.com/generate_content_free_tier_requests"
  quota_id: "GenerateRequestsPerMinutePerProjectPerModel-FreeTier"
  quota_dimensions {
    key: "model"
    value: "gemini-1.5-flash"
  }
  quota_dimensions {
    key: "location"
    value: "global"
  }
  quota_value: 15
}
, links {
  description: "Learn more about Gemini API quotas"
  url: "https://ai.google.dev/gemini-api/docs/rate-limits"
}
, retry_delay {
  seconds: 53
}
]
.
