2025-06-15 07:26:55 INFO --- GNBG Problem Parameters for f8 ---
  Dimension: 30, MaxEvals: 500000
  Search Bounds: [-100, 100]
  Number of Components: 1
  Known Optimum Value: -656.788998
  Lambda (Curvature): [1]
  Mu (Asymmetry/Depth): [0.2 0.2]
----------------------------------------
2025-06-15 07:26:56 INFO --- GNBG Problem Parameters for f8 ---
  Dimension: 30, MaxEvals: 500000
  Search Bounds: [-100, 100]
  Number of Components: 1
  Known Optimum Value: -656.788998
  Lambda (Curvature): [1]
  Mu (Asymmetry/Depth): [0.2 0.2]
----------------------------------------
2025-06-15 07:26:56 INFO --- GNBG Problem Parameters for f8 ---
  Dimension: 30, MaxEvals: 500000
  Search Bounds: [-100, 100]
  Number of Components: 1
  Known Optimum Value: -656.788998
  Lambda (Curvature): [1]
  Mu (Asymmetry/Depth): [0.2 0.2]
----------------------------------------
2025-06-15 07:26:56 INFO --- GNBG Problem Parameters for f8 ---
  Dimension: 30, MaxEvals: 500000
  Search Bounds: [-100, 100]
  Number of Components: 1
  Known Optimum Value: -656.788998
  Lambda (Curvature): [1]
  Mu (Asymmetry/Depth): [0.2 0.2]
----------------------------------------
2025-06-15 07:26:57 INFO --- GNBG Problem Parameters for f8 ---
  Dimension: 30, MaxEvals: 500000
  Search Bounds: [-100, 100]
  Number of Components: 1
  Known Optimum Value: -656.788998
  Lambda (Curvature): [1]
  Mu (Asymmetry/Depth): [0.2 0.2]
----------------------------------------
2025-06-15 07:27:00 INFO Run function 8 complete. FEHistory len: 50000, AOCC: 0.0000
2025-06-15 07:27:00 INFO FeHistory: [150511.05824033 241380.864142   193833.75199372 ...  48201.97014914
  48746.89399708  48233.33879328]
2025-06-15 07:27:00 INFO Expected Optimum FE: -656.7889979935655
2025-06-15 07:27:00 INFO Multimodal (single component) AOCC mean: 0.0000
2025-06-15 07:27:00 INFO AOCC mean: 0.0000
2025-06-15 07:27:02 INFO Run function 8 complete. FEHistory len: 50000, AOCC: 0.0000
2025-06-15 07:27:02 INFO FeHistory: [189381.91988827 179799.32353429 213882.03484434 ...  38727.45907664
  38727.4590829   38727.45908422]
2025-06-15 07:27:02 INFO Expected Optimum FE: -656.7889979935655
2025-06-15 07:27:02 INFO Multimodal (single component) AOCC mean: 0.0000
2025-06-15 07:27:02 INFO AOCC mean: 0.0000
2025-06-15 07:27:14 INFO Run function 8 complete. FEHistory len: 50000, AOCC: 0.0000
2025-06-15 07:27:14 INFO FeHistory: [144071.30082221 341883.40398043 178559.22488653 ...  38252.42103039
  34884.79091862  34887.2487382 ]
2025-06-15 07:27:14 INFO Expected Optimum FE: -656.7889979935655
2025-06-15 07:27:14 INFO Multimodal (single component) AOCC mean: 0.0000
2025-06-15 07:27:14 INFO AOCC mean: 0.0000
2025-06-15 07:27:14 INFO Run function 8 complete. FEHistory len: 50000, AOCC: 0.0000
2025-06-15 07:27:14 INFO FeHistory: [ 98120.03323553 232493.50270622 129335.84867342 ...  22556.99616603
  28143.61647182  22307.02282212]
2025-06-15 07:27:14 INFO Expected Optimum FE: -656.7889979935655
2025-06-15 07:27:14 INFO Multimodal (single component) AOCC mean: 0.0000
2025-06-15 07:27:14 INFO AOCC mean: 0.0000
2025-06-15 07:27:15 INFO Run function 8 complete. FEHistory len: 50000, AOCC: 0.0000
2025-06-15 07:27:15 INFO FeHistory: [104701.404483   259855.22753519 251723.93573802 ...  49448.98989624
  45032.65641466  48955.58584926]
2025-06-15 07:27:15 INFO Expected Optimum FE: -656.7889979935655
2025-06-15 07:27:15 INFO Multimodal (single component) AOCC mean: 0.0000
2025-06-15 07:27:15 INFO AOCC mean: 0.0000
2025-06-15 07:27:23 INFO --- GNBG Problem Parameters for f8 ---
  Dimension: 30, MaxEvals: 500000
  Search Bounds: [-100, 100]
  Number of Components: 1
  Known Optimum Value: -656.788998
  Lambda (Curvature): [1]
  Mu (Asymmetry/Depth): [0.2 0.2]
----------------------------------------
2025-06-15 07:27:23 INFO --- GNBG Problem Parameters for f8 ---
  Dimension: 30, MaxEvals: 500000
  Search Bounds: [-100, 100]
  Number of Components: 1
  Known Optimum Value: -656.788998
  Lambda (Curvature): [1]
  Mu (Asymmetry/Depth): [0.2 0.2]
----------------------------------------
2025-06-15 07:27:23 INFO --- GNBG Problem Parameters for f8 ---
  Dimension: 30, MaxEvals: 500000
  Search Bounds: [-100, 100]
  Number of Components: 1
  Known Optimum Value: -656.788998
  Lambda (Curvature): [1]
  Mu (Asymmetry/Depth): [0.2 0.2]
----------------------------------------
2025-06-15 07:27:23 INFO --- GNBG Problem Parameters for f8 ---
  Dimension: 30, MaxEvals: 500000
  Search Bounds: [-100, 100]
  Number of Components: 1
  Known Optimum Value: -656.788998
  Lambda (Curvature): [1]
  Mu (Asymmetry/Depth): [0.2 0.2]
----------------------------------------
2025-06-15 07:27:24 INFO --- GNBG Problem Parameters for f8 ---
  Dimension: 30, MaxEvals: 500000
  Search Bounds: [-100, 100]
  Number of Components: 1
  Known Optimum Value: -656.788998
  Lambda (Curvature): [1]
  Mu (Asymmetry/Depth): [0.2 0.2]
----------------------------------------
2025-06-15 07:27:31 INFO Run function 8 complete. FEHistory len: 50000, AOCC: 0.0000
2025-06-15 07:27:31 INFO FeHistory: [215795.29628026 188882.8999426  206259.89372519 ...  66938.25623901
  66938.29875599  66938.23768144]
2025-06-15 07:27:31 INFO Expected Optimum FE: -656.7889979935655
2025-06-15 07:27:31 INFO Multimodal (single component) AOCC mean: 0.0000
2025-06-15 07:27:31 INFO AOCC mean: 0.0000
2025-06-15 07:27:31 INFO Run function 8 complete. FEHistory len: 50000, AOCC: 0.0000
2025-06-15 07:27:31 INFO FeHistory: [184508.29243768 207206.50025237 213296.88386454 ...  35502.23732879
  35502.23742306  35502.23700552]
2025-06-15 07:27:31 INFO Expected Optimum FE: -656.7889979935655
2025-06-15 07:27:31 INFO Multimodal (single component) AOCC mean: 0.0000
2025-06-15 07:27:31 INFO AOCC mean: 0.0000
2025-06-15 07:27:31 INFO Run function 8 complete. FEHistory len: 50000, AOCC: 0.0000
2025-06-15 07:27:31 INFO FeHistory: [145160.99321726 240786.8628156  125636.08755542 ...  15421.46776111
  15421.52244367  15420.95456987]
2025-06-15 07:27:31 INFO Expected Optimum FE: -656.7889979935655
2025-06-15 07:27:31 INFO Multimodal (single component) AOCC mean: 0.0000
2025-06-15 07:27:31 INFO AOCC mean: 0.0000
2025-06-15 07:27:31 INFO Run function 8 complete. FEHistory len: 50000, AOCC: 0.0000
2025-06-15 07:27:31 INFO FeHistory: [235672.86591187 215411.45586925 239079.24422966 ...  37641.58388295
  37267.28167548  37679.77752777]
2025-06-15 07:27:31 INFO Expected Optimum FE: -656.7889979935655
2025-06-15 07:27:31 INFO Multimodal (single component) AOCC mean: 0.0000
2025-06-15 07:27:31 INFO AOCC mean: 0.0000
2025-06-15 07:27:43 INFO Run function 8 complete. FEHistory len: 50000, AOCC: 0.0000
2025-06-15 07:27:43 INFO FeHistory: [170913.61549004 103331.5884219  233497.8107726  ...  42810.71632622
  43952.70825242  41799.53651328]
2025-06-15 07:27:43 INFO Expected Optimum FE: -656.7889979935655
2025-06-15 07:27:43 INFO Multimodal (single component) AOCC mean: 0.0000
2025-06-15 07:27:43 INFO AOCC mean: 0.0000
2025-06-15 07:27:44 INFO An exception occured: Traceback (most recent call last):
  File "/Users/macbook/Documents/Code/LLMdesignedEA-comp/llamea/llamea_multi_prompts.py", line 367, in evolve_solution
    evolved_individual = self.llm.sample_solution(
                         ^^^^^^^^^^^^^^^^^^^^^^^^^
  File "/Users/macbook/Documents/Code/LLMdesignedEA-comp/llamea/llm.py", line 106, in sample_solution
    message = self.query(session_messages)
              ^^^^^^^^^^^^^^^^^^^^^^^^^^^^
  File "/Users/macbook/Documents/Code/LLMdesignedEA-comp/llamea/llm.py", line 277, in query
    response = chat_session.send_message(last["content"])
               ^^^^^^^^^^^^^^^^^^^^^^^^^^^^^^^^^^^^^^^^^^
  File "/Users/macbook/miniconda3/envs/eoh/lib/python3.12/site-packages/google/generativeai/generative_models.py", line 578, in send_message
    response = self.model.generate_content(
               ^^^^^^^^^^^^^^^^^^^^^^^^^^^^
  File "/Users/macbook/miniconda3/envs/eoh/lib/python3.12/site-packages/google/generativeai/generative_models.py", line 331, in generate_content
    response = self._client.generate_content(
               ^^^^^^^^^^^^^^^^^^^^^^^^^^^^^^
  File "/Users/macbook/miniconda3/envs/eoh/lib/python3.12/site-packages/google/ai/generativelanguage_v1beta/services/generative_service/client.py", line 835, in generate_content
    response = rpc(
               ^^^^
  File "/Users/macbook/miniconda3/envs/eoh/lib/python3.12/site-packages/google/api_core/gapic_v1/method.py", line 131, in __call__
    return wrapped_func(*args, **kwargs)
           ^^^^^^^^^^^^^^^^^^^^^^^^^^^^^
  File "/Users/macbook/miniconda3/envs/eoh/lib/python3.12/site-packages/google/api_core/retry/retry_unary.py", line 294, in retry_wrapped_func
    return retry_target(
           ^^^^^^^^^^^^^
  File "/Users/macbook/miniconda3/envs/eoh/lib/python3.12/site-packages/google/api_core/retry/retry_unary.py", line 156, in retry_target
    next_sleep = _retry_error_helper(
                 ^^^^^^^^^^^^^^^^^^^^
  File "/Users/macbook/miniconda3/envs/eoh/lib/python3.12/site-packages/google/api_core/retry/retry_base.py", line 214, in _retry_error_helper
    raise final_exc from source_exc
  File "/Users/macbook/miniconda3/envs/eoh/lib/python3.12/site-packages/google/api_core/retry/retry_unary.py", line 147, in retry_target
    result = target()
             ^^^^^^^^
  File "/Users/macbook/miniconda3/envs/eoh/lib/python3.12/site-packages/google/api_core/timeout.py", line 130, in func_with_timeout
    return func(*args, **kwargs)
           ^^^^^^^^^^^^^^^^^^^^^
  File "/Users/macbook/miniconda3/envs/eoh/lib/python3.12/site-packages/google/api_core/grpc_helpers.py", line 78, in error_remapped_callable
    raise exceptions.from_grpc_error(exc) from exc
google.api_core.exceptions.ResourceExhausted: 429 You exceeded your current quota, please check your plan and billing details. For more information on this error, head to: https://ai.google.dev/gemini-api/docs/rate-limits. [violations {
  quota_metric: "generativelanguage.googleapis.com/generate_content_free_tier_requests"
  quota_id: "GenerateRequestsPerMinutePerProjectPerModel-FreeTier"
  quota_dimensions {
    key: "model"
    value: "gemini-1.5-flash"
  }
  quota_dimensions {
    key: "location"
    value: "global"
  }
  quota_value: 15
}
, links {
  description: "Learn more about Gemini API quotas"
  url: "https://ai.google.dev/gemini-api/docs/rate-limits"
}
, retry_delay {
  seconds: 15
}
]
.
2025-06-15 07:27:44 INFO An exception occured: Traceback (most recent call last):
  File "/Users/macbook/Documents/Code/LLMdesignedEA-comp/llamea/llamea_multi_prompts.py", line 367, in evolve_solution
    evolved_individual = self.llm.sample_solution(
                         ^^^^^^^^^^^^^^^^^^^^^^^^^
  File "/Users/macbook/Documents/Code/LLMdesignedEA-comp/llamea/llm.py", line 106, in sample_solution
    message = self.query(session_messages)
              ^^^^^^^^^^^^^^^^^^^^^^^^^^^^
  File "/Users/macbook/Documents/Code/LLMdesignedEA-comp/llamea/llm.py", line 277, in query
    response = chat_session.send_message(last["content"])
               ^^^^^^^^^^^^^^^^^^^^^^^^^^^^^^^^^^^^^^^^^^
  File "/Users/macbook/miniconda3/envs/eoh/lib/python3.12/site-packages/google/generativeai/generative_models.py", line 578, in send_message
    response = self.model.generate_content(
               ^^^^^^^^^^^^^^^^^^^^^^^^^^^^
  File "/Users/macbook/miniconda3/envs/eoh/lib/python3.12/site-packages/google/generativeai/generative_models.py", line 331, in generate_content
    response = self._client.generate_content(
               ^^^^^^^^^^^^^^^^^^^^^^^^^^^^^^
  File "/Users/macbook/miniconda3/envs/eoh/lib/python3.12/site-packages/google/ai/generativelanguage_v1beta/services/generative_service/client.py", line 835, in generate_content
    response = rpc(
               ^^^^
  File "/Users/macbook/miniconda3/envs/eoh/lib/python3.12/site-packages/google/api_core/gapic_v1/method.py", line 131, in __call__
    return wrapped_func(*args, **kwargs)
           ^^^^^^^^^^^^^^^^^^^^^^^^^^^^^
  File "/Users/macbook/miniconda3/envs/eoh/lib/python3.12/site-packages/google/api_core/retry/retry_unary.py", line 294, in retry_wrapped_func
    return retry_target(
           ^^^^^^^^^^^^^
  File "/Users/macbook/miniconda3/envs/eoh/lib/python3.12/site-packages/google/api_core/retry/retry_unary.py", line 156, in retry_target
    next_sleep = _retry_error_helper(
                 ^^^^^^^^^^^^^^^^^^^^
  File "/Users/macbook/miniconda3/envs/eoh/lib/python3.12/site-packages/google/api_core/retry/retry_base.py", line 214, in _retry_error_helper
    raise final_exc from source_exc
  File "/Users/macbook/miniconda3/envs/eoh/lib/python3.12/site-packages/google/api_core/retry/retry_unary.py", line 147, in retry_target
    result = target()
             ^^^^^^^^
  File "/Users/macbook/miniconda3/envs/eoh/lib/python3.12/site-packages/google/api_core/timeout.py", line 130, in func_with_timeout
    return func(*args, **kwargs)
           ^^^^^^^^^^^^^^^^^^^^^
  File "/Users/macbook/miniconda3/envs/eoh/lib/python3.12/site-packages/google/api_core/grpc_helpers.py", line 78, in error_remapped_callable
    raise exceptions.from_grpc_error(exc) from exc
google.api_core.exceptions.ResourceExhausted: 429 You exceeded your current quota, please check your plan and billing details. For more information on this error, head to: https://ai.google.dev/gemini-api/docs/rate-limits. [violations {
  quota_metric: "generativelanguage.googleapis.com/generate_content_free_tier_requests"
  quota_id: "GenerateRequestsPerMinutePerProjectPerModel-FreeTier"
  quota_dimensions {
    key: "model"
    value: "gemini-1.5-flash"
  }
  quota_dimensions {
    key: "location"
    value: "global"
  }
  quota_value: 15
}
, links {
  description: "Learn more about Gemini API quotas"
  url: "https://ai.google.dev/gemini-api/docs/rate-limits"
}
, retry_delay {
  seconds: 15
}
]
.
2025-06-15 07:27:51 INFO --- GNBG Problem Parameters for f8 ---
  Dimension: 30, MaxEvals: 500000
  Search Bounds: [-100, 100]
  Number of Components: 1
  Known Optimum Value: -656.788998
  Lambda (Curvature): [1]
  Mu (Asymmetry/Depth): [0.2 0.2]
----------------------------------------
2025-06-15 07:27:52 INFO --- GNBG Problem Parameters for f8 ---
  Dimension: 30, MaxEvals: 500000
  Search Bounds: [-100, 100]
  Number of Components: 1
  Known Optimum Value: -656.788998
  Lambda (Curvature): [1]
  Mu (Asymmetry/Depth): [0.2 0.2]
----------------------------------------
2025-06-15 07:27:52 INFO --- GNBG Problem Parameters for f8 ---
  Dimension: 30, MaxEvals: 500000
  Search Bounds: [-100, 100]
  Number of Components: 1
  Known Optimum Value: -656.788998
  Lambda (Curvature): [1]
  Mu (Asymmetry/Depth): [0.2 0.2]
----------------------------------------
2025-06-15 07:27:55 INFO Run function 8 complete. FEHistory len: 50000, AOCC: 0.0000
2025-06-15 07:27:55 INFO FeHistory: [231357.9812079  189776.76820409 153897.84544338 ...  41619.49792886
  41619.49792886  41619.49792886]
2025-06-15 07:27:55 INFO Expected Optimum FE: -656.7889979935655
2025-06-15 07:27:55 INFO Multimodal (single component) AOCC mean: 0.0000
2025-06-15 07:27:55 INFO AOCC mean: 0.0000
2025-06-15 07:27:56 INFO Run function 8 complete. FEHistory len: 50000, AOCC: 0.0000
2025-06-15 07:27:56 INFO FeHistory: [186114.52645017 200742.23693735 211150.92545321 ...  21184.03527683
  21710.50766131  21710.49612299]
2025-06-15 07:27:56 INFO Expected Optimum FE: -656.7889979935655
2025-06-15 07:27:56 INFO Multimodal (single component) AOCC mean: 0.0000
2025-06-15 07:27:56 INFO AOCC mean: 0.0000
2025-06-15 07:27:57 INFO Run function 8 complete. FEHistory len: 50000, AOCC: 0.0000
2025-06-15 07:27:57 INFO FeHistory: [184867.36134651 206362.09113038 228233.41593097 ...  25180.28011873
  25180.28011873  25180.28011873]
2025-06-15 07:27:57 INFO Expected Optimum FE: -656.7889979935655
2025-06-15 07:27:57 INFO Multimodal (single component) AOCC mean: 0.0000
2025-06-15 07:27:57 INFO AOCC mean: 0.0000
2025-06-15 07:27:57 INFO An exception occured: Traceback (most recent call last):
  File "/Users/macbook/Documents/Code/LLMdesignedEA-comp/llamea/llamea_multi_prompts.py", line 367, in evolve_solution
    evolved_individual = self.llm.sample_solution(
                         ^^^^^^^^^^^^^^^^^^^^^^^^^
  File "/Users/macbook/Documents/Code/LLMdesignedEA-comp/llamea/llm.py", line 106, in sample_solution
    message = self.query(session_messages)
              ^^^^^^^^^^^^^^^^^^^^^^^^^^^^
  File "/Users/macbook/Documents/Code/LLMdesignedEA-comp/llamea/llm.py", line 277, in query
    response = chat_session.send_message(last["content"])
               ^^^^^^^^^^^^^^^^^^^^^^^^^^^^^^^^^^^^^^^^^^
  File "/Users/macbook/miniconda3/envs/eoh/lib/python3.12/site-packages/google/generativeai/generative_models.py", line 578, in send_message
    response = self.model.generate_content(
               ^^^^^^^^^^^^^^^^^^^^^^^^^^^^
  File "/Users/macbook/miniconda3/envs/eoh/lib/python3.12/site-packages/google/generativeai/generative_models.py", line 331, in generate_content
    response = self._client.generate_content(
               ^^^^^^^^^^^^^^^^^^^^^^^^^^^^^^
  File "/Users/macbook/miniconda3/envs/eoh/lib/python3.12/site-packages/google/ai/generativelanguage_v1beta/services/generative_service/client.py", line 835, in generate_content
    response = rpc(
               ^^^^
  File "/Users/macbook/miniconda3/envs/eoh/lib/python3.12/site-packages/google/api_core/gapic_v1/method.py", line 131, in __call__
    return wrapped_func(*args, **kwargs)
           ^^^^^^^^^^^^^^^^^^^^^^^^^^^^^
  File "/Users/macbook/miniconda3/envs/eoh/lib/python3.12/site-packages/google/api_core/retry/retry_unary.py", line 294, in retry_wrapped_func
    return retry_target(
           ^^^^^^^^^^^^^
  File "/Users/macbook/miniconda3/envs/eoh/lib/python3.12/site-packages/google/api_core/retry/retry_unary.py", line 156, in retry_target
    next_sleep = _retry_error_helper(
                 ^^^^^^^^^^^^^^^^^^^^
  File "/Users/macbook/miniconda3/envs/eoh/lib/python3.12/site-packages/google/api_core/retry/retry_base.py", line 214, in _retry_error_helper
    raise final_exc from source_exc
  File "/Users/macbook/miniconda3/envs/eoh/lib/python3.12/site-packages/google/api_core/retry/retry_unary.py", line 147, in retry_target
    result = target()
             ^^^^^^^^
  File "/Users/macbook/miniconda3/envs/eoh/lib/python3.12/site-packages/google/api_core/timeout.py", line 130, in func_with_timeout
    return func(*args, **kwargs)
           ^^^^^^^^^^^^^^^^^^^^^
  File "/Users/macbook/miniconda3/envs/eoh/lib/python3.12/site-packages/google/api_core/grpc_helpers.py", line 78, in error_remapped_callable
    raise exceptions.from_grpc_error(exc) from exc
google.api_core.exceptions.ResourceExhausted: 429 You exceeded your current quota, please check your plan and billing details. For more information on this error, head to: https://ai.google.dev/gemini-api/docs/rate-limits. [violations {
  quota_metric: "generativelanguage.googleapis.com/generate_content_free_tier_requests"
  quota_id: "GenerateRequestsPerMinutePerProjectPerModel-FreeTier"
  quota_dimensions {
    key: "model"
    value: "gemini-1.5-flash"
  }
  quota_dimensions {
    key: "location"
    value: "global"
  }
  quota_value: 15
}
, links {
  description: "Learn more about Gemini API quotas"
  url: "https://ai.google.dev/gemini-api/docs/rate-limits"
}
, retry_delay {
  seconds: 2
}
]
.
2025-06-15 07:27:57 INFO An exception occured: Traceback (most recent call last):
  File "/Users/macbook/Documents/Code/LLMdesignedEA-comp/llamea/llamea_multi_prompts.py", line 367, in evolve_solution
    evolved_individual = self.llm.sample_solution(
                         ^^^^^^^^^^^^^^^^^^^^^^^^^
  File "/Users/macbook/Documents/Code/LLMdesignedEA-comp/llamea/llm.py", line 106, in sample_solution
    message = self.query(session_messages)
              ^^^^^^^^^^^^^^^^^^^^^^^^^^^^
  File "/Users/macbook/Documents/Code/LLMdesignedEA-comp/llamea/llm.py", line 277, in query
    response = chat_session.send_message(last["content"])
               ^^^^^^^^^^^^^^^^^^^^^^^^^^^^^^^^^^^^^^^^^^
  File "/Users/macbook/miniconda3/envs/eoh/lib/python3.12/site-packages/google/generativeai/generative_models.py", line 578, in send_message
    response = self.model.generate_content(
               ^^^^^^^^^^^^^^^^^^^^^^^^^^^^
  File "/Users/macbook/miniconda3/envs/eoh/lib/python3.12/site-packages/google/generativeai/generative_models.py", line 331, in generate_content
    response = self._client.generate_content(
               ^^^^^^^^^^^^^^^^^^^^^^^^^^^^^^
  File "/Users/macbook/miniconda3/envs/eoh/lib/python3.12/site-packages/google/ai/generativelanguage_v1beta/services/generative_service/client.py", line 835, in generate_content
    response = rpc(
               ^^^^
  File "/Users/macbook/miniconda3/envs/eoh/lib/python3.12/site-packages/google/api_core/gapic_v1/method.py", line 131, in __call__
    return wrapped_func(*args, **kwargs)
           ^^^^^^^^^^^^^^^^^^^^^^^^^^^^^
  File "/Users/macbook/miniconda3/envs/eoh/lib/python3.12/site-packages/google/api_core/retry/retry_unary.py", line 294, in retry_wrapped_func
    return retry_target(
           ^^^^^^^^^^^^^
  File "/Users/macbook/miniconda3/envs/eoh/lib/python3.12/site-packages/google/api_core/retry/retry_unary.py", line 156, in retry_target
    next_sleep = _retry_error_helper(
                 ^^^^^^^^^^^^^^^^^^^^
  File "/Users/macbook/miniconda3/envs/eoh/lib/python3.12/site-packages/google/api_core/retry/retry_base.py", line 214, in _retry_error_helper
    raise final_exc from source_exc
  File "/Users/macbook/miniconda3/envs/eoh/lib/python3.12/site-packages/google/api_core/retry/retry_unary.py", line 147, in retry_target
    result = target()
             ^^^^^^^^
  File "/Users/macbook/miniconda3/envs/eoh/lib/python3.12/site-packages/google/api_core/timeout.py", line 130, in func_with_timeout
    return func(*args, **kwargs)
           ^^^^^^^^^^^^^^^^^^^^^
  File "/Users/macbook/miniconda3/envs/eoh/lib/python3.12/site-packages/google/api_core/grpc_helpers.py", line 78, in error_remapped_callable
    raise exceptions.from_grpc_error(exc) from exc
google.api_core.exceptions.ResourceExhausted: 429 You exceeded your current quota, please check your plan and billing details. For more information on this error, head to: https://ai.google.dev/gemini-api/docs/rate-limits. [violations {
  quota_metric: "generativelanguage.googleapis.com/generate_content_free_tier_requests"
  quota_id: "GenerateRequestsPerMinutePerProjectPerModel-FreeTier"
  quota_dimensions {
    key: "model"
    value: "gemini-1.5-flash"
  }
  quota_dimensions {
    key: "location"
    value: "global"
  }
  quota_value: 15
}
, links {
  description: "Learn more about Gemini API quotas"
  url: "https://ai.google.dev/gemini-api/docs/rate-limits"
}
, retry_delay {
  seconds: 2
}
]
.
2025-06-15 07:27:57 INFO An exception occured: Traceback (most recent call last):
  File "/Users/macbook/Documents/Code/LLMdesignedEA-comp/llamea/llamea_multi_prompts.py", line 367, in evolve_solution
    evolved_individual = self.llm.sample_solution(
                         ^^^^^^^^^^^^^^^^^^^^^^^^^
  File "/Users/macbook/Documents/Code/LLMdesignedEA-comp/llamea/llm.py", line 106, in sample_solution
    message = self.query(session_messages)
              ^^^^^^^^^^^^^^^^^^^^^^^^^^^^
  File "/Users/macbook/Documents/Code/LLMdesignedEA-comp/llamea/llm.py", line 277, in query
    response = chat_session.send_message(last["content"])
               ^^^^^^^^^^^^^^^^^^^^^^^^^^^^^^^^^^^^^^^^^^
  File "/Users/macbook/miniconda3/envs/eoh/lib/python3.12/site-packages/google/generativeai/generative_models.py", line 578, in send_message
    response = self.model.generate_content(
               ^^^^^^^^^^^^^^^^^^^^^^^^^^^^
  File "/Users/macbook/miniconda3/envs/eoh/lib/python3.12/site-packages/google/generativeai/generative_models.py", line 331, in generate_content
    response = self._client.generate_content(
               ^^^^^^^^^^^^^^^^^^^^^^^^^^^^^^
  File "/Users/macbook/miniconda3/envs/eoh/lib/python3.12/site-packages/google/ai/generativelanguage_v1beta/services/generative_service/client.py", line 835, in generate_content
    response = rpc(
               ^^^^
  File "/Users/macbook/miniconda3/envs/eoh/lib/python3.12/site-packages/google/api_core/gapic_v1/method.py", line 131, in __call__
    return wrapped_func(*args, **kwargs)
           ^^^^^^^^^^^^^^^^^^^^^^^^^^^^^
  File "/Users/macbook/miniconda3/envs/eoh/lib/python3.12/site-packages/google/api_core/retry/retry_unary.py", line 294, in retry_wrapped_func
    return retry_target(
           ^^^^^^^^^^^^^
  File "/Users/macbook/miniconda3/envs/eoh/lib/python3.12/site-packages/google/api_core/retry/retry_unary.py", line 156, in retry_target
    next_sleep = _retry_error_helper(
                 ^^^^^^^^^^^^^^^^^^^^
  File "/Users/macbook/miniconda3/envs/eoh/lib/python3.12/site-packages/google/api_core/retry/retry_base.py", line 214, in _retry_error_helper
    raise final_exc from source_exc
  File "/Users/macbook/miniconda3/envs/eoh/lib/python3.12/site-packages/google/api_core/retry/retry_unary.py", line 147, in retry_target
    result = target()
             ^^^^^^^^
  File "/Users/macbook/miniconda3/envs/eoh/lib/python3.12/site-packages/google/api_core/timeout.py", line 130, in func_with_timeout
    return func(*args, **kwargs)
           ^^^^^^^^^^^^^^^^^^^^^
  File "/Users/macbook/miniconda3/envs/eoh/lib/python3.12/site-packages/google/api_core/grpc_helpers.py", line 78, in error_remapped_callable
    raise exceptions.from_grpc_error(exc) from exc
google.api_core.exceptions.ResourceExhausted: 429 You exceeded your current quota, please check your plan and billing details. For more information on this error, head to: https://ai.google.dev/gemini-api/docs/rate-limits. [violations {
  quota_metric: "generativelanguage.googleapis.com/generate_content_free_tier_requests"
  quota_id: "GenerateRequestsPerMinutePerProjectPerModel-FreeTier"
  quota_dimensions {
    key: "model"
    value: "gemini-1.5-flash"
  }
  quota_dimensions {
    key: "location"
    value: "global"
  }
  quota_value: 15
}
, links {
  description: "Learn more about Gemini API quotas"
  url: "https://ai.google.dev/gemini-api/docs/rate-limits"
}
, retry_delay {
  seconds: 2
}
]
.
2025-06-15 07:27:57 INFO An exception occured: Traceback (most recent call last):
  File "/Users/macbook/Documents/Code/LLMdesignedEA-comp/llamea/llamea_multi_prompts.py", line 367, in evolve_solution
    evolved_individual = self.llm.sample_solution(
                         ^^^^^^^^^^^^^^^^^^^^^^^^^
  File "/Users/macbook/Documents/Code/LLMdesignedEA-comp/llamea/llm.py", line 106, in sample_solution
    message = self.query(session_messages)
              ^^^^^^^^^^^^^^^^^^^^^^^^^^^^
  File "/Users/macbook/Documents/Code/LLMdesignedEA-comp/llamea/llm.py", line 277, in query
    response = chat_session.send_message(last["content"])
               ^^^^^^^^^^^^^^^^^^^^^^^^^^^^^^^^^^^^^^^^^^
  File "/Users/macbook/miniconda3/envs/eoh/lib/python3.12/site-packages/google/generativeai/generative_models.py", line 578, in send_message
    response = self.model.generate_content(
               ^^^^^^^^^^^^^^^^^^^^^^^^^^^^
  File "/Users/macbook/miniconda3/envs/eoh/lib/python3.12/site-packages/google/generativeai/generative_models.py", line 331, in generate_content
    response = self._client.generate_content(
               ^^^^^^^^^^^^^^^^^^^^^^^^^^^^^^
  File "/Users/macbook/miniconda3/envs/eoh/lib/python3.12/site-packages/google/ai/generativelanguage_v1beta/services/generative_service/client.py", line 835, in generate_content
    response = rpc(
               ^^^^
  File "/Users/macbook/miniconda3/envs/eoh/lib/python3.12/site-packages/google/api_core/gapic_v1/method.py", line 131, in __call__
    return wrapped_func(*args, **kwargs)
           ^^^^^^^^^^^^^^^^^^^^^^^^^^^^^
  File "/Users/macbook/miniconda3/envs/eoh/lib/python3.12/site-packages/google/api_core/retry/retry_unary.py", line 294, in retry_wrapped_func
    return retry_target(
           ^^^^^^^^^^^^^
  File "/Users/macbook/miniconda3/envs/eoh/lib/python3.12/site-packages/google/api_core/retry/retry_unary.py", line 156, in retry_target
    next_sleep = _retry_error_helper(
                 ^^^^^^^^^^^^^^^^^^^^
  File "/Users/macbook/miniconda3/envs/eoh/lib/python3.12/site-packages/google/api_core/retry/retry_base.py", line 214, in _retry_error_helper
    raise final_exc from source_exc
  File "/Users/macbook/miniconda3/envs/eoh/lib/python3.12/site-packages/google/api_core/retry/retry_unary.py", line 147, in retry_target
    result = target()
             ^^^^^^^^
  File "/Users/macbook/miniconda3/envs/eoh/lib/python3.12/site-packages/google/api_core/timeout.py", line 130, in func_with_timeout
    return func(*args, **kwargs)
           ^^^^^^^^^^^^^^^^^^^^^
  File "/Users/macbook/miniconda3/envs/eoh/lib/python3.12/site-packages/google/api_core/grpc_helpers.py", line 78, in error_remapped_callable
    raise exceptions.from_grpc_error(exc) from exc
google.api_core.exceptions.ResourceExhausted: 429 You exceeded your current quota, please check your plan and billing details. For more information on this error, head to: https://ai.google.dev/gemini-api/docs/rate-limits. [violations {
  quota_metric: "generativelanguage.googleapis.com/generate_content_free_tier_requests"
  quota_id: "GenerateRequestsPerMinutePerProjectPerModel-FreeTier"
  quota_dimensions {
    key: "model"
    value: "gemini-1.5-flash"
  }
  quota_dimensions {
    key: "location"
    value: "global"
  }
  quota_value: 15
}
, links {
  description: "Learn more about Gemini API quotas"
  url: "https://ai.google.dev/gemini-api/docs/rate-limits"
}
, retry_delay {
  seconds: 2
}
]
.
2025-06-15 07:27:57 INFO An exception occured: Traceback (most recent call last):
  File "/Users/macbook/Documents/Code/LLMdesignedEA-comp/llamea/llamea_multi_prompts.py", line 367, in evolve_solution
    evolved_individual = self.llm.sample_solution(
                         ^^^^^^^^^^^^^^^^^^^^^^^^^
  File "/Users/macbook/Documents/Code/LLMdesignedEA-comp/llamea/llm.py", line 106, in sample_solution
    message = self.query(session_messages)
              ^^^^^^^^^^^^^^^^^^^^^^^^^^^^
  File "/Users/macbook/Documents/Code/LLMdesignedEA-comp/llamea/llm.py", line 277, in query
    response = chat_session.send_message(last["content"])
               ^^^^^^^^^^^^^^^^^^^^^^^^^^^^^^^^^^^^^^^^^^
  File "/Users/macbook/miniconda3/envs/eoh/lib/python3.12/site-packages/google/generativeai/generative_models.py", line 578, in send_message
    response = self.model.generate_content(
               ^^^^^^^^^^^^^^^^^^^^^^^^^^^^
  File "/Users/macbook/miniconda3/envs/eoh/lib/python3.12/site-packages/google/generativeai/generative_models.py", line 331, in generate_content
    response = self._client.generate_content(
               ^^^^^^^^^^^^^^^^^^^^^^^^^^^^^^
  File "/Users/macbook/miniconda3/envs/eoh/lib/python3.12/site-packages/google/ai/generativelanguage_v1beta/services/generative_service/client.py", line 835, in generate_content
    response = rpc(
               ^^^^
  File "/Users/macbook/miniconda3/envs/eoh/lib/python3.12/site-packages/google/api_core/gapic_v1/method.py", line 131, in __call__
    return wrapped_func(*args, **kwargs)
           ^^^^^^^^^^^^^^^^^^^^^^^^^^^^^
  File "/Users/macbook/miniconda3/envs/eoh/lib/python3.12/site-packages/google/api_core/retry/retry_unary.py", line 294, in retry_wrapped_func
    return retry_target(
           ^^^^^^^^^^^^^
  File "/Users/macbook/miniconda3/envs/eoh/lib/python3.12/site-packages/google/api_core/retry/retry_unary.py", line 156, in retry_target
    next_sleep = _retry_error_helper(
                 ^^^^^^^^^^^^^^^^^^^^
  File "/Users/macbook/miniconda3/envs/eoh/lib/python3.12/site-packages/google/api_core/retry/retry_base.py", line 214, in _retry_error_helper
    raise final_exc from source_exc
  File "/Users/macbook/miniconda3/envs/eoh/lib/python3.12/site-packages/google/api_core/retry/retry_unary.py", line 147, in retry_target
    result = target()
             ^^^^^^^^
  File "/Users/macbook/miniconda3/envs/eoh/lib/python3.12/site-packages/google/api_core/timeout.py", line 130, in func_with_timeout
    return func(*args, **kwargs)
           ^^^^^^^^^^^^^^^^^^^^^
  File "/Users/macbook/miniconda3/envs/eoh/lib/python3.12/site-packages/google/api_core/grpc_helpers.py", line 78, in error_remapped_callable
    raise exceptions.from_grpc_error(exc) from exc
google.api_core.exceptions.ResourceExhausted: 429 You exceeded your current quota, please check your plan and billing details. For more information on this error, head to: https://ai.google.dev/gemini-api/docs/rate-limits. [violations {
  quota_metric: "generativelanguage.googleapis.com/generate_content_free_tier_requests"
  quota_id: "GenerateRequestsPerMinutePerProjectPerModel-FreeTier"
  quota_dimensions {
    key: "model"
    value: "gemini-1.5-flash"
  }
  quota_dimensions {
    key: "location"
    value: "global"
  }
  quota_value: 15
}
, links {
  description: "Learn more about Gemini API quotas"
  url: "https://ai.google.dev/gemini-api/docs/rate-limits"
}
, retry_delay {
  seconds: 2
}
]
.
2025-06-15 07:27:58 INFO An exception occured: Traceback (most recent call last):
  File "/Users/macbook/Documents/Code/LLMdesignedEA-comp/llamea/llamea_multi_prompts.py", line 367, in evolve_solution
    evolved_individual = self.llm.sample_solution(
                         ^^^^^^^^^^^^^^^^^^^^^^^^^
  File "/Users/macbook/Documents/Code/LLMdesignedEA-comp/llamea/llm.py", line 106, in sample_solution
    message = self.query(session_messages)
              ^^^^^^^^^^^^^^^^^^^^^^^^^^^^
  File "/Users/macbook/Documents/Code/LLMdesignedEA-comp/llamea/llm.py", line 277, in query
    response = chat_session.send_message(last["content"])
               ^^^^^^^^^^^^^^^^^^^^^^^^^^^^^^^^^^^^^^^^^^
  File "/Users/macbook/miniconda3/envs/eoh/lib/python3.12/site-packages/google/generativeai/generative_models.py", line 578, in send_message
    response = self.model.generate_content(
               ^^^^^^^^^^^^^^^^^^^^^^^^^^^^
  File "/Users/macbook/miniconda3/envs/eoh/lib/python3.12/site-packages/google/generativeai/generative_models.py", line 331, in generate_content
    response = self._client.generate_content(
               ^^^^^^^^^^^^^^^^^^^^^^^^^^^^^^
  File "/Users/macbook/miniconda3/envs/eoh/lib/python3.12/site-packages/google/ai/generativelanguage_v1beta/services/generative_service/client.py", line 835, in generate_content
    response = rpc(
               ^^^^
  File "/Users/macbook/miniconda3/envs/eoh/lib/python3.12/site-packages/google/api_core/gapic_v1/method.py", line 131, in __call__
    return wrapped_func(*args, **kwargs)
           ^^^^^^^^^^^^^^^^^^^^^^^^^^^^^
  File "/Users/macbook/miniconda3/envs/eoh/lib/python3.12/site-packages/google/api_core/retry/retry_unary.py", line 294, in retry_wrapped_func
    return retry_target(
           ^^^^^^^^^^^^^
  File "/Users/macbook/miniconda3/envs/eoh/lib/python3.12/site-packages/google/api_core/retry/retry_unary.py", line 156, in retry_target
    next_sleep = _retry_error_helper(
                 ^^^^^^^^^^^^^^^^^^^^
  File "/Users/macbook/miniconda3/envs/eoh/lib/python3.12/site-packages/google/api_core/retry/retry_base.py", line 214, in _retry_error_helper
    raise final_exc from source_exc
  File "/Users/macbook/miniconda3/envs/eoh/lib/python3.12/site-packages/google/api_core/retry/retry_unary.py", line 147, in retry_target
    result = target()
             ^^^^^^^^
  File "/Users/macbook/miniconda3/envs/eoh/lib/python3.12/site-packages/google/api_core/timeout.py", line 130, in func_with_timeout
    return func(*args, **kwargs)
           ^^^^^^^^^^^^^^^^^^^^^
  File "/Users/macbook/miniconda3/envs/eoh/lib/python3.12/site-packages/google/api_core/grpc_helpers.py", line 78, in error_remapped_callable
    raise exceptions.from_grpc_error(exc) from exc
google.api_core.exceptions.ResourceExhausted: 429 You exceeded your current quota, please check your plan and billing details. For more information on this error, head to: https://ai.google.dev/gemini-api/docs/rate-limits. [violations {
  quota_metric: "generativelanguage.googleapis.com/generate_content_free_tier_requests"
  quota_id: "GenerateRequestsPerMinutePerProjectPerModel-FreeTier"
  quota_dimensions {
    key: "model"
    value: "gemini-1.5-flash"
  }
  quota_dimensions {
    key: "location"
    value: "global"
  }
  quota_value: 15
}
, links {
  description: "Learn more about Gemini API quotas"
  url: "https://ai.google.dev/gemini-api/docs/rate-limits"
}
, retry_delay {
  seconds: 1
}
]
.
2025-06-15 07:27:58 INFO An exception occured: Traceback (most recent call last):
  File "/Users/macbook/Documents/Code/LLMdesignedEA-comp/llamea/llamea_multi_prompts.py", line 367, in evolve_solution
    evolved_individual = self.llm.sample_solution(
                         ^^^^^^^^^^^^^^^^^^^^^^^^^
  File "/Users/macbook/Documents/Code/LLMdesignedEA-comp/llamea/llm.py", line 106, in sample_solution
    message = self.query(session_messages)
              ^^^^^^^^^^^^^^^^^^^^^^^^^^^^
  File "/Users/macbook/Documents/Code/LLMdesignedEA-comp/llamea/llm.py", line 277, in query
    response = chat_session.send_message(last["content"])
               ^^^^^^^^^^^^^^^^^^^^^^^^^^^^^^^^^^^^^^^^^^
  File "/Users/macbook/miniconda3/envs/eoh/lib/python3.12/site-packages/google/generativeai/generative_models.py", line 578, in send_message
    response = self.model.generate_content(
               ^^^^^^^^^^^^^^^^^^^^^^^^^^^^
  File "/Users/macbook/miniconda3/envs/eoh/lib/python3.12/site-packages/google/generativeai/generative_models.py", line 331, in generate_content
    response = self._client.generate_content(
               ^^^^^^^^^^^^^^^^^^^^^^^^^^^^^^
  File "/Users/macbook/miniconda3/envs/eoh/lib/python3.12/site-packages/google/ai/generativelanguage_v1beta/services/generative_service/client.py", line 835, in generate_content
    response = rpc(
               ^^^^
  File "/Users/macbook/miniconda3/envs/eoh/lib/python3.12/site-packages/google/api_core/gapic_v1/method.py", line 131, in __call__
    return wrapped_func(*args, **kwargs)
           ^^^^^^^^^^^^^^^^^^^^^^^^^^^^^
  File "/Users/macbook/miniconda3/envs/eoh/lib/python3.12/site-packages/google/api_core/retry/retry_unary.py", line 294, in retry_wrapped_func
    return retry_target(
           ^^^^^^^^^^^^^
  File "/Users/macbook/miniconda3/envs/eoh/lib/python3.12/site-packages/google/api_core/retry/retry_unary.py", line 156, in retry_target
    next_sleep = _retry_error_helper(
                 ^^^^^^^^^^^^^^^^^^^^
  File "/Users/macbook/miniconda3/envs/eoh/lib/python3.12/site-packages/google/api_core/retry/retry_base.py", line 214, in _retry_error_helper
    raise final_exc from source_exc
  File "/Users/macbook/miniconda3/envs/eoh/lib/python3.12/site-packages/google/api_core/retry/retry_unary.py", line 147, in retry_target
    result = target()
             ^^^^^^^^
  File "/Users/macbook/miniconda3/envs/eoh/lib/python3.12/site-packages/google/api_core/timeout.py", line 130, in func_with_timeout
    return func(*args, **kwargs)
           ^^^^^^^^^^^^^^^^^^^^^
  File "/Users/macbook/miniconda3/envs/eoh/lib/python3.12/site-packages/google/api_core/grpc_helpers.py", line 78, in error_remapped_callable
    raise exceptions.from_grpc_error(exc) from exc
google.api_core.exceptions.ResourceExhausted: 429 You exceeded your current quota, please check your plan and billing details. For more information on this error, head to: https://ai.google.dev/gemini-api/docs/rate-limits. [violations {
  quota_metric: "generativelanguage.googleapis.com/generate_content_free_tier_requests"
  quota_id: "GenerateRequestsPerMinutePerProjectPerModel-FreeTier"
  quota_dimensions {
    key: "model"
    value: "gemini-1.5-flash"
  }
  quota_dimensions {
    key: "location"
    value: "global"
  }
  quota_value: 15
}
, links {
  description: "Learn more about Gemini API quotas"
  url: "https://ai.google.dev/gemini-api/docs/rate-limits"
}
, retry_delay {
  seconds: 1
}
]
.
2025-06-15 07:27:58 INFO An exception occured: Traceback (most recent call last):
  File "/Users/macbook/Documents/Code/LLMdesignedEA-comp/llamea/llamea_multi_prompts.py", line 367, in evolve_solution
    evolved_individual = self.llm.sample_solution(
                         ^^^^^^^^^^^^^^^^^^^^^^^^^
  File "/Users/macbook/Documents/Code/LLMdesignedEA-comp/llamea/llm.py", line 106, in sample_solution
    message = self.query(session_messages)
              ^^^^^^^^^^^^^^^^^^^^^^^^^^^^
  File "/Users/macbook/Documents/Code/LLMdesignedEA-comp/llamea/llm.py", line 277, in query
    response = chat_session.send_message(last["content"])
               ^^^^^^^^^^^^^^^^^^^^^^^^^^^^^^^^^^^^^^^^^^
  File "/Users/macbook/miniconda3/envs/eoh/lib/python3.12/site-packages/google/generativeai/generative_models.py", line 578, in send_message
    response = self.model.generate_content(
               ^^^^^^^^^^^^^^^^^^^^^^^^^^^^
  File "/Users/macbook/miniconda3/envs/eoh/lib/python3.12/site-packages/google/generativeai/generative_models.py", line 331, in generate_content
    response = self._client.generate_content(
               ^^^^^^^^^^^^^^^^^^^^^^^^^^^^^^
  File "/Users/macbook/miniconda3/envs/eoh/lib/python3.12/site-packages/google/ai/generativelanguage_v1beta/services/generative_service/client.py", line 835, in generate_content
    response = rpc(
               ^^^^
  File "/Users/macbook/miniconda3/envs/eoh/lib/python3.12/site-packages/google/api_core/gapic_v1/method.py", line 131, in __call__
    return wrapped_func(*args, **kwargs)
           ^^^^^^^^^^^^^^^^^^^^^^^^^^^^^
  File "/Users/macbook/miniconda3/envs/eoh/lib/python3.12/site-packages/google/api_core/retry/retry_unary.py", line 294, in retry_wrapped_func
    return retry_target(
           ^^^^^^^^^^^^^
  File "/Users/macbook/miniconda3/envs/eoh/lib/python3.12/site-packages/google/api_core/retry/retry_unary.py", line 156, in retry_target
    next_sleep = _retry_error_helper(
                 ^^^^^^^^^^^^^^^^^^^^
  File "/Users/macbook/miniconda3/envs/eoh/lib/python3.12/site-packages/google/api_core/retry/retry_base.py", line 214, in _retry_error_helper
    raise final_exc from source_exc
  File "/Users/macbook/miniconda3/envs/eoh/lib/python3.12/site-packages/google/api_core/retry/retry_unary.py", line 147, in retry_target
    result = target()
             ^^^^^^^^
  File "/Users/macbook/miniconda3/envs/eoh/lib/python3.12/site-packages/google/api_core/timeout.py", line 130, in func_with_timeout
    return func(*args, **kwargs)
           ^^^^^^^^^^^^^^^^^^^^^
  File "/Users/macbook/miniconda3/envs/eoh/lib/python3.12/site-packages/google/api_core/grpc_helpers.py", line 78, in error_remapped_callable
    raise exceptions.from_grpc_error(exc) from exc
google.api_core.exceptions.ResourceExhausted: 429 You exceeded your current quota, please check your plan and billing details. For more information on this error, head to: https://ai.google.dev/gemini-api/docs/rate-limits. [violations {
  quota_metric: "generativelanguage.googleapis.com/generate_content_free_tier_requests"
  quota_id: "GenerateRequestsPerMinutePerProjectPerModel-FreeTier"
  quota_dimensions {
    key: "model"
    value: "gemini-1.5-flash"
  }
  quota_dimensions {
    key: "location"
    value: "global"
  }
  quota_value: 15
}
, links {
  description: "Learn more about Gemini API quotas"
  url: "https://ai.google.dev/gemini-api/docs/rate-limits"
}
, retry_delay {
  seconds: 1
}
]
.
2025-06-15 07:27:58 INFO An exception occured: Traceback (most recent call last):
  File "/Users/macbook/Documents/Code/LLMdesignedEA-comp/llamea/llamea_multi_prompts.py", line 367, in evolve_solution
    evolved_individual = self.llm.sample_solution(
                         ^^^^^^^^^^^^^^^^^^^^^^^^^
  File "/Users/macbook/Documents/Code/LLMdesignedEA-comp/llamea/llm.py", line 106, in sample_solution
    message = self.query(session_messages)
              ^^^^^^^^^^^^^^^^^^^^^^^^^^^^
  File "/Users/macbook/Documents/Code/LLMdesignedEA-comp/llamea/llm.py", line 277, in query
    response = chat_session.send_message(last["content"])
               ^^^^^^^^^^^^^^^^^^^^^^^^^^^^^^^^^^^^^^^^^^
  File "/Users/macbook/miniconda3/envs/eoh/lib/python3.12/site-packages/google/generativeai/generative_models.py", line 578, in send_message
    response = self.model.generate_content(
               ^^^^^^^^^^^^^^^^^^^^^^^^^^^^
  File "/Users/macbook/miniconda3/envs/eoh/lib/python3.12/site-packages/google/generativeai/generative_models.py", line 331, in generate_content
    response = self._client.generate_content(
               ^^^^^^^^^^^^^^^^^^^^^^^^^^^^^^
  File "/Users/macbook/miniconda3/envs/eoh/lib/python3.12/site-packages/google/ai/generativelanguage_v1beta/services/generative_service/client.py", line 835, in generate_content
    response = rpc(
               ^^^^
  File "/Users/macbook/miniconda3/envs/eoh/lib/python3.12/site-packages/google/api_core/gapic_v1/method.py", line 131, in __call__
    return wrapped_func(*args, **kwargs)
           ^^^^^^^^^^^^^^^^^^^^^^^^^^^^^
  File "/Users/macbook/miniconda3/envs/eoh/lib/python3.12/site-packages/google/api_core/retry/retry_unary.py", line 294, in retry_wrapped_func
    return retry_target(
           ^^^^^^^^^^^^^
  File "/Users/macbook/miniconda3/envs/eoh/lib/python3.12/site-packages/google/api_core/retry/retry_unary.py", line 156, in retry_target
    next_sleep = _retry_error_helper(
                 ^^^^^^^^^^^^^^^^^^^^
  File "/Users/macbook/miniconda3/envs/eoh/lib/python3.12/site-packages/google/api_core/retry/retry_base.py", line 214, in _retry_error_helper
    raise final_exc from source_exc
  File "/Users/macbook/miniconda3/envs/eoh/lib/python3.12/site-packages/google/api_core/retry/retry_unary.py", line 147, in retry_target
    result = target()
             ^^^^^^^^
  File "/Users/macbook/miniconda3/envs/eoh/lib/python3.12/site-packages/google/api_core/timeout.py", line 130, in func_with_timeout
    return func(*args, **kwargs)
           ^^^^^^^^^^^^^^^^^^^^^
  File "/Users/macbook/miniconda3/envs/eoh/lib/python3.12/site-packages/google/api_core/grpc_helpers.py", line 78, in error_remapped_callable
    raise exceptions.from_grpc_error(exc) from exc
google.api_core.exceptions.ResourceExhausted: 429 You exceeded your current quota, please check your plan and billing details. For more information on this error, head to: https://ai.google.dev/gemini-api/docs/rate-limits. [violations {
  quota_metric: "generativelanguage.googleapis.com/generate_content_free_tier_requests"
  quota_id: "GenerateRequestsPerMinutePerProjectPerModel-FreeTier"
  quota_dimensions {
    key: "model"
    value: "gemini-1.5-flash"
  }
  quota_dimensions {
    key: "location"
    value: "global"
  }
  quota_value: 15
}
, links {
  description: "Learn more about Gemini API quotas"
  url: "https://ai.google.dev/gemini-api/docs/rate-limits"
}
, retry_delay {
  seconds: 1
}
]
.
2025-06-15 07:27:58 INFO An exception occured: Traceback (most recent call last):
  File "/Users/macbook/Documents/Code/LLMdesignedEA-comp/llamea/llamea_multi_prompts.py", line 367, in evolve_solution
    evolved_individual = self.llm.sample_solution(
                         ^^^^^^^^^^^^^^^^^^^^^^^^^
  File "/Users/macbook/Documents/Code/LLMdesignedEA-comp/llamea/llm.py", line 106, in sample_solution
    message = self.query(session_messages)
              ^^^^^^^^^^^^^^^^^^^^^^^^^^^^
  File "/Users/macbook/Documents/Code/LLMdesignedEA-comp/llamea/llm.py", line 277, in query
    response = chat_session.send_message(last["content"])
               ^^^^^^^^^^^^^^^^^^^^^^^^^^^^^^^^^^^^^^^^^^
  File "/Users/macbook/miniconda3/envs/eoh/lib/python3.12/site-packages/google/generativeai/generative_models.py", line 578, in send_message
    response = self.model.generate_content(
               ^^^^^^^^^^^^^^^^^^^^^^^^^^^^
  File "/Users/macbook/miniconda3/envs/eoh/lib/python3.12/site-packages/google/generativeai/generative_models.py", line 331, in generate_content
    response = self._client.generate_content(
               ^^^^^^^^^^^^^^^^^^^^^^^^^^^^^^
  File "/Users/macbook/miniconda3/envs/eoh/lib/python3.12/site-packages/google/ai/generativelanguage_v1beta/services/generative_service/client.py", line 835, in generate_content
    response = rpc(
               ^^^^
  File "/Users/macbook/miniconda3/envs/eoh/lib/python3.12/site-packages/google/api_core/gapic_v1/method.py", line 131, in __call__
    return wrapped_func(*args, **kwargs)
           ^^^^^^^^^^^^^^^^^^^^^^^^^^^^^
  File "/Users/macbook/miniconda3/envs/eoh/lib/python3.12/site-packages/google/api_core/retry/retry_unary.py", line 294, in retry_wrapped_func
    return retry_target(
           ^^^^^^^^^^^^^
  File "/Users/macbook/miniconda3/envs/eoh/lib/python3.12/site-packages/google/api_core/retry/retry_unary.py", line 156, in retry_target
    next_sleep = _retry_error_helper(
                 ^^^^^^^^^^^^^^^^^^^^
  File "/Users/macbook/miniconda3/envs/eoh/lib/python3.12/site-packages/google/api_core/retry/retry_base.py", line 214, in _retry_error_helper
    raise final_exc from source_exc
  File "/Users/macbook/miniconda3/envs/eoh/lib/python3.12/site-packages/google/api_core/retry/retry_unary.py", line 147, in retry_target
    result = target()
             ^^^^^^^^
  File "/Users/macbook/miniconda3/envs/eoh/lib/python3.12/site-packages/google/api_core/timeout.py", line 130, in func_with_timeout
    return func(*args, **kwargs)
           ^^^^^^^^^^^^^^^^^^^^^
  File "/Users/macbook/miniconda3/envs/eoh/lib/python3.12/site-packages/google/api_core/grpc_helpers.py", line 78, in error_remapped_callable
    raise exceptions.from_grpc_error(exc) from exc
google.api_core.exceptions.ResourceExhausted: 429 You exceeded your current quota, please check your plan and billing details. For more information on this error, head to: https://ai.google.dev/gemini-api/docs/rate-limits. [violations {
  quota_metric: "generativelanguage.googleapis.com/generate_content_free_tier_requests"
  quota_id: "GenerateRequestsPerMinutePerProjectPerModel-FreeTier"
  quota_dimensions {
    key: "model"
    value: "gemini-1.5-flash"
  }
  quota_dimensions {
    key: "location"
    value: "global"
  }
  quota_value: 15
}
, links {
  description: "Learn more about Gemini API quotas"
  url: "https://ai.google.dev/gemini-api/docs/rate-limits"
}
, retry_delay {
  seconds: 1
}
]
.
2025-06-15 07:27:58 INFO An exception occured: Traceback (most recent call last):
  File "/Users/macbook/Documents/Code/LLMdesignedEA-comp/llamea/llamea_multi_prompts.py", line 367, in evolve_solution
    evolved_individual = self.llm.sample_solution(
                         ^^^^^^^^^^^^^^^^^^^^^^^^^
  File "/Users/macbook/Documents/Code/LLMdesignedEA-comp/llamea/llm.py", line 106, in sample_solution
    message = self.query(session_messages)
              ^^^^^^^^^^^^^^^^^^^^^^^^^^^^
  File "/Users/macbook/Documents/Code/LLMdesignedEA-comp/llamea/llm.py", line 277, in query
    response = chat_session.send_message(last["content"])
               ^^^^^^^^^^^^^^^^^^^^^^^^^^^^^^^^^^^^^^^^^^
  File "/Users/macbook/miniconda3/envs/eoh/lib/python3.12/site-packages/google/generativeai/generative_models.py", line 578, in send_message
    response = self.model.generate_content(
               ^^^^^^^^^^^^^^^^^^^^^^^^^^^^
  File "/Users/macbook/miniconda3/envs/eoh/lib/python3.12/site-packages/google/generativeai/generative_models.py", line 331, in generate_content
    response = self._client.generate_content(
               ^^^^^^^^^^^^^^^^^^^^^^^^^^^^^^
  File "/Users/macbook/miniconda3/envs/eoh/lib/python3.12/site-packages/google/ai/generativelanguage_v1beta/services/generative_service/client.py", line 835, in generate_content
    response = rpc(
               ^^^^
  File "/Users/macbook/miniconda3/envs/eoh/lib/python3.12/site-packages/google/api_core/gapic_v1/method.py", line 131, in __call__
    return wrapped_func(*args, **kwargs)
           ^^^^^^^^^^^^^^^^^^^^^^^^^^^^^
  File "/Users/macbook/miniconda3/envs/eoh/lib/python3.12/site-packages/google/api_core/retry/retry_unary.py", line 294, in retry_wrapped_func
    return retry_target(
           ^^^^^^^^^^^^^
  File "/Users/macbook/miniconda3/envs/eoh/lib/python3.12/site-packages/google/api_core/retry/retry_unary.py", line 156, in retry_target
    next_sleep = _retry_error_helper(
                 ^^^^^^^^^^^^^^^^^^^^
  File "/Users/macbook/miniconda3/envs/eoh/lib/python3.12/site-packages/google/api_core/retry/retry_base.py", line 214, in _retry_error_helper
    raise final_exc from source_exc
  File "/Users/macbook/miniconda3/envs/eoh/lib/python3.12/site-packages/google/api_core/retry/retry_unary.py", line 147, in retry_target
    result = target()
             ^^^^^^^^
  File "/Users/macbook/miniconda3/envs/eoh/lib/python3.12/site-packages/google/api_core/timeout.py", line 130, in func_with_timeout
    return func(*args, **kwargs)
           ^^^^^^^^^^^^^^^^^^^^^
  File "/Users/macbook/miniconda3/envs/eoh/lib/python3.12/site-packages/google/api_core/grpc_helpers.py", line 78, in error_remapped_callable
    raise exceptions.from_grpc_error(exc) from exc
google.api_core.exceptions.ResourceExhausted: 429 You exceeded your current quota, please check your plan and billing details. For more information on this error, head to: https://ai.google.dev/gemini-api/docs/rate-limits. [violations {
  quota_metric: "generativelanguage.googleapis.com/generate_content_free_tier_requests"
  quota_id: "GenerateRequestsPerMinutePerProjectPerModel-FreeTier"
  quota_dimensions {
    key: "model"
    value: "gemini-1.5-flash"
  }
  quota_dimensions {
    key: "location"
    value: "global"
  }
  quota_value: 15
}
, links {
  description: "Learn more about Gemini API quotas"
  url: "https://ai.google.dev/gemini-api/docs/rate-limits"
}
, retry_delay {
  seconds: 1
}
]
.
2025-06-15 07:27:58 INFO An exception occured: Traceback (most recent call last):
  File "/Users/macbook/Documents/Code/LLMdesignedEA-comp/llamea/llamea_multi_prompts.py", line 367, in evolve_solution
    evolved_individual = self.llm.sample_solution(
                         ^^^^^^^^^^^^^^^^^^^^^^^^^
  File "/Users/macbook/Documents/Code/LLMdesignedEA-comp/llamea/llm.py", line 106, in sample_solution
    message = self.query(session_messages)
              ^^^^^^^^^^^^^^^^^^^^^^^^^^^^
  File "/Users/macbook/Documents/Code/LLMdesignedEA-comp/llamea/llm.py", line 277, in query
    response = chat_session.send_message(last["content"])
               ^^^^^^^^^^^^^^^^^^^^^^^^^^^^^^^^^^^^^^^^^^
  File "/Users/macbook/miniconda3/envs/eoh/lib/python3.12/site-packages/google/generativeai/generative_models.py", line 578, in send_message
    response = self.model.generate_content(
               ^^^^^^^^^^^^^^^^^^^^^^^^^^^^
  File "/Users/macbook/miniconda3/envs/eoh/lib/python3.12/site-packages/google/generativeai/generative_models.py", line 331, in generate_content
    response = self._client.generate_content(
               ^^^^^^^^^^^^^^^^^^^^^^^^^^^^^^
  File "/Users/macbook/miniconda3/envs/eoh/lib/python3.12/site-packages/google/ai/generativelanguage_v1beta/services/generative_service/client.py", line 835, in generate_content
    response = rpc(
               ^^^^
  File "/Users/macbook/miniconda3/envs/eoh/lib/python3.12/site-packages/google/api_core/gapic_v1/method.py", line 131, in __call__
    return wrapped_func(*args, **kwargs)
           ^^^^^^^^^^^^^^^^^^^^^^^^^^^^^
  File "/Users/macbook/miniconda3/envs/eoh/lib/python3.12/site-packages/google/api_core/retry/retry_unary.py", line 294, in retry_wrapped_func
    return retry_target(
           ^^^^^^^^^^^^^
  File "/Users/macbook/miniconda3/envs/eoh/lib/python3.12/site-packages/google/api_core/retry/retry_unary.py", line 156, in retry_target
    next_sleep = _retry_error_helper(
                 ^^^^^^^^^^^^^^^^^^^^
  File "/Users/macbook/miniconda3/envs/eoh/lib/python3.12/site-packages/google/api_core/retry/retry_base.py", line 214, in _retry_error_helper
    raise final_exc from source_exc
  File "/Users/macbook/miniconda3/envs/eoh/lib/python3.12/site-packages/google/api_core/retry/retry_unary.py", line 147, in retry_target
    result = target()
             ^^^^^^^^
  File "/Users/macbook/miniconda3/envs/eoh/lib/python3.12/site-packages/google/api_core/timeout.py", line 130, in func_with_timeout
    return func(*args, **kwargs)
           ^^^^^^^^^^^^^^^^^^^^^
  File "/Users/macbook/miniconda3/envs/eoh/lib/python3.12/site-packages/google/api_core/grpc_helpers.py", line 78, in error_remapped_callable
    raise exceptions.from_grpc_error(exc) from exc
google.api_core.exceptions.ResourceExhausted: 429 You exceeded your current quota, please check your plan and billing details. For more information on this error, head to: https://ai.google.dev/gemini-api/docs/rate-limits. [violations {
  quota_metric: "generativelanguage.googleapis.com/generate_content_free_tier_requests"
  quota_id: "GenerateRequestsPerMinutePerProjectPerModel-FreeTier"
  quota_dimensions {
    key: "model"
    value: "gemini-1.5-flash"
  }
  quota_dimensions {
    key: "location"
    value: "global"
  }
  quota_value: 15
}
, links {
  description: "Learn more about Gemini API quotas"
  url: "https://ai.google.dev/gemini-api/docs/rate-limits"
}
, retry_delay {
  seconds: 1
}
]
.
2025-06-15 07:27:58 INFO An exception occured: Traceback (most recent call last):
  File "/Users/macbook/Documents/Code/LLMdesignedEA-comp/llamea/llamea_multi_prompts.py", line 367, in evolve_solution
    evolved_individual = self.llm.sample_solution(
                         ^^^^^^^^^^^^^^^^^^^^^^^^^
  File "/Users/macbook/Documents/Code/LLMdesignedEA-comp/llamea/llm.py", line 106, in sample_solution
    message = self.query(session_messages)
              ^^^^^^^^^^^^^^^^^^^^^^^^^^^^
  File "/Users/macbook/Documents/Code/LLMdesignedEA-comp/llamea/llm.py", line 277, in query
    response = chat_session.send_message(last["content"])
               ^^^^^^^^^^^^^^^^^^^^^^^^^^^^^^^^^^^^^^^^^^
  File "/Users/macbook/miniconda3/envs/eoh/lib/python3.12/site-packages/google/generativeai/generative_models.py", line 578, in send_message
    response = self.model.generate_content(
               ^^^^^^^^^^^^^^^^^^^^^^^^^^^^
  File "/Users/macbook/miniconda3/envs/eoh/lib/python3.12/site-packages/google/generativeai/generative_models.py", line 331, in generate_content
    response = self._client.generate_content(
               ^^^^^^^^^^^^^^^^^^^^^^^^^^^^^^
  File "/Users/macbook/miniconda3/envs/eoh/lib/python3.12/site-packages/google/ai/generativelanguage_v1beta/services/generative_service/client.py", line 835, in generate_content
    response = rpc(
               ^^^^
  File "/Users/macbook/miniconda3/envs/eoh/lib/python3.12/site-packages/google/api_core/gapic_v1/method.py", line 131, in __call__
    return wrapped_func(*args, **kwargs)
           ^^^^^^^^^^^^^^^^^^^^^^^^^^^^^
  File "/Users/macbook/miniconda3/envs/eoh/lib/python3.12/site-packages/google/api_core/retry/retry_unary.py", line 294, in retry_wrapped_func
    return retry_target(
           ^^^^^^^^^^^^^
  File "/Users/macbook/miniconda3/envs/eoh/lib/python3.12/site-packages/google/api_core/retry/retry_unary.py", line 156, in retry_target
    next_sleep = _retry_error_helper(
                 ^^^^^^^^^^^^^^^^^^^^
  File "/Users/macbook/miniconda3/envs/eoh/lib/python3.12/site-packages/google/api_core/retry/retry_base.py", line 214, in _retry_error_helper
    raise final_exc from source_exc
  File "/Users/macbook/miniconda3/envs/eoh/lib/python3.12/site-packages/google/api_core/retry/retry_unary.py", line 147, in retry_target
    result = target()
             ^^^^^^^^
  File "/Users/macbook/miniconda3/envs/eoh/lib/python3.12/site-packages/google/api_core/timeout.py", line 130, in func_with_timeout
    return func(*args, **kwargs)
           ^^^^^^^^^^^^^^^^^^^^^
  File "/Users/macbook/miniconda3/envs/eoh/lib/python3.12/site-packages/google/api_core/grpc_helpers.py", line 78, in error_remapped_callable
    raise exceptions.from_grpc_error(exc) from exc
google.api_core.exceptions.ResourceExhausted: 429 You exceeded your current quota, please check your plan and billing details. For more information on this error, head to: https://ai.google.dev/gemini-api/docs/rate-limits. [violations {
  quota_metric: "generativelanguage.googleapis.com/generate_content_free_tier_requests"
  quota_id: "GenerateRequestsPerMinutePerProjectPerModel-FreeTier"
  quota_dimensions {
    key: "model"
    value: "gemini-1.5-flash"
  }
  quota_dimensions {
    key: "location"
    value: "global"
  }
  quota_value: 15
}
, links {
  description: "Learn more about Gemini API quotas"
  url: "https://ai.google.dev/gemini-api/docs/rate-limits"
}
, retry_delay {
  seconds: 1
}
]
.
2025-06-15 07:27:58 INFO An exception occured: Traceback (most recent call last):
  File "/Users/macbook/Documents/Code/LLMdesignedEA-comp/llamea/llamea_multi_prompts.py", line 367, in evolve_solution
    evolved_individual = self.llm.sample_solution(
                         ^^^^^^^^^^^^^^^^^^^^^^^^^
  File "/Users/macbook/Documents/Code/LLMdesignedEA-comp/llamea/llm.py", line 106, in sample_solution
    message = self.query(session_messages)
              ^^^^^^^^^^^^^^^^^^^^^^^^^^^^
  File "/Users/macbook/Documents/Code/LLMdesignedEA-comp/llamea/llm.py", line 277, in query
    response = chat_session.send_message(last["content"])
               ^^^^^^^^^^^^^^^^^^^^^^^^^^^^^^^^^^^^^^^^^^
  File "/Users/macbook/miniconda3/envs/eoh/lib/python3.12/site-packages/google/generativeai/generative_models.py", line 578, in send_message
    response = self.model.generate_content(
               ^^^^^^^^^^^^^^^^^^^^^^^^^^^^
  File "/Users/macbook/miniconda3/envs/eoh/lib/python3.12/site-packages/google/generativeai/generative_models.py", line 331, in generate_content
    response = self._client.generate_content(
               ^^^^^^^^^^^^^^^^^^^^^^^^^^^^^^
  File "/Users/macbook/miniconda3/envs/eoh/lib/python3.12/site-packages/google/ai/generativelanguage_v1beta/services/generative_service/client.py", line 835, in generate_content
    response = rpc(
               ^^^^
  File "/Users/macbook/miniconda3/envs/eoh/lib/python3.12/site-packages/google/api_core/gapic_v1/method.py", line 131, in __call__
    return wrapped_func(*args, **kwargs)
           ^^^^^^^^^^^^^^^^^^^^^^^^^^^^^
  File "/Users/macbook/miniconda3/envs/eoh/lib/python3.12/site-packages/google/api_core/retry/retry_unary.py", line 294, in retry_wrapped_func
    return retry_target(
           ^^^^^^^^^^^^^
  File "/Users/macbook/miniconda3/envs/eoh/lib/python3.12/site-packages/google/api_core/retry/retry_unary.py", line 156, in retry_target
    next_sleep = _retry_error_helper(
                 ^^^^^^^^^^^^^^^^^^^^
  File "/Users/macbook/miniconda3/envs/eoh/lib/python3.12/site-packages/google/api_core/retry/retry_base.py", line 214, in _retry_error_helper
    raise final_exc from source_exc
  File "/Users/macbook/miniconda3/envs/eoh/lib/python3.12/site-packages/google/api_core/retry/retry_unary.py", line 147, in retry_target
    result = target()
             ^^^^^^^^
  File "/Users/macbook/miniconda3/envs/eoh/lib/python3.12/site-packages/google/api_core/timeout.py", line 130, in func_with_timeout
    return func(*args, **kwargs)
           ^^^^^^^^^^^^^^^^^^^^^
  File "/Users/macbook/miniconda3/envs/eoh/lib/python3.12/site-packages/google/api_core/grpc_helpers.py", line 78, in error_remapped_callable
    raise exceptions.from_grpc_error(exc) from exc
google.api_core.exceptions.ResourceExhausted: 429 You exceeded your current quota, please check your plan and billing details. For more information on this error, head to: https://ai.google.dev/gemini-api/docs/rate-limits. [violations {
  quota_metric: "generativelanguage.googleapis.com/generate_content_free_tier_requests"
  quota_id: "GenerateRequestsPerMinutePerProjectPerModel-FreeTier"
  quota_dimensions {
    key: "model"
    value: "gemini-1.5-flash"
  }
  quota_dimensions {
    key: "location"
    value: "global"
  }
  quota_value: 15
}
, links {
  description: "Learn more about Gemini API quotas"
  url: "https://ai.google.dev/gemini-api/docs/rate-limits"
}
, retry_delay {
  seconds: 1
}
]
.
2025-06-15 07:27:58 INFO An exception occured: Traceback (most recent call last):
  File "/Users/macbook/Documents/Code/LLMdesignedEA-comp/llamea/llamea_multi_prompts.py", line 367, in evolve_solution
    evolved_individual = self.llm.sample_solution(
                         ^^^^^^^^^^^^^^^^^^^^^^^^^
  File "/Users/macbook/Documents/Code/LLMdesignedEA-comp/llamea/llm.py", line 106, in sample_solution
    message = self.query(session_messages)
              ^^^^^^^^^^^^^^^^^^^^^^^^^^^^
  File "/Users/macbook/Documents/Code/LLMdesignedEA-comp/llamea/llm.py", line 277, in query
    response = chat_session.send_message(last["content"])
               ^^^^^^^^^^^^^^^^^^^^^^^^^^^^^^^^^^^^^^^^^^
  File "/Users/macbook/miniconda3/envs/eoh/lib/python3.12/site-packages/google/generativeai/generative_models.py", line 578, in send_message
    response = self.model.generate_content(
               ^^^^^^^^^^^^^^^^^^^^^^^^^^^^
  File "/Users/macbook/miniconda3/envs/eoh/lib/python3.12/site-packages/google/generativeai/generative_models.py", line 331, in generate_content
    response = self._client.generate_content(
               ^^^^^^^^^^^^^^^^^^^^^^^^^^^^^^
  File "/Users/macbook/miniconda3/envs/eoh/lib/python3.12/site-packages/google/ai/generativelanguage_v1beta/services/generative_service/client.py", line 835, in generate_content
    response = rpc(
               ^^^^
  File "/Users/macbook/miniconda3/envs/eoh/lib/python3.12/site-packages/google/api_core/gapic_v1/method.py", line 131, in __call__
    return wrapped_func(*args, **kwargs)
           ^^^^^^^^^^^^^^^^^^^^^^^^^^^^^
  File "/Users/macbook/miniconda3/envs/eoh/lib/python3.12/site-packages/google/api_core/retry/retry_unary.py", line 294, in retry_wrapped_func
    return retry_target(
           ^^^^^^^^^^^^^
  File "/Users/macbook/miniconda3/envs/eoh/lib/python3.12/site-packages/google/api_core/retry/retry_unary.py", line 156, in retry_target
    next_sleep = _retry_error_helper(
                 ^^^^^^^^^^^^^^^^^^^^
  File "/Users/macbook/miniconda3/envs/eoh/lib/python3.12/site-packages/google/api_core/retry/retry_base.py", line 214, in _retry_error_helper
    raise final_exc from source_exc
  File "/Users/macbook/miniconda3/envs/eoh/lib/python3.12/site-packages/google/api_core/retry/retry_unary.py", line 147, in retry_target
    result = target()
             ^^^^^^^^
  File "/Users/macbook/miniconda3/envs/eoh/lib/python3.12/site-packages/google/api_core/timeout.py", line 130, in func_with_timeout
    return func(*args, **kwargs)
           ^^^^^^^^^^^^^^^^^^^^^
  File "/Users/macbook/miniconda3/envs/eoh/lib/python3.12/site-packages/google/api_core/grpc_helpers.py", line 78, in error_remapped_callable
    raise exceptions.from_grpc_error(exc) from exc
google.api_core.exceptions.ResourceExhausted: 429 You exceeded your current quota, please check your plan and billing details. For more information on this error, head to: https://ai.google.dev/gemini-api/docs/rate-limits. [violations {
  quota_metric: "generativelanguage.googleapis.com/generate_content_free_tier_requests"
  quota_id: "GenerateRequestsPerMinutePerProjectPerModel-FreeTier"
  quota_dimensions {
    key: "model"
    value: "gemini-1.5-flash"
  }
  quota_dimensions {
    key: "location"
    value: "global"
  }
  quota_value: 15
}
, links {
  description: "Learn more about Gemini API quotas"
  url: "https://ai.google.dev/gemini-api/docs/rate-limits"
}
, retry_delay {
  seconds: 1
}
]
.
2025-06-15 07:27:59 INFO An exception occured: Traceback (most recent call last):
  File "/Users/macbook/Documents/Code/LLMdesignedEA-comp/llamea/llamea_multi_prompts.py", line 367, in evolve_solution
    evolved_individual = self.llm.sample_solution(
                         ^^^^^^^^^^^^^^^^^^^^^^^^^
  File "/Users/macbook/Documents/Code/LLMdesignedEA-comp/llamea/llm.py", line 106, in sample_solution
    message = self.query(session_messages)
              ^^^^^^^^^^^^^^^^^^^^^^^^^^^^
  File "/Users/macbook/Documents/Code/LLMdesignedEA-comp/llamea/llm.py", line 277, in query
    response = chat_session.send_message(last["content"])
               ^^^^^^^^^^^^^^^^^^^^^^^^^^^^^^^^^^^^^^^^^^
  File "/Users/macbook/miniconda3/envs/eoh/lib/python3.12/site-packages/google/generativeai/generative_models.py", line 578, in send_message
    response = self.model.generate_content(
               ^^^^^^^^^^^^^^^^^^^^^^^^^^^^
  File "/Users/macbook/miniconda3/envs/eoh/lib/python3.12/site-packages/google/generativeai/generative_models.py", line 331, in generate_content
    response = self._client.generate_content(
               ^^^^^^^^^^^^^^^^^^^^^^^^^^^^^^
  File "/Users/macbook/miniconda3/envs/eoh/lib/python3.12/site-packages/google/ai/generativelanguage_v1beta/services/generative_service/client.py", line 835, in generate_content
    response = rpc(
               ^^^^
  File "/Users/macbook/miniconda3/envs/eoh/lib/python3.12/site-packages/google/api_core/gapic_v1/method.py", line 131, in __call__
    return wrapped_func(*args, **kwargs)
           ^^^^^^^^^^^^^^^^^^^^^^^^^^^^^
  File "/Users/macbook/miniconda3/envs/eoh/lib/python3.12/site-packages/google/api_core/retry/retry_unary.py", line 294, in retry_wrapped_func
    return retry_target(
           ^^^^^^^^^^^^^
  File "/Users/macbook/miniconda3/envs/eoh/lib/python3.12/site-packages/google/api_core/retry/retry_unary.py", line 156, in retry_target
    next_sleep = _retry_error_helper(
                 ^^^^^^^^^^^^^^^^^^^^
  File "/Users/macbook/miniconda3/envs/eoh/lib/python3.12/site-packages/google/api_core/retry/retry_base.py", line 214, in _retry_error_helper
    raise final_exc from source_exc
  File "/Users/macbook/miniconda3/envs/eoh/lib/python3.12/site-packages/google/api_core/retry/retry_unary.py", line 147, in retry_target
    result = target()
             ^^^^^^^^
  File "/Users/macbook/miniconda3/envs/eoh/lib/python3.12/site-packages/google/api_core/timeout.py", line 130, in func_with_timeout
    return func(*args, **kwargs)
           ^^^^^^^^^^^^^^^^^^^^^
  File "/Users/macbook/miniconda3/envs/eoh/lib/python3.12/site-packages/google/api_core/grpc_helpers.py", line 78, in error_remapped_callable
    raise exceptions.from_grpc_error(exc) from exc
google.api_core.exceptions.ResourceExhausted: 429 You exceeded your current quota, please check your plan and billing details. For more information on this error, head to: https://ai.google.dev/gemini-api/docs/rate-limits. [violations {
  quota_metric: "generativelanguage.googleapis.com/generate_content_free_tier_requests"
  quota_id: "GenerateRequestsPerMinutePerProjectPerModel-FreeTier"
  quota_dimensions {
    key: "model"
    value: "gemini-1.5-flash"
  }
  quota_dimensions {
    key: "location"
    value: "global"
  }
  quota_value: 15
}
, links {
  description: "Learn more about Gemini API quotas"
  url: "https://ai.google.dev/gemini-api/docs/rate-limits"
}
, retry_delay {
}
]
.
2025-06-15 07:27:59 INFO An exception occured: Traceback (most recent call last):
  File "/Users/macbook/Documents/Code/LLMdesignedEA-comp/llamea/llamea_multi_prompts.py", line 367, in evolve_solution
    evolved_individual = self.llm.sample_solution(
                         ^^^^^^^^^^^^^^^^^^^^^^^^^
  File "/Users/macbook/Documents/Code/LLMdesignedEA-comp/llamea/llm.py", line 106, in sample_solution
    message = self.query(session_messages)
              ^^^^^^^^^^^^^^^^^^^^^^^^^^^^
  File "/Users/macbook/Documents/Code/LLMdesignedEA-comp/llamea/llm.py", line 277, in query
    response = chat_session.send_message(last["content"])
               ^^^^^^^^^^^^^^^^^^^^^^^^^^^^^^^^^^^^^^^^^^
  File "/Users/macbook/miniconda3/envs/eoh/lib/python3.12/site-packages/google/generativeai/generative_models.py", line 578, in send_message
    response = self.model.generate_content(
               ^^^^^^^^^^^^^^^^^^^^^^^^^^^^
  File "/Users/macbook/miniconda3/envs/eoh/lib/python3.12/site-packages/google/generativeai/generative_models.py", line 331, in generate_content
    response = self._client.generate_content(
               ^^^^^^^^^^^^^^^^^^^^^^^^^^^^^^
  File "/Users/macbook/miniconda3/envs/eoh/lib/python3.12/site-packages/google/ai/generativelanguage_v1beta/services/generative_service/client.py", line 835, in generate_content
    response = rpc(
               ^^^^
  File "/Users/macbook/miniconda3/envs/eoh/lib/python3.12/site-packages/google/api_core/gapic_v1/method.py", line 131, in __call__
    return wrapped_func(*args, **kwargs)
           ^^^^^^^^^^^^^^^^^^^^^^^^^^^^^
  File "/Users/macbook/miniconda3/envs/eoh/lib/python3.12/site-packages/google/api_core/retry/retry_unary.py", line 294, in retry_wrapped_func
    return retry_target(
           ^^^^^^^^^^^^^
  File "/Users/macbook/miniconda3/envs/eoh/lib/python3.12/site-packages/google/api_core/retry/retry_unary.py", line 156, in retry_target
    next_sleep = _retry_error_helper(
                 ^^^^^^^^^^^^^^^^^^^^
  File "/Users/macbook/miniconda3/envs/eoh/lib/python3.12/site-packages/google/api_core/retry/retry_base.py", line 214, in _retry_error_helper
    raise final_exc from source_exc
  File "/Users/macbook/miniconda3/envs/eoh/lib/python3.12/site-packages/google/api_core/retry/retry_unary.py", line 147, in retry_target
    result = target()
             ^^^^^^^^
  File "/Users/macbook/miniconda3/envs/eoh/lib/python3.12/site-packages/google/api_core/timeout.py", line 130, in func_with_timeout
    return func(*args, **kwargs)
           ^^^^^^^^^^^^^^^^^^^^^
  File "/Users/macbook/miniconda3/envs/eoh/lib/python3.12/site-packages/google/api_core/grpc_helpers.py", line 78, in error_remapped_callable
    raise exceptions.from_grpc_error(exc) from exc
google.api_core.exceptions.ResourceExhausted: 429 You exceeded your current quota, please check your plan and billing details. For more information on this error, head to: https://ai.google.dev/gemini-api/docs/rate-limits. [violations {
  quota_metric: "generativelanguage.googleapis.com/generate_content_free_tier_requests"
  quota_id: "GenerateRequestsPerMinutePerProjectPerModel-FreeTier"
  quota_dimensions {
    key: "model"
    value: "gemini-1.5-flash"
  }
  quota_dimensions {
    key: "location"
    value: "global"
  }
  quota_value: 15
}
, links {
  description: "Learn more about Gemini API quotas"
  url: "https://ai.google.dev/gemini-api/docs/rate-limits"
}
, retry_delay {
}
]
.
2025-06-15 07:27:59 INFO An exception occured: Traceback (most recent call last):
  File "/Users/macbook/Documents/Code/LLMdesignedEA-comp/llamea/llamea_multi_prompts.py", line 367, in evolve_solution
    evolved_individual = self.llm.sample_solution(
                         ^^^^^^^^^^^^^^^^^^^^^^^^^
  File "/Users/macbook/Documents/Code/LLMdesignedEA-comp/llamea/llm.py", line 106, in sample_solution
    message = self.query(session_messages)
              ^^^^^^^^^^^^^^^^^^^^^^^^^^^^
  File "/Users/macbook/Documents/Code/LLMdesignedEA-comp/llamea/llm.py", line 277, in query
    response = chat_session.send_message(last["content"])
               ^^^^^^^^^^^^^^^^^^^^^^^^^^^^^^^^^^^^^^^^^^
  File "/Users/macbook/miniconda3/envs/eoh/lib/python3.12/site-packages/google/generativeai/generative_models.py", line 578, in send_message
    response = self.model.generate_content(
               ^^^^^^^^^^^^^^^^^^^^^^^^^^^^
  File "/Users/macbook/miniconda3/envs/eoh/lib/python3.12/site-packages/google/generativeai/generative_models.py", line 331, in generate_content
    response = self._client.generate_content(
               ^^^^^^^^^^^^^^^^^^^^^^^^^^^^^^
  File "/Users/macbook/miniconda3/envs/eoh/lib/python3.12/site-packages/google/ai/generativelanguage_v1beta/services/generative_service/client.py", line 835, in generate_content
    response = rpc(
               ^^^^
  File "/Users/macbook/miniconda3/envs/eoh/lib/python3.12/site-packages/google/api_core/gapic_v1/method.py", line 131, in __call__
    return wrapped_func(*args, **kwargs)
           ^^^^^^^^^^^^^^^^^^^^^^^^^^^^^
  File "/Users/macbook/miniconda3/envs/eoh/lib/python3.12/site-packages/google/api_core/retry/retry_unary.py", line 294, in retry_wrapped_func
    return retry_target(
           ^^^^^^^^^^^^^
  File "/Users/macbook/miniconda3/envs/eoh/lib/python3.12/site-packages/google/api_core/retry/retry_unary.py", line 156, in retry_target
    next_sleep = _retry_error_helper(
                 ^^^^^^^^^^^^^^^^^^^^
  File "/Users/macbook/miniconda3/envs/eoh/lib/python3.12/site-packages/google/api_core/retry/retry_base.py", line 214, in _retry_error_helper
    raise final_exc from source_exc
  File "/Users/macbook/miniconda3/envs/eoh/lib/python3.12/site-packages/google/api_core/retry/retry_unary.py", line 147, in retry_target
    result = target()
             ^^^^^^^^
  File "/Users/macbook/miniconda3/envs/eoh/lib/python3.12/site-packages/google/api_core/timeout.py", line 130, in func_with_timeout
    return func(*args, **kwargs)
           ^^^^^^^^^^^^^^^^^^^^^
  File "/Users/macbook/miniconda3/envs/eoh/lib/python3.12/site-packages/google/api_core/grpc_helpers.py", line 78, in error_remapped_callable
    raise exceptions.from_grpc_error(exc) from exc
google.api_core.exceptions.ResourceExhausted: 429 You exceeded your current quota, please check your plan and billing details. For more information on this error, head to: https://ai.google.dev/gemini-api/docs/rate-limits. [violations {
  quota_metric: "generativelanguage.googleapis.com/generate_content_free_tier_requests"
  quota_id: "GenerateRequestsPerMinutePerProjectPerModel-FreeTier"
  quota_dimensions {
    key: "model"
    value: "gemini-1.5-flash"
  }
  quota_dimensions {
    key: "location"
    value: "global"
  }
  quota_value: 15
}
, links {
  description: "Learn more about Gemini API quotas"
  url: "https://ai.google.dev/gemini-api/docs/rate-limits"
}
, retry_delay {
}
]
.
2025-06-15 07:27:59 INFO An exception occured: Traceback (most recent call last):
  File "/Users/macbook/Documents/Code/LLMdesignedEA-comp/llamea/llamea_multi_prompts.py", line 367, in evolve_solution
    evolved_individual = self.llm.sample_solution(
                         ^^^^^^^^^^^^^^^^^^^^^^^^^
  File "/Users/macbook/Documents/Code/LLMdesignedEA-comp/llamea/llm.py", line 106, in sample_solution
    message = self.query(session_messages)
              ^^^^^^^^^^^^^^^^^^^^^^^^^^^^
  File "/Users/macbook/Documents/Code/LLMdesignedEA-comp/llamea/llm.py", line 277, in query
    response = chat_session.send_message(last["content"])
               ^^^^^^^^^^^^^^^^^^^^^^^^^^^^^^^^^^^^^^^^^^
  File "/Users/macbook/miniconda3/envs/eoh/lib/python3.12/site-packages/google/generativeai/generative_models.py", line 578, in send_message
    response = self.model.generate_content(
               ^^^^^^^^^^^^^^^^^^^^^^^^^^^^
  File "/Users/macbook/miniconda3/envs/eoh/lib/python3.12/site-packages/google/generativeai/generative_models.py", line 331, in generate_content
    response = self._client.generate_content(
               ^^^^^^^^^^^^^^^^^^^^^^^^^^^^^^
  File "/Users/macbook/miniconda3/envs/eoh/lib/python3.12/site-packages/google/ai/generativelanguage_v1beta/services/generative_service/client.py", line 835, in generate_content
    response = rpc(
               ^^^^
  File "/Users/macbook/miniconda3/envs/eoh/lib/python3.12/site-packages/google/api_core/gapic_v1/method.py", line 131, in __call__
    return wrapped_func(*args, **kwargs)
           ^^^^^^^^^^^^^^^^^^^^^^^^^^^^^
  File "/Users/macbook/miniconda3/envs/eoh/lib/python3.12/site-packages/google/api_core/retry/retry_unary.py", line 294, in retry_wrapped_func
    return retry_target(
           ^^^^^^^^^^^^^
  File "/Users/macbook/miniconda3/envs/eoh/lib/python3.12/site-packages/google/api_core/retry/retry_unary.py", line 156, in retry_target
    next_sleep = _retry_error_helper(
                 ^^^^^^^^^^^^^^^^^^^^
  File "/Users/macbook/miniconda3/envs/eoh/lib/python3.12/site-packages/google/api_core/retry/retry_base.py", line 214, in _retry_error_helper
    raise final_exc from source_exc
  File "/Users/macbook/miniconda3/envs/eoh/lib/python3.12/site-packages/google/api_core/retry/retry_unary.py", line 147, in retry_target
    result = target()
             ^^^^^^^^
  File "/Users/macbook/miniconda3/envs/eoh/lib/python3.12/site-packages/google/api_core/timeout.py", line 130, in func_with_timeout
    return func(*args, **kwargs)
           ^^^^^^^^^^^^^^^^^^^^^
  File "/Users/macbook/miniconda3/envs/eoh/lib/python3.12/site-packages/google/api_core/grpc_helpers.py", line 78, in error_remapped_callable
    raise exceptions.from_grpc_error(exc) from exc
google.api_core.exceptions.ResourceExhausted: 429 You exceeded your current quota, please check your plan and billing details. For more information on this error, head to: https://ai.google.dev/gemini-api/docs/rate-limits. [violations {
  quota_metric: "generativelanguage.googleapis.com/generate_content_free_tier_requests"
  quota_id: "GenerateRequestsPerMinutePerProjectPerModel-FreeTier"
  quota_dimensions {
    key: "model"
    value: "gemini-1.5-flash"
  }
  quota_dimensions {
    key: "location"
    value: "global"
  }
  quota_value: 15
}
, links {
  description: "Learn more about Gemini API quotas"
  url: "https://ai.google.dev/gemini-api/docs/rate-limits"
}
, retry_delay {
}
]
.
2025-06-15 07:27:59 INFO An exception occured: Traceback (most recent call last):
  File "/Users/macbook/Documents/Code/LLMdesignedEA-comp/llamea/llamea_multi_prompts.py", line 367, in evolve_solution
    evolved_individual = self.llm.sample_solution(
                         ^^^^^^^^^^^^^^^^^^^^^^^^^
  File "/Users/macbook/Documents/Code/LLMdesignedEA-comp/llamea/llm.py", line 106, in sample_solution
    message = self.query(session_messages)
              ^^^^^^^^^^^^^^^^^^^^^^^^^^^^
  File "/Users/macbook/Documents/Code/LLMdesignedEA-comp/llamea/llm.py", line 277, in query
    response = chat_session.send_message(last["content"])
               ^^^^^^^^^^^^^^^^^^^^^^^^^^^^^^^^^^^^^^^^^^
  File "/Users/macbook/miniconda3/envs/eoh/lib/python3.12/site-packages/google/generativeai/generative_models.py", line 578, in send_message
    response = self.model.generate_content(
               ^^^^^^^^^^^^^^^^^^^^^^^^^^^^
  File "/Users/macbook/miniconda3/envs/eoh/lib/python3.12/site-packages/google/generativeai/generative_models.py", line 331, in generate_content
    response = self._client.generate_content(
               ^^^^^^^^^^^^^^^^^^^^^^^^^^^^^^
  File "/Users/macbook/miniconda3/envs/eoh/lib/python3.12/site-packages/google/ai/generativelanguage_v1beta/services/generative_service/client.py", line 835, in generate_content
    response = rpc(
               ^^^^
  File "/Users/macbook/miniconda3/envs/eoh/lib/python3.12/site-packages/google/api_core/gapic_v1/method.py", line 131, in __call__
    return wrapped_func(*args, **kwargs)
           ^^^^^^^^^^^^^^^^^^^^^^^^^^^^^
  File "/Users/macbook/miniconda3/envs/eoh/lib/python3.12/site-packages/google/api_core/retry/retry_unary.py", line 294, in retry_wrapped_func
    return retry_target(
           ^^^^^^^^^^^^^
  File "/Users/macbook/miniconda3/envs/eoh/lib/python3.12/site-packages/google/api_core/retry/retry_unary.py", line 156, in retry_target
    next_sleep = _retry_error_helper(
                 ^^^^^^^^^^^^^^^^^^^^
  File "/Users/macbook/miniconda3/envs/eoh/lib/python3.12/site-packages/google/api_core/retry/retry_base.py", line 214, in _retry_error_helper
    raise final_exc from source_exc
  File "/Users/macbook/miniconda3/envs/eoh/lib/python3.12/site-packages/google/api_core/retry/retry_unary.py", line 147, in retry_target
    result = target()
             ^^^^^^^^
  File "/Users/macbook/miniconda3/envs/eoh/lib/python3.12/site-packages/google/api_core/timeout.py", line 130, in func_with_timeout
    return func(*args, **kwargs)
           ^^^^^^^^^^^^^^^^^^^^^
  File "/Users/macbook/miniconda3/envs/eoh/lib/python3.12/site-packages/google/api_core/grpc_helpers.py", line 78, in error_remapped_callable
    raise exceptions.from_grpc_error(exc) from exc
google.api_core.exceptions.ResourceExhausted: 429 You exceeded your current quota, please check your plan and billing details. For more information on this error, head to: https://ai.google.dev/gemini-api/docs/rate-limits. [violations {
  quota_metric: "generativelanguage.googleapis.com/generate_content_free_tier_requests"
  quota_id: "GenerateRequestsPerMinutePerProjectPerModel-FreeTier"
  quota_dimensions {
    key: "model"
    value: "gemini-1.5-flash"
  }
  quota_dimensions {
    key: "location"
    value: "global"
  }
  quota_value: 15
}
, links {
  description: "Learn more about Gemini API quotas"
  url: "https://ai.google.dev/gemini-api/docs/rate-limits"
}
, retry_delay {
}
]
.
2025-06-15 07:27:59 INFO An exception occured: Traceback (most recent call last):
  File "/Users/macbook/Documents/Code/LLMdesignedEA-comp/llamea/llamea_multi_prompts.py", line 367, in evolve_solution
    evolved_individual = self.llm.sample_solution(
                         ^^^^^^^^^^^^^^^^^^^^^^^^^
  File "/Users/macbook/Documents/Code/LLMdesignedEA-comp/llamea/llm.py", line 106, in sample_solution
    message = self.query(session_messages)
              ^^^^^^^^^^^^^^^^^^^^^^^^^^^^
  File "/Users/macbook/Documents/Code/LLMdesignedEA-comp/llamea/llm.py", line 277, in query
    response = chat_session.send_message(last["content"])
               ^^^^^^^^^^^^^^^^^^^^^^^^^^^^^^^^^^^^^^^^^^
  File "/Users/macbook/miniconda3/envs/eoh/lib/python3.12/site-packages/google/generativeai/generative_models.py", line 578, in send_message
    response = self.model.generate_content(
               ^^^^^^^^^^^^^^^^^^^^^^^^^^^^
  File "/Users/macbook/miniconda3/envs/eoh/lib/python3.12/site-packages/google/generativeai/generative_models.py", line 331, in generate_content
    response = self._client.generate_content(
               ^^^^^^^^^^^^^^^^^^^^^^^^^^^^^^
  File "/Users/macbook/miniconda3/envs/eoh/lib/python3.12/site-packages/google/ai/generativelanguage_v1beta/services/generative_service/client.py", line 835, in generate_content
    response = rpc(
               ^^^^
  File "/Users/macbook/miniconda3/envs/eoh/lib/python3.12/site-packages/google/api_core/gapic_v1/method.py", line 131, in __call__
    return wrapped_func(*args, **kwargs)
           ^^^^^^^^^^^^^^^^^^^^^^^^^^^^^
  File "/Users/macbook/miniconda3/envs/eoh/lib/python3.12/site-packages/google/api_core/retry/retry_unary.py", line 294, in retry_wrapped_func
    return retry_target(
           ^^^^^^^^^^^^^
  File "/Users/macbook/miniconda3/envs/eoh/lib/python3.12/site-packages/google/api_core/retry/retry_unary.py", line 156, in retry_target
    next_sleep = _retry_error_helper(
                 ^^^^^^^^^^^^^^^^^^^^
  File "/Users/macbook/miniconda3/envs/eoh/lib/python3.12/site-packages/google/api_core/retry/retry_base.py", line 214, in _retry_error_helper
    raise final_exc from source_exc
  File "/Users/macbook/miniconda3/envs/eoh/lib/python3.12/site-packages/google/api_core/retry/retry_unary.py", line 147, in retry_target
    result = target()
             ^^^^^^^^
  File "/Users/macbook/miniconda3/envs/eoh/lib/python3.12/site-packages/google/api_core/timeout.py", line 130, in func_with_timeout
    return func(*args, **kwargs)
           ^^^^^^^^^^^^^^^^^^^^^
  File "/Users/macbook/miniconda3/envs/eoh/lib/python3.12/site-packages/google/api_core/grpc_helpers.py", line 78, in error_remapped_callable
    raise exceptions.from_grpc_error(exc) from exc
google.api_core.exceptions.ResourceExhausted: 429 You exceeded your current quota, please check your plan and billing details. For more information on this error, head to: https://ai.google.dev/gemini-api/docs/rate-limits. [violations {
  quota_metric: "generativelanguage.googleapis.com/generate_content_free_tier_requests"
  quota_id: "GenerateRequestsPerMinutePerProjectPerModel-FreeTier"
  quota_dimensions {
    key: "model"
    value: "gemini-1.5-flash"
  }
  quota_dimensions {
    key: "location"
    value: "global"
  }
  quota_value: 15
}
, links {
  description: "Learn more about Gemini API quotas"
  url: "https://ai.google.dev/gemini-api/docs/rate-limits"
}
, retry_delay {
}
]
.
2025-06-15 07:28:00 INFO An exception occured: Traceback (most recent call last):
  File "/Users/macbook/Documents/Code/LLMdesignedEA-comp/llamea/llamea_multi_prompts.py", line 367, in evolve_solution
    evolved_individual = self.llm.sample_solution(
                         ^^^^^^^^^^^^^^^^^^^^^^^^^
  File "/Users/macbook/Documents/Code/LLMdesignedEA-comp/llamea/llm.py", line 106, in sample_solution
    message = self.query(session_messages)
              ^^^^^^^^^^^^^^^^^^^^^^^^^^^^
  File "/Users/macbook/Documents/Code/LLMdesignedEA-comp/llamea/llm.py", line 277, in query
    response = chat_session.send_message(last["content"])
               ^^^^^^^^^^^^^^^^^^^^^^^^^^^^^^^^^^^^^^^^^^
  File "/Users/macbook/miniconda3/envs/eoh/lib/python3.12/site-packages/google/generativeai/generative_models.py", line 578, in send_message
    response = self.model.generate_content(
               ^^^^^^^^^^^^^^^^^^^^^^^^^^^^
  File "/Users/macbook/miniconda3/envs/eoh/lib/python3.12/site-packages/google/generativeai/generative_models.py", line 331, in generate_content
    response = self._client.generate_content(
               ^^^^^^^^^^^^^^^^^^^^^^^^^^^^^^
  File "/Users/macbook/miniconda3/envs/eoh/lib/python3.12/site-packages/google/ai/generativelanguage_v1beta/services/generative_service/client.py", line 835, in generate_content
    response = rpc(
               ^^^^
  File "/Users/macbook/miniconda3/envs/eoh/lib/python3.12/site-packages/google/api_core/gapic_v1/method.py", line 131, in __call__
    return wrapped_func(*args, **kwargs)
           ^^^^^^^^^^^^^^^^^^^^^^^^^^^^^
  File "/Users/macbook/miniconda3/envs/eoh/lib/python3.12/site-packages/google/api_core/retry/retry_unary.py", line 294, in retry_wrapped_func
    return retry_target(
           ^^^^^^^^^^^^^
  File "/Users/macbook/miniconda3/envs/eoh/lib/python3.12/site-packages/google/api_core/retry/retry_unary.py", line 156, in retry_target
    next_sleep = _retry_error_helper(
                 ^^^^^^^^^^^^^^^^^^^^
  File "/Users/macbook/miniconda3/envs/eoh/lib/python3.12/site-packages/google/api_core/retry/retry_base.py", line 214, in _retry_error_helper
    raise final_exc from source_exc
  File "/Users/macbook/miniconda3/envs/eoh/lib/python3.12/site-packages/google/api_core/retry/retry_unary.py", line 147, in retry_target
    result = target()
             ^^^^^^^^
  File "/Users/macbook/miniconda3/envs/eoh/lib/python3.12/site-packages/google/api_core/timeout.py", line 130, in func_with_timeout
    return func(*args, **kwargs)
           ^^^^^^^^^^^^^^^^^^^^^
  File "/Users/macbook/miniconda3/envs/eoh/lib/python3.12/site-packages/google/api_core/grpc_helpers.py", line 78, in error_remapped_callable
    raise exceptions.from_grpc_error(exc) from exc
google.api_core.exceptions.ResourceExhausted: 429 You exceeded your current quota, please check your plan and billing details. For more information on this error, head to: https://ai.google.dev/gemini-api/docs/rate-limits. [violations {
  quota_metric: "generativelanguage.googleapis.com/generate_content_free_tier_requests"
  quota_id: "GenerateRequestsPerMinutePerProjectPerModel-FreeTier"
  quota_dimensions {
    key: "model"
    value: "gemini-1.5-flash"
  }
  quota_dimensions {
    key: "location"
    value: "global"
  }
  quota_value: 15
}
, links {
  description: "Learn more about Gemini API quotas"
  url: "https://ai.google.dev/gemini-api/docs/rate-limits"
}
, retry_delay {
}
]
.
2025-06-15 07:28:00 INFO An exception occured: Traceback (most recent call last):
  File "/Users/macbook/Documents/Code/LLMdesignedEA-comp/llamea/llamea_multi_prompts.py", line 367, in evolve_solution
    evolved_individual = self.llm.sample_solution(
                         ^^^^^^^^^^^^^^^^^^^^^^^^^
  File "/Users/macbook/Documents/Code/LLMdesignedEA-comp/llamea/llm.py", line 106, in sample_solution
    message = self.query(session_messages)
              ^^^^^^^^^^^^^^^^^^^^^^^^^^^^
  File "/Users/macbook/Documents/Code/LLMdesignedEA-comp/llamea/llm.py", line 277, in query
    response = chat_session.send_message(last["content"])
               ^^^^^^^^^^^^^^^^^^^^^^^^^^^^^^^^^^^^^^^^^^
  File "/Users/macbook/miniconda3/envs/eoh/lib/python3.12/site-packages/google/generativeai/generative_models.py", line 578, in send_message
    response = self.model.generate_content(
               ^^^^^^^^^^^^^^^^^^^^^^^^^^^^
  File "/Users/macbook/miniconda3/envs/eoh/lib/python3.12/site-packages/google/generativeai/generative_models.py", line 331, in generate_content
    response = self._client.generate_content(
               ^^^^^^^^^^^^^^^^^^^^^^^^^^^^^^
  File "/Users/macbook/miniconda3/envs/eoh/lib/python3.12/site-packages/google/ai/generativelanguage_v1beta/services/generative_service/client.py", line 835, in generate_content
    response = rpc(
               ^^^^
  File "/Users/macbook/miniconda3/envs/eoh/lib/python3.12/site-packages/google/api_core/gapic_v1/method.py", line 131, in __call__
    return wrapped_func(*args, **kwargs)
           ^^^^^^^^^^^^^^^^^^^^^^^^^^^^^
  File "/Users/macbook/miniconda3/envs/eoh/lib/python3.12/site-packages/google/api_core/retry/retry_unary.py", line 294, in retry_wrapped_func
    return retry_target(
           ^^^^^^^^^^^^^
  File "/Users/macbook/miniconda3/envs/eoh/lib/python3.12/site-packages/google/api_core/retry/retry_unary.py", line 156, in retry_target
    next_sleep = _retry_error_helper(
                 ^^^^^^^^^^^^^^^^^^^^
  File "/Users/macbook/miniconda3/envs/eoh/lib/python3.12/site-packages/google/api_core/retry/retry_base.py", line 214, in _retry_error_helper
    raise final_exc from source_exc
  File "/Users/macbook/miniconda3/envs/eoh/lib/python3.12/site-packages/google/api_core/retry/retry_unary.py", line 147, in retry_target
    result = target()
             ^^^^^^^^
  File "/Users/macbook/miniconda3/envs/eoh/lib/python3.12/site-packages/google/api_core/timeout.py", line 130, in func_with_timeout
    return func(*args, **kwargs)
           ^^^^^^^^^^^^^^^^^^^^^
  File "/Users/macbook/miniconda3/envs/eoh/lib/python3.12/site-packages/google/api_core/grpc_helpers.py", line 78, in error_remapped_callable
    raise exceptions.from_grpc_error(exc) from exc
google.api_core.exceptions.ResourceExhausted: 429 You exceeded your current quota, please check your plan and billing details. For more information on this error, head to: https://ai.google.dev/gemini-api/docs/rate-limits. [violations {
  quota_metric: "generativelanguage.googleapis.com/generate_content_free_tier_requests"
  quota_id: "GenerateRequestsPerMinutePerProjectPerModel-FreeTier"
  quota_dimensions {
    key: "model"
    value: "gemini-1.5-flash"
  }
  quota_dimensions {
    key: "location"
    value: "global"
  }
  quota_value: 15
}
, links {
  description: "Learn more about Gemini API quotas"
  url: "https://ai.google.dev/gemini-api/docs/rate-limits"
}
, retry_delay {
}
]
.
2025-06-15 07:28:00 INFO An exception occured: Traceback (most recent call last):
  File "/Users/macbook/Documents/Code/LLMdesignedEA-comp/llamea/llamea_multi_prompts.py", line 367, in evolve_solution
    evolved_individual = self.llm.sample_solution(
                         ^^^^^^^^^^^^^^^^^^^^^^^^^
  File "/Users/macbook/Documents/Code/LLMdesignedEA-comp/llamea/llm.py", line 106, in sample_solution
    message = self.query(session_messages)
              ^^^^^^^^^^^^^^^^^^^^^^^^^^^^
  File "/Users/macbook/Documents/Code/LLMdesignedEA-comp/llamea/llm.py", line 277, in query
    response = chat_session.send_message(last["content"])
               ^^^^^^^^^^^^^^^^^^^^^^^^^^^^^^^^^^^^^^^^^^
  File "/Users/macbook/miniconda3/envs/eoh/lib/python3.12/site-packages/google/generativeai/generative_models.py", line 578, in send_message
    response = self.model.generate_content(
               ^^^^^^^^^^^^^^^^^^^^^^^^^^^^
  File "/Users/macbook/miniconda3/envs/eoh/lib/python3.12/site-packages/google/generativeai/generative_models.py", line 331, in generate_content
    response = self._client.generate_content(
               ^^^^^^^^^^^^^^^^^^^^^^^^^^^^^^
  File "/Users/macbook/miniconda3/envs/eoh/lib/python3.12/site-packages/google/ai/generativelanguage_v1beta/services/generative_service/client.py", line 835, in generate_content
    response = rpc(
               ^^^^
  File "/Users/macbook/miniconda3/envs/eoh/lib/python3.12/site-packages/google/api_core/gapic_v1/method.py", line 131, in __call__
    return wrapped_func(*args, **kwargs)
           ^^^^^^^^^^^^^^^^^^^^^^^^^^^^^
  File "/Users/macbook/miniconda3/envs/eoh/lib/python3.12/site-packages/google/api_core/retry/retry_unary.py", line 294, in retry_wrapped_func
    return retry_target(
           ^^^^^^^^^^^^^
  File "/Users/macbook/miniconda3/envs/eoh/lib/python3.12/site-packages/google/api_core/retry/retry_unary.py", line 156, in retry_target
    next_sleep = _retry_error_helper(
                 ^^^^^^^^^^^^^^^^^^^^
  File "/Users/macbook/miniconda3/envs/eoh/lib/python3.12/site-packages/google/api_core/retry/retry_base.py", line 214, in _retry_error_helper
    raise final_exc from source_exc
  File "/Users/macbook/miniconda3/envs/eoh/lib/python3.12/site-packages/google/api_core/retry/retry_unary.py", line 147, in retry_target
    result = target()
             ^^^^^^^^
  File "/Users/macbook/miniconda3/envs/eoh/lib/python3.12/site-packages/google/api_core/timeout.py", line 130, in func_with_timeout
    return func(*args, **kwargs)
           ^^^^^^^^^^^^^^^^^^^^^
  File "/Users/macbook/miniconda3/envs/eoh/lib/python3.12/site-packages/google/api_core/grpc_helpers.py", line 78, in error_remapped_callable
    raise exceptions.from_grpc_error(exc) from exc
google.api_core.exceptions.ResourceExhausted: 429 You exceeded your current quota, please check your plan and billing details. For more information on this error, head to: https://ai.google.dev/gemini-api/docs/rate-limits. [violations {
  quota_metric: "generativelanguage.googleapis.com/generate_content_free_tier_requests"
  quota_id: "GenerateRequestsPerMinutePerProjectPerModel-FreeTier"
  quota_dimensions {
    key: "model"
    value: "gemini-1.5-flash"
  }
  quota_dimensions {
    key: "location"
    value: "global"
  }
  quota_value: 15
}
, links {
  description: "Learn more about Gemini API quotas"
  url: "https://ai.google.dev/gemini-api/docs/rate-limits"
}
, retry_delay {
}
]
.
2025-06-15 07:28:00 INFO An exception occured: Traceback (most recent call last):
  File "/Users/macbook/Documents/Code/LLMdesignedEA-comp/llamea/llamea_multi_prompts.py", line 367, in evolve_solution
    evolved_individual = self.llm.sample_solution(
                         ^^^^^^^^^^^^^^^^^^^^^^^^^
  File "/Users/macbook/Documents/Code/LLMdesignedEA-comp/llamea/llm.py", line 106, in sample_solution
    message = self.query(session_messages)
              ^^^^^^^^^^^^^^^^^^^^^^^^^^^^
  File "/Users/macbook/Documents/Code/LLMdesignedEA-comp/llamea/llm.py", line 277, in query
    response = chat_session.send_message(last["content"])
               ^^^^^^^^^^^^^^^^^^^^^^^^^^^^^^^^^^^^^^^^^^
  File "/Users/macbook/miniconda3/envs/eoh/lib/python3.12/site-packages/google/generativeai/generative_models.py", line 578, in send_message
    response = self.model.generate_content(
               ^^^^^^^^^^^^^^^^^^^^^^^^^^^^
  File "/Users/macbook/miniconda3/envs/eoh/lib/python3.12/site-packages/google/generativeai/generative_models.py", line 331, in generate_content
    response = self._client.generate_content(
               ^^^^^^^^^^^^^^^^^^^^^^^^^^^^^^
  File "/Users/macbook/miniconda3/envs/eoh/lib/python3.12/site-packages/google/ai/generativelanguage_v1beta/services/generative_service/client.py", line 835, in generate_content
    response = rpc(
               ^^^^
  File "/Users/macbook/miniconda3/envs/eoh/lib/python3.12/site-packages/google/api_core/gapic_v1/method.py", line 131, in __call__
    return wrapped_func(*args, **kwargs)
           ^^^^^^^^^^^^^^^^^^^^^^^^^^^^^
  File "/Users/macbook/miniconda3/envs/eoh/lib/python3.12/site-packages/google/api_core/retry/retry_unary.py", line 294, in retry_wrapped_func
    return retry_target(
           ^^^^^^^^^^^^^
  File "/Users/macbook/miniconda3/envs/eoh/lib/python3.12/site-packages/google/api_core/retry/retry_unary.py", line 156, in retry_target
    next_sleep = _retry_error_helper(
                 ^^^^^^^^^^^^^^^^^^^^
  File "/Users/macbook/miniconda3/envs/eoh/lib/python3.12/site-packages/google/api_core/retry/retry_base.py", line 214, in _retry_error_helper
    raise final_exc from source_exc
  File "/Users/macbook/miniconda3/envs/eoh/lib/python3.12/site-packages/google/api_core/retry/retry_unary.py", line 147, in retry_target
    result = target()
             ^^^^^^^^
  File "/Users/macbook/miniconda3/envs/eoh/lib/python3.12/site-packages/google/api_core/timeout.py", line 130, in func_with_timeout
    return func(*args, **kwargs)
           ^^^^^^^^^^^^^^^^^^^^^
  File "/Users/macbook/miniconda3/envs/eoh/lib/python3.12/site-packages/google/api_core/grpc_helpers.py", line 78, in error_remapped_callable
    raise exceptions.from_grpc_error(exc) from exc
google.api_core.exceptions.ResourceExhausted: 429 You exceeded your current quota, please check your plan and billing details. For more information on this error, head to: https://ai.google.dev/gemini-api/docs/rate-limits. [violations {
  quota_metric: "generativelanguage.googleapis.com/generate_content_free_tier_requests"
  quota_id: "GenerateRequestsPerMinutePerProjectPerModel-FreeTier"
  quota_dimensions {
    key: "model"
    value: "gemini-1.5-flash"
  }
  quota_dimensions {
    key: "location"
    value: "global"
  }
  quota_value: 15
}
, links {
  description: "Learn more about Gemini API quotas"
  url: "https://ai.google.dev/gemini-api/docs/rate-limits"
}
, retry_delay {
}
]
.
2025-06-15 07:28:00 INFO An exception occured: Traceback (most recent call last):
  File "/Users/macbook/Documents/Code/LLMdesignedEA-comp/llamea/llamea_multi_prompts.py", line 367, in evolve_solution
    evolved_individual = self.llm.sample_solution(
                         ^^^^^^^^^^^^^^^^^^^^^^^^^
  File "/Users/macbook/Documents/Code/LLMdesignedEA-comp/llamea/llm.py", line 106, in sample_solution
    message = self.query(session_messages)
              ^^^^^^^^^^^^^^^^^^^^^^^^^^^^
  File "/Users/macbook/Documents/Code/LLMdesignedEA-comp/llamea/llm.py", line 277, in query
    response = chat_session.send_message(last["content"])
               ^^^^^^^^^^^^^^^^^^^^^^^^^^^^^^^^^^^^^^^^^^
  File "/Users/macbook/miniconda3/envs/eoh/lib/python3.12/site-packages/google/generativeai/generative_models.py", line 578, in send_message
    response = self.model.generate_content(
               ^^^^^^^^^^^^^^^^^^^^^^^^^^^^
  File "/Users/macbook/miniconda3/envs/eoh/lib/python3.12/site-packages/google/generativeai/generative_models.py", line 331, in generate_content
    response = self._client.generate_content(
               ^^^^^^^^^^^^^^^^^^^^^^^^^^^^^^
  File "/Users/macbook/miniconda3/envs/eoh/lib/python3.12/site-packages/google/ai/generativelanguage_v1beta/services/generative_service/client.py", line 835, in generate_content
    response = rpc(
               ^^^^
  File "/Users/macbook/miniconda3/envs/eoh/lib/python3.12/site-packages/google/api_core/gapic_v1/method.py", line 131, in __call__
    return wrapped_func(*args, **kwargs)
           ^^^^^^^^^^^^^^^^^^^^^^^^^^^^^
  File "/Users/macbook/miniconda3/envs/eoh/lib/python3.12/site-packages/google/api_core/retry/retry_unary.py", line 294, in retry_wrapped_func
    return retry_target(
           ^^^^^^^^^^^^^
  File "/Users/macbook/miniconda3/envs/eoh/lib/python3.12/site-packages/google/api_core/retry/retry_unary.py", line 156, in retry_target
    next_sleep = _retry_error_helper(
                 ^^^^^^^^^^^^^^^^^^^^
  File "/Users/macbook/miniconda3/envs/eoh/lib/python3.12/site-packages/google/api_core/retry/retry_base.py", line 214, in _retry_error_helper
    raise final_exc from source_exc
  File "/Users/macbook/miniconda3/envs/eoh/lib/python3.12/site-packages/google/api_core/retry/retry_unary.py", line 147, in retry_target
    result = target()
             ^^^^^^^^
  File "/Users/macbook/miniconda3/envs/eoh/lib/python3.12/site-packages/google/api_core/timeout.py", line 130, in func_with_timeout
    return func(*args, **kwargs)
           ^^^^^^^^^^^^^^^^^^^^^
  File "/Users/macbook/miniconda3/envs/eoh/lib/python3.12/site-packages/google/api_core/grpc_helpers.py", line 78, in error_remapped_callable
    raise exceptions.from_grpc_error(exc) from exc
google.api_core.exceptions.ResourceExhausted: 429 You exceeded your current quota, please check your plan and billing details. For more information on this error, head to: https://ai.google.dev/gemini-api/docs/rate-limits. [violations {
  quota_metric: "generativelanguage.googleapis.com/generate_content_free_tier_requests"
  quota_id: "GenerateRequestsPerMinutePerProjectPerModel-FreeTier"
  quota_dimensions {
    key: "model"
    value: "gemini-1.5-flash"
  }
  quota_dimensions {
    key: "location"
    value: "global"
  }
  quota_value: 15
}
, links {
  description: "Learn more about Gemini API quotas"
  url: "https://ai.google.dev/gemini-api/docs/rate-limits"
}
, retry_delay {
  seconds: 59
}
]
.
2025-06-15 07:28:00 INFO An exception occured: Traceback (most recent call last):
  File "/Users/macbook/Documents/Code/LLMdesignedEA-comp/llamea/llamea_multi_prompts.py", line 367, in evolve_solution
    evolved_individual = self.llm.sample_solution(
                         ^^^^^^^^^^^^^^^^^^^^^^^^^
  File "/Users/macbook/Documents/Code/LLMdesignedEA-comp/llamea/llm.py", line 106, in sample_solution
    message = self.query(session_messages)
              ^^^^^^^^^^^^^^^^^^^^^^^^^^^^
  File "/Users/macbook/Documents/Code/LLMdesignedEA-comp/llamea/llm.py", line 277, in query
    response = chat_session.send_message(last["content"])
               ^^^^^^^^^^^^^^^^^^^^^^^^^^^^^^^^^^^^^^^^^^
  File "/Users/macbook/miniconda3/envs/eoh/lib/python3.12/site-packages/google/generativeai/generative_models.py", line 578, in send_message
    response = self.model.generate_content(
               ^^^^^^^^^^^^^^^^^^^^^^^^^^^^
  File "/Users/macbook/miniconda3/envs/eoh/lib/python3.12/site-packages/google/generativeai/generative_models.py", line 331, in generate_content
    response = self._client.generate_content(
               ^^^^^^^^^^^^^^^^^^^^^^^^^^^^^^
  File "/Users/macbook/miniconda3/envs/eoh/lib/python3.12/site-packages/google/ai/generativelanguage_v1beta/services/generative_service/client.py", line 835, in generate_content
    response = rpc(
               ^^^^
  File "/Users/macbook/miniconda3/envs/eoh/lib/python3.12/site-packages/google/api_core/gapic_v1/method.py", line 131, in __call__
    return wrapped_func(*args, **kwargs)
           ^^^^^^^^^^^^^^^^^^^^^^^^^^^^^
  File "/Users/macbook/miniconda3/envs/eoh/lib/python3.12/site-packages/google/api_core/retry/retry_unary.py", line 294, in retry_wrapped_func
    return retry_target(
           ^^^^^^^^^^^^^
  File "/Users/macbook/miniconda3/envs/eoh/lib/python3.12/site-packages/google/api_core/retry/retry_unary.py", line 156, in retry_target
    next_sleep = _retry_error_helper(
                 ^^^^^^^^^^^^^^^^^^^^
  File "/Users/macbook/miniconda3/envs/eoh/lib/python3.12/site-packages/google/api_core/retry/retry_base.py", line 214, in _retry_error_helper
    raise final_exc from source_exc
  File "/Users/macbook/miniconda3/envs/eoh/lib/python3.12/site-packages/google/api_core/retry/retry_unary.py", line 147, in retry_target
    result = target()
             ^^^^^^^^
  File "/Users/macbook/miniconda3/envs/eoh/lib/python3.12/site-packages/google/api_core/timeout.py", line 130, in func_with_timeout
    return func(*args, **kwargs)
           ^^^^^^^^^^^^^^^^^^^^^
  File "/Users/macbook/miniconda3/envs/eoh/lib/python3.12/site-packages/google/api_core/grpc_helpers.py", line 78, in error_remapped_callable
    raise exceptions.from_grpc_error(exc) from exc
google.api_core.exceptions.ResourceExhausted: 429 You exceeded your current quota, please check your plan and billing details. For more information on this error, head to: https://ai.google.dev/gemini-api/docs/rate-limits. [violations {
  quota_metric: "generativelanguage.googleapis.com/generate_content_free_tier_requests"
  quota_id: "GenerateRequestsPerMinutePerProjectPerModel-FreeTier"
  quota_dimensions {
    key: "model"
    value: "gemini-1.5-flash"
  }
  quota_dimensions {
    key: "location"
    value: "global"
  }
  quota_value: 15
}
, links {
  description: "Learn more about Gemini API quotas"
  url: "https://ai.google.dev/gemini-api/docs/rate-limits"
}
, retry_delay {
  seconds: 59
}
]
.
2025-06-15 07:28:00 INFO An exception occured: Traceback (most recent call last):
  File "/Users/macbook/Documents/Code/LLMdesignedEA-comp/llamea/llamea_multi_prompts.py", line 367, in evolve_solution
    evolved_individual = self.llm.sample_solution(
                         ^^^^^^^^^^^^^^^^^^^^^^^^^
  File "/Users/macbook/Documents/Code/LLMdesignedEA-comp/llamea/llm.py", line 106, in sample_solution
    message = self.query(session_messages)
              ^^^^^^^^^^^^^^^^^^^^^^^^^^^^
  File "/Users/macbook/Documents/Code/LLMdesignedEA-comp/llamea/llm.py", line 277, in query
    response = chat_session.send_message(last["content"])
               ^^^^^^^^^^^^^^^^^^^^^^^^^^^^^^^^^^^^^^^^^^
  File "/Users/macbook/miniconda3/envs/eoh/lib/python3.12/site-packages/google/generativeai/generative_models.py", line 578, in send_message
    response = self.model.generate_content(
               ^^^^^^^^^^^^^^^^^^^^^^^^^^^^
  File "/Users/macbook/miniconda3/envs/eoh/lib/python3.12/site-packages/google/generativeai/generative_models.py", line 331, in generate_content
    response = self._client.generate_content(
               ^^^^^^^^^^^^^^^^^^^^^^^^^^^^^^
  File "/Users/macbook/miniconda3/envs/eoh/lib/python3.12/site-packages/google/ai/generativelanguage_v1beta/services/generative_service/client.py", line 835, in generate_content
    response = rpc(
               ^^^^
  File "/Users/macbook/miniconda3/envs/eoh/lib/python3.12/site-packages/google/api_core/gapic_v1/method.py", line 131, in __call__
    return wrapped_func(*args, **kwargs)
           ^^^^^^^^^^^^^^^^^^^^^^^^^^^^^
  File "/Users/macbook/miniconda3/envs/eoh/lib/python3.12/site-packages/google/api_core/retry/retry_unary.py", line 294, in retry_wrapped_func
    return retry_target(
           ^^^^^^^^^^^^^
  File "/Users/macbook/miniconda3/envs/eoh/lib/python3.12/site-packages/google/api_core/retry/retry_unary.py", line 156, in retry_target
    next_sleep = _retry_error_helper(
                 ^^^^^^^^^^^^^^^^^^^^
  File "/Users/macbook/miniconda3/envs/eoh/lib/python3.12/site-packages/google/api_core/retry/retry_base.py", line 214, in _retry_error_helper
    raise final_exc from source_exc
  File "/Users/macbook/miniconda3/envs/eoh/lib/python3.12/site-packages/google/api_core/retry/retry_unary.py", line 147, in retry_target
    result = target()
             ^^^^^^^^
  File "/Users/macbook/miniconda3/envs/eoh/lib/python3.12/site-packages/google/api_core/timeout.py", line 130, in func_with_timeout
    return func(*args, **kwargs)
           ^^^^^^^^^^^^^^^^^^^^^
  File "/Users/macbook/miniconda3/envs/eoh/lib/python3.12/site-packages/google/api_core/grpc_helpers.py", line 78, in error_remapped_callable
    raise exceptions.from_grpc_error(exc) from exc
google.api_core.exceptions.ResourceExhausted: 429 You exceeded your current quota, please check your plan and billing details. For more information on this error, head to: https://ai.google.dev/gemini-api/docs/rate-limits. [violations {
  quota_metric: "generativelanguage.googleapis.com/generate_content_free_tier_requests"
  quota_id: "GenerateRequestsPerMinutePerProjectPerModel-FreeTier"
  quota_dimensions {
    key: "model"
    value: "gemini-1.5-flash"
  }
  quota_dimensions {
    key: "location"
    value: "global"
  }
  quota_value: 15
}
, links {
  description: "Learn more about Gemini API quotas"
  url: "https://ai.google.dev/gemini-api/docs/rate-limits"
}
, retry_delay {
  seconds: 59
}
]
.
2025-06-15 07:28:00 INFO An exception occured: Traceback (most recent call last):
  File "/Users/macbook/Documents/Code/LLMdesignedEA-comp/llamea/llamea_multi_prompts.py", line 367, in evolve_solution
    evolved_individual = self.llm.sample_solution(
                         ^^^^^^^^^^^^^^^^^^^^^^^^^
  File "/Users/macbook/Documents/Code/LLMdesignedEA-comp/llamea/llm.py", line 106, in sample_solution
    message = self.query(session_messages)
              ^^^^^^^^^^^^^^^^^^^^^^^^^^^^
  File "/Users/macbook/Documents/Code/LLMdesignedEA-comp/llamea/llm.py", line 277, in query
    response = chat_session.send_message(last["content"])
               ^^^^^^^^^^^^^^^^^^^^^^^^^^^^^^^^^^^^^^^^^^
  File "/Users/macbook/miniconda3/envs/eoh/lib/python3.12/site-packages/google/generativeai/generative_models.py", line 578, in send_message
    response = self.model.generate_content(
               ^^^^^^^^^^^^^^^^^^^^^^^^^^^^
  File "/Users/macbook/miniconda3/envs/eoh/lib/python3.12/site-packages/google/generativeai/generative_models.py", line 331, in generate_content
    response = self._client.generate_content(
               ^^^^^^^^^^^^^^^^^^^^^^^^^^^^^^
  File "/Users/macbook/miniconda3/envs/eoh/lib/python3.12/site-packages/google/ai/generativelanguage_v1beta/services/generative_service/client.py", line 835, in generate_content
    response = rpc(
               ^^^^
  File "/Users/macbook/miniconda3/envs/eoh/lib/python3.12/site-packages/google/api_core/gapic_v1/method.py", line 131, in __call__
    return wrapped_func(*args, **kwargs)
           ^^^^^^^^^^^^^^^^^^^^^^^^^^^^^
  File "/Users/macbook/miniconda3/envs/eoh/lib/python3.12/site-packages/google/api_core/retry/retry_unary.py", line 294, in retry_wrapped_func
    return retry_target(
           ^^^^^^^^^^^^^
  File "/Users/macbook/miniconda3/envs/eoh/lib/python3.12/site-packages/google/api_core/retry/retry_unary.py", line 156, in retry_target
    next_sleep = _retry_error_helper(
                 ^^^^^^^^^^^^^^^^^^^^
  File "/Users/macbook/miniconda3/envs/eoh/lib/python3.12/site-packages/google/api_core/retry/retry_base.py", line 214, in _retry_error_helper
    raise final_exc from source_exc
  File "/Users/macbook/miniconda3/envs/eoh/lib/python3.12/site-packages/google/api_core/retry/retry_unary.py", line 147, in retry_target
    result = target()
             ^^^^^^^^
  File "/Users/macbook/miniconda3/envs/eoh/lib/python3.12/site-packages/google/api_core/timeout.py", line 130, in func_with_timeout
    return func(*args, **kwargs)
           ^^^^^^^^^^^^^^^^^^^^^
  File "/Users/macbook/miniconda3/envs/eoh/lib/python3.12/site-packages/google/api_core/grpc_helpers.py", line 78, in error_remapped_callable
    raise exceptions.from_grpc_error(exc) from exc
google.api_core.exceptions.ResourceExhausted: 429 You exceeded your current quota, please check your plan and billing details. For more information on this error, head to: https://ai.google.dev/gemini-api/docs/rate-limits. [violations {
  quota_metric: "generativelanguage.googleapis.com/generate_content_free_tier_requests"
  quota_id: "GenerateRequestsPerMinutePerProjectPerModel-FreeTier"
  quota_dimensions {
    key: "model"
    value: "gemini-1.5-flash"
  }
  quota_dimensions {
    key: "location"
    value: "global"
  }
  quota_value: 15
}
, links {
  description: "Learn more about Gemini API quotas"
  url: "https://ai.google.dev/gemini-api/docs/rate-limits"
}
, retry_delay {
  seconds: 59
}
]
.
2025-06-15 07:28:00 INFO An exception occured: Traceback (most recent call last):
  File "/Users/macbook/Documents/Code/LLMdesignedEA-comp/llamea/llamea_multi_prompts.py", line 367, in evolve_solution
    evolved_individual = self.llm.sample_solution(
                         ^^^^^^^^^^^^^^^^^^^^^^^^^
  File "/Users/macbook/Documents/Code/LLMdesignedEA-comp/llamea/llm.py", line 106, in sample_solution
    message = self.query(session_messages)
              ^^^^^^^^^^^^^^^^^^^^^^^^^^^^
  File "/Users/macbook/Documents/Code/LLMdesignedEA-comp/llamea/llm.py", line 277, in query
    response = chat_session.send_message(last["content"])
               ^^^^^^^^^^^^^^^^^^^^^^^^^^^^^^^^^^^^^^^^^^
  File "/Users/macbook/miniconda3/envs/eoh/lib/python3.12/site-packages/google/generativeai/generative_models.py", line 578, in send_message
    response = self.model.generate_content(
               ^^^^^^^^^^^^^^^^^^^^^^^^^^^^
  File "/Users/macbook/miniconda3/envs/eoh/lib/python3.12/site-packages/google/generativeai/generative_models.py", line 331, in generate_content
    response = self._client.generate_content(
               ^^^^^^^^^^^^^^^^^^^^^^^^^^^^^^
  File "/Users/macbook/miniconda3/envs/eoh/lib/python3.12/site-packages/google/ai/generativelanguage_v1beta/services/generative_service/client.py", line 835, in generate_content
    response = rpc(
               ^^^^
  File "/Users/macbook/miniconda3/envs/eoh/lib/python3.12/site-packages/google/api_core/gapic_v1/method.py", line 131, in __call__
    return wrapped_func(*args, **kwargs)
           ^^^^^^^^^^^^^^^^^^^^^^^^^^^^^
  File "/Users/macbook/miniconda3/envs/eoh/lib/python3.12/site-packages/google/api_core/retry/retry_unary.py", line 294, in retry_wrapped_func
    return retry_target(
           ^^^^^^^^^^^^^
  File "/Users/macbook/miniconda3/envs/eoh/lib/python3.12/site-packages/google/api_core/retry/retry_unary.py", line 156, in retry_target
    next_sleep = _retry_error_helper(
                 ^^^^^^^^^^^^^^^^^^^^
  File "/Users/macbook/miniconda3/envs/eoh/lib/python3.12/site-packages/google/api_core/retry/retry_base.py", line 214, in _retry_error_helper
    raise final_exc from source_exc
  File "/Users/macbook/miniconda3/envs/eoh/lib/python3.12/site-packages/google/api_core/retry/retry_unary.py", line 147, in retry_target
    result = target()
             ^^^^^^^^
  File "/Users/macbook/miniconda3/envs/eoh/lib/python3.12/site-packages/google/api_core/timeout.py", line 130, in func_with_timeout
    return func(*args, **kwargs)
           ^^^^^^^^^^^^^^^^^^^^^
  File "/Users/macbook/miniconda3/envs/eoh/lib/python3.12/site-packages/google/api_core/grpc_helpers.py", line 78, in error_remapped_callable
    raise exceptions.from_grpc_error(exc) from exc
google.api_core.exceptions.ResourceExhausted: 429 You exceeded your current quota, please check your plan and billing details. For more information on this error, head to: https://ai.google.dev/gemini-api/docs/rate-limits. [violations {
  quota_metric: "generativelanguage.googleapis.com/generate_content_free_tier_requests"
  quota_id: "GenerateRequestsPerMinutePerProjectPerModel-FreeTier"
  quota_dimensions {
    key: "model"
    value: "gemini-1.5-flash"
  }
  quota_dimensions {
    key: "location"
    value: "global"
  }
  quota_value: 15
}
, links {
  description: "Learn more about Gemini API quotas"
  url: "https://ai.google.dev/gemini-api/docs/rate-limits"
}
, retry_delay {
  seconds: 59
}
]
.
2025-06-15 07:28:01 INFO An exception occured: Traceback (most recent call last):
  File "/Users/macbook/Documents/Code/LLMdesignedEA-comp/llamea/llamea_multi_prompts.py", line 367, in evolve_solution
    evolved_individual = self.llm.sample_solution(
                         ^^^^^^^^^^^^^^^^^^^^^^^^^
  File "/Users/macbook/Documents/Code/LLMdesignedEA-comp/llamea/llm.py", line 106, in sample_solution
    message = self.query(session_messages)
              ^^^^^^^^^^^^^^^^^^^^^^^^^^^^
  File "/Users/macbook/Documents/Code/LLMdesignedEA-comp/llamea/llm.py", line 277, in query
    response = chat_session.send_message(last["content"])
               ^^^^^^^^^^^^^^^^^^^^^^^^^^^^^^^^^^^^^^^^^^
  File "/Users/macbook/miniconda3/envs/eoh/lib/python3.12/site-packages/google/generativeai/generative_models.py", line 578, in send_message
    response = self.model.generate_content(
               ^^^^^^^^^^^^^^^^^^^^^^^^^^^^
  File "/Users/macbook/miniconda3/envs/eoh/lib/python3.12/site-packages/google/generativeai/generative_models.py", line 331, in generate_content
    response = self._client.generate_content(
               ^^^^^^^^^^^^^^^^^^^^^^^^^^^^^^
  File "/Users/macbook/miniconda3/envs/eoh/lib/python3.12/site-packages/google/ai/generativelanguage_v1beta/services/generative_service/client.py", line 835, in generate_content
    response = rpc(
               ^^^^
  File "/Users/macbook/miniconda3/envs/eoh/lib/python3.12/site-packages/google/api_core/gapic_v1/method.py", line 131, in __call__
    return wrapped_func(*args, **kwargs)
           ^^^^^^^^^^^^^^^^^^^^^^^^^^^^^
  File "/Users/macbook/miniconda3/envs/eoh/lib/python3.12/site-packages/google/api_core/retry/retry_unary.py", line 294, in retry_wrapped_func
    return retry_target(
           ^^^^^^^^^^^^^
  File "/Users/macbook/miniconda3/envs/eoh/lib/python3.12/site-packages/google/api_core/retry/retry_unary.py", line 156, in retry_target
    next_sleep = _retry_error_helper(
                 ^^^^^^^^^^^^^^^^^^^^
  File "/Users/macbook/miniconda3/envs/eoh/lib/python3.12/site-packages/google/api_core/retry/retry_base.py", line 214, in _retry_error_helper
    raise final_exc from source_exc
  File "/Users/macbook/miniconda3/envs/eoh/lib/python3.12/site-packages/google/api_core/retry/retry_unary.py", line 147, in retry_target
    result = target()
             ^^^^^^^^
  File "/Users/macbook/miniconda3/envs/eoh/lib/python3.12/site-packages/google/api_core/timeout.py", line 130, in func_with_timeout
    return func(*args, **kwargs)
           ^^^^^^^^^^^^^^^^^^^^^
  File "/Users/macbook/miniconda3/envs/eoh/lib/python3.12/site-packages/google/api_core/grpc_helpers.py", line 78, in error_remapped_callable
    raise exceptions.from_grpc_error(exc) from exc
google.api_core.exceptions.ResourceExhausted: 429 You exceeded your current quota, please check your plan and billing details. For more information on this error, head to: https://ai.google.dev/gemini-api/docs/rate-limits. [violations {
  quota_metric: "generativelanguage.googleapis.com/generate_content_free_tier_requests"
  quota_id: "GenerateRequestsPerMinutePerProjectPerModel-FreeTier"
  quota_dimensions {
    key: "model"
    value: "gemini-1.5-flash"
  }
  quota_dimensions {
    key: "location"
    value: "global"
  }
  quota_value: 15
}
, links {
  description: "Learn more about Gemini API quotas"
  url: "https://ai.google.dev/gemini-api/docs/rate-limits"
}
, retry_delay {
  seconds: 58
}
]
.
2025-06-15 07:28:01 INFO An exception occured: Traceback (most recent call last):
  File "/Users/macbook/Documents/Code/LLMdesignedEA-comp/llamea/llamea_multi_prompts.py", line 367, in evolve_solution
    evolved_individual = self.llm.sample_solution(
                         ^^^^^^^^^^^^^^^^^^^^^^^^^
  File "/Users/macbook/Documents/Code/LLMdesignedEA-comp/llamea/llm.py", line 106, in sample_solution
    message = self.query(session_messages)
              ^^^^^^^^^^^^^^^^^^^^^^^^^^^^
  File "/Users/macbook/Documents/Code/LLMdesignedEA-comp/llamea/llm.py", line 277, in query
    response = chat_session.send_message(last["content"])
               ^^^^^^^^^^^^^^^^^^^^^^^^^^^^^^^^^^^^^^^^^^
  File "/Users/macbook/miniconda3/envs/eoh/lib/python3.12/site-packages/google/generativeai/generative_models.py", line 578, in send_message
    response = self.model.generate_content(
               ^^^^^^^^^^^^^^^^^^^^^^^^^^^^
  File "/Users/macbook/miniconda3/envs/eoh/lib/python3.12/site-packages/google/generativeai/generative_models.py", line 331, in generate_content
    response = self._client.generate_content(
               ^^^^^^^^^^^^^^^^^^^^^^^^^^^^^^
  File "/Users/macbook/miniconda3/envs/eoh/lib/python3.12/site-packages/google/ai/generativelanguage_v1beta/services/generative_service/client.py", line 835, in generate_content
    response = rpc(
               ^^^^
  File "/Users/macbook/miniconda3/envs/eoh/lib/python3.12/site-packages/google/api_core/gapic_v1/method.py", line 131, in __call__
    return wrapped_func(*args, **kwargs)
           ^^^^^^^^^^^^^^^^^^^^^^^^^^^^^
  File "/Users/macbook/miniconda3/envs/eoh/lib/python3.12/site-packages/google/api_core/retry/retry_unary.py", line 294, in retry_wrapped_func
    return retry_target(
           ^^^^^^^^^^^^^
  File "/Users/macbook/miniconda3/envs/eoh/lib/python3.12/site-packages/google/api_core/retry/retry_unary.py", line 156, in retry_target
    next_sleep = _retry_error_helper(
                 ^^^^^^^^^^^^^^^^^^^^
  File "/Users/macbook/miniconda3/envs/eoh/lib/python3.12/site-packages/google/api_core/retry/retry_base.py", line 214, in _retry_error_helper
    raise final_exc from source_exc
  File "/Users/macbook/miniconda3/envs/eoh/lib/python3.12/site-packages/google/api_core/retry/retry_unary.py", line 147, in retry_target
    result = target()
             ^^^^^^^^
  File "/Users/macbook/miniconda3/envs/eoh/lib/python3.12/site-packages/google/api_core/timeout.py", line 130, in func_with_timeout
    return func(*args, **kwargs)
           ^^^^^^^^^^^^^^^^^^^^^
  File "/Users/macbook/miniconda3/envs/eoh/lib/python3.12/site-packages/google/api_core/grpc_helpers.py", line 78, in error_remapped_callable
    raise exceptions.from_grpc_error(exc) from exc
google.api_core.exceptions.ResourceExhausted: 429 You exceeded your current quota, please check your plan and billing details. For more information on this error, head to: https://ai.google.dev/gemini-api/docs/rate-limits. [violations {
  quota_metric: "generativelanguage.googleapis.com/generate_content_free_tier_requests"
  quota_id: "GenerateRequestsPerMinutePerProjectPerModel-FreeTier"
  quota_dimensions {
    key: "model"
    value: "gemini-1.5-flash"
  }
  quota_dimensions {
    key: "location"
    value: "global"
  }
  quota_value: 15
}
, links {
  description: "Learn more about Gemini API quotas"
  url: "https://ai.google.dev/gemini-api/docs/rate-limits"
}
, retry_delay {
  seconds: 58
}
]
.
2025-06-15 07:28:01 INFO An exception occured: Traceback (most recent call last):
  File "/Users/macbook/Documents/Code/LLMdesignedEA-comp/llamea/llamea_multi_prompts.py", line 367, in evolve_solution
    evolved_individual = self.llm.sample_solution(
                         ^^^^^^^^^^^^^^^^^^^^^^^^^
  File "/Users/macbook/Documents/Code/LLMdesignedEA-comp/llamea/llm.py", line 106, in sample_solution
    message = self.query(session_messages)
              ^^^^^^^^^^^^^^^^^^^^^^^^^^^^
  File "/Users/macbook/Documents/Code/LLMdesignedEA-comp/llamea/llm.py", line 277, in query
    response = chat_session.send_message(last["content"])
               ^^^^^^^^^^^^^^^^^^^^^^^^^^^^^^^^^^^^^^^^^^
  File "/Users/macbook/miniconda3/envs/eoh/lib/python3.12/site-packages/google/generativeai/generative_models.py", line 578, in send_message
    response = self.model.generate_content(
               ^^^^^^^^^^^^^^^^^^^^^^^^^^^^
  File "/Users/macbook/miniconda3/envs/eoh/lib/python3.12/site-packages/google/generativeai/generative_models.py", line 331, in generate_content
    response = self._client.generate_content(
               ^^^^^^^^^^^^^^^^^^^^^^^^^^^^^^
  File "/Users/macbook/miniconda3/envs/eoh/lib/python3.12/site-packages/google/ai/generativelanguage_v1beta/services/generative_service/client.py", line 835, in generate_content
    response = rpc(
               ^^^^
  File "/Users/macbook/miniconda3/envs/eoh/lib/python3.12/site-packages/google/api_core/gapic_v1/method.py", line 131, in __call__
    return wrapped_func(*args, **kwargs)
           ^^^^^^^^^^^^^^^^^^^^^^^^^^^^^
  File "/Users/macbook/miniconda3/envs/eoh/lib/python3.12/site-packages/google/api_core/retry/retry_unary.py", line 294, in retry_wrapped_func
    return retry_target(
           ^^^^^^^^^^^^^
  File "/Users/macbook/miniconda3/envs/eoh/lib/python3.12/site-packages/google/api_core/retry/retry_unary.py", line 156, in retry_target
    next_sleep = _retry_error_helper(
                 ^^^^^^^^^^^^^^^^^^^^
  File "/Users/macbook/miniconda3/envs/eoh/lib/python3.12/site-packages/google/api_core/retry/retry_base.py", line 214, in _retry_error_helper
    raise final_exc from source_exc
  File "/Users/macbook/miniconda3/envs/eoh/lib/python3.12/site-packages/google/api_core/retry/retry_unary.py", line 147, in retry_target
    result = target()
             ^^^^^^^^
  File "/Users/macbook/miniconda3/envs/eoh/lib/python3.12/site-packages/google/api_core/timeout.py", line 130, in func_with_timeout
    return func(*args, **kwargs)
           ^^^^^^^^^^^^^^^^^^^^^
  File "/Users/macbook/miniconda3/envs/eoh/lib/python3.12/site-packages/google/api_core/grpc_helpers.py", line 78, in error_remapped_callable
    raise exceptions.from_grpc_error(exc) from exc
google.api_core.exceptions.ResourceExhausted: 429 You exceeded your current quota, please check your plan and billing details. For more information on this error, head to: https://ai.google.dev/gemini-api/docs/rate-limits. [violations {
  quota_metric: "generativelanguage.googleapis.com/generate_content_free_tier_requests"
  quota_id: "GenerateRequestsPerMinutePerProjectPerModel-FreeTier"
  quota_dimensions {
    key: "model"
    value: "gemini-1.5-flash"
  }
  quota_dimensions {
    key: "location"
    value: "global"
  }
  quota_value: 15
}
, links {
  description: "Learn more about Gemini API quotas"
  url: "https://ai.google.dev/gemini-api/docs/rate-limits"
}
, retry_delay {
  seconds: 58
}
]
.
2025-06-15 07:28:01 INFO An exception occured: Traceback (most recent call last):
  File "/Users/macbook/Documents/Code/LLMdesignedEA-comp/llamea/llamea_multi_prompts.py", line 367, in evolve_solution
    evolved_individual = self.llm.sample_solution(
                         ^^^^^^^^^^^^^^^^^^^^^^^^^
  File "/Users/macbook/Documents/Code/LLMdesignedEA-comp/llamea/llm.py", line 106, in sample_solution
    message = self.query(session_messages)
              ^^^^^^^^^^^^^^^^^^^^^^^^^^^^
  File "/Users/macbook/Documents/Code/LLMdesignedEA-comp/llamea/llm.py", line 277, in query
    response = chat_session.send_message(last["content"])
               ^^^^^^^^^^^^^^^^^^^^^^^^^^^^^^^^^^^^^^^^^^
  File "/Users/macbook/miniconda3/envs/eoh/lib/python3.12/site-packages/google/generativeai/generative_models.py", line 578, in send_message
    response = self.model.generate_content(
               ^^^^^^^^^^^^^^^^^^^^^^^^^^^^
  File "/Users/macbook/miniconda3/envs/eoh/lib/python3.12/site-packages/google/generativeai/generative_models.py", line 331, in generate_content
    response = self._client.generate_content(
               ^^^^^^^^^^^^^^^^^^^^^^^^^^^^^^
  File "/Users/macbook/miniconda3/envs/eoh/lib/python3.12/site-packages/google/ai/generativelanguage_v1beta/services/generative_service/client.py", line 835, in generate_content
    response = rpc(
               ^^^^
  File "/Users/macbook/miniconda3/envs/eoh/lib/python3.12/site-packages/google/api_core/gapic_v1/method.py", line 131, in __call__
    return wrapped_func(*args, **kwargs)
           ^^^^^^^^^^^^^^^^^^^^^^^^^^^^^
  File "/Users/macbook/miniconda3/envs/eoh/lib/python3.12/site-packages/google/api_core/retry/retry_unary.py", line 294, in retry_wrapped_func
    return retry_target(
           ^^^^^^^^^^^^^
  File "/Users/macbook/miniconda3/envs/eoh/lib/python3.12/site-packages/google/api_core/retry/retry_unary.py", line 156, in retry_target
    next_sleep = _retry_error_helper(
                 ^^^^^^^^^^^^^^^^^^^^
  File "/Users/macbook/miniconda3/envs/eoh/lib/python3.12/site-packages/google/api_core/retry/retry_base.py", line 214, in _retry_error_helper
    raise final_exc from source_exc
  File "/Users/macbook/miniconda3/envs/eoh/lib/python3.12/site-packages/google/api_core/retry/retry_unary.py", line 147, in retry_target
    result = target()
             ^^^^^^^^
  File "/Users/macbook/miniconda3/envs/eoh/lib/python3.12/site-packages/google/api_core/timeout.py", line 130, in func_with_timeout
    return func(*args, **kwargs)
           ^^^^^^^^^^^^^^^^^^^^^
  File "/Users/macbook/miniconda3/envs/eoh/lib/python3.12/site-packages/google/api_core/grpc_helpers.py", line 78, in error_remapped_callable
    raise exceptions.from_grpc_error(exc) from exc
google.api_core.exceptions.ResourceExhausted: 429 You exceeded your current quota, please check your plan and billing details. For more information on this error, head to: https://ai.google.dev/gemini-api/docs/rate-limits. [violations {
  quota_metric: "generativelanguage.googleapis.com/generate_content_free_tier_requests"
  quota_id: "GenerateRequestsPerMinutePerProjectPerModel-FreeTier"
  quota_dimensions {
    key: "model"
    value: "gemini-1.5-flash"
  }
  quota_dimensions {
    key: "location"
    value: "global"
  }
  quota_value: 15
}
, links {
  description: "Learn more about Gemini API quotas"
  url: "https://ai.google.dev/gemini-api/docs/rate-limits"
}
, retry_delay {
  seconds: 58
}
]
.
2025-06-15 07:28:01 INFO An exception occured: Traceback (most recent call last):
  File "/Users/macbook/Documents/Code/LLMdesignedEA-comp/llamea/llamea_multi_prompts.py", line 367, in evolve_solution
    evolved_individual = self.llm.sample_solution(
                         ^^^^^^^^^^^^^^^^^^^^^^^^^
  File "/Users/macbook/Documents/Code/LLMdesignedEA-comp/llamea/llm.py", line 106, in sample_solution
    message = self.query(session_messages)
              ^^^^^^^^^^^^^^^^^^^^^^^^^^^^
  File "/Users/macbook/Documents/Code/LLMdesignedEA-comp/llamea/llm.py", line 277, in query
    response = chat_session.send_message(last["content"])
               ^^^^^^^^^^^^^^^^^^^^^^^^^^^^^^^^^^^^^^^^^^
  File "/Users/macbook/miniconda3/envs/eoh/lib/python3.12/site-packages/google/generativeai/generative_models.py", line 578, in send_message
    response = self.model.generate_content(
               ^^^^^^^^^^^^^^^^^^^^^^^^^^^^
  File "/Users/macbook/miniconda3/envs/eoh/lib/python3.12/site-packages/google/generativeai/generative_models.py", line 331, in generate_content
    response = self._client.generate_content(
               ^^^^^^^^^^^^^^^^^^^^^^^^^^^^^^
  File "/Users/macbook/miniconda3/envs/eoh/lib/python3.12/site-packages/google/ai/generativelanguage_v1beta/services/generative_service/client.py", line 835, in generate_content
    response = rpc(
               ^^^^
  File "/Users/macbook/miniconda3/envs/eoh/lib/python3.12/site-packages/google/api_core/gapic_v1/method.py", line 131, in __call__
    return wrapped_func(*args, **kwargs)
           ^^^^^^^^^^^^^^^^^^^^^^^^^^^^^
  File "/Users/macbook/miniconda3/envs/eoh/lib/python3.12/site-packages/google/api_core/retry/retry_unary.py", line 294, in retry_wrapped_func
    return retry_target(
           ^^^^^^^^^^^^^
  File "/Users/macbook/miniconda3/envs/eoh/lib/python3.12/site-packages/google/api_core/retry/retry_unary.py", line 156, in retry_target
    next_sleep = _retry_error_helper(
                 ^^^^^^^^^^^^^^^^^^^^
  File "/Users/macbook/miniconda3/envs/eoh/lib/python3.12/site-packages/google/api_core/retry/retry_base.py", line 214, in _retry_error_helper
    raise final_exc from source_exc
  File "/Users/macbook/miniconda3/envs/eoh/lib/python3.12/site-packages/google/api_core/retry/retry_unary.py", line 147, in retry_target
    result = target()
             ^^^^^^^^
  File "/Users/macbook/miniconda3/envs/eoh/lib/python3.12/site-packages/google/api_core/timeout.py", line 130, in func_with_timeout
    return func(*args, **kwargs)
           ^^^^^^^^^^^^^^^^^^^^^
  File "/Users/macbook/miniconda3/envs/eoh/lib/python3.12/site-packages/google/api_core/grpc_helpers.py", line 78, in error_remapped_callable
    raise exceptions.from_grpc_error(exc) from exc
google.api_core.exceptions.ResourceExhausted: 429 You exceeded your current quota, please check your plan and billing details. For more information on this error, head to: https://ai.google.dev/gemini-api/docs/rate-limits. [violations {
  quota_metric: "generativelanguage.googleapis.com/generate_content_free_tier_requests"
  quota_id: "GenerateRequestsPerMinutePerProjectPerModel-FreeTier"
  quota_dimensions {
    key: "model"
    value: "gemini-1.5-flash"
  }
  quota_dimensions {
    key: "location"
    value: "global"
  }
  quota_value: 15
}
, links {
  description: "Learn more about Gemini API quotas"
  url: "https://ai.google.dev/gemini-api/docs/rate-limits"
}
, retry_delay {
  seconds: 58
}
]
.
